Workbook

Sheet Übersicht
A1: Übersicht Cashflow – SmartInfra / DuSL
A2: SmartInfra / DuSL · Juli 2026 – Dezember 2030
A3: Alle Werte werden automatisch aus dem Blatt „Cashflow“ übernommen.
A5: Kennzahl | B5: Betrag
A6: H2 2026 (Jul – Dez 2026)
A7: Einnahmen H2 2026 | B7: =Cashflow!BE76
A8: Ausgaben H2 2026 | B8: =Cashflow!BE77
A9: Netto-Cashflow H2 2026 | B9: =Cashflow!BE78
A10: Geschäftsjahr 2027
A11: Einnahmen 2027 | B11: =Cashflow!BF76
A12: Ausgaben 2027 | B12: =Cashflow!BF77
A13: Netto-Cashflow 2027 | B13: =Cashflow!BF78
A14: Geschäftsjahr 2028
A15: Einnahmen 2028 | B15: =Cashflow!BG76
A16: Ausgaben 2028 | B16: =Cashflow!BG77
A17: Netto-Cashflow 2028 | B17: =Cashflow!BG78
A18: Geschäftsjahr 2029
A19: Einnahmen 2029 | B19: =Cashflow!BH76
A20: Ausgaben 2029 | B20: =Cashflow!BH77
A21: Netto-Cashflow 2029 | B21: =Cashflow!BH78
A22: Geschäftsjahr 2030
A23: Einnahmen 2030 | B23: =Cashflow!BI76
A24: Ausgaben 2030 | B24: =Cashflow!BI77
A25: Netto-Cashflow 2030 | B25: =Cashflow!BI78
A26: Gesamtzeitraum (54 Monate)
A27: Gesamteinnahmen | B27: =Cashflow!BJ76
A28: Gesamtausgaben | B28: =Cashflow!BJ77
A29: Gesamt-Netto-Cashflow | B29: =Cashflow!BJ78

Sheet Cashflow
A1: Cashflow-Planung
A2: Bereich: SmartInfra / DuSL
A3: Zeitraum: Juli 2026 – Dezember 2027 (18 Monate, monatlich)
A4: Alle Beträge werden automatisch aus dem Reiter „Aufträge“ berechnet – im Cashflow werden nur Position und Kostenstelle (gelb) gepflegt.
C5: 46204 | D5: 46235 | E5: 46266 | F5: 46296 | G5: 46327 | H5: 46357 | I5: 46388 | J5: 46419 | K5: 46447 | L5: 46478 | M5: 46508 | N5: 46539 | O5: 46569 | P5: 46600 | Q5: 46631 | R5: 46661 | S5: 46692 | T5: 46722 | U5: 46753 | V5: 46784 | W5: 46813 | X5: 46844 | Y5: 46874 | Z5: 46905 | AA5: 46935 | AB5: 46966 | AC5: 46997 | AD5: 47027 | AE5: 47058 | AF5: 47088 | AG5: 47119 | AH5: 47150 | AI5: 47178 | AJ5: 47209 | AK5: 47239 | AL5: 47270 | AM5: 47300 | AN5: 47331 | AO5: 47362 | AP5: 47392 | AQ5: 47423 | AR5: 47453 | AS5: 47484 | AT5: 47515 | AU5: 47543 | AV5: 47574 | AW5: 47604 | AX5: 47635 | AY5: 47665 | AZ5: 47696 | BA5: 47727 | BB5: 47757 | BC5: 47788 | BD5: 47818
B6: Kostenstelle | C6: Jul 26 | D6: Aug 26 | E6: Sep 26 | F6: Okt 26 | G6: Nov 26 | H6: Dez 26 | I6: Jan 27 | J6: Feb 27 | K6: Mär 27 | L6: Apr 27 | M6: Mai 27 | N6: Jun 27 | O6: Jul 27 | P6: Aug 27 | Q6: Sep 27 | R6: Okt 27 | S6: Nov 27 | T6: Dez 27 | U6: Jan 28 | V6: Feb 28 | W6: Mär 28 | X6: Apr 28 | Y6: Mai 28 | Z6: Jun 28 | AA6: Jul 28 | AB6: Aug 28 | AC6: Sep 28 | AD6: Okt 28 | AE6: Nov 28 | AF6: Dez 28 | AG6: Jan 29 | AH6: Feb 29 | AI6: Mär 29 | AJ6: Apr 29 | AK6: Mai 29 | AL6: Jun 29 | AM6: Jul 29 | AN6: Aug 29 | AO6: Sep 29 | AP6: Okt 29 | AQ6: Nov 29 | AR6: Dez 29 | AS6: Jan 30 | AT6: Feb 30 | AU6: Mär 30 | AV6: Apr 30 | AW6: Mai 30 | AX6: Jun 30 | AY6: Jul 30 | AZ6: Aug 30 | BA6: Sep 30 | BB6: Okt 30 | BC6: Nov 30 | BD6: Dez 30 | BE6: Summe H2 2026 | BF6: Summe 2027 | BG6: Summe 2028 | BH6: Summe 2029 | BI6: Summe 2030 | BJ6: Gesamt
B7: 1 EINNAHMEN (Quelle: Reiter „Aufträge“) | C7: Jul 26 | D7: Aug 26 | E7: Sep 26 | F7: Okt 26 | G7: Nov 26 | H7: Dez 26 | I7: Jan 27 | J7: Feb 27 | K7: Mrz 27 | L7: Apr 27 | M7: Mai 27 | N7: Jun 27 | O7: Jul 27 | P7: Aug 27 | Q7: Sep 27 | R7: Okt 27 | S7: Nov 27 | T7: Dez 27 | U7: Jan 28 | V7: Feb 28 | W7: Mär 28 | X7: Apr 28 | Y7: Mai 28 | Z7: Jun 28 | AA7: Jul 28 | AB7: Aug 28 | AC7: Sep 28 | AD7: Okt 28 | AE7: Nov 28 | AF7: Dez 28 | AG7: Jan 29 | AH7: Feb 29 | AI7: Mär 29 | AJ7: Apr 29 | AK7: Mai 29 | AL7: Jun 29 | AM7: Jul 29 | AN7: Aug 29 | AO7: Sep 29 | AP7: Okt 29 | AQ7: Nov 29 | AR7: Dez 29 | AS7: Jan 30 | AT7: Feb 30 | AU7: Mär 30 | AV7: Apr 30 | AW7: Mai 30 | AX7: Jun 30 | AY7: Jul 30 | AZ7: Aug 30 | BA7: Sep 30 | BB7: Okt 30 | BC7: Nov 30 | BD7: Dez 30 | BE7: Summe H2 26 | BF7: Summe 27 | BG7: Summe 28 | BH7: Summe 29 | BI7: Summe 30 | BJ7: Gesamt
B8: 87001004 - Airbus | C8: =IF($B8="",0,SUMIFS(tblAuftraege[Kalk. Einnahmen],tblAuftraege[Datum Einnahmen],">="&C$5,tblAuftraege[Datum Einnahmen],"<"&EDATE(C$5,1),tblAuftraege[Kostenstelle],$B8)) | D8: =IF($B8="",0,SUMIFS(tblAuftraege[Kalk. Einnahmen],tblAuftraege[Datum Einnahmen],">="&D$5,tblAuftraege[Datum Einnahmen],"<"&EDATE(D$5,1),tblAuftraege[Kostenstelle],$B8)) | E8: =IF($B8="",0,SUMIFS(tblAuftraege[Kalk. Einnahmen],tblAuftraege[Datum Einnahmen],">="&E$5,tblAuftraege[Datum Einnahmen],"<"&EDATE(E$5,1),tblAuftraege[Kostenstelle],$B8)) | F8: =IF($B8="",0,SUMIFS(tblAuftraege[Kalk. Einnahmen],tblAuftraege[Datum Einnahmen],">="&F$5,tblAuftraege[Datum Einnahmen],"<"&EDATE(F$5,1),tblAuftraege[Kostenstelle],$B8)) | G8: =IF($B8="",0,SUMIFS(tblAuftraege[Kalk. Einnahmen],tblAuftraege[Datum Einnahmen],">="&G$5,tblAuftraege[Datum Einnahmen],"<"&EDATE(G$5,1),tblAuftraege[Kostenstelle],$B8)) | H8: =IF($B8="",0,SUMIFS(tblAuftraege[Kalk. Einnahmen],tblAuftraege[Datum Einnahmen],">="&H$5,tblAuftraege[Datum Einnahmen],"<"&EDATE(H$5,1),tblAuftraege[Kostenstelle],$B8)) | I8: =IF($B8="",0,SUMIFS(tblAuftraege[Kalk. Einnahmen],tblAuftraege[Datum Einnahmen],">="&I$5,tblAuftraege[Datum Einnahmen],"<"&EDATE(I$5,1),tblAuftraege[Kostenstelle],$B8)) | J8: =IF($B8="",0,SUMIFS(tblAuftraege[Kalk. Einnahmen],tblAuftraege[Datum Einnahmen],">="&J$5,tblAuftraege[Datum Einnahmen],"<"&EDATE(J$5,1),tblAuftraege[Kostenstelle],$B8)) | ... BD8: =IF($B8="",0,SUMIFS(tblAuftraege[Kalk. Einnahmen],tblAuftraege[Datum Einnahmen],">="&BD$5,tblAuftraege[Datum Einnahmen],"<"&EDATE(BD$5,1),tblAuftraege[Kostenstelle],$B8)) | BE8: =SUM(C8:H8) | BF8: =SUM(I8:T8) | BG8: =SUM(U8:AF8) | BH8: =SUM(AG8:AR8) | BI8: =SUM(AS8:BD8) | BJ8: =SUM(C8:BD8)
B9: 87001001 - Stadt Rendsburg | C9: =IF($B9="",0,SUMIFS(tblAuftraege[Kalk. Einnahmen],tblAuftraege[Datum Einnahmen],">="&C$5,tblAuftraege[Datum Einnahmen],"<"&EDATE(C$5,1),tblAuftraege[Kostenstelle],$B9)) | D9: =IF($B9="",0,SUMIFS(tblAuftraege[Kalk. Einnahmen],tblAuftraege[Datum Einnahmen],">="&D$5,tblAuftraege[Datum Einnahmen],"<"&EDATE(D$5,1),tblAuftraege[Kostenstelle],$B9)) | E9: =IF($B9="",0,SUMIFS(tblAuftraege[Kalk. Einnahmen],tblAuftraege[Datum Einnahmen],">="&E$5,tblAuftraege[Datum Einnahmen],"<"&EDATE(E$5,1),tblAuftraege[Kostenstelle],$B9)) | F9: =IF($B9="",0,SUMIFS(tblAuftraege[Kalk. Einnahmen],tblAuftraege[Datum Einnahmen],">="&F$5,tblAuftraege[Datum Einnahmen],"<"&EDATE(F$5,1),tblAuftraege[Kostenstelle],$B9)) | G9: =IF($B9="",0,SUMIFS(tblAuftraege[Kalk. Einnahmen],tblAuftraege[Datum Einnahmen],">="&G$5,tblAuftraege[Datum Einnahmen],"<"&EDATE(G$5,1),tblAuftraege[Kostenstelle],$B9)) | H9: =IF($B9="",0,SUMIFS(tblAuftraege[Kalk. Einnahmen],tblAuftraege[Datum Einnahmen],">="&H$5,tblAuftraege[Datum Einnahmen],"<"&EDATE(H$5,1),tblAuftraege[Kostenstelle],$B9)) | I9: =IF($B9="",0,SUMIFS(tblAuftraege[Kalk. Einnahmen],tblAuftraege[Datum Einnahmen],">="&I$5,tblAuftraege[Datum Einnahmen],"<"&EDATE(I$5,1),tblAuftraege[Kostenstelle],$B9)) | J9: =IF($B9="",0,SUMIFS(tblAuftraege[Kalk. Einnahmen],tblAuftraege[Datum Einnahmen],">="&J$5,tblAuftraege[Datum Einnahmen],"<"&EDATE(J$5,1),tblAuftraege[Kostenstelle],$B9)) | ... BD9: =IF($B9="",0,SUMIFS(tblAuftraege[Kalk. Einnahmen],tblAuftraege[Datum Einnahmen],">="&BD$5,tblAuftraege[Datum Einnahmen],"<"&EDATE(BD$5,1),tblAuftraege[Kostenstelle],$B9)) | BE9: =SUM(C9:H9) | BF9: =SUM(I9:T9) | BG9: =SUM(U9:AF9) | BH9: =SUM(AG9:AR9) | BI9: =SUM(AS9:BD9) | BJ9: =SUM(C9:BD9)
B10: 87001009 - Stadtwerke Husum | C10: =IF($B10="",0,SUMIFS(tblAuftraege[Kalk. Einnahmen],tblAuftraege[Datum Einnahmen],">="&C$5,tblAuftraege[Datum Einnahmen],"<"&EDATE(C$5,1),tblAuftraege[Kostenstelle],$B10)) | D10: =IF($B10="",0,SUMIFS(tblAuftraege[Kalk. Einnahmen],tblAuftraege[Datum Einnahmen],">="&D$5,tblAuftraege[Datum Einnahmen],"<"&EDATE(D$5,1),tblAuftraege[Kostenstelle],$B10)) | E10: =IF($B10="",0,SUMIFS(tblAuftraege[Kalk. Einnahmen],tblAuftraege[Datum Einnahmen],">="&E$5,tblAuftraege[Datum Einnahmen],"<"&EDATE(E$5,1),tblAuftraege[Kostenstelle],$B10)) | F10: =IF($B10="",0,SUMIFS(tblAuftraege[Kalk. Einnahmen],tblAuftraege[Datum Einnahmen],">="&F$5,tblAuftraege[Datum Einnahmen],"<"&EDATE(F$5,1),tblAuftraege[Kostenstelle],$B10)) | G10: =IF($B10="",0,SUMIFS(tblAuftraege[Kalk. Einnahmen],tblAuftraege[Datum Einnahmen],">="&G$5,tblAuftraege[Datum Einnahmen],"<"&EDATE(G$5,1),tblAuftraege[Kostenstelle],$B10)) | H10: =IF($B10="",0,SUMIFS(tblAuftraege[Kalk. Einnahmen],tblAuftraege[Datum Einnahmen],">="&H$5,tblAuftraege[Datum Einnahmen],"<"&EDATE(H$5,1),tblAuftraege[Kostenstelle],$B10)) | I10: =IF($B10="",0,SUMIFS(tblAuftraege[Kalk. Einnahmen],tblAuftraege[Datum Einnahmen],">="&I$5,tblAuftraege[Datum Einnahmen],"<"&EDATE(I$5,1),tblAuftraege[Kostenstelle],$B10)) | J10: =IF($B10="",0,SUMIFS(tblAuftraege[Kalk. Einnahmen],tblAuftraege[Datum Einnahmen],">="&J$5,tblAuftraege[Datum Einnahmen],"<"&EDATE(J$5,1),tblAuftraege[Kostenstelle],$B10)) | ... BD10: =IF($B10="",0,SUMIFS(tblAuftraege[Kalk. Einnahmen],tblAuftraege[Datum Einnahmen],">="&BD$5,tblAuftraege[Datum Einnahmen],"<"&EDATE(BD$5,1),tblAuftraege[Kostenstelle],$B10)) | BE10: =SUM(C10:H10) | BF10: =SUM(I10:T10) | BG10: =SUM(U10:AF10) | BH10: =SUM(AG10:AR10) | BI10: =SUM(AS10:BD10) | BJ10: =SUM(C10:BD10)
B11: 87001011 - Stadtwerke NMS | C11: =IF($B11="",0,SUMIFS(tblAuftraege[Kalk. Einnahmen],tblAuftraege[Datum Einnahmen],">="&C$5,tblAuftraege[Datum Einnahmen],"<"&EDATE(C$5,1),tblAuftraege[Kostenstelle],$B11)) | D11: =IF($B11="",0,SUMIFS(tblAuftraege[Kalk. Einnahmen],tblAuftraege[Datum Einnahmen],">="&D$5,tblAuftraege[Datum Einnahmen],"<"&EDATE(D$5,1),tblAuftraege[Kostenstelle],$B11)) | E11: =IF($B11="",0,SUMIFS(tblAuftraege[Kalk. Einnahmen],tblAuftraege[Datum Einnahmen],">="&E$5,tblAuftraege[Datum Einnahmen],"<"&EDATE(E$5,1),tblAuftraege[Kostenstelle],$B11)) | F11: =IF($B11="",0,SUMIFS(tblAuftraege[Kalk. Einnahmen],tblAuftraege[Datum Einnahmen],">="&F$5,tblAuftraege[Datum Einnahmen],"<"&EDATE(F$5,1),tblAuftraege[Kostenstelle],$B11)) | G11: =IF($B11="",0,SUMIFS(tblAuftraege[Kalk. Einnahmen],tblAuftraege[Datum Einnahmen],">="&G$5,tblAuftraege[Datum Einnahmen],"<"&EDATE(G$5,1),tblAuftraege[Kostenstelle],$B11)) | H11: =IF($B11="",0,SUMIFS(tblAuftraege[Kalk. Einnahmen],tblAuftraege[Datum Einnahmen],">="&H$5,tblAuftraege[Datum Einnahmen],"<"&EDATE(H$5,1),tblAuftraege[Kostenstelle],$B11)) | I11: =IF($B11="",0,SUMIFS(tblAuftraege[Kalk. Einnahmen],tblAuftraege[Datum Einnahmen],">="&I$5,tblAuftraege[Datum Einnahmen],"<"&EDATE(I$5,1),tblAuftraege[Kostenstelle],$B11)) | J11: =IF($B11="",0,SUMIFS(tblAuftraege[Kalk. Einnahmen],tblAuftraege[Datum Einnahmen],">="&J$5,tblAuftraege[Datum Einnahmen],"<"&EDATE(J$5,1),tblAuftraege[Kostenstelle],$B11)) | ... BD11: =IF($B11="",0,SUMIFS(tblAuftraege[Kalk. Einnahmen],tblAuftraege[Datum Einnahmen],">="&BD$5,tblAuftraege[Datum Einnahmen],"<"&EDATE(BD$5,1),tblAuftraege[Kostenstelle],$B11)) | BE11: =SUM(C11:H11) | BF11: =SUM(I11:T11) | BG11: =SUM(U11:AF11) | BH11: =SUM(AG11:AR11) | BI11: =SUM(AS11:BD11) | BJ11: =SUM(C11:BD11)
B12: 87002004 - Statdwerke Neustadt | C12: =IF($B12="",0,SUMIFS(tblAuftraege[Kalk. Einnahmen],tblAuftraege[Datum Einnahmen],">="&C$5,tblAuftraege[Datum Einnahmen],"<"&EDATE(C$5,1),tblAuftraege[Kostenstelle],$B12)) | D12: =IF($B12="",0,SUMIFS(tblAuftraege[Kalk. Einnahmen],tblAuftraege[Datum Einnahmen],">="&D$5,tblAuftraege[Datum Einnahmen],"<"&EDATE(D$5,1),tblAuftraege[Kostenstelle],$B12)) | E12: =IF($B12="",0,SUMIFS(tblAuftraege[Kalk. Einnahmen],tblAuftraege[Datum Einnahmen],">="&E$5,tblAuftraege[Datum Einnahmen],"<"&EDATE(E$5,1),tblAuftraege[Kostenstelle],$B12)) | F12: =IF($B12="",0,SUMIFS(tblAuftraege[Kalk. Einnahmen],tblAuftraege[Datum Einnahmen],">="&F$5,tblAuftraege[Datum Einnahmen],"<"&EDATE(F$5,1),tblAuftraege[Kostenstelle],$B12)) | G12: =IF($B12="",0,SUMIFS(tblAuftraege[Kalk. Einnahmen],tblAuftraege[Datum Einnahmen],">="&G$5,tblAuftraege[Datum Einnahmen],"<"&EDATE(G$5,1),tblAuftraege[Kostenstelle],$B12)) | H12: =IF($B12="",0,SUMIFS(tblAuftraege[Kalk. Einnahmen],tblAuftraege[Datum Einnahmen],">="&H$5,tblAuftraege[Datum Einnahmen],"<"&EDATE(H$5,1),tblAuftraege[Kostenstelle],$B12)) | I12: =IF($B12="",0,SUMIFS(tblAuftraege[Kalk. Einnahmen],tblAuftraege[Datum Einnahmen],">="&I$5,tblAuftraege[Datum Einnahmen],"<"&EDATE(I$5,1),tblAuftraege[Kostenstelle],$B12)) | J12: =IF($B12="",0,SUMIFS(tblAuftraege[Kalk. Einnahmen],tblAuftraege[Datum Einnahmen],">="&J$5,tblAuftraege[Datum Einnahmen],"<"&EDATE(J$5,1),tblAuftraege[Kostenstelle],$B12)) | ... BD12: =IF($B12="",0,SUMIFS(tblAuftraege[Kalk. Einnahmen],tblAuftraege[Datum Einnahmen],">="&BD$5,tblAuftraege[Datum Einnahmen],"<"&EDATE(BD$5,1),tblAuftraege[Kostenstelle],$B12)) | BE12: =SUM(C12:H12) | BF12: =SUM(I12:T12) | BG12: =SUM(U12:AF12) | BH12: =SUM(AG12:AR12) | BI12: =SUM(AS12:BD12) | BJ12: =SUM(C12:BD12)
B13: 87002007 - Schulbau Hamburg | C13: =IF($B13="",0,SUMIFS(tblAuftraege[Kalk. Einnahmen],tblAuftraege[Datum Einnahmen],">="&C$5,tblAuftraege[Datum Einnahmen],"<"&EDATE(C$5,1),tblAuftraege[Kostenstelle],$B13)) | D13: =IF($B13="",0,SUMIFS(tblAuftraege[Kalk. Einnahmen],tblAuftraege[Datum Einnahmen],">="&D$5,tblAuftraege[Datum Einnahmen],"<"&EDATE(D$5,1),tblAuftraege[Kostenstelle],$B13)) | E13: =IF($B13="",0,SUMIFS(tblAuftraege[Kalk. Einnahmen],tblAuftraege[Datum Einnahmen],">="&E$5,tblAuftraege[Datum Einnahmen],"<"&EDATE(E$5,1),tblAuftraege[Kostenstelle],$B13)) | F13: =IF($B13="",0,SUMIFS(tblAuftraege[Kalk. Einnahmen],tblAuftraege[Datum Einnahmen],">="&F$5,tblAuftraege[Datum Einnahmen],"<"&EDATE(F$5,1),tblAuftraege[Kostenstelle],$B13)) | G13: =IF($B13="",0,SUMIFS(tblAuftraege[Kalk. Einnahmen],tblAuftraege[Datum Einnahmen],">="&G$5,tblAuftraege[Datum Einnahmen],"<"&EDATE(G$5,1),tblAuftraege[Kostenstelle],$B13)) | H13: =IF($B13="",0,SUMIFS(tblAuftraege[Kalk. Einnahmen],tblAuftraege[Datum Einnahmen],">="&H$5,tblAuftraege[Datum Einnahmen],"<"&EDATE(H$5,1),tblAuftraege[Kostenstelle],$B13)) | I13: =IF($B13="",0,SUMIFS(tblAuftraege[Kalk. Einnahmen],tblAuftraege[Datum Einnahmen],">="&I$5,tblAuftraege[Datum Einnahmen],"<"&EDATE(I$5,1),tblAuftraege[Kostenstelle],$B13)) | J13: =IF($B13="",0,SUMIFS(tblAuftraege[Kalk. Einnahmen],tblAuftraege[Datum Einnahmen],">="&J$5,tblAuftraege[Datum Einnahmen],"<"&EDATE(J$5,1),tblAuftraege[Kostenstelle],$B13)) | ... BD13: =IF($B13="",0,SUMIFS(tblAuftraege[Kalk. Einnahmen],tblAuftraege[Datum Einnahmen],">="&BD$5,tblAuftraege[Datum Einnahmen],"<"&EDATE(BD$5,1),tblAuftraege[Kostenstelle],$B13)) | BE13: =SUM(C13:H13) | BF13: =SUM(I13:T13) | BG13: =SUM(U13:AF13) | BH13: =SUM(AG13:AR13) | BI13: =SUM(AS13:BD13) | BJ13: =SUM(C13:BD13)
B14: 87002011 - Bayernwerk | C14: =IF($B14="",0,SUMIFS(tblAuftraege[Kalk. Einnahmen],tblAuftraege[Datum Einnahmen],">="&C$5,tblAuftraege[Datum Einnahmen],"<"&EDATE(C$5,1),tblAuftraege[Kostenstelle],$B14)) | D14: =IF($B14="",0,SUMIFS(tblAuftraege[Kalk. Einnahmen],tblAuftraege[Datum Einnahmen],">="&D$5,tblAuftraege[Datum Einnahmen],"<"&EDATE(D$5,1),tblAuftraege[Kostenstelle],$B14)) | E14: =IF($B14="",0,SUMIFS(tblAuftraege[Kalk. Einnahmen],tblAuftraege[Datum Einnahmen],">="&E$5,tblAuftraege[Datum Einnahmen],"<"&EDATE(E$5,1),tblAuftraege[Kostenstelle],$B14)) | F14: =IF($B14="",0,SUMIFS(tblAuftraege[Kalk. Einnahmen],tblAuftraege[Datum Einnahmen],">="&F$5,tblAuftraege[Datum Einnahmen],"<"&EDATE(F$5,1),tblAuftraege[Kostenstelle],$B14)) | G14: =IF($B14="",0,SUMIFS(tblAuftraege[Kalk. Einnahmen],tblAuftraege[Datum Einnahmen],">="&G$5,tblAuftraege[Datum Einnahmen],"<"&EDATE(G$5,1),tblAuftraege[Kostenstelle],$B14)) | H14: =IF($B14="",0,SUMIFS(tblAuftraege[Kalk. Einnahmen],tblAuftraege[Datum Einnahmen],">="&H$5,tblAuftraege[Datum Einnahmen],"<"&EDATE(H$5,1),tblAuftraege[Kostenstelle],$B14)) | I14: =IF($B14="",0,SUMIFS(tblAuftraege[Kalk. Einnahmen],tblAuftraege[Datum Einnahmen],">="&I$5,tblAuftraege[Datum Einnahmen],"<"&EDATE(I$5,1),tblAuftraege[Kostenstelle],$B14)) | J14: =IF($B14="",0,SUMIFS(tblAuftraege[Kalk. Einnahmen],tblAuftraege[Datum Einnahmen],">="&J$5,tblAuftraege[Datum Einnahmen],"<"&EDATE(J$5,1),tblAuftraege[Kostenstelle],$B14)) | ... BD14: =IF($B14="",0,SUMIFS(tblAuftraege[Kalk. Einnahmen],tblAuftraege[Datum Einnahmen],">="&BD$5,tblAuftraege[Datum Einnahmen],"<"&EDATE(BD$5,1),tblAuftraege[Kostenstelle],$B14)) | BE14: =SUM(C14:H14) | BF14: =SUM(I14:T14) | BG14: =SUM(U14:AF14) | BH14: =SUM(AG14:AR14) | BI14: =SUM(AS14:BD14) | BJ14: =SUM(C14:BD14)
B15: 87003001 - Stadtwerke Rendsburg | C15: =IF($B15="",0,SUMIFS(tblAuftraege[Kalk. Einnahmen],tblAuftraege[Datum Einnahmen],">="&C$5,tblAuftraege[Datum Einnahmen],"<"&EDATE(C$5,1),tblAuftraege[Kostenstelle],$B15)) | D15: =IF($B15="",0,SUMIFS(tblAuftraege[Kalk. Einnahmen],tblAuftraege[Datum Einnahmen],">="&D$5,tblAuftraege[Datum Einnahmen],"<"&EDATE(D$5,1),tblAuftraege[Kostenstelle],$B15)) | E15: =IF($B15="",0,SUMIFS(tblAuftraege[Kalk. Einnahmen],tblAuftraege[Datum Einnahmen],">="&E$5,tblAuftraege[Datum Einnahmen],"<"&EDATE(E$5,1),tblAuftraege[Kostenstelle],$B15)) | F15: =IF($B15="",0,SUMIFS(tblAuftraege[Kalk. Einnahmen],tblAuftraege[Datum Einnahmen],">="&F$5,tblAuftraege[Datum Einnahmen],"<"&EDATE(F$5,1),tblAuftraege[Kostenstelle],$B15)) | G15: =IF($B15="",0,SUMIFS(tblAuftraege[Kalk. Einnahmen],tblAuftraege[Datum Einnahmen],">="&G$5,tblAuftraege[Datum Einnahmen],"<"&EDATE(G$5,1),tblAuftraege[Kostenstelle],$B15)) | H15: =IF($B15="",0,SUMIFS(tblAuftraege[Kalk. Einnahmen],tblAuftraege[Datum Einnahmen],">="&H$5,tblAuftraege[Datum Einnahmen],"<"&EDATE(H$5,1),tblAuftraege[Kostenstelle],$B15)) | I15: =IF($B15="",0,SUMIFS(tblAuftraege[Kalk. Einnahmen],tblAuftraege[Datum Einnahmen],">="&I$5,tblAuftraege[Datum Einnahmen],"<"&EDATE(I$5,1),tblAuftraege[Kostenstelle],$B15)) | J15: =IF($B15="",0,SUMIFS(tblAuftraege[Kalk. Einnahmen],tblAuftraege[Datum Einnahmen],">="&J$5,tblAuftraege[Datum Einnahmen],"<"&EDATE(J$5,1),tblAuftraege[Kostenstelle],$B15)) | ... BD15: =IF($B15="",0,SUMIFS(tblAuftraege[Kalk. Einnahmen],tblAuftraege[Datum Einnahmen],">="&BD$5,tblAuftraege[Datum Einnahmen],"<"&EDATE(BD$5,1),tblAuftraege[Kostenstelle],$B15)) | BE15: =SUM(C15:H15) | BF15: =SUM(I15:T15) | BG15: =SUM(U15:AF15) | BH15: =SUM(AG15:AR15) | BI15: =SUM(AS15:BD15) | BJ15: =SUM(C15:BD15)
B16: 87004001 - Dataport | C16: =IF($B16="",0,SUMIFS(tblAuftraege[Kalk. Einnahmen],tblAuftraege[Datum Einnahmen],">="&C$5,tblAuftraege[Datum Einnahmen],"<"&EDATE(C$5,1),tblAuftraege[Kostenstelle],$B16)) | D16: =IF($B16="",0,SUMIFS(tblAuftraege[Kalk. Einnahmen],tblAuftraege[Datum Einnahmen],">="&D$5,tblAuftraege[Datum Einnahmen],"<"&EDATE(D$5,1),tblAuftraege[Kostenstelle],$B16)) | E16: =IF($B16="",0,SUMIFS(tblAuftraege[Kalk. Einnahmen],tblAuftraege[Datum Einnahmen],">="&E$5,tblAuftraege[Datum Einnahmen],"<"&EDATE(E$5,1),tblAuftraege[Kostenstelle],$B16)) | F16: =IF($B16="",0,SUMIFS(tblAuftraege[Kalk. Einnahmen],tblAuftraege[Datum Einnahmen],">="&F$5,tblAuftraege[Datum Einnahmen],"<"&EDATE(F$5,1),tblAuftraege[Kostenstelle],$B16)) | G16: =IF($B16="",0,SUMIFS(tblAuftraege[Kalk. Einnahmen],tblAuftraege[Datum Einnahmen],">="&G$5,tblAuftraege[Datum Einnahmen],"<"&EDATE(G$5,1),tblAuftraege[Kostenstelle],$B16)) | H16: =IF($B16="",0,SUMIFS(tblAuftraege[Kalk. Einnahmen],tblAuftraege[Datum Einnahmen],">="&H$5,tblAuftraege[Datum Einnahmen],"<"&EDATE(H$5,1),tblAuftraege[Kostenstelle],$B16)) | I16: =IF($B16="",0,SUMIFS(tblAuftraege[Kalk. Einnahmen],tblAuftraege[Datum Einnahmen],">="&I$5,tblAuftraege[Datum Einnahmen],"<"&EDATE(I$5,1),tblAuftraege[Kostenstelle],$B16)) | J16: =IF($B16="",0,SUMIFS(tblAuftraege[Kalk. Einnahmen],tblAuftraege[Datum Einnahmen],">="&J$5,tblAuftraege[Datum Einnahmen],"<"&EDATE(J$5,1),tblAuftraege[Kostenstelle],$B16)) | ... BD16: =IF($B16="",0,SUMIFS(tblAuftraege[Kalk. Einnahmen],tblAuftraege[Datum Einnahmen],">="&BD$5,tblAuftraege[Datum Einnahmen],"<"&EDATE(BD$5,1),tblAuftraege[Kostenstelle],$B16)) | BE16: =SUM(C16:H16) | BF16: =SUM(I16:T16) | BG16: =SUM(U16:AF16) | BH16: =SUM(AG16:AR16) | BI16: =SUM(AS16:BD16) | BJ16: =SUM(C16:BD16)
B17: 87004006 - Autostrom PKW | C17: =IF($B17="",0,SUMIFS(tblAuftraege[Kalk. Einnahmen],tblAuftraege[Datum Einnahmen],">="&C$5,tblAuftraege[Datum Einnahmen],"<"&EDATE(C$5,1),tblAuftraege[Kostenstelle],$B17)) | D17: =IF($B17="",0,SUMIFS(tblAuftraege[Kalk. Einnahmen],tblAuftraege[Datum Einnahmen],">="&D$5,tblAuftraege[Datum Einnahmen],"<"&EDATE(D$5,1),tblAuftraege[Kostenstelle],$B17)) | E17: =IF($B17="",0,SUMIFS(tblAuftraege[Kalk. Einnahmen],tblAuftraege[Datum Einnahmen],">="&E$5,tblAuftraege[Datum Einnahmen],"<"&EDATE(E$5,1),tblAuftraege[Kostenstelle],$B17)) | F17: =IF($B17="",0,SUMIFS(tblAuftraege[Kalk. Einnahmen],tblAuftraege[Datum Einnahmen],">="&F$5,tblAuftraege[Datum Einnahmen],"<"&EDATE(F$5,1),tblAuftraege[Kostenstelle],$B17)) | G17: =IF($B17="",0,SUMIFS(tblAuftraege[Kalk. Einnahmen],tblAuftraege[Datum Einnahmen],">="&G$5,tblAuftraege[Datum Einnahmen],"<"&EDATE(G$5,1),tblAuftraege[Kostenstelle],$B17)) | H17: =IF($B17="",0,SUMIFS(tblAuftraege[Kalk. Einnahmen],tblAuftraege[Datum Einnahmen],">="&H$5,tblAuftraege[Datum Einnahmen],"<"&EDATE(H$5,1),tblAuftraege[Kostenstelle],$B17)) | I17: =IF($B17="",0,SUMIFS(tblAuftraege[Kalk. Einnahmen],tblAuftraege[Datum Einnahmen],">="&I$5,tblAuftraege[Datum Einnahmen],"<"&EDATE(I$5,1),tblAuftraege[Kostenstelle],$B17)) | J17: =IF($B17="",0,SUMIFS(tblAuftraege[Kalk. Einnahmen],tblAuftraege[Datum Einnahmen],">="&J$5,tblAuftraege[Datum Einnahmen],"<"&EDATE(J$5,1),tblAuftraege[Kostenstelle],$B17)) | ... BD17: =IF($B17="",0,SUMIFS(tblAuftraege[Kalk. Einnahmen],tblAuftraege[Datum Einnahmen],">="&BD$5,tblAuftraege[Datum Einnahmen],"<"&EDATE(BD$5,1),tblAuftraege[Kostenstelle],$B17)) | BE17: =SUM(C17:H17) | BF17: =SUM(I17:T17) | BG17: =SUM(U17:AF17) | BH17: =SUM(AG17:AR17) | BI17: =SUM(AS17:BD17) | BJ17: =SUM(C17:BD17)
B18: 87105002 - eWerk Sachsenwald | C18: =IF($B18="",0,SUMIFS(tblAuftraege[Kalk. Einnahmen],tblAuftraege[Datum Einnahmen],">="&C$5,tblAuftraege[Datum Einnahmen],"<"&EDATE(C$5,1),tblAuftraege[Kostenstelle],$B18)) | D18: =IF($B18="",0,SUMIFS(tblAuftraege[Kalk. Einnahmen],tblAuftraege[Datum Einnahmen],">="&D$5,tblAuftraege[Datum Einnahmen],"<"&EDATE(D$5,1),tblAuftraege[Kostenstelle],$B18)) | E18: =IF($B18="",0,SUMIFS(tblAuftraege[Kalk. Einnahmen],tblAuftraege[Datum Einnahmen],">="&E$5,tblAuftraege[Datum Einnahmen],"<"&EDATE(E$5,1),tblAuftraege[Kostenstelle],$B18)) | F18: =IF($B18="",0,SUMIFS(tblAuftraege[Kalk. Einnahmen],tblAuftraege[Datum Einnahmen],">="&F$5,tblAuftraege[Datum Einnahmen],"<"&EDATE(F$5,1),tblAuftraege[Kostenstelle],$B18)) | G18: =IF($B18="",0,SUMIFS(tblAuftraege[Kalk. Einnahmen],tblAuftraege[Datum Einnahmen],">="&G$5,tblAuftraege[Datum Einnahmen],"<"&EDATE(G$5,1),tblAuftraege[Kostenstelle],$B18)) | H18: =IF($B18="",0,SUMIFS(tblAuftraege[Kalk. Einnahmen],tblAuftraege[Datum Einnahmen],">="&H$5,tblAuftraege[Datum Einnahmen],"<"&EDATE(H$5,1),tblAuftraege[Kostenstelle],$B18)) | I18: =IF($B18="",0,SUMIFS(tblAuftraege[Kalk. Einnahmen],tblAuftraege[Datum Einnahmen],">="&I$5,tblAuftraege[Datum Einnahmen],"<"&EDATE(I$5,1),tblAuftraege[Kostenstelle],$B18)) | J18: =IF($B18="",0,SUMIFS(tblAuftraege[Kalk. Einnahmen],tblAuftraege[Datum Einnahmen],">="&J$5,tblAuftraege[Datum Einnahmen],"<"&EDATE(J$5,1),tblAuftraege[Kostenstelle],$B18)) | ... BD18: =IF($B18="",0,SUMIFS(tblAuftraege[Kalk. Einnahmen],tblAuftraege[Datum Einnahmen],">="&BD$5,tblAuftraege[Datum Einnahmen],"<"&EDATE(BD$5,1),tblAuftraege[Kostenstelle],$B18)) | BE18: =SUM(C18:H18) | BF18: =SUM(I18:T18) | BG18: =SUM(U18:AF18) | BH18: =SUM(AG18:AR18) | BI18: =SUM(AS18:BD18) | BJ18: =SUM(C18:BD18)
B19: 87105003 - HNE Allgemein | C19: =IF($B19="",0,SUMIFS(tblAuftraege[Kalk. Einnahmen],tblAuftraege[Datum Einnahmen],">="&C$5,tblAuftraege[Datum Einnahmen],"<"&EDATE(C$5,1),tblAuftraege[Kostenstelle],$B19)) | D19: =IF($B19="",0,SUMIFS(tblAuftraege[Kalk. Einnahmen],tblAuftraege[Datum Einnahmen],">="&D$5,tblAuftraege[Datum Einnahmen],"<"&EDATE(D$5,1),tblAuftraege[Kostenstelle],$B19)) | E19: =IF($B19="",0,SUMIFS(tblAuftraege[Kalk. Einnahmen],tblAuftraege[Datum Einnahmen],">="&E$5,tblAuftraege[Datum Einnahmen],"<"&EDATE(E$5,1),tblAuftraege[Kostenstelle],$B19)) | F19: =IF($B19="",0,SUMIFS(tblAuftraege[Kalk. Einnahmen],tblAuftraege[Datum Einnahmen],">="&F$5,tblAuftraege[Datum Einnahmen],"<"&EDATE(F$5,1),tblAuftraege[Kostenstelle],$B19)) | G19: =IF($B19="",0,SUMIFS(tblAuftraege[Kalk. Einnahmen],tblAuftraege[Datum Einnahmen],">="&G$5,tblAuftraege[Datum Einnahmen],"<"&EDATE(G$5,1),tblAuftraege[Kostenstelle],$B19)) | H19: =IF($B19="",0,SUMIFS(tblAuftraege[Kalk. Einnahmen],tblAuftraege[Datum Einnahmen],">="&H$5,tblAuftraege[Datum Einnahmen],"<"&EDATE(H$5,1),tblAuftraege[Kostenstelle],$B19)) | I19: =IF($B19="",0,SUMIFS(tblAuftraege[Kalk. Einnahmen],tblAuftraege[Datum Einnahmen],">="&I$5,tblAuftraege[Datum Einnahmen],"<"&EDATE(I$5,1),tblAuftraege[Kostenstelle],$B19)) | J19: =IF($B19="",0,SUMIFS(tblAuftraege[Kalk. Einnahmen],tblAuftraege[Datum Einnahmen],">="&J$5,tblAuftraege[Datum Einnahmen],"<"&EDATE(J$5,1),tblAuftraege[Kostenstelle],$B19)) | ... BD19: =IF($B19="",0,SUMIFS(tblAuftraege[Kalk. Einnahmen],tblAuftraege[Datum Einnahmen],">="&BD$5,tblAuftraege[Datum Einnahmen],"<"&EDATE(BD$5,1),tblAuftraege[Kostenstelle],$B19)) | BE19: =SUM(C19:H19) | BF19: =SUM(I19:T19) | BG19: =SUM(U19:AF19) | BH19: =SUM(AG19:AR19) | BI19: =SUM(AS19:BD19) | BJ19: =SUM(C19:BD19)
... B24: 85109000 - Bereichskostenstelle IoT | C24: =IF($B24="",0,SUMIFS(tblAuftraege[Kalk. Einnahmen],tblAuftraege[Datum Einnahmen],">="&C$5,tblAuftraege[Datum Einnahmen],"<"&EDATE(C$5,1),tblAuftraege[Kostenstelle],$B24)) | D24: =IF($B24="",0,SUMIFS(tblAuftraege[Kalk. Einnahmen],tblAuftraege[Datum Einnahmen],">="&D$5,tblAuftraege[Datum Einnahmen],"<"&EDATE(D$5,1),tblAuftraege[Kostenstelle],$B24)) | E24: =IF($B24="",0,SUMIFS(tblAuftraege[Kalk. Einnahmen],tblAuftraege[Datum Einnahmen],">="&E$5,tblAuftraege[Datum Einnahmen],"<"&EDATE(E$5,1),tblAuftraege[Kostenstelle],$B24)) | F24: =IF($B24="",0,SUMIFS(tblAuftraege[Kalk. Einnahmen],tblAuftraege[Datum Einnahmen],">="&F$5,tblAuftraege[Datum Einnahmen],"<"&EDATE(F$5,1),tblAuftraege[Kostenstelle],$B24)) | G24: =IF($B24="",0,SUMIFS(tblAuftraege[Kalk. Einnahmen],tblAuftraege[Datum Einnahmen],">="&G$5,tblAuftraege[Datum Einnahmen],"<"&EDATE(G$5,1),tblAuftraege[Kostenstelle],$B24)) | H24: =IF($B24="",0,SUMIFS(tblAuftraege[Kalk. Einnahmen],tblAuftraege[Datum Einnahmen],">="&H$5,tblAuftraege[Datum Einnahmen],"<"&EDATE(H$5,1),tblAuftraege[Kostenstelle],$B24)) | I24: =IF($B24="",0,SUMIFS(tblAuftraege[Kalk. Einnahmen],tblAuftraege[Datum Einnahmen],">="&I$5,tblAuftraege[Datum Einnahmen],"<"&EDATE(I$5,1),tblAuftraege[Kostenstelle],$B24)) | J24: =IF($B24="",0,SUMIFS(tblAuftraege[Kalk. Einnahmen],tblAuftraege[Datum Einnahmen],">="&J$5,tblAuftraege[Datum Einnahmen],"<"&EDATE(J$5,1),tblAuftraege[Kostenstelle],$B24)) | ... BD24: =IF($B24="",0,SUMIFS(tblAuftraege[Kalk. Einnahmen],tblAuftraege[Datum Einnahmen],">="&BD$5,tblAuftraege[Datum Einnahmen],"<"&EDATE(BD$5,1),tblAuftraege[Kostenstelle],$B24)) | BE24: =SUM(C24:H24) | BF24: =SUM(I24:T24) | BG24: =SUM(U24:AF24) | BH24: =SUM(AG24:AR24) | BI24: =SUM(AS24:BD24) | BJ24: =SUM(C24:BD24)
C25: =IF($B25="",0,SUMIFS(tblAuftraege[Kalk. Einnahmen],tblAuftraege[Datum Einnahmen],">="&C$5,tblAuftraege[Datum Einnahmen],"<"&EDATE(C$5,1),tblAuftraege[Kostenstelle],$B25)) | D25: =IF($B25="",0,SUMIFS(tblAuftraege[Kalk. Einnahmen],tblAuftraege[Datum Einnahmen],">="&D$5,tblAuftraege[Datum Einnahmen],"<"&EDATE(D$5,1),tblAuftraege[Kostenstelle],$B25)) | E25: =IF($B25="",0,SUMIFS(tblAuftraege[Kalk. Einnahmen],tblAuftraege[Datum Einnahmen],">="&E$5,tblAuftraege[Datum Einnahmen],"<"&EDATE(E$5,1),tblAuftraege[Kostenstelle],$B25)) | F25: =IF($B25="",0,SUMIFS(tblAuftraege[Kalk. Einnahmen],tblAuftraege[Datum Einnahmen],">="&F$5,tblAuftraege[Datum Einnahmen],"<"&EDATE(F$5,1),tblAuftraege[Kostenstelle],$B25)) | G25: =IF($B25="",0,SUMIFS(tblAuftraege[Kalk. Einnahmen],tblAuftraege[Datum Einnahmen],">="&G$5,tblAuftraege[Datum Einnahmen],"<"&EDATE(G$5,1),tblAuftraege[Kostenstelle],$B25)) | H25: =IF($B25="",0,SUMIFS(tblAuftraege[Kalk. Einnahmen],tblAuftraege[Datum Einnahmen],">="&H$5,tblAuftraege[Datum Einnahmen],"<"&EDATE(H$5,1),tblAuftraege[Kostenstelle],$B25)) | I25: =IF($B25="",0,SUMIFS(tblAuftraege[Kalk. Einnahmen],tblAuftraege[Datum Einnahmen],">="&I$5,tblAuftraege[Datum Einnahmen],"<"&EDATE(I$5,1),tblAuftraege[Kostenstelle],$B25)) | J25: =IF($B25="",0,SUMIFS(tblAuftraege[Kalk. Einnahmen],tblAuftraege[Datum Einnahmen],">="&J$5,tblAuftraege[Datum Einnahmen],"<"&EDATE(J$5,1),tblAuftraege[Kostenstelle],$B25)) | ... BD25: =IF($B25="",0,SUMIFS(tblAuftraege[Kalk. Einnahmen],tblAuftraege[Datum Einnahmen],">="&BD$5,tblAuftraege[Datum Einnahmen],"<"&EDATE(BD$5,1),tblAuftraege[Kostenstelle],$B25)) | BE25: =SUM(C25:H25) | BF25: =SUM(I25:T25) | BG25: =SUM(U25:AF25) | BH25: =SUM(AG25:AR25) | BI25: =SUM(AS25:BD25) | BJ25: =SUM(C25:BD25)
C26: =IF($B26="",0,SUMIFS(tblAuftraege[Kalk. Einnahmen],tblAuftraege[Datum Einnahmen],">="&C$5,tblAuftraege[Datum Einnahmen],"<"&EDATE(C$5,1),tblAuftraege[Kostenstelle],$B26)) | D26: =IF($B26="",0,SUMIFS(tblAuftraege[Kalk. Einnahmen],tblAuftraege[Datum Einnahmen],">="&D$5,tblAuftraege[Datum Einnahmen],"<"&EDATE(D$5,1),tblAuftraege[Kostenstelle],$B26)) | E26: =IF($B26="",0,SUMIFS(tblAuftraege[Kalk. Einnahmen],tblAuftraege[Datum Einnahmen],">="&E$5,tblAuftraege[Datum Einnahmen],"<"&EDATE(E$5,1),tblAuftraege[Kostenstelle],$B26)) | F26: =IF($B26="",0,SUMIFS(tblAuftraege[Kalk. Einnahmen],tblAuftraege[Datum Einnahmen],">="&F$5,tblAuftraege[Datum Einnahmen],"<"&EDATE(F$5,1),tblAuftraege[Kostenstelle],$B26)) | G26: =IF($B26="",0,SUMIFS(tblAuftraege[Kalk. Einnahmen],tblAuftraege[Datum Einnahmen],">="&G$5,tblAuftraege[Datum Einnahmen],"<"&EDATE(G$5,1),tblAuftraege[Kostenstelle],$B26)) | H26: =IF($B26="",0,SUMIFS(tblAuftraege[Kalk. Einnahmen],tblAuftraege[Datum Einnahmen],">="&H$5,tblAuftraege[Datum Einnahmen],"<"&EDATE(H$5,1),tblAuftraege[Kostenstelle],$B26)) | I26: =IF($B26="",0,SUMIFS(tblAuftraege[Kalk. Einnahmen],tblAuftraege[Datum Einnahmen],">="&I$5,tblAuftraege[Datum Einnahmen],"<"&EDATE(I$5,1),tblAuftraege[Kostenstelle],$B26)) | J26: =IF($B26="",0,SUMIFS(tblAuftraege[Kalk. Einnahmen],tblAuftraege[Datum Einnahmen],">="&J$5,tblAuftraege[Datum Einnahmen],"<"&EDATE(J$5,1),tblAuftraege[Kostenstelle],$B26)) | ... BD26: =IF($B26="",0,SUMIFS(tblAuftraege[Kalk. Einnahmen],tblAuftraege[Datum Einnahmen],">="&BD$5,tblAuftraege[Datum Einnahmen],"<"&EDATE(BD$5,1),tblAuftraege[Kostenstelle],$B26)) | BE26: =SUM(C26:H26) | BF26: =SUM(I26:T26) | BG26: =SUM(U26:AF26) | BH26: =SUM(AG26:AR26) | BI26: =SUM(AS26:BD26) | BJ26: =SUM(C26:BD26)
C27: =IF($B27="",0,SUMIFS(tblAuftraege[Kalk. Einnahmen],tblAuftraege[Datum Einnahmen],">="&C$5,tblAuftraege[Datum Einnahmen],"<"&EDATE(C$5,1),tblAuftraege[Kostenstelle],$B27)) | D27: =IF($B27="",0,SUMIFS(tblAuftraege[Kalk. Einnahmen],tblAuftraege[Datum Einnahmen],">="&D$5,tblAuftraege[Datum Einnahmen],"<"&EDATE(D$5,1),tblAuftraege[Kostenstelle],$B27)) | E27: =IF($B27="",0,SUMIFS(tblAuftraege[Kalk. Einnahmen],tblAuftraege[Datum Einnahmen],">="&E$5,tblAuftraege[Datum Einnahmen],"<"&EDATE(E$5,1),tblAuftraege[Kostenstelle],$B27)) | F27: =IF($B27="",0,SUMIFS(tblAuftraege[Kalk. Einnahmen],tblAuftraege[Datum Einnahmen],">="&F$5,tblAuftraege[Datum Einnahmen],"<"&EDATE(F$5,1),tblAuftraege[Kostenstelle],$B27)) | G27: =IF($B27="",0,SUMIFS(tblAuftraege[Kalk. Einnahmen],tblAuftraege[Datum Einnahmen],">="&G$5,tblAuftraege[Datum Einnahmen],"<"&EDATE(G$5,1),tblAuftraege[Kostenstelle],$B27)) | H27: =IF($B27="",0,SUMIFS(tblAuftraege[Kalk. Einnahmen],tblAuftraege[Datum Einnahmen],">="&H$5,tblAuftraege[Datum Einnahmen],"<"&EDATE(H$5,1),tblAuftraege[Kostenstelle],$B27)) | I27: =IF($B27="",0,SUMIFS(tblAuftraege[Kalk. Einnahmen],tblAuftraege[Datum Einnahmen],">="&I$5,tblAuftraege[Datum Einnahmen],"<"&EDATE(I$5,1),tblAuftraege[Kostenstelle],$B27)) | J27: =IF($B27="",0,SUMIFS(tblAuftraege[Kalk. Einnahmen],tblAuftraege[Datum Einnahmen],">="&J$5,tblAuftraege[Datum Einnahmen],"<"&EDATE(J$5,1),tblAuftraege[Kostenstelle],$B27)) | ... BD27: =IF($B27="",0,SUMIFS(tblAuftraege[Kalk. Einnahmen],tblAuftraege[Datum Einnahmen],">="&BD$5,tblAuftraege[Datum Einnahmen],"<"&EDATE(BD$5,1),tblAuftraege[Kostenstelle],$B27)) | BE27: =SUM(C27:H27) | BF27: =SUM(I27:T27) | BG27: =SUM(U27:AF27) | BH27: =SUM(AG27:AR27) | BI27: =SUM(AS27:BD27) | BJ27: =SUM(C27:BD27)
C28: =IF($B28="",0,SUMIFS(tblAuftraege[Kalk. Einnahmen],tblAuftraege[Datum Einnahmen],">="&C$5,tblAuftraege[Datum Einnahmen],"<"&EDATE(C$5,1),tblAuftraege[Kostenstelle],$B28)) | D28: =IF($B28="",0,SUMIFS(tblAuftraege[Kalk. Einnahmen],tblAuftraege[Datum Einnahmen],">="&D$5,tblAuftraege[Datum Einnahmen],"<"&EDATE(D$5,1),tblAuftraege[Kostenstelle],$B28)) | E28: =IF($B28="",0,SUMIFS(tblAuftraege[Kalk. Einnahmen],tblAuftraege[Datum Einnahmen],">="&E$5,tblAuftraege[Datum Einnahmen],"<"&EDATE(E$5,1),tblAuftraege[Kostenstelle],$B28)) | F28: =IF($B28="",0,SUMIFS(tblAuftraege[Kalk. Einnahmen],tblAuftraege[Datum Einnahmen],">="&F$5,tblAuftraege[Datum Einnahmen],"<"&EDATE(F$5,1),tblAuftraege[Kostenstelle],$B28)) | G28: =IF($B28="",0,SUMIFS(tblAuftraege[Kalk. Einnahmen],tblAuftraege[Datum Einnahmen],">="&G$5,tblAuftraege[Datum Einnahmen],"<"&EDATE(G$5,1),tblAuftraege[Kostenstelle],$B28)) | H28: =IF($B28="",0,SUMIFS(tblAuftraege[Kalk. Einnahmen],tblAuftraege[Datum Einnahmen],">="&H$5,tblAuftraege[Datum Einnahmen],"<"&EDATE(H$5,1),tblAuftraege[Kostenstelle],$B28)) | I28: =IF($B28="",0,SUMIFS(tblAuftraege[Kalk. Einnahmen],tblAuftraege[Datum Einnahmen],">="&I$5,tblAuftraege[Datum Einnahmen],"<"&EDATE(I$5,1),tblAuftraege[Kostenstelle],$B28)) | J28: =IF($B28="",0,SUMIFS(tblAuftraege[Kalk. Einnahmen],tblAuftraege[Datum Einnahmen],">="&J$5,tblAuftraege[Datum Einnahmen],"<"&EDATE(J$5,1),tblAuftraege[Kostenstelle],$B28)) | ... BD28: =IF($B28="",0,SUMIFS(tblAuftraege[Kalk. Einnahmen],tblAuftraege[Datum Einnahmen],">="&BD$5,tblAuftraege[Datum Einnahmen],"<"&EDATE(BD$5,1),tblAuftraege[Kostenstelle],$B28)) | BE28: =SUM(C28:H28) | BF28: =SUM(I28:T28) | BG28: =SUM(U28:AF28) | BH28: =SUM(AG28:AR28) | BI28: =SUM(AS28:BD28) | BJ28: =SUM(C28:BD28)
C29: =IF($B29="",0,SUMIFS(tblAuftraege[Kalk. Einnahmen],tblAuftraege[Datum Einnahmen],">="&C$5,tblAuftraege[Datum Einnahmen],"<"&EDATE(C$5,1),tblAuftraege[Kostenstelle],$B29)) | D29: =IF($B29="",0,SUMIFS(tblAuftraege[Kalk. Einnahmen],tblAuftraege[Datum Einnahmen],">="&D$5,tblAuftraege[Datum Einnahmen],"<"&EDATE(D$5,1),tblAuftraege[Kostenstelle],$B29)) | E29: =IF($B29="",0,SUMIFS(tblAuftraege[Kalk. Einnahmen],tblAuftraege[Datum Einnahmen],">="&E$5,tblAuftraege[Datum Einnahmen],"<"&EDATE(E$5,1),tblAuftraege[Kostenstelle],$B29)) | F29: =IF($B29="",0,SUMIFS(tblAuftraege[Kalk. Einnahmen],tblAuftraege[Datum Einnahmen],">="&F$5,tblAuftraege[Datum Einnahmen],"<"&EDATE(F$5,1),tblAuftraege[Kostenstelle],$B29)) | G29: =IF($B29="",0,SUMIFS(tblAuftraege[Kalk. Einnahmen],tblAuftraege[Datum Einnahmen],">="&G$5,tblAuftraege[Datum Einnahmen],"<"&EDATE(G$5,1),tblAuftraege[Kostenstelle],$B29)) | H29: =IF($B29="",0,SUMIFS(tblAuftraege[Kalk. Einnahmen],tblAuftraege[Datum Einnahmen],">="&H$5,tblAuftraege[Datum Einnahmen],"<"&EDATE(H$5,1),tblAuftraege[Kostenstelle],$B29)) | I29: =IF($B29="",0,SUMIFS(tblAuftraege[Kalk. Einnahmen],tblAuftraege[Datum Einnahmen],">="&I$5,tblAuftraege[Datum Einnahmen],"<"&EDATE(I$5,1),tblAuftraege[Kostenstelle],$B29)) | J29: =IF($B29="",0,SUMIFS(tblAuftraege[Kalk. Einnahmen],tblAuftraege[Datum Einnahmen],">="&J$5,tblAuftraege[Datum Einnahmen],"<"&EDATE(J$5,1),tblAuftraege[Kostenstelle],$B29)) | ... BD29: =IF($B29="",0,SUMIFS(tblAuftraege[Kalk. Einnahmen],tblAuftraege[Datum Einnahmen],">="&BD$5,tblAuftraege[Datum Einnahmen],"<"&EDATE(BD$5,1),tblAuftraege[Kostenstelle],$B29)) | BE29: =SUM(C29:H29) | BF29: =SUM(I29:T29) | BG29: =SUM(U29:AF29) | BH29: =SUM(AG29:AR29) | BI29: =SUM(AS29:BD29) | BJ29: =SUM(C29:BD29)
C30: =IF($B30="",0,SUMIFS(tblAuftraege[Kalk. Einnahmen],tblAuftraege[Datum Einnahmen],">="&C$5,tblAuftraege[Datum Einnahmen],"<"&EDATE(C$5,1),tblAuftraege[Kostenstelle],$B30)) | D30: =IF($B30="",0,SUMIFS(tblAuftraege[Kalk. Einnahmen],tblAuftraege[Datum Einnahmen],">="&D$5,tblAuftraege[Datum Einnahmen],"<"&EDATE(D$5,1),tblAuftraege[Kostenstelle],$B30)) | E30: =IF($B30="",0,SUMIFS(tblAuftraege[Kalk. Einnahmen],tblAuftraege[Datum Einnahmen],">="&E$5,tblAuftraege[Datum Einnahmen],"<"&EDATE(E$5,1),tblAuftraege[Kostenstelle],$B30)) | F30: =IF($B30="",0,SUMIFS(tblAuftraege[Kalk. Einnahmen],tblAuftraege[Datum Einnahmen],">="&F$5,tblAuftraege[Datum Einnahmen],"<"&EDATE(F$5,1),tblAuftraege[Kostenstelle],$B30)) | G30: =IF($B30="",0,SUMIFS(tblAuftraege[Kalk. Einnahmen],tblAuftraege[Datum Einnahmen],">="&G$5,tblAuftraege[Datum Einnahmen],"<"&EDATE(G$5,1),tblAuftraege[Kostenstelle],$B30)) | H30: =IF($B30="",0,SUMIFS(tblAuftraege[Kalk. Einnahmen],tblAuftraege[Datum Einnahmen],">="&H$5,tblAuftraege[Datum Einnahmen],"<"&EDATE(H$5,1),tblAuftraege[Kostenstelle],$B30)) | I30: =IF($B30="",0,SUMIFS(tblAuftraege[Kalk. Einnahmen],tblAuftraege[Datum Einnahmen],">="&I$5,tblAuftraege[Datum Einnahmen],"<"&EDATE(I$5,1),tblAuftraege[Kostenstelle],$B30)) | J30: =IF($B30="",0,SUMIFS(tblAuftraege[Kalk. Einnahmen],tblAuftraege[Datum Einnahmen],">="&J$5,tblAuftraege[Datum Einnahmen],"<"&EDATE(J$5,1),tblAuftraege[Kostenstelle],$B30)) | ... BD30: =IF($B30="",0,SUMIFS(tblAuftraege[Kalk. Einnahmen],tblAuftraege[Datum Einnahmen],">="&BD$5,tblAuftraege[Datum Einnahmen],"<"&EDATE(BD$5,1),tblAuftraege[Kostenstelle],$B30)) | BE30: =SUM(C30:H30) | BF30: =SUM(I30:T30) | BG30: =SUM(U30:AF30) | BH30: =SUM(AG30:AR30) | BI30: =SUM(AS30:BD30) | BJ30: =SUM(C30:BD30)
C31: =IF($B31="",0,SUMIFS(tblAuftraege[Kalk. Einnahmen],tblAuftraege[Datum Einnahmen],">="&C$5,tblAuftraege[Datum Einnahmen],"<"&EDATE(C$5,1),tblAuftraege[Kostenstelle],$B31)) | D31: =IF($B31="",0,SUMIFS(tblAuftraege[Kalk. Einnahmen],tblAuftraege[Datum Einnahmen],">="&D$5,tblAuftraege[Datum Einnahmen],"<"&EDATE(D$5,1),tblAuftraege[Kostenstelle],$B31)) | E31: =IF($B31="",0,SUMIFS(tblAuftraege[Kalk. Einnahmen],tblAuftraege[Datum Einnahmen],">="&E$5,tblAuftraege[Datum Einnahmen],"<"&EDATE(E$5,1),tblAuftraege[Kostenstelle],$B31)) | F31: =IF($B31="",0,SUMIFS(tblAuftraege[Kalk. Einnahmen],tblAuftraege[Datum Einnahmen],">="&F$5,tblAuftraege[Datum Einnahmen],"<"&EDATE(F$5,1),tblAuftraege[Kostenstelle],$B31)) | G31: =IF($B31="",0,SUMIFS(tblAuftraege[Kalk. Einnahmen],tblAuftraege[Datum Einnahmen],">="&G$5,tblAuftraege[Datum Einnahmen],"<"&EDATE(G$5,1),tblAuftraege[Kostenstelle],$B31)) | H31: =IF($B31="",0,SUMIFS(tblAuftraege[Kalk. Einnahmen],tblAuftraege[Datum Einnahmen],">="&H$5,tblAuftraege[Datum Einnahmen],"<"&EDATE(H$5,1),tblAuftraege[Kostenstelle],$B31)) | I31: =IF($B31="",0,SUMIFS(tblAuftraege[Kalk. Einnahmen],tblAuftraege[Datum Einnahmen],">="&I$5,tblAuftraege[Datum Einnahmen],"<"&EDATE(I$5,1),tblAuftraege[Kostenstelle],$B31)) | J31: =IF($B31="",0,SUMIFS(tblAuftraege[Kalk. Einnahmen],tblAuftraege[Datum Einnahmen],">="&J$5,tblAuftraege[Datum Einnahmen],"<"&EDATE(J$5,1),tblAuftraege[Kostenstelle],$B31)) | ... BD31: =IF($B31="",0,SUMIFS(tblAuftraege[Kalk. Einnahmen],tblAuftraege[Datum Einnahmen],">="&BD$5,tblAuftraege[Datum Einnahmen],"<"&EDATE(BD$5,1),tblAuftraege[Kostenstelle],$B31)) | BE31: =SUM(C31:H31) | BF31: =SUM(I31:T31) | BG31: =SUM(U31:AF31) | BH31: =SUM(AG31:AR31) | BI31: =SUM(AS31:BD31) | BJ31: =SUM(C31:BD31)
C32: =IF($B32="",0,SUMIFS(tblAuftraege[Kalk. Einnahmen],tblAuftraege[Datum Einnahmen],">="&C$5,tblAuftraege[Datum Einnahmen],"<"&EDATE(C$5,1),tblAuftraege[Kostenstelle],$B32)) | D32: =IF($B32="",0,SUMIFS(tblAuftraege[Kalk. Einnahmen],tblAuftraege[Datum Einnahmen],">="&D$5,tblAuftraege[Datum Einnahmen],"<"&EDATE(D$5,1),tblAuftraege[Kostenstelle],$B32)) | E32: =IF($B32="",0,SUMIFS(tblAuftraege[Kalk. Einnahmen],tblAuftraege[Datum Einnahmen],">="&E$5,tblAuftraege[Datum Einnahmen],"<"&EDATE(E$5,1),tblAuftraege[Kostenstelle],$B32)) | F32: =IF($B32="",0,SUMIFS(tblAuftraege[Kalk. Einnahmen],tblAuftraege[Datum Einnahmen],">="&F$5,tblAuftraege[Datum Einnahmen],"<"&EDATE(F$5,1),tblAuftraege[Kostenstelle],$B32)) | G32: =IF($B32="",0,SUMIFS(tblAuftraege[Kalk. Einnahmen],tblAuftraege[Datum Einnahmen],">="&G$5,tblAuftraege[Datum Einnahmen],"<"&EDATE(G$5,1),tblAuftraege[Kostenstelle],$B32)) | H32: =IF($B32="",0,SUMIFS(tblAuftraege[Kalk. Einnahmen],tblAuftraege[Datum Einnahmen],">="&H$5,tblAuftraege[Datum Einnahmen],"<"&EDATE(H$5,1),tblAuftraege[Kostenstelle],$B32)) | I32: =IF($B32="",0,SUMIFS(tblAuftraege[Kalk. Einnahmen],tblAuftraege[Datum Einnahmen],">="&I$5,tblAuftraege[Datum Einnahmen],"<"&EDATE(I$5,1),tblAuftraege[Kostenstelle],$B32)) | J32: =IF($B32="",0,SUMIFS(tblAuftraege[Kalk. Einnahmen],tblAuftraege[Datum Einnahmen],">="&J$5,tblAuftraege[Datum Einnahmen],"<"&EDATE(J$5,1),tblAuftraege[Kostenstelle],$B32)) | ... BD32: =IF($B32="",0,SUMIFS(tblAuftraege[Kalk. Einnahmen],tblAuftraege[Datum Einnahmen],">="&BD$5,tblAuftraege[Datum Einnahmen],"<"&EDATE(BD$5,1),tblAuftraege[Kostenstelle],$B32)) | BE32: =SUM(C32:H32) | BF32: =SUM(I32:T32) | BG32: =SUM(U32:AF32) | BH32: =SUM(AG32:AR32) | BI32: =SUM(AS32:BD32) | BJ32: =SUM(C32:BD32)
C33: =IF($B33="",0,SUMIFS(tblAuftraege[Kalk. Einnahmen],tblAuftraege[Datum Einnahmen],">="&C$5,tblAuftraege[Datum Einnahmen],"<"&EDATE(C$5,1),tblAuftraege[Kostenstelle],$B33)) | D33: =IF($B33="",0,SUMIFS(tblAuftraege[Kalk. Einnahmen],tblAuftraege[Datum Einnahmen],">="&D$5,tblAuftraege[Datum Einnahmen],"<"&EDATE(D$5,1),tblAuftraege[Kostenstelle],$B33)) | E33: =IF($B33="",0,SUMIFS(tblAuftraege[Kalk. Einnahmen],tblAuftraege[Datum Einnahmen],">="&E$5,tblAuftraege[Datum Einnahmen],"<"&EDATE(E$5,1),tblAuftraege[Kostenstelle],$B33)) | F33: =IF($B33="",0,SUMIFS(tblAuftraege[Kalk. Einnahmen],tblAuftraege[Datum Einnahmen],">="&F$5,tblAuftraege[Datum Einnahmen],"<"&EDATE(F$5,1),tblAuftraege[Kostenstelle],$B33)) | G33: =IF($B33="",0,SUMIFS(tblAuftraege[Kalk. Einnahmen],tblAuftraege[Datum Einnahmen],">="&G$5,tblAuftraege[Datum Einnahmen],"<"&EDATE(G$5,1),tblAuftraege[Kostenstelle],$B33)) | H33: =IF($B33="",0,SUMIFS(tblAuftraege[Kalk. Einnahmen],tblAuftraege[Datum Einnahmen],">="&H$5,tblAuftraege[Datum Einnahmen],"<"&EDATE(H$5,1),tblAuftraege[Kostenstelle],$B33)) | I33: =IF($B33="",0,SUMIFS(tblAuftraege[Kalk. Einnahmen],tblAuftraege[Datum Einnahmen],">="&I$5,tblAuftraege[Datum Einnahmen],"<"&EDATE(I$5,1),tblAuftraege[Kostenstelle],$B33)) | J33: =IF($B33="",0,SUMIFS(tblAuftraege[Kalk. Einnahmen],tblAuftraege[Datum Einnahmen],">="&J$5,tblAuftraege[Datum Einnahmen],"<"&EDATE(J$5,1),tblAuftraege[Kostenstelle],$B33)) | ... BD33: =IF($B33="",0,SUMIFS(tblAuftraege[Kalk. Einnahmen],tblAuftraege[Datum Einnahmen],">="&BD$5,tblAuftraege[Datum Einnahmen],"<"&EDATE(BD$5,1),tblAuftraege[Kostenstelle],$B33)) | BE33: =SUM(C33:H33) | BF33: =SUM(I33:T33) | BG33: =SUM(U33:AF33) | BH33: =SUM(AG33:AR33) | BI33: =SUM(AS33:BD33) | BJ33: =SUM(C33:BD33)
C34: =IF($B34="",0,SUMIFS(tblAuftraege[Kalk. Einnahmen],tblAuftraege[Datum Einnahmen],">="&C$5,tblAuftraege[Datum Einnahmen],"<"&EDATE(C$5,1),tblAuftraege[Kostenstelle],$B34)) | D34: =IF($B34="",0,SUMIFS(tblAuftraege[Kalk. Einnahmen],tblAuftraege[Datum Einnahmen],">="&D$5,tblAuftraege[Datum Einnahmen],"<"&EDATE(D$5,1),tblAuftraege[Kostenstelle],$B34)) | E34: =IF($B34="",0,SUMIFS(tblAuftraege[Kalk. Einnahmen],tblAuftraege[Datum Einnahmen],">="&E$5,tblAuftraege[Datum Einnahmen],"<"&EDATE(E$5,1),tblAuftraege[Kostenstelle],$B34)) | F34: =IF($B34="",0,SUMIFS(tblAuftraege[Kalk. Einnahmen],tblAuftraege[Datum Einnahmen],">="&F$5,tblAuftraege[Datum Einnahmen],"<"&EDATE(F$5,1),tblAuftraege[Kostenstelle],$B34)) | G34: =IF($B34="",0,SUMIFS(tblAuftraege[Kalk. Einnahmen],tblAuftraege[Datum Einnahmen],">="&G$5,tblAuftraege[Datum Einnahmen],"<"&EDATE(G$5,1),tblAuftraege[Kostenstelle],$B34)) | H34: =IF($B34="",0,SUMIFS(tblAuftraege[Kalk. Einnahmen],tblAuftraege[Datum Einnahmen],">="&H$5,tblAuftraege[Datum Einnahmen],"<"&EDATE(H$5,1),tblAuftraege[Kostenstelle],$B34)) | I34: =IF($B34="",0,SUMIFS(tblAuftraege[Kalk. Einnahmen],tblAuftraege[Datum Einnahmen],">="&I$5,tblAuftraege[Datum Einnahmen],"<"&EDATE(I$5,1),tblAuftraege[Kostenstelle],$B34)) | J34: =IF($B34="",0,SUMIFS(tblAuftraege[Kalk. Einnahmen],tblAuftraege[Datum Einnahmen],">="&J$5,tblAuftraege[Datum Einnahmen],"<"&EDATE(J$5,1),tblAuftraege[Kostenstelle],$B34)) | ... BD34: =IF($B34="",0,SUMIFS(tblAuftraege[Kalk. Einnahmen],tblAuftraege[Datum Einnahmen],">="&BD$5,tblAuftraege[Datum Einnahmen],"<"&EDATE(BD$5,1),tblAuftraege[Kostenstelle],$B34)) | BE34: =SUM(C34:H34) | BF34: =SUM(I34:T34) | BG34: =SUM(U34:AF34) | BH34: =SUM(AG34:AR34) | BI34: =SUM(AS34:BD34) | BJ34: =SUM(C34:BD34)
C35: =IF($B35="",0,SUMIFS(tblAuftraege[Kalk. Einnahmen],tblAuftraege[Datum Einnahmen],">="&C$5,tblAuftraege[Datum Einnahmen],"<"&EDATE(C$5,1),tblAuftraege[Kostenstelle],$B35)) | D35: =IF($B35="",0,SUMIFS(tblAuftraege[Kalk. Einnahmen],tblAuftraege[Datum Einnahmen],">="&D$5,tblAuftraege[Datum Einnahmen],"<"&EDATE(D$5,1),tblAuftraege[Kostenstelle],$B35)) | E35: =IF($B35="",0,SUMIFS(tblAuftraege[Kalk. Einnahmen],tblAuftraege[Datum Einnahmen],">="&E$5,tblAuftraege[Datum Einnahmen],"<"&EDATE(E$5,1),tblAuftraege[Kostenstelle],$B35)) | F35: =IF($B35="",0,SUMIFS(tblAuftraege[Kalk. Einnahmen],tblAuftraege[Datum Einnahmen],">="&F$5,tblAuftraege[Datum Einnahmen],"<"&EDATE(F$5,1),tblAuftraege[Kostenstelle],$B35)) | G35: =IF($B35="",0,SUMIFS(tblAuftraege[Kalk. Einnahmen],tblAuftraege[Datum Einnahmen],">="&G$5,tblAuftraege[Datum Einnahmen],"<"&EDATE(G$5,1),tblAuftraege[Kostenstelle],$B35)) | H35: =IF($B35="",0,SUMIFS(tblAuftraege[Kalk. Einnahmen],tblAuftraege[Datum Einnahmen],">="&H$5,tblAuftraege[Datum Einnahmen],"<"&EDATE(H$5,1),tblAuftraege[Kostenstelle],$B35)) | I35: =IF($B35="",0,SUMIFS(tblAuftraege[Kalk. Einnahmen],tblAuftraege[Datum Einnahmen],">="&I$5,tblAuftraege[Datum Einnahmen],"<"&EDATE(I$5,1),tblAuftraege[Kostenstelle],$B35)) | J35: =IF($B35="",0,SUMIFS(tblAuftraege[Kalk. Einnahmen],tblAuftraege[Datum Einnahmen],">="&J$5,tblAuftraege[Datum Einnahmen],"<"&EDATE(J$5,1),tblAuftraege[Kostenstelle],$B35)) | ... BD35: =IF($B35="",0,SUMIFS(tblAuftraege[Kalk. Einnahmen],tblAuftraege[Datum Einnahmen],">="&BD$5,tblAuftraege[Datum Einnahmen],"<"&EDATE(BD$5,1),tblAuftraege[Kostenstelle],$B35)) | BE35: =SUM(C35:H35) | BF35: =SUM(I35:T35) | BG35: =SUM(U35:AF35) | BH35: =SUM(AG35:AR35) | BI35: =SUM(AS35:BD35) | BJ35: =SUM(C35:BD35)
C36: =IF($B36="",0,SUMIFS(tblAuftraege[Kalk. Einnahmen],tblAuftraege[Datum Einnahmen],">="&C$5,tblAuftraege[Datum Einnahmen],"<"&EDATE(C$5,1),tblAuftraege[Kostenstelle],$B36)) | D36: =IF($B36="",0,SUMIFS(tblAuftraege[Kalk. Einnahmen],tblAuftraege[Datum Einnahmen],">="&D$5,tblAuftraege[Datum Einnahmen],"<"&EDATE(D$5,1),tblAuftraege[Kostenstelle],$B36)) | E36: =IF($B36="",0,SUMIFS(tblAuftraege[Kalk. Einnahmen],tblAuftraege[Datum Einnahmen],">="&E$5,tblAuftraege[Datum Einnahmen],"<"&EDATE(E$5,1),tblAuftraege[Kostenstelle],$B36)) | F36: =IF($B36="",0,SUMIFS(tblAuftraege[Kalk. Einnahmen],tblAuftraege[Datum Einnahmen],">="&F$5,tblAuftraege[Datum Einnahmen],"<"&EDATE(F$5,1),tblAuftraege[Kostenstelle],$B36)) | G36: =IF($B36="",0,SUMIFS(tblAuftraege[Kalk. Einnahmen],tblAuftraege[Datum Einnahmen],">="&G$5,tblAuftraege[Datum Einnahmen],"<"&EDATE(G$5,1),tblAuftraege[Kostenstelle],$B36)) | H36: =IF($B36="",0,SUMIFS(tblAuftraege[Kalk. Einnahmen],tblAuftraege[Datum Einnahmen],">="&H$5,tblAuftraege[Datum Einnahmen],"<"&EDATE(H$5,1),tblAuftraege[Kostenstelle],$B36)) | I36: =IF($B36="",0,SUMIFS(tblAuftraege[Kalk. Einnahmen],tblAuftraege[Datum Einnahmen],">="&I$5,tblAuftraege[Datum Einnahmen],"<"&EDATE(I$5,1),tblAuftraege[Kostenstelle],$B36)) | J36: =IF($B36="",0,SUMIFS(tblAuftraege[Kalk. Einnahmen],tblAuftraege[Datum Einnahmen],">="&J$5,tblAuftraege[Datum Einnahmen],"<"&EDATE(J$5,1),tblAuftraege[Kostenstelle],$B36)) | ... BD36: =IF($B36="",0,SUMIFS(tblAuftraege[Kalk. Einnahmen],tblAuftraege[Datum Einnahmen],">="&BD$5,tblAuftraege[Datum Einnahmen],"<"&EDATE(BD$5,1),tblAuftraege[Kostenstelle],$B36)) | BE36: =SUM(C36:H36) | BF36: =SUM(I36:T36) | BG36: =SUM(U36:AF36) | BH36: =SUM(AG36:AR36) | BI36: =SUM(AS36:BD36) | BJ36: =SUM(C36:BD36)
C37: =IF($B37="",0,SUMIFS(tblAuftraege[Kalk. Einnahmen],tblAuftraege[Datum Einnahmen],">="&C$5,tblAuftraege[Datum Einnahmen],"<"&EDATE(C$5,1),tblAuftraege[Kostenstelle],$B37)) | D37: =IF($B37="",0,SUMIFS(tblAuftraege[Kalk. Einnahmen],tblAuftraege[Datum Einnahmen],">="&D$5,tblAuftraege[Datum Einnahmen],"<"&EDATE(D$5,1),tblAuftraege[Kostenstelle],$B37)) | E37: =IF($B37="",0,SUMIFS(tblAuftraege[Kalk. Einnahmen],tblAuftraege[Datum Einnahmen],">="&E$5,tblAuftraege[Datum Einnahmen],"<"&EDATE(E$5,1),tblAuftraege[Kostenstelle],$B37)) | F37: =IF($B37="",0,SUMIFS(tblAuftraege[Kalk. Einnahmen],tblAuftraege[Datum Einnahmen],">="&F$5,tblAuftraege[Datum Einnahmen],"<"&EDATE(F$5,1),tblAuftraege[Kostenstelle],$B37)) | G37: =IF($B37="",0,SUMIFS(tblAuftraege[Kalk. Einnahmen],tblAuftraege[Datum Einnahmen],">="&G$5,tblAuftraege[Datum Einnahmen],"<"&EDATE(G$5,1),tblAuftraege[Kostenstelle],$B37)) | H37: =IF($B37="",0,SUMIFS(tblAuftraege[Kalk. Einnahmen],tblAuftraege[Datum Einnahmen],">="&H$5,tblAuftraege[Datum Einnahmen],"<"&EDATE(H$5,1),tblAuftraege[Kostenstelle],$B37)) | I37: =IF($B37="",0,SUMIFS(tblAuftraege[Kalk. Einnahmen],tblAuftraege[Datum Einnahmen],">="&I$5,tblAuftraege[Datum Einnahmen],"<"&EDATE(I$5,1),tblAuftraege[Kostenstelle],$B37)) | J37: =IF($B37="",0,SUMIFS(tblAuftraege[Kalk. Einnahmen],tblAuftraege[Datum Einnahmen],">="&J$5,tblAuftraege[Datum Einnahmen],"<"&EDATE(J$5,1),tblAuftraege[Kostenstelle],$B37)) | ... BD37: =IF($B37="",0,SUMIFS(tblAuftraege[Kalk. Einnahmen],tblAuftraege[Datum Einnahmen],">="&BD$5,tblAuftraege[Datum Einnahmen],"<"&EDATE(BD$5,1),tblAuftraege[Kostenstelle],$B37)) | BE37: =SUM(C37:H37) | BF37: =SUM(I37:T37) | BG37: =SUM(U37:AF37) | BH37: =SUM(AG37:AR37) | BI37: =SUM(AS37:BD37) | BJ37: =SUM(C37:BD37)
B38: Aufträge ohne Kostenstellen-Zuordnung | C38: =C39-SUM(C8:C37) | D38: =D39-SUM(D8:D37) | E38: =E39-SUM(E8:E37) | F38: =F39-SUM(F8:F37) | G38: =G39-SUM(G8:G37) | H38: =H39-SUM(H8:H37) | I38: =I39-SUM(I8:I37) | J38: =J39-SUM(J8:J37) | ... BJ38: =BJ39-SUM(BJ8:BJ37)
B39: Summe Einnahmen | C39: =SUMIFS(tblAuftraege[Kalk. Einnahmen],tblAuftraege[Datum Einnahmen],">="&C$5,tblAuftraege[Datum Einnahmen],"<"&EDATE(C$5,1)) | D39: =SUMIFS(tblAuftraege[Kalk. Einnahmen],tblAuftraege[Datum Einnahmen],">="&D$5,tblAuftraege[Datum Einnahmen],"<"&EDATE(D$5,1)) | E39: =SUMIFS(tblAuftraege[Kalk. Einnahmen],tblAuftraege[Datum Einnahmen],">="&E$5,tblAuftraege[Datum Einnahmen],"<"&EDATE(E$5,1)) | F39: =SUMIFS(tblAuftraege[Kalk. Einnahmen],tblAuftraege[Datum Einnahmen],">="&F$5,tblAuftraege[Datum Einnahmen],"<"&EDATE(F$5,1)) | G39: =SUMIFS(tblAuftraege[Kalk. Einnahmen],tblAuftraege[Datum Einnahmen],">="&G$5,tblAuftraege[Datum Einnahmen],"<"&EDATE(G$5,1)) | H39: =SUMIFS(tblAuftraege[Kalk. Einnahmen],tblAuftraege[Datum Einnahmen],">="&H$5,tblAuftraege[Datum Einnahmen],"<"&EDATE(H$5,1)) | I39: =SUMIFS(tblAuftraege[Kalk. Einnahmen],tblAuftraege[Datum Einnahmen],">="&I$5,tblAuftraege[Datum Einnahmen],"<"&EDATE(I$5,1)) | J39: =SUMIFS(tblAuftraege[Kalk. Einnahmen],tblAuftraege[Datum Einnahmen],">="&J$5,tblAuftraege[Datum Einnahmen],"<"&EDATE(J$5,1)) | ... BD39: =SUMIFS(tblAuftraege[Kalk. Einnahmen],tblAuftraege[Datum Einnahmen],">="&BD$5,tblAuftraege[Datum Einnahmen],"<"&EDATE(BD$5,1)) | BE39: =SUM(C39:H39) | BF39: =SUM(I39:T39) | BG39: =SUM(U39:AF39) | BH39: =SUM(AG39:AR39) | BI39: =SUM(AS39:BD39) | BJ39: =SUM(C39:BD39)
B41: 2 AUSGABEN (Quelle: Reiter „Aufträge“) | C41: Jul 26 | D41: Aug 26 | E41: Sep 26 | F41: Okt 26 | G41: Nov 26 | H41: Dez 26 | I41: Jan 27 | J41: Feb 27 | K41: Mrz 27 | L41: Apr 27 | M41: Mai 27 | N41: Jun 27 | O41: Jul 27 | P41: Aug 27 | Q41: Sep 27 | R41: Okt 27 | S41: Nov 27 | T41: Dez 27 | U41: Jan 28 | V41: Feb 28 | W41: Mär 28 | X41: Apr 28 | Y41: Mai 28 | Z41: Jun 28 | AA41: Jul 28 | AB41: Aug 28 | AC41: Sep 28 | AD41: Okt 28 | AE41: Nov 28 | AF41: Dez 28 | AG41: Jan 29 | AH41: Feb 29 | AI41: Mär 29 | AJ41: Apr 29 | AK41: Mai 29 | AL41: Jun 29 | AM41: Jul 29 | AN41: Aug 29 | AO41: Sep 29 | AP41: Okt 29 | AQ41: Nov 29 | AR41: Dez 29 | AS41: Jan 30 | AT41: Feb 30 | AU41: Mär 30 | AV41: Apr 30 | AW41: Mai 30 | AX41: Jun 30 | AY41: Jul 30 | AZ41: Aug 30 | BA41: Sep 30 | BB41: Okt 30 | BC41: Nov 30 | BD41: Dez 30 | BE41: Summe H2 26 | BF41: Summe 27 | BG41: Summe 28 | BH41: Summe 29 | BI41: Summe 30 | BJ41: Gesamt
B42: =IF(ISBLANK(B8),"",B8) | C42: =IF($B42="",0,SUMIFS(tblAuftraege[Kalk. Ausgaben],tblAuftraege[Datum Ausgaben],">="&C$5,tblAuftraege[Datum Ausgaben],"<"&EDATE(C$5,1),tblAuftraege[Kostenstelle],$B42)) | D42: =IF($B42="",0,SUMIFS(tblAuftraege[Kalk. Ausgaben],tblAuftraege[Datum Ausgaben],">="&D$5,tblAuftraege[Datum Ausgaben],"<"&EDATE(D$5,1),tblAuftraege[Kostenstelle],$B42)) | E42: =IF($B42="",0,SUMIFS(tblAuftraege[Kalk. Ausgaben],tblAuftraege[Datum Ausgaben],">="&E$5,tblAuftraege[Datum Ausgaben],"<"&EDATE(E$5,1),tblAuftraege[Kostenstelle],$B42)) | F42: =IF($B42="",0,SUMIFS(tblAuftraege[Kalk. Ausgaben],tblAuftraege[Datum Ausgaben],">="&F$5,tblAuftraege[Datum Ausgaben],"<"&EDATE(F$5,1),tblAuftraege[Kostenstelle],$B42)) | G42: =IF($B42="",0,SUMIFS(tblAuftraege[Kalk. Ausgaben],tblAuftraege[Datum Ausgaben],">="&G$5,tblAuftraege[Datum Ausgaben],"<"&EDATE(G$5,1),tblAuftraege[Kostenstelle],$B42)) | H42: =IF($B42="",0,SUMIFS(tblAuftraege[Kalk. Ausgaben],tblAuftraege[Datum Ausgaben],">="&H$5,tblAuftraege[Datum Ausgaben],"<"&EDATE(H$5,1),tblAuftraege[Kostenstelle],$B42)) | I42: =IF($B42="",0,SUMIFS(tblAuftraege[Kalk. Ausgaben],tblAuftraege[Datum Ausgaben],">="&I$5,tblAuftraege[Datum Ausgaben],"<"&EDATE(I$5,1),tblAuftraege[Kostenstelle],$B42)) | J42: =IF($B42="",0,SUMIFS(tblAuftraege[Kalk. Ausgaben],tblAuftraege[Datum Ausgaben],">="&J$5,tblAuftraege[Datum Ausgaben],"<"&EDATE(J$5,1),tblAuftraege[Kostenstelle],$B42)) | ... BD42: =IF($B42="",0,SUMIFS(tblAuftraege[Kalk. Ausgaben],tblAuftraege[Datum Ausgaben],">="&BD$5,tblAuftraege[Datum Ausgaben],"<"&EDATE(BD$5,1),tblAuftraege[Kostenstelle],$B42)) | BE42: =SUM(C42:H42) | BF42: =SUM(I42:T42) | BG42: =SUM(U42:AF42) | BH42: =SUM(AG42:AR42) | BI42: =SUM(AS42:BD42) | BJ42: =SUM(C42:BD42)
B43: =IF(ISBLANK(B9),"",B9) | C43: =IF($B43="",0,SUMIFS(tblAuftraege[Kalk. Ausgaben],tblAuftraege[Datum Ausgaben],">="&C$5,tblAuftraege[Datum Ausgaben],"<"&EDATE(C$5,1),tblAuftraege[Kostenstelle],$B43)) | D43: =IF($B43="",0,SUMIFS(tblAuftraege[Kalk. Ausgaben],tblAuftraege[Datum Ausgaben],">="&D$5,tblAuftraege[Datum Ausgaben],"<"&EDATE(D$5,1),tblAuftraege[Kostenstelle],$B43)) | E43: =IF($B43="",0,SUMIFS(tblAuftraege[Kalk. Ausgaben],tblAuftraege[Datum Ausgaben],">="&E$5,tblAuftraege[Datum Ausgaben],"<"&EDATE(E$5,1),tblAuftraege[Kostenstelle],$B43)) | F43: =IF($B43="",0,SUMIFS(tblAuftraege[Kalk. Ausgaben],tblAuftraege[Datum Ausgaben],">="&F$5,tblAuftraege[Datum Ausgaben],"<"&EDATE(F$5,1),tblAuftraege[Kostenstelle],$B43)) | G43: =IF($B43="",0,SUMIFS(tblAuftraege[Kalk. Ausgaben],tblAuftraege[Datum Ausgaben],">="&G$5,tblAuftraege[Datum Ausgaben],"<"&EDATE(G$5,1),tblAuftraege[Kostenstelle],$B43)) | H43: =IF($B43="",0,SUMIFS(tblAuftraege[Kalk. Ausgaben],tblAuftraege[Datum Ausgaben],">="&H$5,tblAuftraege[Datum Ausgaben],"<"&EDATE(H$5,1),tblAuftraege[Kostenstelle],$B43)) | I43: =IF($B43="",0,SUMIFS(tblAuftraege[Kalk. Ausgaben],tblAuftraege[Datum Ausgaben],">="&I$5,tblAuftraege[Datum Ausgaben],"<"&EDATE(I$5,1),tblAuftraege[Kostenstelle],$B43)) | J43: =IF($B43="",0,SUMIFS(tblAuftraege[Kalk. Ausgaben],tblAuftraege[Datum Ausgaben],">="&J$5,tblAuftraege[Datum Ausgaben],"<"&EDATE(J$5,1),tblAuftraege[Kostenstelle],$B43)) | ... BD43: =IF($B43="",0,SUMIFS(tblAuftraege[Kalk. Ausgaben],tblAuftraege[Datum Ausgaben],">="&BD$5,tblAuftraege[Datum Ausgaben],"<"&EDATE(BD$5,1),tblAuftraege[Kostenstelle],$B43)) | BE43: =SUM(C43:H43) | BF43: =SUM(I43:T43) | BG43: =SUM(U43:AF43) | BH43: =SUM(AG43:AR43) | BI43: =SUM(AS43:BD43) | BJ43: =SUM(C43:BD43)
B44: =IF(ISBLANK(B10),"",B10) | C44: =IF($B44="",0,SUMIFS(tblAuftraege[Kalk. Ausgaben],tblAuftraege[Datum Ausgaben],">="&C$5,tblAuftraege[Datum Ausgaben],"<"&EDATE(C$5,1),tblAuftraege[Kostenstelle],$B44)) | D44: =IF($B44="",0,SUMIFS(tblAuftraege[Kalk. Ausgaben],tblAuftraege[Datum Ausgaben],">="&D$5,tblAuftraege[Datum Ausgaben],"<"&EDATE(D$5,1),tblAuftraege[Kostenstelle],$B44)) | E44: =IF($B44="",0,SUMIFS(tblAuftraege[Kalk. Ausgaben],tblAuftraege[Datum Ausgaben],">="&E$5,tblAuftraege[Datum Ausgaben],"<"&EDATE(E$5,1),tblAuftraege[Kostenstelle],$B44)) | F44: =IF($B44="",0,SUMIFS(tblAuftraege[Kalk. Ausgaben],tblAuftraege[Datum Ausgaben],">="&F$5,tblAuftraege[Datum Ausgaben],"<"&EDATE(F$5,1),tblAuftraege[Kostenstelle],$B44)) | G44: =IF($B44="",0,SUMIFS(tblAuftraege[Kalk. Ausgaben],tblAuftraege[Datum Ausgaben],">="&G$5,tblAuftraege[Datum Ausgaben],"<"&EDATE(G$5,1),tblAuftraege[Kostenstelle],$B44)) | H44: =IF($B44="",0,SUMIFS(tblAuftraege[Kalk. Ausgaben],tblAuftraege[Datum Ausgaben],">="&H$5,tblAuftraege[Datum Ausgaben],"<"&EDATE(H$5,1),tblAuftraege[Kostenstelle],$B44)) | I44: =IF($B44="",0,SUMIFS(tblAuftraege[Kalk. Ausgaben],tblAuftraege[Datum Ausgaben],">="&I$5,tblAuftraege[Datum Ausgaben],"<"&EDATE(I$5,1),tblAuftraege[Kostenstelle],$B44)) | J44: =IF($B44="",0,SUMIFS(tblAuftraege[Kalk. Ausgaben],tblAuftraege[Datum Ausgaben],">="&J$5,tblAuftraege[Datum Ausgaben],"<"&EDATE(J$5,1),tblAuftraege[Kostenstelle],$B44)) | ... BD44: =IF($B44="",0,SUMIFS(tblAuftraege[Kalk. Ausgaben],tblAuftraege[Datum Ausgaben],">="&BD$5,tblAuftraege[Datum Ausgaben],"<"&EDATE(BD$5,1),tblAuftraege[Kostenstelle],$B44)) | BE44: =SUM(C44:H44) | BF44: =SUM(I44:T44) | BG44: =SUM(U44:AF44) | BH44: =SUM(AG44:AR44) | BI44: =SUM(AS44:BD44) | BJ44: =SUM(C44:BD44)
B45: =IF(ISBLANK(B11),"",B11) | C45: =IF($B45="",0,SUMIFS(tblAuftraege[Kalk. Ausgaben],tblAuftraege[Datum Ausgaben],">="&C$5,tblAuftraege[Datum Ausgaben],"<"&EDATE(C$5,1),tblAuftraege[Kostenstelle],$B45)) | D45: =IF($B45="",0,SUMIFS(tblAuftraege[Kalk. Ausgaben],tblAuftraege[Datum Ausgaben],">="&D$5,tblAuftraege[Datum Ausgaben],"<"&EDATE(D$5,1),tblAuftraege[Kostenstelle],$B45)) | E45: =IF($B45="",0,SUMIFS(tblAuftraege[Kalk. Ausgaben],tblAuftraege[Datum Ausgaben],">="&E$5,tblAuftraege[Datum Ausgaben],"<"&EDATE(E$5,1),tblAuftraege[Kostenstelle],$B45)) | F45: =IF($B45="",0,SUMIFS(tblAuftraege[Kalk. Ausgaben],tblAuftraege[Datum Ausgaben],">="&F$5,tblAuftraege[Datum Ausgaben],"<"&EDATE(F$5,1),tblAuftraege[Kostenstelle],$B45)) | G45: =IF($B45="",0,SUMIFS(tblAuftraege[Kalk. Ausgaben],tblAuftraege[Datum Ausgaben],">="&G$5,tblAuftraege[Datum Ausgaben],"<"&EDATE(G$5,1),tblAuftraege[Kostenstelle],$B45)) | H45: =IF($B45="",0,SUMIFS(tblAuftraege[Kalk. Ausgaben],tblAuftraege[Datum Ausgaben],">="&H$5,tblAuftraege[Datum Ausgaben],"<"&EDATE(H$5,1),tblAuftraege[Kostenstelle],$B45)) | I45: =IF($B45="",0,SUMIFS(tblAuftraege[Kalk. Ausgaben],tblAuftraege[Datum Ausgaben],">="&I$5,tblAuftraege[Datum Ausgaben],"<"&EDATE(I$5,1),tblAuftraege[Kostenstelle],$B45)) | J45: =IF($B45="",0,SUMIFS(tblAuftraege[Kalk. Ausgaben],tblAuftraege[Datum Ausgaben],">="&J$5,tblAuftraege[Datum Ausgaben],"<"&EDATE(J$5,1),tblAuftraege[Kostenstelle],$B45)) | ... BD45: =IF($B45="",0,SUMIFS(tblAuftraege[Kalk. Ausgaben],tblAuftraege[Datum Ausgaben],">="&BD$5,tblAuftraege[Datum Ausgaben],"<"&EDATE(BD$5,1),tblAuftraege[Kostenstelle],$B45)) | BE45: =SUM(C45:H45) | BF45: =SUM(I45:T45) | BG45: =SUM(U45:AF45) | BH45: =SUM(AG45:AR45) | BI45: =SUM(AS45:BD45) | BJ45: =SUM(C45:BD45)
...

Sheet Aufträge
A1: Aufträge – zentrale Datenerfassung
A2: SmartInfra / IoT-Büro · DusL Plus Autostrom
A3: Jeder Auftrag bzw. finanzielle Vorgang wird hier einmalig erfasst. Der Reiter „Cashflow“ aggregiert daraus automatisch nach Monat.
A4: Datum Einnahmen und Datum Ausgaben sind unabhängig – ein Auftrag kann z. B. im September Ausgaben und erst im November Einnahmen haben. LLM = Lastmanagement.
B6: Themenfeld | C6: Kostenstelle | D6: Kategorie | E6: Auftrag | F6: Datum Ausgaben | G6: Ausgaben | H6: Datum Einnahmen | I6: Einnahmen | J6: Auftrags- wahrscheinlichkeit | K6: Bemerkung | L6: Kalk. Ausgaben | M6: Kalk. Einnahmen
