Workbook

Sheet Cashflow
A1: Cashflow-Planung
A2: Bereich: SmartInfra / IoT-Büro
A3: Zeitraum: Juli 2026 – Dezember 2027 (18 Monate, monatliche Granularität)
A4: Alle Beträge werden automatisch aus dem Reiter „Aufträge“ berechnet – hier wird links nur die Auftragsnummer (gelb) eingetragen.
E5: 46204 | F5: 46235 | G5: 46266 | H5: 46296 | I5: 46327 | J5: 46357 | K5: 46388 | L5: 46419 | M5: 46447 | N5: 46478 | O5: 46508 | P5: 46539 | Q5: 46569 | R5: 46600 | S5: 46631 | T5: 46661 | U5: 46692 | V5: 46722
A6: Auftrag | B6: Kostenstelle | C6: Themenfeld | D6: Kategorie | E6: Jul 26 | F6: Aug 26 | G6: Sep 26 | H6: Okt 26 | I6: Nov 26 | J6: Dez 26 | K6: Jan 27 | L6: Feb 27 | M6: Mär 27 | N6: Apr 27 | O6: Mai 27 | P6: Jun 27 | Q6: Jul 27 | R6: Aug 27 | S6: Sep 27 | T6: Okt 27 | U6: Nov 27 | V6: Dez 27 | W6: Summe H2 2026 | X6: Summe 2027 | Y6: Gesamt
A7: 1 EINNAHMEN JE AUFTRAG (Quelle: Reiter „Aufträge“)
B8: =IF($A8="","",IFERROR(INDEX(tblAuftraege[Kostenstelle],MATCH($A8,tblAuftraege[Auftrag],0)),"")) | C8: =IF($A8="","",IFERROR(INDEX(tblAuftraege[Themenfeld],MATCH($A8,tblAuftraege[Auftrag],0)),"")) | D8: =IF($A8="","",IFERROR(INDEX(tblAuftraege[Kategorie],MATCH($A8,tblAuftraege[Auftrag],0)),"")) | E8: =IF($A8="",0,SUMIFS(tblAuftraege[Einnahmen],tblAuftraege[Datum Einnahmen],">="&E$5,tblAuftraege[Datum Einnahmen],"<"&EDATE(E$5,1),tblAuftraege[Auftrag],$A8)) -> 0 | F8: =IF($A8="",0,SUMIFS(tblAuftraege[Einnahmen],tblAuftraege[Datum Einnahmen],">="&F$5,tblAuftraege[Datum Einnahmen],"<"&EDATE(F$5,1),tblAuftraege[Auftrag],$A8)) -> 0 | G8: =IF($A8="",0,SUMIFS(tblAuftraege[Einnahmen],tblAuftraege[Datum Einnahmen],">="&G$5,tblAuftraege[Datum Einnahmen],"<"&EDATE(G$5,1),tblAuftraege[Auftrag],$A8)) -> 0 | H8: =IF($A8="",0,SUMIFS(tblAuftraege[Einnahmen],tblAuftraege[Datum Einnahmen],">="&H$5,tblAuftraege[Datum Einnahmen],"<"&EDATE(H$5,1),tblAuftraege[Auftrag],$A8)) -> 0 | I8: =IF($A8="",0,SUMIFS(tblAuftraege[Einnahmen],tblAuftraege[Datum Einnahmen],">="&I$5,tblAuftraege[Datum Einnahmen],"<"&EDATE(I$5,1),tblAuftraege[Auftrag],$A8)) -> 0 | J8: =IF($A8="",0,SUMIFS(tblAuftraege[Einnahmen],tblAuftraege[Datum Einnahmen],">="&J$5,tblAuftraege[Datum Einnahmen],"<"&EDATE(J$5,1),tblAuftraege[Auftrag],$A8)) -> 0 | K8: =IF($A8="",0,SUMIFS(tblAuftraege[Einnahmen],tblAuftraege[Datum Einnahmen],">="&K$5,tblAuftraege[Datum Einnahmen],"<"&EDATE(K$5,1),tblAuftraege[Auftrag],$A8)) -> 0 | L8: =IF($A8="",0,SUMIFS(tblAuftraege[Einnahmen],tblAuftraege[Datum Einnahmen],">="&L$5,tblAuftraege[Datum Einnahmen],"<"&EDATE(L$5,1),tblAuftraege[Auftrag],$A8)) -> 0 | ... V8: =IF($A8="",0,SUMIFS(tblAuftraege[Einnahmen],tblAuftraege[Datum Einnahmen],">="&V$5,tblAuftraege[Datum Einnahmen],"<"&EDATE(V$5,1),tblAuftraege[Auftrag],$A8)) -> 0 | W8: =SUM(E8:J8) -> 0 | X8: =SUM(K8:V8) -> 0 | Y8: =SUM(E8:V8) -> 0
B9: =IF($A9="","",IFERROR(INDEX(tblAuftraege[Kostenstelle],MATCH($A9,tblAuftraege[Auftrag],0)),"")) | C9: =IF($A9="","",IFERROR(INDEX(tblAuftraege[Themenfeld],MATCH($A9,tblAuftraege[Auftrag],0)),"")) | D9: =IF($A9="","",IFERROR(INDEX(tblAuftraege[Kategorie],MATCH($A9,tblAuftraege[Auftrag],0)),"")) | E9: =IF($A9="",0,SUMIFS(tblAuftraege[Einnahmen],tblAuftraege[Datum Einnahmen],">="&E$5,tblAuftraege[Datum Einnahmen],"<"&EDATE(E$5,1),tblAuftraege[Auftrag],$A9)) -> 0 | F9: =IF($A9="",0,SUMIFS(tblAuftraege[Einnahmen],tblAuftraege[Datum Einnahmen],">="&F$5,tblAuftraege[Datum Einnahmen],"<"&EDATE(F$5,1),tblAuftraege[Auftrag],$A9)) -> 0 | G9: =IF($A9="",0,SUMIFS(tblAuftraege[Einnahmen],tblAuftraege[Datum Einnahmen],">="&G$5,tblAuftraege[Datum Einnahmen],"<"&EDATE(G$5,1),tblAuftraege[Auftrag],$A9)) -> 0 | H9: =IF($A9="",0,SUMIFS(tblAuftraege[Einnahmen],tblAuftraege[Datum Einnahmen],">="&H$5,tblAuftraege[Datum Einnahmen],"<"&EDATE(H$5,1),tblAuftraege[Auftrag],$A9)) -> 0 | I9: =IF($A9="",0,SUMIFS(tblAuftraege[Einnahmen],tblAuftraege[Datum Einnahmen],">="&I$5,tblAuftraege[Datum Einnahmen],"<"&EDATE(I$5,1),tblAuftraege[Auftrag],$A9)) -> 0 | J9: =IF($A9="",0,SUMIFS(tblAuftraege[Einnahmen],tblAuftraege[Datum Einnahmen],">="&J$5,tblAuftraege[Datum Einnahmen],"<"&EDATE(J$5,1),tblAuftraege[Auftrag],$A9)) -> 0 | K9: =IF($A9="",0,SUMIFS(tblAuftraege[Einnahmen],tblAuftraege[Datum Einnahmen],">="&K$5,tblAuftraege[Datum Einnahmen],"<"&EDATE(K$5,1),tblAuftraege[Auftrag],$A9)) -> 0 | L9: =IF($A9="",0,SUMIFS(tblAuftraege[Einnahmen],tblAuftraege[Datum Einnahmen],">="&L$5,tblAuftraege[Datum Einnahmen],"<"&EDATE(L$5,1),tblAuftraege[Auftrag],$A9)) -> 0 | ... V9: =IF($A9="",0,SUMIFS(tblAuftraege[Einnahmen],tblAuftraege[Datum Einnahmen],">="&V$5,tblAuftraege[Datum Einnahmen],"<"&EDATE(V$5,1),tblAuftraege[Auftrag],$A9)) -> 0 | W9: =SUM(E9:J9) -> 0 | X9: =SUM(K9:V9) -> 0 | Y9: =SUM(E9:V9) -> 0
B10: =IF($A10="","",IFERROR(INDEX(tblAuftraege[Kostenstelle],MATCH($A10,tblAuftraege[Auftrag],0)),"")) | C10: =IF($A10="","",IFERROR(INDEX(tblAuftraege[Themenfeld],MATCH($A10,tblAuftraege[Auftrag],0)),"")) | D10: =IF($A10="","",IFERROR(INDEX(tblAuftraege[Kategorie],MATCH($A10,tblAuftraege[Auftrag],0)),"")) | E10: =IF($A10="",0,SUMIFS(tblAuftraege[Einnahmen],tblAuftraege[Datum Einnahmen],">="&E$5,tblAuftraege[Datum Einnahmen],"<"&EDATE(E$5,1),tblAuftraege[Auftrag],$A10)) -> 0 | F10: =IF($A10="",0,SUMIFS(tblAuftraege[Einnahmen],tblAuftraege[Datum Einnahmen],">="&F$5,tblAuftraege[Datum Einnahmen],"<"&EDATE(F$5,1),tblAuftraege[Auftrag],$A10)) -> 0 | G10: =IF($A10="",0,SUMIFS(tblAuftraege[Einnahmen],tblAuftraege[Datum Einnahmen],">="&G$5,tblAuftraege[Datum Einnahmen],"<"&EDATE(G$5,1),tblAuftraege[Auftrag],$A10)) -> 0 | H10: =IF($A10="",0,SUMIFS(tblAuftraege[Einnahmen],tblAuftraege[Datum Einnahmen],">="&H$5,tblAuftraege[Datum Einnahmen],"<"&EDATE(H$5,1),tblAuftraege[Auftrag],$A10)) -> 0 | I10: =IF($A10="",0,SUMIFS(tblAuftraege[Einnahmen],tblAuftraege[Datum Einnahmen],">="&I$5,tblAuftraege[Datum Einnahmen],"<"&EDATE(I$5,1),tblAuftraege[Auftrag],$A10)) -> 0 | J10: =IF($A10="",0,SUMIFS(tblAuftraege[Einnahmen],tblAuftraege[Datum Einnahmen],">="&J$5,tblAuftraege[Datum Einnahmen],"<"&EDATE(J$5,1),tblAuftraege[Auftrag],$A10)) -> 0 | K10: =IF($A10="",0,SUMIFS(tblAuftraege[Einnahmen],tblAuftraege[Datum Einnahmen],">="&K$5,tblAuftraege[Datum Einnahmen],"<"&EDATE(K$5,1),tblAuftraege[Auftrag],$A10)) -> 0 | L10: =IF($A10="",0,SUMIFS(tblAuftraege[Einnahmen],tblAuftraege[Datum Einnahmen],">="&L$5,tblAuftraege[Datum Einnahmen],"<"&EDATE(L$5,1),tblAuftraege[Auftrag],$A10)) -> 0 | ... V10: =IF($A10="",0,SUMIFS(tblAuftraege[Einnahmen],tblAuftraege[Datum Einnahmen],">="&V$5,tblAuftraege[Datum Einnahmen],"<"&EDATE(V$5,1),tblAuftraege[Auftrag],$A10)) -> 0 | W10: =SUM(E10:J10) -> 0 | X10: =SUM(K10:V10) -> 0 | Y10: =SUM(E10:V10) -> 0
B11: =IF($A11="","",IFERROR(INDEX(tblAuftraege[Kostenstelle],MATCH($A11,tblAuftraege[Auftrag],0)),"")) | C11: =IF($A11="","",IFERROR(INDEX(tblAuftraege[Themenfeld],MATCH($A11,tblAuftraege[Auftrag],0)),"")) | D11: =IF($A11="","",IFERROR(INDEX(tblAuftraege[Kategorie],MATCH($A11,tblAuftraege[Auftrag],0)),"")) | E11: =IF($A11="",0,SUMIFS(tblAuftraege[Einnahmen],tblAuftraege[Datum Einnahmen],">="&E$5,tblAuftraege[Datum Einnahmen],"<"&EDATE(E$5,1),tblAuftraege[Auftrag],$A11)) -> 0 | F11: =IF($A11="",0,SUMIFS(tblAuftraege[Einnahmen],tblAuftraege[Datum Einnahmen],">="&F$5,tblAuftraege[Datum Einnahmen],"<"&EDATE(F$5,1),tblAuftraege[Auftrag],$A11)) -> 0 | G11: =IF($A11="",0,SUMIFS(tblAuftraege[Einnahmen],tblAuftraege[Datum Einnahmen],">="&G$5,tblAuftraege[Datum Einnahmen],"<"&EDATE(G$5,1),tblAuftraege[Auftrag],$A11)) -> 0 | H11: =IF($A11="",0,SUMIFS(tblAuftraege[Einnahmen],tblAuftraege[Datum Einnahmen],">="&H$5,tblAuftraege[Datum Einnahmen],"<"&EDATE(H$5,1),tblAuftraege[Auftrag],$A11)) -> 0 | I11: =IF($A11="",0,SUMIFS(tblAuftraege[Einnahmen],tblAuftraege[Datum Einnahmen],">="&I$5,tblAuftraege[Datum Einnahmen],"<"&EDATE(I$5,1),tblAuftraege[Auftrag],$A11)) -> 0 | J11: =IF($A11="",0,SUMIFS(tblAuftraege[Einnahmen],tblAuftraege[Datum Einnahmen],">="&J$5,tblAuftraege[Datum Einnahmen],"<"&EDATE(J$5,1),tblAuftraege[Auftrag],$A11)) -> 0 | K11: =IF($A11="",0,SUMIFS(tblAuftraege[Einnahmen],tblAuftraege[Datum Einnahmen],">="&K$5,tblAuftraege[Datum Einnahmen],"<"&EDATE(K$5,1),tblAuftraege[Auftrag],$A11)) -> 0 | L11: =IF($A11="",0,SUMIFS(tblAuftraege[Einnahmen],tblAuftraege[Datum Einnahmen],">="&L$5,tblAuftraege[Datum Einnahmen],"<"&EDATE(L$5,1),tblAuftraege[Auftrag],$A11)) -> 0 | ... V11: =IF($A11="",0,SUMIFS(tblAuftraege[Einnahmen],tblAuftraege[Datum Einnahmen],">="&V$5,tblAuftraege[Datum Einnahmen],"<"&EDATE(V$5,1),tblAuftraege[Auftrag],$A11)) -> 0 | W11: =SUM(E11:J11) -> 0 | X11: =SUM(K11:V11) -> 0 | Y11: =SUM(E11:V11) -> 0
B12: =IF($A12="","",IFERROR(INDEX(tblAuftraege[Kostenstelle],MATCH($A12,tblAuftraege[Auftrag],0)),"")) | C12: =IF($A12="","",IFERROR(INDEX(tblAuftraege[Themenfeld],MATCH($A12,tblAuftraege[Auftrag],0)),"")) | D12: =IF($A12="","",IFERROR(INDEX(tblAuftraege[Kategorie],MATCH($A12,tblAuftraege[Auftrag],0)),"")) | E12: =IF($A12="",0,SUMIFS(tblAuftraege[Einnahmen],tblAuftraege[Datum Einnahmen],">="&E$5,tblAuftraege[Datum Einnahmen],"<"&EDATE(E$5,1),tblAuftraege[Auftrag],$A12)) -> 0 | F12: =IF($A12="",0,SUMIFS(tblAuftraege[Einnahmen],tblAuftraege[Datum Einnahmen],">="&F$5,tblAuftraege[Datum Einnahmen],"<"&EDATE(F$5,1),tblAuftraege[Auftrag],$A12)) -> 0 | G12: =IF($A12="",0,SUMIFS(tblAuftraege[Einnahmen],tblAuftraege[Datum Einnahmen],">="&G$5,tblAuftraege[Datum Einnahmen],"<"&EDATE(G$5,1),tblAuftraege[Auftrag],$A12)) -> 0 | H12: =IF($A12="",0,SUMIFS(tblAuftraege[Einnahmen],tblAuftraege[Datum Einnahmen],">="&H$5,tblAuftraege[Datum Einnahmen],"<"&EDATE(H$5,1),tblAuftraege[Auftrag],$A12)) -> 0 | I12: =IF($A12="",0,SUMIFS(tblAuftraege[Einnahmen],tblAuftraege[Datum Einnahmen],">="&I$5,tblAuftraege[Datum Einnahmen],"<"&EDATE(I$5,1),tblAuftraege[Auftrag],$A12)) -> 0 | J12: =IF($A12="",0,SUMIFS(tblAuftraege[Einnahmen],tblAuftraege[Datum Einnahmen],">="&J$5,tblAuftraege[Datum Einnahmen],"<"&EDATE(J$5,1),tblAuftraege[Auftrag],$A12)) -> 0 | K12: =IF($A12="",0,SUMIFS(tblAuftraege[Einnahmen],tblAuftraege[Datum Einnahmen],">="&K$5,tblAuftraege[Datum Einnahmen],"<"&EDATE(K$5,1),tblAuftraege[Auftrag],$A12)) -> 0 | L12: =IF($A12="",0,SUMIFS(tblAuftraege[Einnahmen],tblAuftraege[Datum Einnahmen],">="&L$5,tblAuftraege[Datum Einnahmen],"<"&EDATE(L$5,1),tblAuftraege[Auftrag],$A12)) -> 0 | ... V12: =IF($A12="",0,SUMIFS(tblAuftraege[Einnahmen],tblAuftraege[Datum Einnahmen],">="&V$5,tblAuftraege[Datum Einnahmen],"<"&EDATE(V$5,1),tblAuftraege[Auftrag],$A12)) -> 0 | W12: =SUM(E12:J12) -> 0 | X12: =SUM(K12:V12) -> 0 | Y12: =SUM(E12:V12) -> 0
B13: =IF($A13="","",IFERROR(INDEX(tblAuftraege[Kostenstelle],MATCH($A13,tblAuftraege[Auftrag],0)),"")) | C13: =IF($A13="","",IFERROR(INDEX(tblAuftraege[Themenfeld],MATCH($A13,tblAuftraege[Auftrag],0)),"")) | D13: =IF($A13="","",IFERROR(INDEX(tblAuftraege[Kategorie],MATCH($A13,tblAuftraege[Auftrag],0)),"")) | E13: =IF($A13="",0,SUMIFS(tblAuftraege[Einnahmen],tblAuftraege[Datum Einnahmen],">="&E$5,tblAuftraege[Datum Einnahmen],"<"&EDATE(E$5,1),tblAuftraege[Auftrag],$A13)) -> 0 | F13: =IF($A13="",0,SUMIFS(tblAuftraege[Einnahmen],tblAuftraege[Datum Einnahmen],">="&F$5,tblAuftraege[Datum Einnahmen],"<"&EDATE(F$5,1),tblAuftraege[Auftrag],$A13)) -> 0 | G13: =IF($A13="",0,SUMIFS(tblAuftraege[Einnahmen],tblAuftraege[Datum Einnahmen],">="&G$5,tblAuftraege[Datum Einnahmen],"<"&EDATE(G$5,1),tblAuftraege[Auftrag],$A13)) -> 0 | H13: =IF($A13="",0,SUMIFS(tblAuftraege[Einnahmen],tblAuftraege[Datum Einnahmen],">="&H$5,tblAuftraege[Datum Einnahmen],"<"&EDATE(H$5,1),tblAuftraege[Auftrag],$A13)) -> 0 | I13: =IF($A13="",0,SUMIFS(tblAuftraege[Einnahmen],tblAuftraege[Datum Einnahmen],">="&I$5,tblAuftraege[Datum Einnahmen],"<"&EDATE(I$5,1),tblAuftraege[Auftrag],$A13)) -> 0 | J13: =IF($A13="",0,SUMIFS(tblAuftraege[Einnahmen],tblAuftraege[Datum Einnahmen],">="&J$5,tblAuftraege[Datum Einnahmen],"<"&EDATE(J$5,1),tblAuftraege[Auftrag],$A13)) -> 0 | K13: =IF($A13="",0,SUMIFS(tblAuftraege[Einnahmen],tblAuftraege[Datum Einnahmen],">="&K$5,tblAuftraege[Datum Einnahmen],"<"&EDATE(K$5,1),tblAuftraege[Auftrag],$A13)) -> 0 | L13: =IF($A13="",0,SUMIFS(tblAuftraege[Einnahmen],tblAuftraege[Datum Einnahmen],">="&L$5,tblAuftraege[Datum Einnahmen],"<"&EDATE(L$5,1),tblAuftraege[Auftrag],$A13)) -> 0 | ... V13: =IF($A13="",0,SUMIFS(tblAuftraege[Einnahmen],tblAuftraege[Datum Einnahmen],">="&V$5,tblAuftraege[Datum Einnahmen],"<"&EDATE(V$5,1),tblAuftraege[Auftrag],$A13)) -> 0 | W13: =SUM(E13:J13) -> 0 | X13: =SUM(K13:V13) -> 0 | Y13: =SUM(E13:V13) -> 0
B14: =IF($A14="","",IFERROR(INDEX(tblAuftraege[Kostenstelle],MATCH($A14,tblAuftraege[Auftrag],0)),"")) | C14: =IF($A14="","",IFERROR(INDEX(tblAuftraege[Themenfeld],MATCH($A14,tblAuftraege[Auftrag],0)),"")) | D14: =IF($A14="","",IFERROR(INDEX(tblAuftraege[Kategorie],MATCH($A14,tblAuftraege[Auftrag],0)),"")) | E14: =IF($A14="",0,SUMIFS(tblAuftraege[Einnahmen],tblAuftraege[Datum Einnahmen],">="&E$5,tblAuftraege[Datum Einnahmen],"<"&EDATE(E$5,1),tblAuftraege[Auftrag],$A14)) -> 0 | F14: =IF($A14="",0,SUMIFS(tblAuftraege[Einnahmen],tblAuftraege[Datum Einnahmen],">="&F$5,tblAuftraege[Datum Einnahmen],"<"&EDATE(F$5,1),tblAuftraege[Auftrag],$A14)) -> 0 | G14: =IF($A14="",0,SUMIFS(tblAuftraege[Einnahmen],tblAuftraege[Datum Einnahmen],">="&G$5,tblAuftraege[Datum Einnahmen],"<"&EDATE(G$5,1),tblAuftraege[Auftrag],$A14)) -> 0 | H14: =IF($A14="",0,SUMIFS(tblAuftraege[Einnahmen],tblAuftraege[Datum Einnahmen],">="&H$5,tblAuftraege[Datum Einnahmen],"<"&EDATE(H$5,1),tblAuftraege[Auftrag],$A14)) -> 0 | I14: =IF($A14="",0,SUMIFS(tblAuftraege[Einnahmen],tblAuftraege[Datum Einnahmen],">="&I$5,tblAuftraege[Datum Einnahmen],"<"&EDATE(I$5,1),tblAuftraege[Auftrag],$A14)) -> 0 | J14: =IF($A14="",0,SUMIFS(tblAuftraege[Einnahmen],tblAuftraege[Datum Einnahmen],">="&J$5,tblAuftraege[Datum Einnahmen],"<"&EDATE(J$5,1),tblAuftraege[Auftrag],$A14)) -> 0 | K14: =IF($A14="",0,SUMIFS(tblAuftraege[Einnahmen],tblAuftraege[Datum Einnahmen],">="&K$5,tblAuftraege[Datum Einnahmen],"<"&EDATE(K$5,1),tblAuftraege[Auftrag],$A14)) -> 0 | L14: =IF($A14="",0,SUMIFS(tblAuftraege[Einnahmen],tblAuftraege[Datum Einnahmen],">="&L$5,tblAuftraege[Datum Einnahmen],"<"&EDATE(L$5,1),tblAuftraege[Auftrag],$A14)) -> 0 | ... V14: =IF($A14="",0,SUMIFS(tblAuftraege[Einnahmen],tblAuftraege[Datum Einnahmen],">="&V$5,tblAuftraege[Datum Einnahmen],"<"&EDATE(V$5,1),tblAuftraege[Auftrag],$A14)) -> 0 | W14: =SUM(E14:J14) -> 0 | X14: =SUM(K14:V14) -> 0 | Y14: =SUM(E14:V14) -> 0
B15: =IF($A15="","",IFERROR(INDEX(tblAuftraege[Kostenstelle],MATCH($A15,tblAuftraege[Auftrag],0)),"")) | C15: =IF($A15="","",IFERROR(INDEX(tblAuftraege[Themenfeld],MATCH($A15,tblAuftraege[Auftrag],0)),"")) | D15: =IF($A15="","",IFERROR(INDEX(tblAuftraege[Kategorie],MATCH($A15,tblAuftraege[Auftrag],0)),"")) | E15: =IF($A15="",0,SUMIFS(tblAuftraege[Einnahmen],tblAuftraege[Datum Einnahmen],">="&E$5,tblAuftraege[Datum Einnahmen],"<"&EDATE(E$5,1),tblAuftraege[Auftrag],$A15)) -> 0 | F15: =IF($A15="",0,SUMIFS(tblAuftraege[Einnahmen],tblAuftraege[Datum Einnahmen],">="&F$5,tblAuftraege[Datum Einnahmen],"<"&EDATE(F$5,1),tblAuftraege[Auftrag],$A15)) -> 0 | G15: =IF($A15="",0,SUMIFS(tblAuftraege[Einnahmen],tblAuftraege[Datum Einnahmen],">="&G$5,tblAuftraege[Datum Einnahmen],"<"&EDATE(G$5,1),tblAuftraege[Auftrag],$A15)) -> 0 | H15: =IF($A15="",0,SUMIFS(tblAuftraege[Einnahmen],tblAuftraege[Datum Einnahmen],">="&H$5,tblAuftraege[Datum Einnahmen],"<"&EDATE(H$5,1),tblAuftraege[Auftrag],$A15)) -> 0 | I15: =IF($A15="",0,SUMIFS(tblAuftraege[Einnahmen],tblAuftraege[Datum Einnahmen],">="&I$5,tblAuftraege[Datum Einnahmen],"<"&EDATE(I$5,1),tblAuftraege[Auftrag],$A15)) -> 0 | J15: =IF($A15="",0,SUMIFS(tblAuftraege[Einnahmen],tblAuftraege[Datum Einnahmen],">="&J$5,tblAuftraege[Datum Einnahmen],"<"&EDATE(J$5,1),tblAuftraege[Auftrag],$A15)) -> 0 | K15: =IF($A15="",0,SUMIFS(tblAuftraege[Einnahmen],tblAuftraege[Datum Einnahmen],">="&K$5,tblAuftraege[Datum Einnahmen],"<"&EDATE(K$5,1),tblAuftraege[Auftrag],$A15)) -> 0 | L15: =IF($A15="",0,SUMIFS(tblAuftraege[Einnahmen],tblAuftraege[Datum Einnahmen],">="&L$5,tblAuftraege[Datum Einnahmen],"<"&EDATE(L$5,1),tblAuftraege[Auftrag],$A15)) -> 0 | ... V15: =IF($A15="",0,SUMIFS(tblAuftraege[Einnahmen],tblAuftraege[Datum Einnahmen],">="&V$5,tblAuftraege[Datum Einnahmen],"<"&EDATE(V$5,1),tblAuftraege[Auftrag],$A15)) -> 0 | W15: =SUM(E15:J15) -> 0 | X15: =SUM(K15:V15) -> 0 | Y15: =SUM(E15:V15) -> 0
B16: =IF($A16="","",IFERROR(INDEX(tblAuftraege[Kostenstelle],MATCH($A16,tblAuftraege[Auftrag],0)),"")) | C16: =IF($A16="","",IFERROR(INDEX(tblAuftraege[Themenfeld],MATCH($A16,tblAuftraege[Auftrag],0)),"")) | D16: =IF($A16="","",IFERROR(INDEX(tblAuftraege[Kategorie],MATCH($A16,tblAuftraege[Auftrag],0)),"")) | E16: =IF($A16="",0,SUMIFS(tblAuftraege[Einnahmen],tblAuftraege[Datum Einnahmen],">="&E$5,tblAuftraege[Datum Einnahmen],"<"&EDATE(E$5,1),tblAuftraege[Auftrag],$A16)) -> 0 | F16: =IF($A16="",0,SUMIFS(tblAuftraege[Einnahmen],tblAuftraege[Datum Einnahmen],">="&F$5,tblAuftraege[Datum Einnahmen],"<"&EDATE(F$5,1),tblAuftraege[Auftrag],$A16)) -> 0 | G16: =IF($A16="",0,SUMIFS(tblAuftraege[Einnahmen],tblAuftraege[Datum Einnahmen],">="&G$5,tblAuftraege[Datum Einnahmen],"<"&EDATE(G$5,1),tblAuftraege[Auftrag],$A16)) -> 0 | H16: =IF($A16="",0,SUMIFS(tblAuftraege[Einnahmen],tblAuftraege[Datum Einnahmen],">="&H$5,tblAuftraege[Datum Einnahmen],"<"&EDATE(H$5,1),tblAuftraege[Auftrag],$A16)) -> 0 | I16: =IF($A16="",0,SUMIFS(tblAuftraege[Einnahmen],tblAuftraege[Datum Einnahmen],">="&I$5,tblAuftraege[Datum Einnahmen],"<"&EDATE(I$5,1),tblAuftraege[Auftrag],$A16)) -> 0 | J16: =IF($A16="",0,SUMIFS(tblAuftraege[Einnahmen],tblAuftraege[Datum Einnahmen],">="&J$5,tblAuftraege[Datum Einnahmen],"<"&EDATE(J$5,1),tblAuftraege[Auftrag],$A16)) -> 0 | K16: =IF($A16="",0,SUMIFS(tblAuftraege[Einnahmen],tblAuftraege[Datum Einnahmen],">="&K$5,tblAuftraege[Datum Einnahmen],"<"&EDATE(K$5,1),tblAuftraege[Auftrag],$A16)) -> 0 | L16: =IF($A16="",0,SUMIFS(tblAuftraege[Einnahmen],tblAuftraege[Datum Einnahmen],">="&L$5,tblAuftraege[Datum Einnahmen],"<"&EDATE(L$5,1),tblAuftraege[Auftrag],$A16)) -> 0 | ... V16: =IF($A16="",0,SUMIFS(tblAuftraege[Einnahmen],tblAuftraege[Datum Einnahmen],">="&V$5,tblAuftraege[Datum Einnahmen],"<"&EDATE(V$5,1),tblAuftraege[Auftrag],$A16)) -> 0 | W16: =SUM(E16:J16) -> 0 | X16: =SUM(K16:V16) -> 0 | Y16: =SUM(E16:V16) -> 0
B17: =IF($A17="","",IFERROR(INDEX(tblAuftraege[Kostenstelle],MATCH($A17,tblAuftraege[Auftrag],0)),"")) | C17: =IF($A17="","",IFERROR(INDEX(tblAuftraege[Themenfeld],MATCH($A17,tblAuftraege[Auftrag],0)),"")) | D17: =IF($A17="","",IFERROR(INDEX(tblAuftraege[Kategorie],MATCH($A17,tblAuftraege[Auftrag],0)),"")) | E17: =IF($A17="",0,SUMIFS(tblAuftraege[Einnahmen],tblAuftraege[Datum Einnahmen],">="&E$5,tblAuftraege[Datum Einnahmen],"<"&EDATE(E$5,1),tblAuftraege[Auftrag],$A17)) -> 0 | F17: =IF($A17="",0,SUMIFS(tblAuftraege[Einnahmen],tblAuftraege[Datum Einnahmen],">="&F$5,tblAuftraege[Datum Einnahmen],"<"&EDATE(F$5,1),tblAuftraege[Auftrag],$A17)) -> 0 | G17: =IF($A17="",0,SUMIFS(tblAuftraege[Einnahmen],tblAuftraege[Datum Einnahmen],">="&G$5,tblAuftraege[Datum Einnahmen],"<"&EDATE(G$5,1),tblAuftraege[Auftrag],$A17)) -> 0 | H17: =IF($A17="",0,SUMIFS(tblAuftraege[Einnahmen],tblAuftraege[Datum Einnahmen],">="&H$5,tblAuftraege[Datum Einnahmen],"<"&EDATE(H$5,1),tblAuftraege[Auftrag],$A17)) -> 0 | I17: =IF($A17="",0,SUMIFS(tblAuftraege[Einnahmen],tblAuftraege[Datum Einnahmen],">="&I$5,tblAuftraege[Datum Einnahmen],"<"&EDATE(I$5,1),tblAuftraege[Auftrag],$A17)) -> 0 | J17: =IF($A17="",0,SUMIFS(tblAuftraege[Einnahmen],tblAuftraege[Datum Einnahmen],">="&J$5,tblAuftraege[Datum Einnahmen],"<"&EDATE(J$5,1),tblAuftraege[Auftrag],$A17)) -> 0 | K17: =IF($A17="",0,SUMIFS(tblAuftraege[Einnahmen],tblAuftraege[Datum Einnahmen],">="&K$5,tblAuftraege[Datum Einnahmen],"<"&EDATE(K$5,1),tblAuftraege[Auftrag],$A17)) -> 0 | L17: =IF($A17="",0,SUMIFS(tblAuftraege[Einnahmen],tblAuftraege[Datum Einnahmen],">="&L$5,tblAuftraege[Datum Einnahmen],"<"&EDATE(L$5,1),tblAuftraege[Auftrag],$A17)) -> 0 | ... V17: =IF($A17="",0,SUMIFS(tblAuftraege[Einnahmen],tblAuftraege[Datum Einnahmen],">="&V$5,tblAuftraege[Datum Einnahmen],"<"&EDATE(V$5,1),tblAuftraege[Auftrag],$A17)) -> 0 | W17: =SUM(E17:J17) -> 0 | X17: =SUM(K17:V17) -> 0 | Y17: =SUM(E17:V17) -> 0
B18: =IF($A18="","",IFERROR(INDEX(tblAuftraege[Kostenstelle],MATCH($A18,tblAuftraege[Auftrag],0)),"")) | C18: =IF($A18="","",IFERROR(INDEX(tblAuftraege[Themenfeld],MATCH($A18,tblAuftraege[Auftrag],0)),"")) | D18: =IF($A18="","",IFERROR(INDEX(tblAuftraege[Kategorie],MATCH($A18,tblAuftraege[Auftrag],0)),"")) | E18: =IF($A18="",0,SUMIFS(tblAuftraege[Einnahmen],tblAuftraege[Datum Einnahmen],">="&E$5,tblAuftraege[Datum Einnahmen],"<"&EDATE(E$5,1),tblAuftraege[Auftrag],$A18)) -> 0 | F18: =IF($A18="",0,SUMIFS(tblAuftraege[Einnahmen],tblAuftraege[Datum Einnahmen],">="&F$5,tblAuftraege[Datum Einnahmen],"<"&EDATE(F$5,1),tblAuftraege[Auftrag],$A18)) -> 0 | G18: =IF($A18="",0,SUMIFS(tblAuftraege[Einnahmen],tblAuftraege[Datum Einnahmen],">="&G$5,tblAuftraege[Datum Einnahmen],"<"&EDATE(G$5,1),tblAuftraege[Auftrag],$A18)) -> 0 | H18: =IF($A18="",0,SUMIFS(tblAuftraege[Einnahmen],tblAuftraege[Datum Einnahmen],">="&H$5,tblAuftraege[Datum Einnahmen],"<"&EDATE(H$5,1),tblAuftraege[Auftrag],$A18)) -> 0 | I18: =IF($A18="",0,SUMIFS(tblAuftraege[Einnahmen],tblAuftraege[Datum Einnahmen],">="&I$5,tblAuftraege[Datum Einnahmen],"<"&EDATE(I$5,1),tblAuftraege[Auftrag],$A18)) -> 0 | J18: =IF($A18="",0,SUMIFS(tblAuftraege[Einnahmen],tblAuftraege[Datum Einnahmen],">="&J$5,tblAuftraege[Datum Einnahmen],"<"&EDATE(J$5,1),tblAuftraege[Auftrag],$A18)) -> 0 | K18: =IF($A18="",0,SUMIFS(tblAuftraege[Einnahmen],tblAuftraege[Datum Einnahmen],">="&K$5,tblAuftraege[Datum Einnahmen],"<"&EDATE(K$5,1),tblAuftraege[Auftrag],$A18)) -> 0 | L18: =IF($A18="",0,SUMIFS(tblAuftraege[Einnahmen],tblAuftraege[Datum Einnahmen],">="&L$5,tblAuftraege[Datum Einnahmen],"<"&EDATE(L$5,1),tblAuftraege[Auftrag],$A18)) -> 0 | ... V18: =IF($A18="",0,SUMIFS(tblAuftraege[Einnahmen],tblAuftraege[Datum Einnahmen],">="&V$5,tblAuftraege[Datum Einnahmen],"<"&EDATE(V$5,1),tblAuftraege[Auftrag],$A18)) -> 0 | W18: =SUM(E18:J18) -> 0 | X18: =SUM(K18:V18) -> 0 | Y18: =SUM(E18:V18) -> 0
B19: =IF($A19="","",IFERROR(INDEX(tblAuftraege[Kostenstelle],MATCH($A19,tblAuftraege[Auftrag],0)),"")) | C19: =IF($A19="","",IFERROR(INDEX(tblAuftraege[Themenfeld],MATCH($A19,tblAuftraege[Auftrag],0)),"")) | D19: =IF($A19="","",IFERROR(INDEX(tblAuftraege[Kategorie],MATCH($A19,tblAuftraege[Auftrag],0)),"")) | E19: =IF($A19="",0,SUMIFS(tblAuftraege[Einnahmen],tblAuftraege[Datum Einnahmen],">="&E$5,tblAuftraege[Datum Einnahmen],"<"&EDATE(E$5,1),tblAuftraege[Auftrag],$A19)) -> 0 | F19: =IF($A19="",0,SUMIFS(tblAuftraege[Einnahmen],tblAuftraege[Datum Einnahmen],">="&F$5,tblAuftraege[Datum Einnahmen],"<"&EDATE(F$5,1),tblAuftraege[Auftrag],$A19)) -> 0 | G19: =IF($A19="",0,SUMIFS(tblAuftraege[Einnahmen],tblAuftraege[Datum Einnahmen],">="&G$5,tblAuftraege[Datum Einnahmen],"<"&EDATE(G$5,1),tblAuftraege[Auftrag],$A19)) -> 0 | H19: =IF($A19="",0,SUMIFS(tblAuftraege[Einnahmen],tblAuftraege[Datum Einnahmen],">="&H$5,tblAuftraege[Datum Einnahmen],"<"&EDATE(H$5,1),tblAuftraege[Auftrag],$A19)) -> 0 | I19: =IF($A19="",0,SUMIFS(tblAuftraege[Einnahmen],tblAuftraege[Datum Einnahmen],">="&I$5,tblAuftraege[Datum Einnahmen],"<"&EDATE(I$5,1),tblAuftraege[Auftrag],$A19)) -> 0 | J19: =IF($A19="",0,SUMIFS(tblAuftraege[Einnahmen],tblAuftraege[Datum Einnahmen],">="&J$5,tblAuftraege[Datum Einnahmen],"<"&EDATE(J$5,1),tblAuftraege[Auftrag],$A19)) -> 0 | K19: =IF($A19="",0,SUMIFS(tblAuftraege[Einnahmen],tblAuftraege[Datum Einnahmen],">="&K$5,tblAuftraege[Datum Einnahmen],"<"&EDATE(K$5,1),tblAuftraege[Auftrag],$A19)) -> 0 | L19: =IF($A19="",0,SUMIFS(tblAuftraege[Einnahmen],tblAuftraege[Datum Einnahmen],">="&L$5,tblAuftraege[Datum Einnahmen],"<"&EDATE(L$5,1),tblAuftraege[Auftrag],$A19)) -> 0 | ... V19: =IF($A19="",0,SUMIFS(tblAuftraege[Einnahmen],tblAuftraege[Datum Einnahmen],">="&V$5,tblAuftraege[Datum Einnahmen],"<"&EDATE(V$5,1),tblAuftraege[Auftrag],$A19)) -> 0 | W19: =SUM(E19:J19) -> 0 | X19: =SUM(K19:V19) -> 0 | Y19: =SUM(E19:V19) -> 0
... B57: =IF($A57="","",IFERROR(INDEX(tblAuftraege[Kostenstelle],MATCH($A57,tblAuftraege[Auftrag],0)),"")) | C57: =IF($A57="","",IFERROR(INDEX(tblAuftraege[Themenfeld],MATCH($A57,tblAuftraege[Auftrag],0)),"")) | D57: =IF($A57="","",IFERROR(INDEX(tblAuftraege[Kategorie],MATCH($A57,tblAuftraege[Auftrag],0)),"")) | E57: =IF($A57="",0,SUMIFS(tblAuftraege[Einnahmen],tblAuftraege[Datum Einnahmen],">="&E$5,tblAuftraege[Datum Einnahmen],"<"&EDATE(E$5,1),tblAuftraege[Auftrag],$A57)) -> 0 | F57: =IF($A57="",0,SUMIFS(tblAuftraege[Einnahmen],tblAuftraege[Datum Einnahmen],">="&F$5,tblAuftraege[Datum Einnahmen],"<"&EDATE(F$5,1),tblAuftraege[Auftrag],$A57)) -> 0 | G57: =IF($A57="",0,SUMIFS(tblAuftraege[Einnahmen],tblAuftraege[Datum Einnahmen],">="&G$5,tblAuftraege[Datum Einnahmen],"<"&EDATE(G$5,1),tblAuftraege[Auftrag],$A57)) -> 0 | H57: =IF($A57="",0,SUMIFS(tblAuftraege[Einnahmen],tblAuftraege[Datum Einnahmen],">="&H$5,tblAuftraege[Datum Einnahmen],"<"&EDATE(H$5,1),tblAuftraege[Auftrag],$A57)) -> 0 | I57: =IF($A57="",0,SUMIFS(tblAuftraege[Einnahmen],tblAuftraege[Datum Einnahmen],">="&I$5,tblAuftraege[Datum Einnahmen],"<"&EDATE(I$5,1),tblAuftraege[Auftrag],$A57)) -> 0 | J57: =IF($A57="",0,SUMIFS(tblAuftraege[Einnahmen],tblAuftraege[Datum Einnahmen],">="&J$5,tblAuftraege[Datum Einnahmen],"<"&EDATE(J$5,1),tblAuftraege[Auftrag],$A57)) -> 0 | K57: =IF($A57="",0,SUMIFS(tblAuftraege[Einnahmen],tblAuftraege[Datum Einnahmen],">="&K$5,tblAuftraege[Datum Einnahmen],"<"&EDATE(K$5,1),tblAuftraege[Auftrag],$A57)) -> 0 | L57: =IF($A57="",0,SUMIFS(tblAuftraege[Einnahmen],tblAuftraege[Datum Einnahmen],">="&L$5,tblAuftraege[Datum Einnahmen],"<"&EDATE(L$5,1),tblAuftraege[Auftrag],$A57)) -> 0 | ... V57: =IF($A57="",0,SUMIFS(tblAuftraege[Einnahmen],tblAuftraege[Datum Einnahmen],">="&V$5,tblAuftraege[Datum Einnahmen],"<"&EDATE(V$5,1),tblAuftraege[Auftrag],$A57)) -> 0 | W57: =SUM(E57:J57) -> 0 | X57: =SUM(K57:V57) -> 0 | Y57: =SUM(E57:V57) -> 0
A58: Noch nicht erfasste Aufträge | B58: Differenz | E58: =E59-SUM(E8:E57) -> 0 | F58: =F59-SUM(F8:F57) -> 0 | G58: =G59-SUM(G8:G57) -> 0 | H58: =H59-SUM(H8:H57) -> 0 | I58: =I59-SUM(I8:I57) -> 0 | J58: =J59-SUM(J8:J57) -> 0 | K58: =K59-SUM(K8:K57) -> 0 | L58: =L59-SUM(L8:L57) -> 0 | ... Y58: =Y59-SUM(Y8:Y57) -> 0
A59: Summe Einnahmen | E59: =SUMIFS(tblAuftraege[Einnahmen],tblAuftraege[Datum Einnahmen],">="&E$5,tblAuftraege[Datum Einnahmen],"<"&EDATE(E$5,1)) -> 0 | F59: =SUMIFS(tblAuftraege[Einnahmen],tblAuftraege[Datum Einnahmen],">="&F$5,tblAuftraege[Datum Einnahmen],"<"&EDATE(F$5,1)) -> 0 | G59: =SUMIFS(tblAuftraege[Einnahmen],tblAuftraege[Datum Einnahmen],">="&G$5,tblAuftraege[Datum Einnahmen],"<"&EDATE(G$5,1)) -> 0 | H59: =SUMIFS(tblAuftraege[Einnahmen],tblAuftraege[Datum Einnahmen],">="&H$5,tblAuftraege[Datum Einnahmen],"<"&EDATE(H$5,1)) -> 0 | I59: =SUMIFS(tblAuftraege[Einnahmen],tblAuftraege[Datum Einnahmen],">="&I$5,tblAuftraege[Datum Einnahmen],"<"&EDATE(I$5,1)) -> 0 | J59: =SUMIFS(tblAuftraege[Einnahmen],tblAuftraege[Datum Einnahmen],">="&J$5,tblAuftraege[Datum Einnahmen],"<"&EDATE(J$5,1)) -> 0 | K59: =SUMIFS(tblAuftraege[Einnahmen],tblAuftraege[Datum Einnahmen],">="&K$5,tblAuftraege[Datum Einnahmen],"<"&EDATE(K$5,1)) -> 0 | L59: =SUMIFS(tblAuftraege[Einnahmen],tblAuftraege[Datum Einnahmen],">="&L$5,tblAuftraege[Datum Einnahmen],"<"&EDATE(L$5,1)) -> 0 | ... V59: =SUMIFS(tblAuftraege[Einnahmen],tblAuftraege[Datum Einnahmen],">="&V$5,tblAuftraege[Datum Einnahmen],"<"&EDATE(V$5,1)) -> 0 | W59: =SUM(E59:J59) -> 0 | X59: =SUM(K59:V59) -> 0 | Y59: =SUM(E59:V59) -> 0
A61: 2 AUSGABEN JE AUFTRAG (Quelle: Reiter „Aufträge“)
B62: =IF($A62="","",IFERROR(INDEX(tblAuftraege[Kostenstelle],MATCH($A62,tblAuftraege[Auftrag],0)),"")) | C62: =IF($A62="","",IFERROR(INDEX(tblAuftraege[Themenfeld],MATCH($A62,tblAuftraege[Auftrag],0)),"")) | D62: =IF($A62="","",IFERROR(INDEX(tblAuftraege[Kategorie],MATCH($A62,tblAuftraege[Auftrag],0)),"")) | E62: =IF($A62="",0,SUMIFS(tblAuftraege[Ausgaben],tblAuftraege[Datum Ausgaben],">="&E$5,tblAuftraege[Datum Ausgaben],"<"&EDATE(E$5,1),tblAuftraege[Auftrag],$A62)) -> 0 | F62: =IF($A62="",0,SUMIFS(tblAuftraege[Ausgaben],tblAuftraege[Datum Ausgaben],">="&F$5,tblAuftraege[Datum Ausgaben],"<"&EDATE(F$5,1),tblAuftraege[Auftrag],$A62)) -> 0 | G62: =IF($A62="",0,SUMIFS(tblAuftraege[Ausgaben],tblAuftraege[Datum Ausgaben],">="&G$5,tblAuftraege[Datum Ausgaben],"<"&EDATE(G$5,1),tblAuftraege[Auftrag],$A62)) -> 0 | H62: =IF($A62="",0,SUMIFS(tblAuftraege[Ausgaben],tblAuftraege[Datum Ausgaben],">="&H$5,tblAuftraege[Datum Ausgaben],"<"&EDATE(H$5,1),tblAuftraege[Auftrag],$A62)) -> 0 | I62: =IF($A62="",0,SUMIFS(tblAuftraege[Ausgaben],tblAuftraege[Datum Ausgaben],">="&I$5,tblAuftraege[Datum Ausgaben],"<"&EDATE(I$5,1),tblAuftraege[Auftrag],$A62)) -> 0 | J62: =IF($A62="",0,SUMIFS(tblAuftraege[Ausgaben],tblAuftraege[Datum Ausgaben],">="&J$5,tblAuftraege[Datum Ausgaben],"<"&EDATE(J$5,1),tblAuftraege[Auftrag],$A62)) -> 0 | K62: =IF($A62="",0,SUMIFS(tblAuftraege[Ausgaben],tblAuftraege[Datum Ausgaben],">="&K$5,tblAuftraege[Datum Ausgaben],"<"&EDATE(K$5,1),tblAuftraege[Auftrag],$A62)) -> 0 | L62: =IF($A62="",0,SUMIFS(tblAuftraege[Ausgaben],tblAuftraege[Datum Ausgaben],">="&L$5,tblAuftraege[Datum Ausgaben],"<"&EDATE(L$5,1),tblAuftraege[Auftrag],$A62)) -> 0 | ... V62: =IF($A62="",0,SUMIFS(tblAuftraege[Ausgaben],tblAuftraege[Datum Ausgaben],">="&V$5,tblAuftraege[Datum Ausgaben],"<"&EDATE(V$5,1),tblAuftraege[Auftrag],$A62)) -> 0 | W62: =SUM(E62:J62) -> 0 | X62: =SUM(K62:V62) -> 0 | Y62: =SUM(E62:V62) -> 0
B63: =IF($A63="","",IFERROR(INDEX(tblAuftraege[Kostenstelle],MATCH($A63,tblAuftraege[Auftrag],0)),"")) | C63: =IF($A63="","",IFERROR(INDEX(tblAuftraege[Themenfeld],MATCH($A63,tblAuftraege[Auftrag],0)),"")) | D63: =IF($A63="","",IFERROR(INDEX(tblAuftraege[Kategorie],MATCH($A63,tblAuftraege[Auftrag],0)),"")) | E63: =IF($A63="",0,SUMIFS(tblAuftraege[Ausgaben],tblAuftraege[Datum Ausgaben],">="&E$5,tblAuftraege[Datum Ausgaben],"<"&EDATE(E$5,1),tblAuftraege[Auftrag],$A63)) -> 0 | F63: =IF($A63="",0,SUMIFS(tblAuftraege[Ausgaben],tblAuftraege[Datum Ausgaben],">="&F$5,tblAuftraege[Datum Ausgaben],"<"&EDATE(F$5,1),tblAuftraege[Auftrag],$A63)) -> 0 | G63: =IF($A63="",0,SUMIFS(tblAuftraege[Ausgaben],tblAuftraege[Datum Ausgaben],">="&G$5,tblAuftraege[Datum Ausgaben],"<"&EDATE(G$5,1),tblAuftraege[Auftrag],$A63)) -> 0 | H63: =IF($A63="",0,SUMIFS(tblAuftraege[Ausgaben],tblAuftraege[Datum Ausgaben],">="&H$5,tblAuftraege[Datum Ausgaben],"<"&EDATE(H$5,1),tblAuftraege[Auftrag],$A63)) -> 0 | I63: =IF($A63="",0,SUMIFS(tblAuftraege[Ausgaben],tblAuftraege[Datum Ausgaben],">="&I$5,tblAuftraege[Datum Ausgaben],"<"&EDATE(I$5,1),tblAuftraege[Auftrag],$A63)) -> 0 | J63: =IF($A63="",0,SUMIFS(tblAuftraege[Ausgaben],tblAuftraege[Datum Ausgaben],">="&J$5,tblAuftraege[Datum Ausgaben],"<"&EDATE(J$5,1),tblAuftraege[Auftrag],$A63)) -> 0 | K63: =IF($A63="",0,SUMIFS(tblAuftraege[Ausgaben],tblAuftraege[Datum Ausgaben],">="&K$5,tblAuftraege[Datum Ausgaben],"<"&EDATE(K$5,1),tblAuftraege[Auftrag],$A63)) -> 0 | L63: =IF($A63="",0,SUMIFS(tblAuftraege[Ausgaben],tblAuftraege[Datum Ausgaben],">="&L$5,tblAuftraege[Datum Ausgaben],"<"&EDATE(L$5,1),tblAuftraege[Auftrag],$A63)) -> 0 | ... V63: =IF($A63="",0,SUMIFS(tblAuftraege[Ausgaben],tblAuftraege[Datum Ausgaben],">="&V$5,tblAuftraege[Datum Ausgaben],"<"&EDATE(V$5,1),tblAuftraege[Auftrag],$A63)) -> 0 | W63: =SUM(E63:J63) -> 0 | X63: =SUM(K63:V63) -> 0 | Y63: =SUM(E63:V63) -> 0
B64: =IF($A64="","",IFERROR(INDEX(tblAuftraege[Kostenstelle],MATCH($A64,tblAuftraege[Auftrag],0)),"")) | C64: =IF($A64="","",IFERROR(INDEX(tblAuftraege[Themenfeld],MATCH($A64,tblAuftraege[Auftrag],0)),"")) | D64: =IF($A64="","",IFERROR(INDEX(tblAuftraege[Kategorie],MATCH($A64,tblAuftraege[Auftrag],0)),"")) | E64: =IF($A64="",0,SUMIFS(tblAuftraege[Ausgaben],tblAuftraege[Datum Ausgaben],">="&E$5,tblAuftraege[Datum Ausgaben],"<"&EDATE(E$5,1),tblAuftraege[Auftrag],$A64)) -> 0 | F64: =IF($A64="",0,SUMIFS(tblAuftraege[Ausgaben],tblAuftraege[Datum Ausgaben],">="&F$5,tblAuftraege[Datum Ausgaben],"<"&EDATE(F$5,1),tblAuftraege[Auftrag],$A64)) -> 0 | G64: =IF($A64="",0,SUMIFS(tblAuftraege[Ausgaben],tblAuftraege[Datum Ausgaben],">="&G$5,tblAuftraege[Datum Ausgaben],"<"&EDATE(G$5,1),tblAuftraege[Auftrag],$A64)) -> 0 | H64: =IF($A64="",0,SUMIFS(tblAuftraege[Ausgaben],tblAuftraege[Datum Ausgaben],">="&H$5,tblAuftraege[Datum Ausgaben],"<"&EDATE(H$5,1),tblAuftraege[Auftrag],$A64)) -> 0 | I64: =IF($A64="",0,SUMIFS(tblAuftraege[Ausgaben],tblAuftraege[Datum Ausgaben],">="&I$5,tblAuftraege[Datum Ausgaben],"<"&EDATE(I$5,1),tblAuftraege[Auftrag],$A64)) -> 0 | J64: =IF($A64="",0,SUMIFS(tblAuftraege[Ausgaben],tblAuftraege[Datum Ausgaben],">="&J$5,tblAuftraege[Datum Ausgaben],"<"&EDATE(J$5,1),tblAuftraege[Auftrag],$A64)) -> 0 | K64: =IF($A64="",0,SUMIFS(tblAuftraege[Ausgaben],tblAuftraege[Datum Ausgaben],">="&K$5,tblAuftraege[Datum Ausgaben],"<"&EDATE(K$5,1),tblAuftraege[Auftrag],$A64)) -> 0 | L64: =IF($A64="",0,SUMIFS(tblAuftraege[Ausgaben],tblAuftraege[Datum Ausgaben],">="&L$5,tblAuftraege[Datum Ausgaben],"<"&EDATE(L$5,1),tblAuftraege[Auftrag],$A64)) -> 0 | ... V64: =IF($A64="",0,SUMIFS(tblAuftraege[Ausgaben],tblAuftraege[Datum Ausgaben],">="&V$5,tblAuftraege[Datum Ausgaben],"<"&EDATE(V$5,1),tblAuftraege[Auftrag],$A64)) -> 0 | W64: =SUM(E64:J64) -> 0 | X64: =SUM(K64:V64) -> 0 | Y64: =SUM(E64:V64) -> 0
B65: =IF($A65="","",IFERROR(INDEX(tblAuftraege[Kostenstelle],MATCH($A65,tblAuftraege[Auftrag],0)),"")) | C65: =IF($A65="","",IFERROR(INDEX(tblAuftraege[Themenfeld],MATCH($A65,tblAuftraege[Auftrag],0)),"")) | D65: =IF($A65="","",IFERROR(INDEX(tblAuftraege[Kategorie],MATCH($A65,tblAuftraege[Auftrag],0)),"")) | E65: =IF($A65="",0,SUMIFS(tblAuftraege[Ausgaben],tblAuftraege[Datum Ausgaben],">="&E$5,tblAuftraege[Datum Ausgaben],"<"&EDATE(E$5,1),tblAuftraege[Auftrag],$A65)) -> 0 | F65: =IF($A65="",0,SUMIFS(tblAuftraege[Ausgaben],tblAuftraege[Datum Ausgaben],">="&F$5,tblAuftraege[Datum Ausgaben],"<"&EDATE(F$5,1),tblAuftraege[Auftrag],$A65)) -> 0 | G65: =IF($A65="",0,SUMIFS(tblAuftraege[Ausgaben],tblAuftraege[Datum Ausgaben],">="&G$5,tblAuftraege[Datum Ausgaben],"<"&EDATE(G$5,1),tblAuftraege[Auftrag],$A65)) -> 0 | H65: =IF($A65="",0,SUMIFS(tblAuftraege[Ausgaben],tblAuftraege[Datum Ausgaben],">="&H$5,tblAuftraege[Datum Ausgaben],"<"&EDATE(H$5,1),tblAuftraege[Auftrag],$A65)) -> 0 | I65: =IF($A65="",0,SUMIFS(tblAuftraege[Ausgaben],tblAuftraege[Datum Ausgaben],">="&I$5,tblAuftraege[Datum Ausgaben],"<"&EDATE(I$5,1),tblAuftraege[Auftrag],$A65)) -> 0 | J65: =IF($A65="",0,SUMIFS(tblAuftraege[Ausgaben],tblAuftraege[Datum Ausgaben],">="&J$5,tblAuftraege[Datum Ausgaben],"<"&EDATE(J$5,1),tblAuftraege[Auftrag],$A65)) -> 0 | K65: =IF($A65="",0,SUMIFS(tblAuftraege[Ausgaben],tblAuftraege[Datum Ausgaben],">="&K$5,tblAuftraege[Datum Ausgaben],"<"&EDATE(K$5,1),tblAuftraege[Auftrag],$A65)) -> 0 | L65: =IF($A65="",0,SUMIFS(tblAuftraege[Ausgaben],tblAuftraege[Datum Ausgaben],">="&L$5,tblAuftraege[Datum Ausgaben],"<"&EDATE(L$5,1),tblAuftraege[Auftrag],$A65)) -> 0 | ... V65: =IF($A65="",0,SUMIFS(tblAuftraege[Ausgaben],tblAuftraege[Datum Ausgaben],">="&V$5,tblAuftraege[Datum Ausgaben],"<"&EDATE(V$5,1),tblAuftraege[Auftrag],$A65)) -> 0 | W65: =SUM(E65:J65) -> 0 | X65: =SUM(K65:V65) -> 0 | Y65: =SUM(E65:V65) -> 0
B66: =IF($A66="","",IFERROR(INDEX(tblAuftraege[Kostenstelle],MATCH($A66,tblAuftraege[Auftrag],0)),"")) | C66: =IF($A66="","",IFERROR(INDEX(tblAuftraege[Themenfeld],MATCH($A66,tblAuftraege[Auftrag],0)),"")) | D66: =IF($A66="","",IFERROR(INDEX(tblAuftraege[Kategorie],MATCH($A66,tblAuftraege[Auftrag],0)),"")) | E66: =IF($A66="",0,SUMIFS(tblAuftraege[Ausgaben],tblAuftraege[Datum Ausgaben],">="&E$5,tblAuftraege[Datum Ausgaben],"<"&EDATE(E$5,1),tblAuftraege[Auftrag],$A66)) -> 0 | F66: =IF($A66="",0,SUMIFS(tblAuftraege[Ausgaben],tblAuftraege[Datum Ausgaben],">="&F$5,tblAuftraege[Datum Ausgaben],"<"&EDATE(F$5,1),tblAuftraege[Auftrag],$A66)) -> 0 | G66: =IF($A66="",0,SUMIFS(tblAuftraege[Ausgaben],tblAuftraege[Datum Ausgaben],">="&G$5,tblAuftraege[Datum Ausgaben],"<"&EDATE(G$5,1),tblAuftraege[Auftrag],$A66)) -> 0 | H66: =IF($A66="",0,SUMIFS(tblAuftraege[Ausgaben],tblAuftraege[Datum Ausgaben],">="&H$5,tblAuftraege[Datum Ausgaben],"<"&EDATE(H$5,1),tblAuftraege[Auftrag],$A66)) -> 0 | I66: =IF($A66="",0,SUMIFS(tblAuftraege[Ausgaben],tblAuftraege[Datum Ausgaben],">="&I$5,tblAuftraege[Datum Ausgaben],"<"&EDATE(I$5,1),tblAuftraege[Auftrag],$A66)) -> 0 | J66: =IF($A66="",0,SUMIFS(tblAuftraege[Ausgaben],tblAuftraege[Datum Ausgaben],">="&J$5,tblAuftraege[Datum Ausgaben],"<"&EDATE(J$5,1),tblAuftraege[Auftrag],$A66)) -> 0 | K66: =IF($A66="",0,SUMIFS(tblAuftraege[Ausgaben],tblAuftraege[Datum Ausgaben],">="&K$5,tblAuftraege[Datum Ausgaben],"<"&EDATE(K$5,1),tblAuftraege[Auftrag],$A66)) -> 0 | L66: =IF($A66="",0,SUMIFS(tblAuftraege[Ausgaben],tblAuftraege[Datum Ausgaben],">="&L$5,tblAuftraege[Datum Ausgaben],"<"&EDATE(L$5,1),tblAuftraege[Auftrag],$A66)) -> 0 | ... V66: =IF($A66="",0,SUMIFS(tblAuftraege[Ausgaben],tblAuftraege[Datum Ausgaben],">="&V$5,tblAuftraege[Datum Ausgaben],"<"&EDATE(V$5,1),tblAuftraege[Auftrag],$A66)) -> 0 | W66: =SUM(E66:J66) -> 0 | X66: =SUM(K66:V66) -> 0 | Y66: =SUM(E66:V66) -> 0
B67: =IF($A67="","",IFERROR(INDEX(tblAuftraege[Kostenstelle],MATCH($A67,tblAuftraege[Auftrag],0)),"")) | C67: =IF($A67="","",IFERROR(INDEX(tblAuftraege[Themenfeld],MATCH($A67,tblAuftraege[Auftrag],0)),"")) | D67: =IF($A67="","",IFERROR(INDEX(tblAuftraege[Kategorie],MATCH($A67,tblAuftraege[Auftrag],0)),"")) | E67: =IF($A67="",0,SUMIFS(tblAuftraege[Ausgaben],tblAuftraege[Datum Ausgaben],">="&E$5,tblAuftraege[Datum Ausgaben],"<"&EDATE(E$5,1),tblAuftraege[Auftrag],$A67)) -> 0 | F67: =IF($A67="",0,SUMIFS(tblAuftraege[Ausgaben],tblAuftraege[Datum Ausgaben],">="&F$5,tblAuftraege[Datum Ausgaben],"<"&EDATE(F$5,1),tblAuftraege[Auftrag],$A67)) -> 0 | G67: =IF($A67="",0,SUMIFS(tblAuftraege[Ausgaben],tblAuftraege[Datum Ausgaben],">="&G$5,tblAuftraege[Datum Ausgaben],"<"&EDATE(G$5,1),tblAuftraege[Auftrag],$A67)) -> 0 | H67: =IF($A67="",0,SUMIFS(tblAuftraege[Ausgaben],tblAuftraege[Datum Ausgaben],">="&H$5,tblAuftraege[Datum Ausgaben],"<"&EDATE(H$5,1),tblAuftraege[Auftrag],$A67)) -> 0 | I67: =IF($A67="",0,SUMIFS(tblAuftraege[Ausgaben],tblAuftraege[Datum Ausgaben],">="&I$5,tblAuftraege[Datum Ausgaben],"<"&EDATE(I$5,1),tblAuftraege[Auftrag],$A67)) -> 0 | J67: =IF($A67="",0,SUMIFS(tblAuftraege[Ausgaben],tblAuftraege[Datum Ausgaben],">="&J$5,tblAuftraege[Datum Ausgaben],"<"&EDATE(J$5,1),tblAuftraege[Auftrag],$A67)) -> 0 | K67: =IF($A67="",0,SUMIFS(tblAuftraege[Ausgaben],tblAuftraege[Datum Ausgaben],">="&K$5,tblAuftraege[Datum Ausgaben],"<"&EDATE(K$5,1),tblAuftraege[Auftrag],$A67)) -> 0 | L67: =IF($A67="",0,SUMIFS(tblAuftraege[Ausgaben],tblAuftraege[Datum Ausgaben],">="&L$5,tblAuftraege[Datum Ausgaben],"<"&EDATE(L$5,1),tblAuftraege[Auftrag],$A67)) -> 0 | ... V67: =IF($A67="",0,SUMIFS(tblAuftraege[Ausgaben],tblAuftraege[Datum Ausgaben],">="&V$5,tblAuftraege[Datum Ausgaben],"<"&EDATE(V$5,1),tblAuftraege[Auftrag],$A67)) -> 0 | W67: =SUM(E67:J67) -> 0 | X67: =SUM(K67:V67) -> 0 | Y67: =SUM(E67:V67) -> 0
B68: =IF($A68="","",IFERROR(INDEX(tblAuftraege[Kostenstelle],MATCH($A68,tblAuftraege[Auftrag],0)),"")) | C68: =IF($A68="","",IFERROR(INDEX(tblAuftraege[Themenfeld],MATCH($A68,tblAuftraege[Auftrag],0)),"")) | D68: =IF($A68="","",IFERROR(INDEX(tblAuftraege[Kategorie],MATCH($A68,tblAuftraege[Auftrag],0)),"")) | E68: =IF($A68="",0,SUMIFS(tblAuftraege[Ausgaben],tblAuftraege[Datum Ausgaben],">="&E$5,tblAuftraege[Datum Ausgaben],"<"&EDATE(E$5,1),tblAuftraege[Auftrag],$A68)) -> 0 | F68: =IF($A68="",0,SUMIFS(tblAuftraege[Ausgaben],tblAuftraege[Datum Ausgaben],">="&F$5,tblAuftraege[Datum Ausgaben],"<"&EDATE(F$5,1),tblAuftraege[Auftrag],$A68)) -> 0 | G68: =IF($A68="",0,SUMIFS(tblAuftraege[Ausgaben],tblAuftraege[Datum Ausgaben],">="&G$5,tblAuftraege[Datum Ausgaben],"<"&EDATE(G$5,1),tblAuftraege[Auftrag],$A68)) -> 0 | H68: =IF($A68="",0,SUMIFS(tblAuftraege[Ausgaben],tblAuftraege[Datum Ausgaben],">="&H$5,tblAuftraege[Datum Ausgaben],"<"&EDATE(H$5,1),tblAuftraege[Auftrag],$A68)) -> 0 | I68: =IF($A68="",0,SUMIFS(tblAuftraege[Ausgaben],tblAuftraege[Datum Ausgaben],">="&I$5,tblAuftraege[Datum Ausgaben],"<"&EDATE(I$5,1),tblAuftraege[Auftrag],$A68)) -> 0 | J68: =IF($A68="",0,SUMIFS(tblAuftraege[Ausgaben],tblAuftraege[Datum Ausgaben],">="&J$5,tblAuftraege[Datum Ausgaben],"<"&EDATE(J$5,1),tblAuftraege[Auftrag],$A68)) -> 0 | K68: =IF($A68="",0,SUMIFS(tblAuftraege[Ausgaben],tblAuftraege[Datum Ausgaben],">="&K$5,tblAuftraege[Datum Ausgaben],"<"&EDATE(K$5,1),tblAuftraege[Auftrag],$A68)) -> 0 | L68: =IF($A68="",0,SUMIFS(tblAuftraege[Ausgaben],tblAuftraege[Datum Ausgaben],">="&L$5,tblAuftraege[Datum Ausgaben],"<"&EDATE(L$5,1),tblAuftraege[Auftrag],$A68)) -> 0 | ... V68: =IF($A68="",0,SUMIFS(tblAuftraege[Ausgaben],tblAuftraege[Datum Ausgaben],">="&V$5,tblAuftraege[Datum Ausgaben],"<"&EDATE(V$5,1),tblAuftraege[Auftrag],$A68)) -> 0 | W68: =SUM(E68:J68) -> 0 | X68: =SUM(K68:V68) -> 0 | Y68: =SUM(E68:V68) -> 0
B69: =IF($A69="","",IFERROR(INDEX(tblAuftraege[Kostenstelle],MATCH($A69,tblAuftraege[Auftrag],0)),"")) | C69: =IF($A69="","",IFERROR(INDEX(tblAuftraege[Themenfeld],MATCH($A69,tblAuftraege[Auftrag],0)),"")) | D69: =IF($A69="","",IFERROR(INDEX(tblAuftraege[Kategorie],MATCH($A69,tblAuftraege[Auftrag],0)),"")) | E69: =IF($A69="",0,SUMIFS(tblAuftraege[Ausgaben],tblAuftraege[Datum Ausgaben],">="&E$5,tblAuftraege[Datum Ausgaben],"<"&EDATE(E$5,1),tblAuftraege[Auftrag],$A69)) -> 0 | F69: =IF($A69="",0,SUMIFS(tblAuftraege[Ausgaben],tblAuftraege[Datum Ausgaben],">="&F$5,tblAuftraege[Datum Ausgaben],"<"&EDATE(F$5,1),tblAuftraege[Auftrag],$A69)) -> 0 | G69: =IF($A69="",0,SUMIFS(tblAuftraege[Ausgaben],tblAuftraege[Datum Ausgaben],">="&G$5,tblAuftraege[Datum Ausgaben],"<"&EDATE(G$5,1),tblAuftraege[Auftrag],$A69)) -> 0 | H69: =IF($A69="",0,SUMIFS(tblAuftraege[Ausgaben],tblAuftraege[Datum Ausgaben],">="&H$5,tblAuftraege[Datum Ausgaben],"<"&EDATE(H$5,1),tblAuftraege[Auftrag],$A69)) -> 0 | I69: =IF($A69="",0,SUMIFS(tblAuftraege[Ausgaben],tblAuftraege[Datum Ausgaben],">="&I$5,tblAuftraege[Datum Ausgaben],"<"&EDATE(I$5,1),tblAuftraege[Auftrag],$A69)) -> 0 | J69: =IF($A69="",0,SUMIFS(tblAuftraege[Ausgaben],tblAuftraege[Datum Ausgaben],">="&J$5,tblAuftraege[Datum Ausgaben],"<"&EDATE(J$5,1),tblAuftraege[Auftrag],$A69)) -> 0 | K69: =IF($A69="",0,SUMIFS(tblAuftraege[Ausgaben],tblAuftraege[Datum Ausgaben],">="&K$5,tblAuftraege[Datum Ausgaben],"<"&EDATE(K$5,1),tblAuftraege[Auftrag],$A69)) -> 0 | L69: =IF($A69="",0,SUMIFS(tblAuftraege[Ausgaben],tblAuftraege[Datum Ausgaben],">="&L$5,tblAuftraege[Datum Ausgaben],"<"&EDATE(L$5,1),tblAuftraege[Auftrag],$A69)) -> 0 | ... V69: =IF($A69="",0,SUMIFS(tblAuftraege[Ausgaben],tblAuftraege[Datum Ausgaben],">="&V$5,tblAuftraege[Datum Ausgaben],"<"&EDATE(V$5,1),tblAuftraege[Auftrag],$A69)) -> 0 | W69: =SUM(E69:J69) -> 0 | X69: =SUM(K69:V69) -> 0 | Y69: =SUM(E69:V69) -> 0
B70: =IF($A70="","",IFERROR(INDEX(tblAuftraege[Kostenstelle],MATCH($A70,tblAuftraege[Auftrag],0)),"")) | C70: =IF($A70="","",IFERROR(INDEX(tblAuftraege[Themenfeld],MATCH($A70,tblAuftraege[Auftrag],0)),"")) | D70: =IF($A70="","",IFERROR(INDEX(tblAuftraege[Kategorie],MATCH($A70,tblAuftraege[Auftrag],0)),"")) | E70: =IF($A70="",0,SUMIFS(tblAuftraege[Ausgaben],tblAuftraege[Datum Ausgaben],">="&E$5,tblAuftraege[Datum Ausgaben],"<"&EDATE(E$5,1),tblAuftraege[Auftrag],$A70)) -> 0 | F70: =IF($A70="",0,SUMIFS(tblAuftraege[Ausgaben],tblAuftraege[Datum Ausgaben],">="&F$5,tblAuftraege[Datum Ausgaben],"<"&EDATE(F$5,1),tblAuftraege[Auftrag],$A70)) -> 0 | G70: =IF($A70="",0,SUMIFS(tblAuftraege[Ausgaben],tblAuftraege[Datum Ausgaben],">="&G$5,tblAuftraege[Datum Ausgaben],"<"&EDATE(G$5,1),tblAuftraege[Auftrag],$A70)) -> 0 | H70: =IF($A70="",0,SUMIFS(tblAuftraege[Ausgaben],tblAuftraege[Datum Ausgaben],">="&H$5,tblAuftraege[Datum Ausgaben],"<"&EDATE(H$5,1),tblAuftraege[Auftrag],$A70)) -> 0 | I70: =IF($A70="",0,SUMIFS(tblAuftraege[Ausgaben],tblAuftraege[Datum Ausgaben],">="&I$5,tblAuftraege[Datum Ausgaben],"<"&EDATE(I$5,1),tblAuftraege[Auftrag],$A70)) -> 0 | J70: =IF($A70="",0,SUMIFS(tblAuftraege[Ausgaben],tblAuftraege[Datum Ausgaben],">="&J$5,tblAuftraege[Datum Ausgaben],"<"&EDATE(J$5,1),tblAuftraege[Auftrag],$A70)) -> 0 | K70: =IF($A70="",0,SUMIFS(tblAuftraege[Ausgaben],tblAuftraege[Datum Ausgaben],">="&K$5,tblAuftraege[Datum Ausgaben],"<"&EDATE(K$5,1),tblAuftraege[Auftrag],$A70)) -> 0 | L70: =IF($A70="",0,SUMIFS(tblAuftraege[Ausgaben],tblAuftraege[Datum Ausgaben],">="&L$5,tblAuftraege[Datum Ausgaben],"<"&EDATE(L$5,1),tblAuftraege[Auftrag],$A70)) -> 0 | ... V70: =IF($A70="",0,SUMIFS(tblAuftraege[Ausgaben],tblAuftraege[Datum Ausgaben],">="&V$5,tblAuftraege[Datum Ausgaben],"<"&EDATE(V$5,1),tblAuftraege[Auftrag],$A70)) -> 0 | W70: =SUM(E70:J70) -> 0 | X70: =SUM(K70:V70) -> 0 | Y70: =SUM(E70:V70) -> 0
B71: =IF($A71="","",IFERROR(INDEX(tblAuftraege[Kostenstelle],MATCH($A71,tblAuftraege[Auftrag],0)),"")) | C71: =IF($A71="","",IFERROR(INDEX(tblAuftraege[Themenfeld],MATCH($A71,tblAuftraege[Auftrag],0)),"")) | D71: =IF($A71="","",IFERROR(INDEX(tblAuftraege[Kategorie],MATCH($A71,tblAuftraege[Auftrag],0)),"")) | E71: =IF($A71="",0,SUMIFS(tblAuftraege[Ausgaben],tblAuftraege[Datum Ausgaben],">="&E$5,tblAuftraege[Datum Ausgaben],"<"&EDATE(E$5,1),tblAuftraege[Auftrag],$A71)) -> 0 | F71: =IF($A71="",0,SUMIFS(tblAuftraege[Ausgaben],tblAuftraege[Datum Ausgaben],">="&F$5,tblAuftraege[Datum Ausgaben],"<"&EDATE(F$5,1),tblAuftraege[Auftrag],$A71)) -> 0 | G71: =IF($A71="",0,SUMIFS(tblAuftraege[Ausgaben],tblAuftraege[Datum Ausgaben],">="&G$5,tblAuftraege[Datum Ausgaben],"<"&EDATE(G$5,1),tblAuftraege[Auftrag],$A71)) -> 0 | H71: =IF($A71="",0,SUMIFS(tblAuftraege[Ausgaben],tblAuftraege[Datum Ausgaben],">="&H$5,tblAuftraege[Datum Ausgaben],"<"&EDATE(H$5,1),tblAuftraege[Auftrag],$A71)) -> 0 | I71: =IF($A71="",0,SUMIFS(tblAuftraege[Ausgaben],tblAuftraege[Datum Ausgaben],">="&I$5,tblAuftraege[Datum Ausgaben],"<"&EDATE(I$5,1),tblAuftraege[Auftrag],$A71)) -> 0 | J71: =IF($A71="",0,SUMIFS(tblAuftraege[Ausgaben],tblAuftraege[Datum Ausgaben],">="&J$5,tblAuftraege[Datum Ausgaben],"<"&EDATE(J$5,1),tblAuftraege[Auftrag],$A71)) -> 0 | K71: =IF($A71="",0,SUMIFS(tblAuftraege[Ausgaben],tblAuftraege[Datum Ausgaben],">="&K$5,tblAuftraege[Datum Ausgaben],"<"&EDATE(K$5,1),tblAuftraege[Auftrag],$A71)) -> 0 | L71: =IF($A71="",0,SUMIFS(tblAuftraege[Ausgaben],tblAuftraege[Datum Ausgaben],">="&L$5,tblAuftraege[Datum Ausgaben],"<"&EDATE(L$5,1),tblAuftraege[Auftrag],$A71)) -> 0 | ... V71: =IF($A71="",0,SUMIFS(tblAuftraege[Ausgaben],tblAuftraege[Datum Ausgaben],">="&V$5,tblAuftraege[Datum Ausgaben],"<"&EDATE(V$5,1),tblAuftraege[Auftrag],$A71)) -> 0 | W71: =SUM(E71:J71) -> 0 | X71: =SUM(K71:V71) -> 0 | Y71: =SUM(E71:V71) -> 0
B72: =IF($A72="","",IFERROR(INDEX(tblAuftraege[Kostenstelle],MATCH($A72,tblAuftraege[Auftrag],0)),"")) | C72: =IF($A72="","",IFERROR(INDEX(tblAuftraege[Themenfeld],MATCH($A72,tblAuftraege[Auftrag],0)),"")) | D72: =IF($A72="","",IFERROR(INDEX(tblAuftraege[Kategorie],MATCH($A72,tblAuftraege[Auftrag],0)),"")) | E72: =IF($A72="",0,SUMIFS(tblAuftraege[Ausgaben],tblAuftraege[Datum Ausgaben],">="&E$5,tblAuftraege[Datum Ausgaben],"<"&EDATE(E$5,1),tblAuftraege[Auftrag],$A72)) -> 0 | F72: =IF($A72="",0,SUMIFS(tblAuftraege[Ausgaben],tblAuftraege[Datum Ausgaben],">="&F$5,tblAuftraege[Datum Ausgaben],"<"&EDATE(F$5,1),tblAuftraege[Auftrag],$A72)) -> 0 | G72: =IF($A72="",0,SUMIFS(tblAuftraege[Ausgaben],tblAuftraege[Datum Ausgaben],">="&G$5,tblAuftraege[Datum Ausgaben],"<"&EDATE(G$5,1),tblAuftraege[Auftrag],$A72)) -> 0 | H72: =IF($A72="",0,SUMIFS(tblAuftraege[Ausgaben],tblAuftraege[Datum Ausgaben],">="&H$5,tblAuftraege[Datum Ausgaben],"<"&EDATE(H$5,1),tblAuftraege[Auftrag],$A72)) -> 0 | I72: =IF($A72="",0,SUMIFS(tblAuftraege[Ausgaben],tblAuftraege[Datum Ausgaben],">="&I$5,tblAuftraege[Datum Ausgaben],"<"&EDATE(I$5,1),tblAuftraege[Auftrag],$A72)) -> 0 | J72: =IF($A72="",0,SUMIFS(tblAuftraege[Ausgaben],tblAuftraege[Datum Ausgaben],">="&J$5,tblAuftraege[Datum Ausgaben],"<"&EDATE(J$5,1),tblAuftraege[Auftrag],$A72)) -> 0 | K72: =IF($A72="",0,SUMIFS(tblAuftraege[Ausgaben],tblAuftraege[Datum Ausgaben],">="&K$5,tblAuftraege[Datum Ausgaben],"<"&EDATE(K$5,1),tblAuftraege[Auftrag],$A72)) -> 0 | L72: =IF($A72="",0,SUMIFS(tblAuftraege[Ausgaben],tblAuftraege[Datum Ausgaben],">="&L$5,tblAuftraege[Datum Ausgaben],"<"&EDATE(L$5,1),tblAuftraege[Auftrag],$A72)) -> 0 | ... V72: =IF($A72="",0,SUMIFS(tblAuftraege[Ausgaben],tblAuftraege[Datum Ausgaben],">="&V$5,tblAuftraege[Datum Ausgaben],"<"&EDATE(V$5,1),tblAuftraege[Auftrag],$A72)) -> 0 | W72: =SUM(E72:J72) -> 0 | X72: =SUM(K72:V72) -> 0 | Y72: =SUM(E72:V72) -> 0
B73: =IF($A73="","",IFERROR(INDEX(tblAuftraege[Kostenstelle],MATCH($A73,tblAuftraege[Auftrag],0)),"")) | C73: =IF($A73="","",IFERROR(INDEX(tblAuftraege[Themenfeld],MATCH($A73,tblAuftraege[Auftrag],0)),"")) | D73: =IF($A73="","",IFERROR(INDEX(tblAuftraege[Kategorie],MATCH($A73,tblAuftraege[Auftrag],0)),"")) | E73: =IF($A73="",0,SUMIFS(tblAuftraege[Ausgaben],tblAuftraege[Datum Ausgaben],">="&E$5,tblAuftraege[Datum Ausgaben],"<"&EDATE(E$5,1),tblAuftraege[Auftrag],$A73)) -> 0 | F73: =IF($A73="",0,SUMIFS(tblAuftraege[Ausgaben],tblAuftraege[Datum Ausgaben],">="&F$5,tblAuftraege[Datum Ausgaben],"<"&EDATE(F$5,1),tblAuftraege[Auftrag],$A73)) -> 0 | G73: =IF($A73="",0,SUMIFS(tblAuftraege[Ausgaben],tblAuftraege[Datum Ausgaben],">="&G$5,tblAuftraege[Datum Ausgaben],"<"&EDATE(G$5,1),tblAuftraege[Auftrag],$A73)) -> 0 | H73: =IF($A73="",0,SUMIFS(tblAuftraege[Ausgaben],tblAuftraege[Datum Ausgaben],">="&H$5,tblAuftraege[Datum Ausgaben],"<"&EDATE(H$5,1),tblAuftraege[Auftrag],$A73)) -> 0 | I73: =IF($A73="",0,SUMIFS(tblAuftraege[Ausgaben],tblAuftraege[Datum Ausgaben],">="&I$5,tblAuftraege[Datum Ausgaben],"<"&EDATE(I$5,1),tblAuftraege[Auftrag],$A73)) -> 0 | J73: =IF($A73="",0,SUMIFS(tblAuftraege[Ausgaben],tblAuftraege[Datum Ausgaben],">="&J$5,tblAuftraege[Datum Ausgaben],"<"&EDATE(J$5,1),tblAuftraege[Auftrag],$A73)) -> 0 | K73: =IF($A73="",0,SUMIFS(tblAuftraege[Ausgaben],tblAuftraege[Datum Ausgaben],">="&K$5,tblAuftraege[Datum Ausgaben],"<"&EDATE(K$5,1),tblAuftraege[Auftrag],$A73)) -> 0 | L73: =IF($A73="",0,SUMIFS(tblAuftraege[Ausgaben],tblAuftraege[Datum Ausgaben],">="&L$5,tblAuftraege[Datum Ausgaben],"<"&EDATE(L$5,1),tblAuftraege[Auftrag],$A73)) -> 0 | ... V73: =IF($A73="",0,SUMIFS(tblAuftraege[Ausgaben],tblAuftraege[Datum Ausgaben],">="&V$5,tblAuftraege[Datum Ausgaben],"<"&EDATE(V$5,1),tblAuftraege[Auftrag],$A73)) -> 0 | W73: =SUM(E73:J73) -> 0 | X73: =SUM(K73:V73) -> 0 | Y73: =SUM(E73:V73) -> 0
... B111: =IF($A111="","",IFERROR(INDEX(tblAuftraege[Kostenstelle],MATCH($A111,tblAuftraege[Auftrag],0)),"")) | C111: =IF($A111="","",IFERROR(INDEX(tblAuftraege[Themenfeld],MATCH($A111,tblAuftraege[Auftrag],0)),"")) | D111: =IF($A111="","",IFERROR(INDEX(tblAuftraege[Kategorie],MATCH($A111,tblAuftraege[Auftrag],0)),"")) | E111: =IF($A111="",0,SUMIFS(tblAuftraege[Ausgaben],tblAuftraege[Datum Ausgaben],">="&E$5,tblAuftraege[Datum Ausgaben],"<"&EDATE(E$5,1),tblAuftraege[Auftrag],$A111)) -> 0 | F111: =IF($A111="",0,SUMIFS(tblAuftraege[Ausgaben],tblAuftraege[Datum Ausgaben],">="&F$5,tblAuftraege[Datum Ausgaben],"<"&EDATE(F$5,1),tblAuftraege[Auftrag],$A111)) -> 0 | G111: =IF($A111="",0,SUMIFS(tblAuftraege[Ausgaben],tblAuftraege[Datum Ausgaben],">="&G$5,tblAuftraege[Datum Ausgaben],"<"&EDATE(G$5,1),tblAuftraege[Auftrag],$A111)) -> 0 | H111: =IF($A111="",0,SUMIFS(tblAuftraege[Ausgaben],tblAuftraege[Datum Ausgaben],">="&H$5,tblAuftraege[Datum Ausgaben],"<"&EDATE(H$5,1),tblAuftraege[Auftrag],$A111)) -> 0 | I111: =IF($A111="",0,SUMIFS(tblAuftraege[Ausgaben],tblAuftraege[Datum Ausgaben],">="&I$5,tblAuftraege[Datum Ausgaben],"<"&EDATE(I$5,1),tblAuftraege[Auftrag],$A111)) -> 0 | J111: =IF($A111="",0,SUMIFS(tblAuftraege[Ausgaben],tblAuftraege[Datum Ausgaben],">="&J$5,tblAuftraege[Datum Ausgaben],"<"&EDATE(J$5,1),tblAuftraege[Auftrag],$A111)) -> 0 | K111: =IF($A111="",0,SUMIFS(tblAuftraege[Ausgaben],tblAuftraege[Datum Ausgaben],">="&K$5,tblAuftraege[Datum Ausgaben],"<"&EDATE(K$5,1),tblAuftraege[Auftrag],$A111)) -> 0 | L111: =IF($A111="",0,SUMIFS(tblAuftraege[Ausgaben],tblAuftraege[Datum Ausgaben],">="&L$5,tblAuftraege[Datum Ausgaben],"<"&EDATE(L$5,1),tblAuftraege[Auftrag],$A111)) -> 0 | ... V111: =IF($A111="",0,SUMIFS(tblAuftraege[Ausgaben],tblAuftraege[Datum Ausgaben],">="&V$5,tblAuftraege[Datum Ausgaben],"<"&EDATE(V$5,1),tblAuftraege[Auftrag],$A111)) -> 0 | W111: =SUM(E111:J111) -> 0 | X111: =SUM(K111:V111) -> 0 | Y111: =SUM(E111:V111) -> 0
A112: Noch nicht erfasste Aufträge | B112: Differenz | E112: =E113-SUM(E62:E111) -> 0 | F112: =F113-SUM(F62:F111) -> 0 | G112: =G113-SUM(G62:G111) -> 0 | H112: =H113-SUM(H62:H111) -> 0 | I112: =I113-SUM(I62:I111) -> 0 | J112: =J113-SUM(J62:J111) -> 0 | K112: =K113-SUM(K62:K111) -> 0 | L112: =L113-SUM(L62:L111) -> 0 | ... Y112: =Y113-SUM(Y62:Y111) -> 0
A113: Summe Ausgaben | E113: =SUMIFS(tblAuftraege[Ausgaben],tblAuftraege[Datum Ausgaben],">="&E$5,tblAuftraege[Datum Ausgaben],"<"&EDATE(E$5,1)) -> 0 | F113: =SUMIFS(tblAuftraege[Ausgaben],tblAuftraege[Datum Ausgaben],">="&F$5,tblAuftraege[Datum Ausgaben],"<"&EDATE(F$5,1)) -> 0 | G113: =SUMIFS(tblAuftraege[Ausgaben],tblAuftraege[Datum Ausgaben],">="&G$5,tblAuftraege[Datum Ausgaben],"<"&EDATE(G$5,1)) -> 0 | H113: =SUMIFS(tblAuftraege[Ausgaben],tblAuftraege[Datum Ausgaben],">="&H$5,tblAuftraege[Datum Ausgaben],"<"&EDATE(H$5,1)) -> 0 | I113: =SUMIFS(tblAuftraege[Ausgaben],tblAuftraege[Datum Ausgaben],">="&I$5,tblAuftraege[Datum Ausgaben],"<"&EDATE(I$5,1)) -> 0 | J113: =SUMIFS(tblAuftraege[Ausgaben],tblAuftraege[Datum Ausgaben],">="&J$5,tblAuftraege[Datum Ausgaben],"<"&EDATE(J$5,1)) -> 0 | K113: =SUMIFS(tblAuftraege[Ausgaben],tblAuftraege[Datum Ausgaben],">="&K$5,tblAuftraege[Datum Ausgaben],"<"&EDATE(K$5,1)) -> 0 | L113: =SUMIFS(tblAuftraege[Ausgaben],tblAuftraege[Datum Ausgaben],">="&L$5,tblAuftraege[Datum Ausgaben],"<"&EDATE(L$5,1)) -> 0 | ... V113: =SUMIFS(tblAuftraege[Ausgaben],tblAuftraege[Datum Ausgaben],">="&V$5,tblAuftraege[Datum Ausgaben],"<"&EDATE(V$5,1)) -> 0 | W113: =SUM(E113:J113) -> 0 | X113: =SUM(K113:V113) -> 0 | Y113: =SUM(E113:V113) -> 0
A115: 3 KENNZAHLEN (automatisch berechnet)
A116: Summe Einnahmen | E116: =E59 -> 0 | F116: =F59 -> 0 | G116: =G59 -> 0 | H116: =H59 -> 0 | I116: =I59 -> 0 | J116: =J59 -> 0 | K116: =K59 -> 0 | L116: =L59 -> 0 | ... Y116: =Y59 -> 0
...

Sheet Aufträge
A1: Aufträge – zentrale Datenerfassung
A2: SmartInfra / IoT-Büro · DusL Plus Autostrom
A3: Jeder Auftrag bzw. finanzielle Vorgang wird hier einmalig erfasst. Der Reiter „Cashflow“ aggregiert daraus automatisch nach Monat.
A4: Datum Einnahmen und Datum Ausgaben sind unabhängig – ein Auftrag kann z. B. im September Ausgaben und erst im November Einnahmen haben. LLM = Lastmanagement.
A6: Themenfeld | B6: Kategorie | C6: Auftrag | D6: Kostenstelle | E6: Datum Einnahmen | F6: Datum Ausgaben | G6: Einnahmen | H6: Ausgaben | I6: Auftragswahrscheinlichkeit

Sheet Übersicht
A1: Übersicht Cashflow – DusL Plus Autostrom
A2: SmartInfra / IoT-Büro · Juli 2026 – Dezember 2027
A3: Alle Werte werden automatisch aus dem Blatt „Cashflow“ übernommen.
A5: Kennzahl | B5: Betrag
A6: H2 2026 (Jul – Dez 2026)
A7: Einnahmen H2 2026 | B7: =Cashflow!W116 -> 0
A8: Ausgaben H2 2026 | B8: =Cashflow!W117 -> 0
A9: Netto-Cashflow H2 2026 | B9: =Cashflow!W118 -> 0
A10: Geschäftsjahr 2027
A11: Einnahmen 2027 | B11: =Cashflow!X116 -> 0
A12: Ausgaben 2027 | B12: =Cashflow!X117 -> 0
A13: Netto-Cashflow 2027 | B13: =Cashflow!X118 -> 0
A14: Gesamtzeitraum (18 Monate)
A15: Gesamteinnahmen | B15: =Cashflow!Y116 -> 0
A16: Gesamtausgaben | B16: =Cashflow!Y117 -> 0
A17: Gesamt-Netto-Cashflow | B17: =Cashflow!Y118 -> 0
