Workbook

Sheet Cashflow
A1: Cashflow-Planung
A2: Bereich: SmartInfra / IoT-Büro
A3: Zeitraum: Juli 2026 – Dezember 2030 (54 Monate, monatliche Granularität)
A4: Alle Beträge werden automatisch aus dem Reiter „Aufträge“ berechnet – hier wird links nur die Auftragsnummer (gelb) eingetragen.
E5: 46204 | F5: 46235 | G5: 46266 | H5: 46296 | I5: 46327 | J5: 46357 | K5: 46388 | L5: 46419 | M5: 46447 | N5: 46478 | O5: 46508 | P5: 46539 | Q5: 46569 | R5: 46600 | S5: 46631 | T5: 46661 | U5: 46692 | V5: 46722 | W5: 46753 | X5: 46784 | Y5: 46813 | Z5: 46844 | AA5: 46874 | AB5: 46905 | AC5: 46935 | AD5: 46966 | AE5: 46997 | AF5: 47027 | AG5: 47058 | AH5: 47088 | AI5: 47119 | AJ5: 47150 | AK5: 47178 | AL5: 47209 | AM5: 47239 | AN5: 47270 | AO5: 47300 | AP5: 47331 | AQ5: 47362 | AR5: 47392 | AS5: 47423 | AT5: 47453 | AU5: 47484 | AV5: 47515 | AW5: 47543 | AX5: 47574 | AY5: 47604 | AZ5: 47635 | BA5: 47665 | BB5: 47696 | BC5: 47727 | BD5: 47757 | BE5: 47788 | BF5: 47818
A6: Auftrag | B6: Kostenstelle | C6: Themenfeld | D6: Kategorie | E6: Jul 26 | F6: Aug 26 | G6: Sep 26 | H6: Okt 26 | I6: Nov 26 | J6: Dez 26 | K6: Jan 27 | L6: Feb 27 | M6: Mär 27 | N6: Apr 27 | O6: Mai 27 | P6: Jun 27 | Q6: Jul 27 | R6: Aug 27 | S6: Sep 27 | T6: Okt 27 | U6: Nov 27 | V6: Dez 27 | W6: Jan 28 | X6: Feb 28 | Y6: Mär 28 | Z6: Apr 28 | AA6: Mai 28 | AB6: Jun 28 | AC6: Jul 28 | AD6: Aug 28 | AE6: Sep 28 | AF6: Okt 28 | AG6: Nov 28 | AH6: Dez 28 | AI6: Jan 29 | AJ6: Feb 29 | AK6: Mär 29 | AL6: Apr 29 | AM6: Mai 29 | AN6: Jun 29 | AO6: Jul 29 | AP6: Aug 29 | AQ6: Sep 29 | AR6: Okt 29 | AS6: Nov 29 | AT6: Dez 29 | AU6: Jan 30 | AV6: Feb 30 | AW6: Mär 30 | AX6: Apr 30 | AY6: Mai 30 | AZ6: Jun 30 | BA6: Jul 30 | BB6: Aug 30 | BC6: Sep 30 | BD6: Okt 30 | BE6: Nov 30 | BF6: Dez 30 | BG6: Summe H2 2026 | BH6: Summe 2027 | BI6: Summe 2028 | BJ6: Summe 2029 | BK6: Summe 2030 | BL6: Gesamt
A7: 1 EINNAHMEN JE AUFTRAG (Quelle: Reiter „Aufträge“)
B8: =IF($A8="","",IFERROR(INDEX(tblAuftraege[Kostenstelle],MATCH($A8,tblAuftraege[Auftrag],0)),"")) | C8: =IF($A8="","",IFERROR(INDEX(tblAuftraege[Themenfeld],MATCH($A8,tblAuftraege[Auftrag],0)),"")) | D8: =IF($A8="","",IFERROR(INDEX(tblAuftraege[Kategorie],MATCH($A8,tblAuftraege[Auftrag],0)),"")) | E8: =IF($A8="",0,SUMIFS(tblAuftraege[Einnahmen],tblAuftraege[Datum Einnahmen],">="&E$5,tblAuftraege[Datum Einnahmen],"<"&EDATE(E$5,1),tblAuftraege[Auftrag],$A8)) -> 0 | F8: =IF($A8="",0,SUMIFS(tblAuftraege[Einnahmen],tblAuftraege[Datum Einnahmen],">="&F$5,tblAuftraege[Datum Einnahmen],"<"&EDATE(F$5,1),tblAuftraege[Auftrag],$A8)) -> 0 | G8: =IF($A8="",0,SUMIFS(tblAuftraege[Einnahmen],tblAuftraege[Datum Einnahmen],">="&G$5,tblAuftraege[Datum Einnahmen],"<"&EDATE(G$5,1),tblAuftraege[Auftrag],$A8)) -> 0 | H8: =IF($A8="",0,SUMIFS(tblAuftraege[Einnahmen],tblAuftraege[Datum Einnahmen],">="&H$5,tblAuftraege[Datum Einnahmen],"<"&EDATE(H$5,1),tblAuftraege[Auftrag],$A8)) -> 0 | I8: =IF($A8="",0,SUMIFS(tblAuftraege[Einnahmen],tblAuftraege[Datum Einnahmen],">="&I$5,tblAuftraege[Datum Einnahmen],"<"&EDATE(I$5,1),tblAuftraege[Auftrag],$A8)) -> 0 | J8: =IF($A8="",0,SUMIFS(tblAuftraege[Einnahmen],tblAuftraege[Datum Einnahmen],">="&J$5,tblAuftraege[Datum Einnahmen],"<"&EDATE(J$5,1),tblAuftraege[Auftrag],$A8)) -> 0 | K8: =IF($A8="",0,SUMIFS(tblAuftraege[Einnahmen],tblAuftraege[Datum Einnahmen],">="&K$5,tblAuftraege[Datum Einnahmen],"<"&EDATE(K$5,1),tblAuftraege[Auftrag],$A8)) -> 0 | L8: =IF($A8="",0,SUMIFS(tblAuftraege[Einnahmen],tblAuftraege[Datum Einnahmen],">="&L$5,tblAuftraege[Datum Einnahmen],"<"&EDATE(L$5,1),tblAuftraege[Auftrag],$A8)) -> 0 | ... BF8: =IF($A8="",0,SUMIFS(tblAuftraege[Einnahmen],tblAuftraege[Datum Einnahmen],">="&BF$5,tblAuftraege[Datum Einnahmen],"<"&EDATE(BF$5,1),tblAuftraege[Auftrag],$A8)) -> 0 | BG8: =SUM(E8:J8) -> 0 | BH8: =SUM(K8:V8) -> 0 | BI8: =SUM(W8:AH8) -> 0 | BJ8: =SUM(AI8:AT8) -> 0 | BK8: =SUM(AU8:BF8) -> 0 | BL8: =SUM(E8:BF8) -> 0
B9: =IF($A9="","",IFERROR(INDEX(tblAuftraege[Kostenstelle],MATCH($A9,tblAuftraege[Auftrag],0)),"")) | C9: =IF($A9="","",IFERROR(INDEX(tblAuftraege[Themenfeld],MATCH($A9,tblAuftraege[Auftrag],0)),"")) | D9: =IF($A9="","",IFERROR(INDEX(tblAuftraege[Kategorie],MATCH($A9,tblAuftraege[Auftrag],0)),"")) | E9: =IF($A9="",0,SUMIFS(tblAuftraege[Einnahmen],tblAuftraege[Datum Einnahmen],">="&E$5,tblAuftraege[Datum Einnahmen],"<"&EDATE(E$5,1),tblAuftraege[Auftrag],$A9)) -> 0 | F9: =IF($A9="",0,SUMIFS(tblAuftraege[Einnahmen],tblAuftraege[Datum Einnahmen],">="&F$5,tblAuftraege[Datum Einnahmen],"<"&EDATE(F$5,1),tblAuftraege[Auftrag],$A9)) -> 0 | G9: =IF($A9="",0,SUMIFS(tblAuftraege[Einnahmen],tblAuftraege[Datum Einnahmen],">="&G$5,tblAuftraege[Datum Einnahmen],"<"&EDATE(G$5,1),tblAuftraege[Auftrag],$A9)) -> 0 | H9: =IF($A9="",0,SUMIFS(tblAuftraege[Einnahmen],tblAuftraege[Datum Einnahmen],">="&H$5,tblAuftraege[Datum Einnahmen],"<"&EDATE(H$5,1),tblAuftraege[Auftrag],$A9)) -> 0 | I9: =IF($A9="",0,SUMIFS(tblAuftraege[Einnahmen],tblAuftraege[Datum Einnahmen],">="&I$5,tblAuftraege[Datum Einnahmen],"<"&EDATE(I$5,1),tblAuftraege[Auftrag],$A9)) -> 0 | J9: =IF($A9="",0,SUMIFS(tblAuftraege[Einnahmen],tblAuftraege[Datum Einnahmen],">="&J$5,tblAuftraege[Datum Einnahmen],"<"&EDATE(J$5,1),tblAuftraege[Auftrag],$A9)) -> 0 | K9: =IF($A9="",0,SUMIFS(tblAuftraege[Einnahmen],tblAuftraege[Datum Einnahmen],">="&K$5,tblAuftraege[Datum Einnahmen],"<"&EDATE(K$5,1),tblAuftraege[Auftrag],$A9)) -> 0 | L9: =IF($A9="",0,SUMIFS(tblAuftraege[Einnahmen],tblAuftraege[Datum Einnahmen],">="&L$5,tblAuftraege[Datum Einnahmen],"<"&EDATE(L$5,1),tblAuftraege[Auftrag],$A9)) -> 0 | ... BF9: =IF($A9="",0,SUMIFS(tblAuftraege[Einnahmen],tblAuftraege[Datum Einnahmen],">="&BF$5,tblAuftraege[Datum Einnahmen],"<"&EDATE(BF$5,1),tblAuftraege[Auftrag],$A9)) -> 0 | BG9: =SUM(E9:J9) -> 0 | BH9: =SUM(K9:V9) -> 0 | BI9: =SUM(W9:AH9) -> 0 | BJ9: =SUM(AI9:AT9) -> 0 | BK9: =SUM(AU9:BF9) -> 0 | BL9: =SUM(E9:BF9) -> 0
B10: =IF($A10="","",IFERROR(INDEX(tblAuftraege[Kostenstelle],MATCH($A10,tblAuftraege[Auftrag],0)),"")) | C10: =IF($A10="","",IFERROR(INDEX(tblAuftraege[Themenfeld],MATCH($A10,tblAuftraege[Auftrag],0)),"")) | D10: =IF($A10="","",IFERROR(INDEX(tblAuftraege[Kategorie],MATCH($A10,tblAuftraege[Auftrag],0)),"")) | E10: =IF($A10="",0,SUMIFS(tblAuftraege[Einnahmen],tblAuftraege[Datum Einnahmen],">="&E$5,tblAuftraege[Datum Einnahmen],"<"&EDATE(E$5,1),tblAuftraege[Auftrag],$A10)) -> 0 | F10: =IF($A10="",0,SUMIFS(tblAuftraege[Einnahmen],tblAuftraege[Datum Einnahmen],">="&F$5,tblAuftraege[Datum Einnahmen],"<"&EDATE(F$5,1),tblAuftraege[Auftrag],$A10)) -> 0 | G10: =IF($A10="",0,SUMIFS(tblAuftraege[Einnahmen],tblAuftraege[Datum Einnahmen],">="&G$5,tblAuftraege[Datum Einnahmen],"<"&EDATE(G$5,1),tblAuftraege[Auftrag],$A10)) -> 0 | H10: =IF($A10="",0,SUMIFS(tblAuftraege[Einnahmen],tblAuftraege[Datum Einnahmen],">="&H$5,tblAuftraege[Datum Einnahmen],"<"&EDATE(H$5,1),tblAuftraege[Auftrag],$A10)) -> 0 | I10: =IF($A10="",0,SUMIFS(tblAuftraege[Einnahmen],tblAuftraege[Datum Einnahmen],">="&I$5,tblAuftraege[Datum Einnahmen],"<"&EDATE(I$5,1),tblAuftraege[Auftrag],$A10)) -> 0 | J10: =IF($A10="",0,SUMIFS(tblAuftraege[Einnahmen],tblAuftraege[Datum Einnahmen],">="&J$5,tblAuftraege[Datum Einnahmen],"<"&EDATE(J$5,1),tblAuftraege[Auftrag],$A10)) -> 0 | K10: =IF($A10="",0,SUMIFS(tblAuftraege[Einnahmen],tblAuftraege[Datum Einnahmen],">="&K$5,tblAuftraege[Datum Einnahmen],"<"&EDATE(K$5,1),tblAuftraege[Auftrag],$A10)) -> 0 | L10: =IF($A10="",0,SUMIFS(tblAuftraege[Einnahmen],tblAuftraege[Datum Einnahmen],">="&L$5,tblAuftraege[Datum Einnahmen],"<"&EDATE(L$5,1),tblAuftraege[Auftrag],$A10)) -> 0 | ... BF10: =IF($A10="",0,SUMIFS(tblAuftraege[Einnahmen],tblAuftraege[Datum Einnahmen],">="&BF$5,tblAuftraege[Datum Einnahmen],"<"&EDATE(BF$5,1),tblAuftraege[Auftrag],$A10)) -> 0 | BG10: =SUM(E10:J10) -> 0 | BH10: =SUM(K10:V10) -> 0 | BI10: =SUM(W10:AH10) -> 0 | BJ10: =SUM(AI10:AT10) -> 0 | BK10: =SUM(AU10:BF10) -> 0 | BL10: =SUM(E10:BF10) -> 0
B11: =IF($A11="","",IFERROR(INDEX(tblAuftraege[Kostenstelle],MATCH($A11,tblAuftraege[Auftrag],0)),"")) | C11: =IF($A11="","",IFERROR(INDEX(tblAuftraege[Themenfeld],MATCH($A11,tblAuftraege[Auftrag],0)),"")) | D11: =IF($A11="","",IFERROR(INDEX(tblAuftraege[Kategorie],MATCH($A11,tblAuftraege[Auftrag],0)),"")) | E11: =IF($A11="",0,SUMIFS(tblAuftraege[Einnahmen],tblAuftraege[Datum Einnahmen],">="&E$5,tblAuftraege[Datum Einnahmen],"<"&EDATE(E$5,1),tblAuftraege[Auftrag],$A11)) -> 0 | F11: =IF($A11="",0,SUMIFS(tblAuftraege[Einnahmen],tblAuftraege[Datum Einnahmen],">="&F$5,tblAuftraege[Datum Einnahmen],"<"&EDATE(F$5,1),tblAuftraege[Auftrag],$A11)) -> 0 | G11: =IF($A11="",0,SUMIFS(tblAuftraege[Einnahmen],tblAuftraege[Datum Einnahmen],">="&G$5,tblAuftraege[Datum Einnahmen],"<"&EDATE(G$5,1),tblAuftraege[Auftrag],$A11)) -> 0 | H11: =IF($A11="",0,SUMIFS(tblAuftraege[Einnahmen],tblAuftraege[Datum Einnahmen],">="&H$5,tblAuftraege[Datum Einnahmen],"<"&EDATE(H$5,1),tblAuftraege[Auftrag],$A11)) -> 0 | I11: =IF($A11="",0,SUMIFS(tblAuftraege[Einnahmen],tblAuftraege[Datum Einnahmen],">="&I$5,tblAuftraege[Datum Einnahmen],"<"&EDATE(I$5,1),tblAuftraege[Auftrag],$A11)) -> 0 | J11: =IF($A11="",0,SUMIFS(tblAuftraege[Einnahmen],tblAuftraege[Datum Einnahmen],">="&J$5,tblAuftraege[Datum Einnahmen],"<"&EDATE(J$5,1),tblAuftraege[Auftrag],$A11)) -> 0 | K11: =IF($A11="",0,SUMIFS(tblAuftraege[Einnahmen],tblAuftraege[Datum Einnahmen],">="&K$5,tblAuftraege[Datum Einnahmen],"<"&EDATE(K$5,1),tblAuftraege[Auftrag],$A11)) -> 0 | L11: =IF($A11="",0,SUMIFS(tblAuftraege[Einnahmen],tblAuftraege[Datum Einnahmen],">="&L$5,tblAuftraege[Datum Einnahmen],"<"&EDATE(L$5,1),tblAuftraege[Auftrag],$A11)) -> 0 | ... BF11: =IF($A11="",0,SUMIFS(tblAuftraege[Einnahmen],tblAuftraege[Datum Einnahmen],">="&BF$5,tblAuftraege[Datum Einnahmen],"<"&EDATE(BF$5,1),tblAuftraege[Auftrag],$A11)) -> 0 | BG11: =SUM(E11:J11) -> 0 | BH11: =SUM(K11:V11) -> 0 | BI11: =SUM(W11:AH11) -> 0 | BJ11: =SUM(AI11:AT11) -> 0 | BK11: =SUM(AU11:BF11) -> 0 | BL11: =SUM(E11:BF11) -> 0
B12: =IF($A12="","",IFERROR(INDEX(tblAuftraege[Kostenstelle],MATCH($A12,tblAuftraege[Auftrag],0)),"")) | C12: =IF($A12="","",IFERROR(INDEX(tblAuftraege[Themenfeld],MATCH($A12,tblAuftraege[Auftrag],0)),"")) | D12: =IF($A12="","",IFERROR(INDEX(tblAuftraege[Kategorie],MATCH($A12,tblAuftraege[Auftrag],0)),"")) | E12: =IF($A12="",0,SUMIFS(tblAuftraege[Einnahmen],tblAuftraege[Datum Einnahmen],">="&E$5,tblAuftraege[Datum Einnahmen],"<"&EDATE(E$5,1),tblAuftraege[Auftrag],$A12)) -> 0 | F12: =IF($A12="",0,SUMIFS(tblAuftraege[Einnahmen],tblAuftraege[Datum Einnahmen],">="&F$5,tblAuftraege[Datum Einnahmen],"<"&EDATE(F$5,1),tblAuftraege[Auftrag],$A12)) -> 0 | G12: =IF($A12="",0,SUMIFS(tblAuftraege[Einnahmen],tblAuftraege[Datum Einnahmen],">="&G$5,tblAuftraege[Datum Einnahmen],"<"&EDATE(G$5,1),tblAuftraege[Auftrag],$A12)) -> 0 | H12: =IF($A12="",0,SUMIFS(tblAuftraege[Einnahmen],tblAuftraege[Datum Einnahmen],">="&H$5,tblAuftraege[Datum Einnahmen],"<"&EDATE(H$5,1),tblAuftraege[Auftrag],$A12)) -> 0 | I12: =IF($A12="",0,SUMIFS(tblAuftraege[Einnahmen],tblAuftraege[Datum Einnahmen],">="&I$5,tblAuftraege[Datum Einnahmen],"<"&EDATE(I$5,1),tblAuftraege[Auftrag],$A12)) -> 0 | J12: =IF($A12="",0,SUMIFS(tblAuftraege[Einnahmen],tblAuftraege[Datum Einnahmen],">="&J$5,tblAuftraege[Datum Einnahmen],"<"&EDATE(J$5,1),tblAuftraege[Auftrag],$A12)) -> 0 | K12: =IF($A12="",0,SUMIFS(tblAuftraege[Einnahmen],tblAuftraege[Datum Einnahmen],">="&K$5,tblAuftraege[Datum Einnahmen],"<"&EDATE(K$5,1),tblAuftraege[Auftrag],$A12)) -> 0 | L12: =IF($A12="",0,SUMIFS(tblAuftraege[Einnahmen],tblAuftraege[Datum Einnahmen],">="&L$5,tblAuftraege[Datum Einnahmen],"<"&EDATE(L$5,1),tblAuftraege[Auftrag],$A12)) -> 0 | ... BF12: =IF($A12="",0,SUMIFS(tblAuftraege[Einnahmen],tblAuftraege[Datum Einnahmen],">="&BF$5,tblAuftraege[Datum Einnahmen],"<"&EDATE(BF$5,1),tblAuftraege[Auftrag],$A12)) -> 0 | BG12: =SUM(E12:J12) -> 0 | BH12: =SUM(K12:V12) -> 0 | BI12: =SUM(W12:AH12) -> 0 | BJ12: =SUM(AI12:AT12) -> 0 | BK12: =SUM(AU12:BF12) -> 0 | BL12: =SUM(E12:BF12) -> 0
B13: =IF($A13="","",IFERROR(INDEX(tblAuftraege[Kostenstelle],MATCH($A13,tblAuftraege[Auftrag],0)),"")) | C13: =IF($A13="","",IFERROR(INDEX(tblAuftraege[Themenfeld],MATCH($A13,tblAuftraege[Auftrag],0)),"")) | D13: =IF($A13="","",IFERROR(INDEX(tblAuftraege[Kategorie],MATCH($A13,tblAuftraege[Auftrag],0)),"")) | E13: =IF($A13="",0,SUMIFS(tblAuftraege[Einnahmen],tblAuftraege[Datum Einnahmen],">="&E$5,tblAuftraege[Datum Einnahmen],"<"&EDATE(E$5,1),tblAuftraege[Auftrag],$A13)) -> 0 | F13: =IF($A13="",0,SUMIFS(tblAuftraege[Einnahmen],tblAuftraege[Datum Einnahmen],">="&F$5,tblAuftraege[Datum Einnahmen],"<"&EDATE(F$5,1),tblAuftraege[Auftrag],$A13)) -> 0 | G13: =IF($A13="",0,SUMIFS(tblAuftraege[Einnahmen],tblAuftraege[Datum Einnahmen],">="&G$5,tblAuftraege[Datum Einnahmen],"<"&EDATE(G$5,1),tblAuftraege[Auftrag],$A13)) -> 0 | H13: =IF($A13="",0,SUMIFS(tblAuftraege[Einnahmen],tblAuftraege[Datum Einnahmen],">="&H$5,tblAuftraege[Datum Einnahmen],"<"&EDATE(H$5,1),tblAuftraege[Auftrag],$A13)) -> 0 | I13: =IF($A13="",0,SUMIFS(tblAuftraege[Einnahmen],tblAuftraege[Datum Einnahmen],">="&I$5,tblAuftraege[Datum Einnahmen],"<"&EDATE(I$5,1),tblAuftraege[Auftrag],$A13)) -> 0 | J13: =IF($A13="",0,SUMIFS(tblAuftraege[Einnahmen],tblAuftraege[Datum Einnahmen],">="&J$5,tblAuftraege[Datum Einnahmen],"<"&EDATE(J$5,1),tblAuftraege[Auftrag],$A13)) -> 0 | K13: =IF($A13="",0,SUMIFS(tblAuftraege[Einnahmen],tblAuftraege[Datum Einnahmen],">="&K$5,tblAuftraege[Datum Einnahmen],"<"&EDATE(K$5,1),tblAuftraege[Auftrag],$A13)) -> 0 | L13: =IF($A13="",0,SUMIFS(tblAuftraege[Einnahmen],tblAuftraege[Datum Einnahmen],">="&L$5,tblAuftraege[Datum Einnahmen],"<"&EDATE(L$5,1),tblAuftraege[Auftrag],$A13)) -> 0 | ... BF13: =IF($A13="",0,SUMIFS(tblAuftraege[Einnahmen],tblAuftraege[Datum Einnahmen],">="&BF$5,tblAuftraege[Datum Einnahmen],"<"&EDATE(BF$5,1),tblAuftraege[Auftrag],$A13)) -> 0 | BG13: =SUM(E13:J13) -> 0 | BH13: =SUM(K13:V13) -> 0 | BI13: =SUM(W13:AH13) -> 0 | BJ13: =SUM(AI13:AT13) -> 0 | BK13: =SUM(AU13:BF13) -> 0 | BL13: =SUM(E13:BF13) -> 0
B14: =IF($A14="","",IFERROR(INDEX(tblAuftraege[Kostenstelle],MATCH($A14,tblAuftraege[Auftrag],0)),"")) | C14: =IF($A14="","",IFERROR(INDEX(tblAuftraege[Themenfeld],MATCH($A14,tblAuftraege[Auftrag],0)),"")) | D14: =IF($A14="","",IFERROR(INDEX(tblAuftraege[Kategorie],MATCH($A14,tblAuftraege[Auftrag],0)),"")) | E14: =IF($A14="",0,SUMIFS(tblAuftraege[Einnahmen],tblAuftraege[Datum Einnahmen],">="&E$5,tblAuftraege[Datum Einnahmen],"<"&EDATE(E$5,1),tblAuftraege[Auftrag],$A14)) -> 0 | F14: =IF($A14="",0,SUMIFS(tblAuftraege[Einnahmen],tblAuftraege[Datum Einnahmen],">="&F$5,tblAuftraege[Datum Einnahmen],"<"&EDATE(F$5,1),tblAuftraege[Auftrag],$A14)) -> 0 | G14: =IF($A14="",0,SUMIFS(tblAuftraege[Einnahmen],tblAuftraege[Datum Einnahmen],">="&G$5,tblAuftraege[Datum Einnahmen],"<"&EDATE(G$5,1),tblAuftraege[Auftrag],$A14)) -> 0 | H14: =IF($A14="",0,SUMIFS(tblAuftraege[Einnahmen],tblAuftraege[Datum Einnahmen],">="&H$5,tblAuftraege[Datum Einnahmen],"<"&EDATE(H$5,1),tblAuftraege[Auftrag],$A14)) -> 0 | I14: =IF($A14="",0,SUMIFS(tblAuftraege[Einnahmen],tblAuftraege[Datum Einnahmen],">="&I$5,tblAuftraege[Datum Einnahmen],"<"&EDATE(I$5,1),tblAuftraege[Auftrag],$A14)) -> 0 | J14: =IF($A14="",0,SUMIFS(tblAuftraege[Einnahmen],tblAuftraege[Datum Einnahmen],">="&J$5,tblAuftraege[Datum Einnahmen],"<"&EDATE(J$5,1),tblAuftraege[Auftrag],$A14)) -> 0 | K14: =IF($A14="",0,SUMIFS(tblAuftraege[Einnahmen],tblAuftraege[Datum Einnahmen],">="&K$5,tblAuftraege[Datum Einnahmen],"<"&EDATE(K$5,1),tblAuftraege[Auftrag],$A14)) -> 0 | L14: =IF($A14="",0,SUMIFS(tblAuftraege[Einnahmen],tblAuftraege[Datum Einnahmen],">="&L$5,tblAuftraege[Datum Einnahmen],"<"&EDATE(L$5,1),tblAuftraege[Auftrag],$A14)) -> 0 | ... BF14: =IF($A14="",0,SUMIFS(tblAuftraege[Einnahmen],tblAuftraege[Datum Einnahmen],">="&BF$5,tblAuftraege[Datum Einnahmen],"<"&EDATE(BF$5,1),tblAuftraege[Auftrag],$A14)) -> 0 | BG14: =SUM(E14:J14) -> 0 | BH14: =SUM(K14:V14) -> 0 | BI14: =SUM(W14:AH14) -> 0 | BJ14: =SUM(AI14:AT14) -> 0 | BK14: =SUM(AU14:BF14) -> 0 | BL14: =SUM(E14:BF14) -> 0
B15: =IF($A15="","",IFERROR(INDEX(tblAuftraege[Kostenstelle],MATCH($A15,tblAuftraege[Auftrag],0)),"")) | C15: =IF($A15="","",IFERROR(INDEX(tblAuftraege[Themenfeld],MATCH($A15,tblAuftraege[Auftrag],0)),"")) | D15: =IF($A15="","",IFERROR(INDEX(tblAuftraege[Kategorie],MATCH($A15,tblAuftraege[Auftrag],0)),"")) | E15: =IF($A15="",0,SUMIFS(tblAuftraege[Einnahmen],tblAuftraege[Datum Einnahmen],">="&E$5,tblAuftraege[Datum Einnahmen],"<"&EDATE(E$5,1),tblAuftraege[Auftrag],$A15)) -> 0 | F15: =IF($A15="",0,SUMIFS(tblAuftraege[Einnahmen],tblAuftraege[Datum Einnahmen],">="&F$5,tblAuftraege[Datum Einnahmen],"<"&EDATE(F$5,1),tblAuftraege[Auftrag],$A15)) -> 0 | G15: =IF($A15="",0,SUMIFS(tblAuftraege[Einnahmen],tblAuftraege[Datum Einnahmen],">="&G$5,tblAuftraege[Datum Einnahmen],"<"&EDATE(G$5,1),tblAuftraege[Auftrag],$A15)) -> 0 | H15: =IF($A15="",0,SUMIFS(tblAuftraege[Einnahmen],tblAuftraege[Datum Einnahmen],">="&H$5,tblAuftraege[Datum Einnahmen],"<"&EDATE(H$5,1),tblAuftraege[Auftrag],$A15)) -> 0 | I15: =IF($A15="",0,SUMIFS(tblAuftraege[Einnahmen],tblAuftraege[Datum Einnahmen],">="&I$5,tblAuftraege[Datum Einnahmen],"<"&EDATE(I$5,1),tblAuftraege[Auftrag],$A15)) -> 0 | J15: =IF($A15="",0,SUMIFS(tblAuftraege[Einnahmen],tblAuftraege[Datum Einnahmen],">="&J$5,tblAuftraege[Datum Einnahmen],"<"&EDATE(J$5,1),tblAuftraege[Auftrag],$A15)) -> 0 | K15: =IF($A15="",0,SUMIFS(tblAuftraege[Einnahmen],tblAuftraege[Datum Einnahmen],">="&K$5,tblAuftraege[Datum Einnahmen],"<"&EDATE(K$5,1),tblAuftraege[Auftrag],$A15)) -> 0 | L15: =IF($A15="",0,SUMIFS(tblAuftraege[Einnahmen],tblAuftraege[Datum Einnahmen],">="&L$5,tblAuftraege[Datum Einnahmen],"<"&EDATE(L$5,1),tblAuftraege[Auftrag],$A15)) -> 0 | ... BF15: =IF($A15="",0,SUMIFS(tblAuftraege[Einnahmen],tblAuftraege[Datum Einnahmen],">="&BF$5,tblAuftraege[Datum Einnahmen],"<"&EDATE(BF$5,1),tblAuftraege[Auftrag],$A15)) -> 0 | BG15: =SUM(E15:J15) -> 0 | BH15: =SUM(K15:V15) -> 0 | BI15: =SUM(W15:AH15) -> 0 | BJ15: =SUM(AI15:AT15) -> 0 | BK15: =SUM(AU15:BF15) -> 0 | BL15: =SUM(E15:BF15) -> 0
B16: =IF($A16="","",IFERROR(INDEX(tblAuftraege[Kostenstelle],MATCH($A16,tblAuftraege[Auftrag],0)),"")) | C16: =IF($A16="","",IFERROR(INDEX(tblAuftraege[Themenfeld],MATCH($A16,tblAuftraege[Auftrag],0)),"")) | D16: =IF($A16="","",IFERROR(INDEX(tblAuftraege[Kategorie],MATCH($A16,tblAuftraege[Auftrag],0)),"")) | E16: =IF($A16="",0,SUMIFS(tblAuftraege[Einnahmen],tblAuftraege[Datum Einnahmen],">="&E$5,tblAuftraege[Datum Einnahmen],"<"&EDATE(E$5,1),tblAuftraege[Auftrag],$A16)) -> 0 | F16: =IF($A16="",0,SUMIFS(tblAuftraege[Einnahmen],tblAuftraege[Datum Einnahmen],">="&F$5,tblAuftraege[Datum Einnahmen],"<"&EDATE(F$5,1),tblAuftraege[Auftrag],$A16)) -> 0 | G16: =IF($A16="",0,SUMIFS(tblAuftraege[Einnahmen],tblAuftraege[Datum Einnahmen],">="&G$5,tblAuftraege[Datum Einnahmen],"<"&EDATE(G$5,1),tblAuftraege[Auftrag],$A16)) -> 0 | H16: =IF($A16="",0,SUMIFS(tblAuftraege[Einnahmen],tblAuftraege[Datum Einnahmen],">="&H$5,tblAuftraege[Datum Einnahmen],"<"&EDATE(H$5,1),tblAuftraege[Auftrag],$A16)) -> 0 | I16: =IF($A16="",0,SUMIFS(tblAuftraege[Einnahmen],tblAuftraege[Datum Einnahmen],">="&I$5,tblAuftraege[Datum Einnahmen],"<"&EDATE(I$5,1),tblAuftraege[Auftrag],$A16)) -> 0 | J16: =IF($A16="",0,SUMIFS(tblAuftraege[Einnahmen],tblAuftraege[Datum Einnahmen],">="&J$5,tblAuftraege[Datum Einnahmen],"<"&EDATE(J$5,1),tblAuftraege[Auftrag],$A16)) -> 0 | K16: =IF($A16="",0,SUMIFS(tblAuftraege[Einnahmen],tblAuftraege[Datum Einnahmen],">="&K$5,tblAuftraege[Datum Einnahmen],"<"&EDATE(K$5,1),tblAuftraege[Auftrag],$A16)) -> 0 | L16: =IF($A16="",0,SUMIFS(tblAuftraege[Einnahmen],tblAuftraege[Datum Einnahmen],">="&L$5,tblAuftraege[Datum Einnahmen],"<"&EDATE(L$5,1),tblAuftraege[Auftrag],$A16)) -> 0 | ... BF16: =IF($A16="",0,SUMIFS(tblAuftraege[Einnahmen],tblAuftraege[Datum Einnahmen],">="&BF$5,tblAuftraege[Datum Einnahmen],"<"&EDATE(BF$5,1),tblAuftraege[Auftrag],$A16)) -> 0 | BG16: =SUM(E16:J16) -> 0 | BH16: =SUM(K16:V16) -> 0 | BI16: =SUM(W16:AH16) -> 0 | BJ16: =SUM(AI16:AT16) -> 0 | BK16: =SUM(AU16:BF16) -> 0 | BL16: =SUM(E16:BF16) -> 0
B17: =IF($A17="","",IFERROR(INDEX(tblAuftraege[Kostenstelle],MATCH($A17,tblAuftraege[Auftrag],0)),"")) | C17: =IF($A17="","",IFERROR(INDEX(tblAuftraege[Themenfeld],MATCH($A17,tblAuftraege[Auftrag],0)),"")) | D17: =IF($A17="","",IFERROR(INDEX(tblAuftraege[Kategorie],MATCH($A17,tblAuftraege[Auftrag],0)),"")) | E17: =IF($A17="",0,SUMIFS(tblAuftraege[Einnahmen],tblAuftraege[Datum Einnahmen],">="&E$5,tblAuftraege[Datum Einnahmen],"<"&EDATE(E$5,1),tblAuftraege[Auftrag],$A17)) -> 0 | F17: =IF($A17="",0,SUMIFS(tblAuftraege[Einnahmen],tblAuftraege[Datum Einnahmen],">="&F$5,tblAuftraege[Datum Einnahmen],"<"&EDATE(F$5,1),tblAuftraege[Auftrag],$A17)) -> 0 | G17: =IF($A17="",0,SUMIFS(tblAuftraege[Einnahmen],tblAuftraege[Datum Einnahmen],">="&G$5,tblAuftraege[Datum Einnahmen],"<"&EDATE(G$5,1),tblAuftraege[Auftrag],$A17)) -> 0 | H17: =IF($A17="",0,SUMIFS(tblAuftraege[Einnahmen],tblAuftraege[Datum Einnahmen],">="&H$5,tblAuftraege[Datum Einnahmen],"<"&EDATE(H$5,1),tblAuftraege[Auftrag],$A17)) -> 0 | I17: =IF($A17="",0,SUMIFS(tblAuftraege[Einnahmen],tblAuftraege[Datum Einnahmen],">="&I$5,tblAuftraege[Datum Einnahmen],"<"&EDATE(I$5,1),tblAuftraege[Auftrag],$A17)) -> 0 | J17: =IF($A17="",0,SUMIFS(tblAuftraege[Einnahmen],tblAuftraege[Datum Einnahmen],">="&J$5,tblAuftraege[Datum Einnahmen],"<"&EDATE(J$5,1),tblAuftraege[Auftrag],$A17)) -> 0 | K17: =IF($A17="",0,SUMIFS(tblAuftraege[Einnahmen],tblAuftraege[Datum Einnahmen],">="&K$5,tblAuftraege[Datum Einnahmen],"<"&EDATE(K$5,1),tblAuftraege[Auftrag],$A17)) -> 0 | L17: =IF($A17="",0,SUMIFS(tblAuftraege[Einnahmen],tblAuftraege[Datum Einnahmen],">="&L$5,tblAuftraege[Datum Einnahmen],"<"&EDATE(L$5,1),tblAuftraege[Auftrag],$A17)) -> 0 | ... BF17: =IF($A17="",0,SUMIFS(tblAuftraege[Einnahmen],tblAuftraege[Datum Einnahmen],">="&BF$5,tblAuftraege[Datum Einnahmen],"<"&EDATE(BF$5,1),tblAuftraege[Auftrag],$A17)) -> 0 | BG17: =SUM(E17:J17) -> 0 | BH17: =SUM(K17:V17) -> 0 | BI17: =SUM(W17:AH17) -> 0 | BJ17: =SUM(AI17:AT17) -> 0 | BK17: =SUM(AU17:BF17) -> 0 | BL17: =SUM(E17:BF17) -> 0
B18: =IF($A18="","",IFERROR(INDEX(tblAuftraege[Kostenstelle],MATCH($A18,tblAuftraege[Auftrag],0)),"")) | C18: =IF($A18="","",IFERROR(INDEX(tblAuftraege[Themenfeld],MATCH($A18,tblAuftraege[Auftrag],0)),"")) | D18: =IF($A18="","",IFERROR(INDEX(tblAuftraege[Kategorie],MATCH($A18,tblAuftraege[Auftrag],0)),"")) | E18: =IF($A18="",0,SUMIFS(tblAuftraege[Einnahmen],tblAuftraege[Datum Einnahmen],">="&E$5,tblAuftraege[Datum Einnahmen],"<"&EDATE(E$5,1),tblAuftraege[Auftrag],$A18)) -> 0 | F18: =IF($A18="",0,SUMIFS(tblAuftraege[Einnahmen],tblAuftraege[Datum Einnahmen],">="&F$5,tblAuftraege[Datum Einnahmen],"<"&EDATE(F$5,1),tblAuftraege[Auftrag],$A18)) -> 0 | G18: =IF($A18="",0,SUMIFS(tblAuftraege[Einnahmen],tblAuftraege[Datum Einnahmen],">="&G$5,tblAuftraege[Datum Einnahmen],"<"&EDATE(G$5,1),tblAuftraege[Auftrag],$A18)) -> 0 | H18: =IF($A18="",0,SUMIFS(tblAuftraege[Einnahmen],tblAuftraege[Datum Einnahmen],">="&H$5,tblAuftraege[Datum Einnahmen],"<"&EDATE(H$5,1),tblAuftraege[Auftrag],$A18)) -> 0 | I18: =IF($A18="",0,SUMIFS(tblAuftraege[Einnahmen],tblAuftraege[Datum Einnahmen],">="&I$5,tblAuftraege[Datum Einnahmen],"<"&EDATE(I$5,1),tblAuftraege[Auftrag],$A18)) -> 0 | J18: =IF($A18="",0,SUMIFS(tblAuftraege[Einnahmen],tblAuftraege[Datum Einnahmen],">="&J$5,tblAuftraege[Datum Einnahmen],"<"&EDATE(J$5,1),tblAuftraege[Auftrag],$A18)) -> 0 | K18: =IF($A18="",0,SUMIFS(tblAuftraege[Einnahmen],tblAuftraege[Datum Einnahmen],">="&K$5,tblAuftraege[Datum Einnahmen],"<"&EDATE(K$5,1),tblAuftraege[Auftrag],$A18)) -> 0 | L18: =IF($A18="",0,SUMIFS(tblAuftraege[Einnahmen],tblAuftraege[Datum Einnahmen],">="&L$5,tblAuftraege[Datum Einnahmen],"<"&EDATE(L$5,1),tblAuftraege[Auftrag],$A18)) -> 0 | ... BF18: =IF($A18="",0,SUMIFS(tblAuftraege[Einnahmen],tblAuftraege[Datum Einnahmen],">="&BF$5,tblAuftraege[Datum Einnahmen],"<"&EDATE(BF$5,1),tblAuftraege[Auftrag],$A18)) -> 0 | BG18: =SUM(E18:J18) -> 0 | BH18: =SUM(K18:V18) -> 0 | BI18: =SUM(W18:AH18) -> 0 | BJ18: =SUM(AI18:AT18) -> 0 | BK18: =SUM(AU18:BF18) -> 0 | BL18: =SUM(E18:BF18) -> 0
B19: =IF($A19="","",IFERROR(INDEX(tblAuftraege[Kostenstelle],MATCH($A19,tblAuftraege[Auftrag],0)),"")) | C19: =IF($A19="","",IFERROR(INDEX(tblAuftraege[Themenfeld],MATCH($A19,tblAuftraege[Auftrag],0)),"")) | D19: =IF($A19="","",IFERROR(INDEX(tblAuftraege[Kategorie],MATCH($A19,tblAuftraege[Auftrag],0)),"")) | E19: =IF($A19="",0,SUMIFS(tblAuftraege[Einnahmen],tblAuftraege[Datum Einnahmen],">="&E$5,tblAuftraege[Datum Einnahmen],"<"&EDATE(E$5,1),tblAuftraege[Auftrag],$A19)) -> 0 | F19: =IF($A19="",0,SUMIFS(tblAuftraege[Einnahmen],tblAuftraege[Datum Einnahmen],">="&F$5,tblAuftraege[Datum Einnahmen],"<"&EDATE(F$5,1),tblAuftraege[Auftrag],$A19)) -> 0 | G19: =IF($A19="",0,SUMIFS(tblAuftraege[Einnahmen],tblAuftraege[Datum Einnahmen],">="&G$5,tblAuftraege[Datum Einnahmen],"<"&EDATE(G$5,1),tblAuftraege[Auftrag],$A19)) -> 0 | H19: =IF($A19="",0,SUMIFS(tblAuftraege[Einnahmen],tblAuftraege[Datum Einnahmen],">="&H$5,tblAuftraege[Datum Einnahmen],"<"&EDATE(H$5,1),tblAuftraege[Auftrag],$A19)) -> 0 | I19: =IF($A19="",0,SUMIFS(tblAuftraege[Einnahmen],tblAuftraege[Datum Einnahmen],">="&I$5,tblAuftraege[Datum Einnahmen],"<"&EDATE(I$5,1),tblAuftraege[Auftrag],$A19)) -> 0 | J19: =IF($A19="",0,SUMIFS(tblAuftraege[Einnahmen],tblAuftraege[Datum Einnahmen],">="&J$5,tblAuftraege[Datum Einnahmen],"<"&EDATE(J$5,1),tblAuftraege[Auftrag],$A19)) -> 0 | K19: =IF($A19="",0,SUMIFS(tblAuftraege[Einnahmen],tblAuftraege[Datum Einnahmen],">="&K$5,tblAuftraege[Datum Einnahmen],"<"&EDATE(K$5,1),tblAuftraege[Auftrag],$A19)) -> 0 | L19: =IF($A19="",0,SUMIFS(tblAuftraege[Einnahmen],tblAuftraege[Datum Einnahmen],">="&L$5,tblAuftraege[Datum Einnahmen],"<"&EDATE(L$5,1),tblAuftraege[Auftrag],$A19)) -> 0 | ... BF19: =IF($A19="",0,SUMIFS(tblAuftraege[Einnahmen],tblAuftraege[Datum Einnahmen],">="&BF$5,tblAuftraege[Datum Einnahmen],"<"&EDATE(BF$5,1),tblAuftraege[Auftrag],$A19)) -> 0 | BG19: =SUM(E19:J19) -> 0 | BH19: =SUM(K19:V19) -> 0 | BI19: =SUM(W19:AH19) -> 0 | BJ19: =SUM(AI19:AT19) -> 0 | BK19: =SUM(AU19:BF19) -> 0 | BL19: =SUM(E19:BF19) -> 0
... B57: =IF($A57="","",IFERROR(INDEX(tblAuftraege[Kostenstelle],MATCH($A57,tblAuftraege[Auftrag],0)),"")) | C57: =IF($A57="","",IFERROR(INDEX(tblAuftraege[Themenfeld],MATCH($A57,tblAuftraege[Auftrag],0)),"")) | D57: =IF($A57="","",IFERROR(INDEX(tblAuftraege[Kategorie],MATCH($A57,tblAuftraege[Auftrag],0)),"")) | E57: =IF($A57="",0,SUMIFS(tblAuftraege[Einnahmen],tblAuftraege[Datum Einnahmen],">="&E$5,tblAuftraege[Datum Einnahmen],"<"&EDATE(E$5,1),tblAuftraege[Auftrag],$A57)) -> 0 | F57: =IF($A57="",0,SUMIFS(tblAuftraege[Einnahmen],tblAuftraege[Datum Einnahmen],">="&F$5,tblAuftraege[Datum Einnahmen],"<"&EDATE(F$5,1),tblAuftraege[Auftrag],$A57)) -> 0 | G57: =IF($A57="",0,SUMIFS(tblAuftraege[Einnahmen],tblAuftraege[Datum Einnahmen],">="&G$5,tblAuftraege[Datum Einnahmen],"<"&EDATE(G$5,1),tblAuftraege[Auftrag],$A57)) -> 0 | H57: =IF($A57="",0,SUMIFS(tblAuftraege[Einnahmen],tblAuftraege[Datum Einnahmen],">="&H$5,tblAuftraege[Datum Einnahmen],"<"&EDATE(H$5,1),tblAuftraege[Auftrag],$A57)) -> 0 | I57: =IF($A57="",0,SUMIFS(tblAuftraege[Einnahmen],tblAuftraege[Datum Einnahmen],">="&I$5,tblAuftraege[Datum Einnahmen],"<"&EDATE(I$5,1),tblAuftraege[Auftrag],$A57)) -> 0 | J57: =IF($A57="",0,SUMIFS(tblAuftraege[Einnahmen],tblAuftraege[Datum Einnahmen],">="&J$5,tblAuftraege[Datum Einnahmen],"<"&EDATE(J$5,1),tblAuftraege[Auftrag],$A57)) -> 0 | K57: =IF($A57="",0,SUMIFS(tblAuftraege[Einnahmen],tblAuftraege[Datum Einnahmen],">="&K$5,tblAuftraege[Datum Einnahmen],"<"&EDATE(K$5,1),tblAuftraege[Auftrag],$A57)) -> 0 | L57: =IF($A57="",0,SUMIFS(tblAuftraege[Einnahmen],tblAuftraege[Datum Einnahmen],">="&L$5,tblAuftraege[Datum Einnahmen],"<"&EDATE(L$5,1),tblAuftraege[Auftrag],$A57)) -> 0 | ... BF57: =IF($A57="",0,SUMIFS(tblAuftraege[Einnahmen],tblAuftraege[Datum Einnahmen],">="&BF$5,tblAuftraege[Datum Einnahmen],"<"&EDATE(BF$5,1),tblAuftraege[Auftrag],$A57)) -> 0 | BG57: =SUM(E57:J57) -> 0 | BH57: =SUM(K57:V57) -> 0 | BI57: =SUM(W57:AH57) -> 0 | BJ57: =SUM(AI57:AT57) -> 0 | BK57: =SUM(AU57:BF57) -> 0 | BL57: =SUM(E57:BF57) -> 0
A58: Noch nicht erfasste Aufträge | B58: Differenz | E58: =E59-SUM(E8:E57) -> 0 | F58: =F59-SUM(F8:F57) -> 0 | G58: =G59-SUM(G8:G57) -> 0 | H58: =H59-SUM(H8:H57) -> 0 | I58: =I59-SUM(I8:I57) -> 0 | J58: =J59-SUM(J8:J57) -> 0 | K58: =K59-SUM(K8:K57) -> 0 | L58: =L59-SUM(L8:L57) -> 0 | ... BL58: =BL59-SUM(BL8:BL57) -> 0
A59: Summe Einnahmen | E59: =SUMIFS(tblAuftraege[Einnahmen],tblAuftraege[Datum Einnahmen],">="&E$5,tblAuftraege[Datum Einnahmen],"<"&EDATE(E$5,1)) -> 0 | F59: =SUMIFS(tblAuftraege[Einnahmen],tblAuftraege[Datum Einnahmen],">="&F$5,tblAuftraege[Datum Einnahmen],"<"&EDATE(F$5,1)) -> 0 | G59: =SUMIFS(tblAuftraege[Einnahmen],tblAuftraege[Datum Einnahmen],">="&G$5,tblAuftraege[Datum Einnahmen],"<"&EDATE(G$5,1)) -> 0 | H59: =SUMIFS(tblAuftraege[Einnahmen],tblAuftraege[Datum Einnahmen],">="&H$5,tblAuftraege[Datum Einnahmen],"<"&EDATE(H$5,1)) -> 0 | I59: =SUMIFS(tblAuftraege[Einnahmen],tblAuftraege[Datum Einnahmen],">="&I$5,tblAuftraege[Datum Einnahmen],"<"&EDATE(I$5,1)) -> 0 | J59: =SUMIFS(tblAuftraege[Einnahmen],tblAuftraege[Datum Einnahmen],">="&J$5,tblAuftraege[Datum Einnahmen],"<"&EDATE(J$5,1)) -> 0 | K59: =SUMIFS(tblAuftraege[Einnahmen],tblAuftraege[Datum Einnahmen],">="&K$5,tblAuftraege[Datum Einnahmen],"<"&EDATE(K$5,1)) -> 0 | L59: =SUMIFS(tblAuftraege[Einnahmen],tblAuftraege[Datum Einnahmen],">="&L$5,tblAuftraege[Datum Einnahmen],"<"&EDATE(L$5,1)) -> 0 | ... BF59: =SUMIFS(tblAuftraege[Einnahmen],tblAuftraege[Datum Einnahmen],">="&BF$5,tblAuftraege[Datum Einnahmen],"<"&EDATE(BF$5,1)) -> 0 | BG59: =SUM(E59:J59) -> 0 | BH59: =SUM(K59:V59) -> 0 | BI59: =SUM(W59:AH59) -> 0 | BJ59: =SUM(AI59:AT59) -> 0 | BK59: =SUM(AU59:BF59) -> 0 | BL59: =SUM(E59:BF59) -> 0
A61: 2 AUSGABEN JE AUFTRAG (Quelle: Reiter „Aufträge“)
B62: =IF($A62="","",IFERROR(INDEX(tblAuftraege[Kostenstelle],MATCH($A62,tblAuftraege[Auftrag],0)),"")) | C62: =IF($A62="","",IFERROR(INDEX(tblAuftraege[Themenfeld],MATCH($A62,tblAuftraege[Auftrag],0)),"")) | D62: =IF($A62="","",IFERROR(INDEX(tblAuftraege[Kategorie],MATCH($A62,tblAuftraege[Auftrag],0)),"")) | E62: =IF($A62="",0,SUMIFS(tblAuftraege[Ausgaben],tblAuftraege[Datum Ausgaben],">="&E$5,tblAuftraege[Datum Ausgaben],"<"&EDATE(E$5,1),tblAuftraege[Auftrag],$A62)) -> 0 | F62: =IF($A62="",0,SUMIFS(tblAuftraege[Ausgaben],tblAuftraege[Datum Ausgaben],">="&F$5,tblAuftraege[Datum Ausgaben],"<"&EDATE(F$5,1),tblAuftraege[Auftrag],$A62)) -> 0 | G62: =IF($A62="",0,SUMIFS(tblAuftraege[Ausgaben],tblAuftraege[Datum Ausgaben],">="&G$5,tblAuftraege[Datum Ausgaben],"<"&EDATE(G$5,1),tblAuftraege[Auftrag],$A62)) -> 0 | H62: =IF($A62="",0,SUMIFS(tblAuftraege[Ausgaben],tblAuftraege[Datum Ausgaben],">="&H$5,tblAuftraege[Datum Ausgaben],"<"&EDATE(H$5,1),tblAuftraege[Auftrag],$A62)) -> 0 | I62: =IF($A62="",0,SUMIFS(tblAuftraege[Ausgaben],tblAuftraege[Datum Ausgaben],">="&I$5,tblAuftraege[Datum Ausgaben],"<"&EDATE(I$5,1),tblAuftraege[Auftrag],$A62)) -> 0 | J62: =IF($A62="",0,SUMIFS(tblAuftraege[Ausgaben],tblAuftraege[Datum Ausgaben],">="&J$5,tblAuftraege[Datum Ausgaben],"<"&EDATE(J$5,1),tblAuftraege[Auftrag],$A62)) -> 0 | K62: =IF($A62="",0,SUMIFS(tblAuftraege[Ausgaben],tblAuftraege[Datum Ausgaben],">="&K$5,tblAuftraege[Datum Ausgaben],"<"&EDATE(K$5,1),tblAuftraege[Auftrag],$A62)) -> 0 | L62: =IF($A62="",0,SUMIFS(tblAuftraege[Ausgaben],tblAuftraege[Datum Ausgaben],">="&L$5,tblAuftraege[Datum Ausgaben],"<"&EDATE(L$5,1),tblAuftraege[Auftrag],$A62)) -> 0 | ... BF62: =IF($A62="",0,SUMIFS(tblAuftraege[Ausgaben],tblAuftraege[Datum Ausgaben],">="&BF$5,tblAuftraege[Datum Ausgaben],"<"&EDATE(BF$5,1),tblAuftraege[Auftrag],$A62)) -> 0 | BG62: =SUM(E62:J62) -> 0 | BH62: =SUM(K62:V62) -> 0 | BI62: =SUM(W62:AH62) -> 0 | BJ62: =SUM(AI62:AT62) -> 0 | BK62: =SUM(AU62:BF62) -> 0 | BL62: =SUM(E62:BF62) -> 0
B63: =IF($A63="","",IFERROR(INDEX(tblAuftraege[Kostenstelle],MATCH($A63,tblAuftraege[Auftrag],0)),"")) | C63: =IF($A63="","",IFERROR(INDEX(tblAuftraege[Themenfeld],MATCH($A63,tblAuftraege[Auftrag],0)),"")) | D63: =IF($A63="","",IFERROR(INDEX(tblAuftraege[Kategorie],MATCH($A63,tblAuftraege[Auftrag],0)),"")) | E63: =IF($A63="",0,SUMIFS(tblAuftraege[Ausgaben],tblAuftraege[Datum Ausgaben],">="&E$5,tblAuftraege[Datum Ausgaben],"<"&EDATE(E$5,1),tblAuftraege[Auftrag],$A63)) -> 0 | F63: =IF($A63="",0,SUMIFS(tblAuftraege[Ausgaben],tblAuftraege[Datum Ausgaben],">="&F$5,tblAuftraege[Datum Ausgaben],"<"&EDATE(F$5,1),tblAuftraege[Auftrag],$A63)) -> 0 | G63: =IF($A63="",0,SUMIFS(tblAuftraege[Ausgaben],tblAuftraege[Datum Ausgaben],">="&G$5,tblAuftraege[Datum Ausgaben],"<"&EDATE(G$5,1),tblAuftraege[Auftrag],$A63)) -> 0 | H63: =IF($A63="",0,SUMIFS(tblAuftraege[Ausgaben],tblAuftraege[Datum Ausgaben],">="&H$5,tblAuftraege[Datum Ausgaben],"<"&EDATE(H$5,1),tblAuftraege[Auftrag],$A63)) -> 0 | I63: =IF($A63="",0,SUMIFS(tblAuftraege[Ausgaben],tblAuftraege[Datum Ausgaben],">="&I$5,tblAuftraege[Datum Ausgaben],"<"&EDATE(I$5,1),tblAuftraege[Auftrag],$A63)) -> 0 | J63: =IF($A63="",0,SUMIFS(tblAuftraege[Ausgaben],tblAuftraege[Datum Ausgaben],">="&J$5,tblAuftraege[Datum Ausgaben],"<"&EDATE(J$5,1),tblAuftraege[Auftrag],$A63)) -> 0 | K63: =IF($A63="",0,SUMIFS(tblAuftraege[Ausgaben],tblAuftraege[Datum Ausgaben],">="&K$5,tblAuftraege[Datum Ausgaben],"<"&EDATE(K$5,1),tblAuftraege[Auftrag],$A63)) -> 0 | L63: =IF($A63="",0,SUMIFS(tblAuftraege[Ausgaben],tblAuftraege[Datum Ausgaben],">="&L$5,tblAuftraege[Datum Ausgaben],"<"&EDATE(L$5,1),tblAuftraege[Auftrag],$A63)) -> 0 | ... BF63: =IF($A63="",0,SUMIFS(tblAuftraege[Ausgaben],tblAuftraege[Datum Ausgaben],">="&BF$5,tblAuftraege[Datum Ausgaben],"<"&EDATE(BF$5,1),tblAuftraege[Auftrag],$A63)) -> 0 | BG63: =SUM(E63:J63) -> 0 | BH63: =SUM(K63:V63) -> 0 | BI63: =SUM(W63:AH63) -> 0 | BJ63: =SUM(AI63:AT63) -> 0 | BK63: =SUM(AU63:BF63) -> 0 | BL63: =SUM(E63:BF63) -> 0
B64: =IF($A64="","",IFERROR(INDEX(tblAuftraege[Kostenstelle],MATCH($A64,tblAuftraege[Auftrag],0)),"")) | C64: =IF($A64="","",IFERROR(INDEX(tblAuftraege[Themenfeld],MATCH($A64,tblAuftraege[Auftrag],0)),"")) | D64: =IF($A64="","",IFERROR(INDEX(tblAuftraege[Kategorie],MATCH($A64,tblAuftraege[Auftrag],0)),"")) | E64: =IF($A64="",0,SUMIFS(tblAuftraege[Ausgaben],tblAuftraege[Datum Ausgaben],">="&E$5,tblAuftraege[Datum Ausgaben],"<"&EDATE(E$5,1),tblAuftraege[Auftrag],$A64)) -> 0 | F64: =IF($A64="",0,SUMIFS(tblAuftraege[Ausgaben],tblAuftraege[Datum Ausgaben],">="&F$5,tblAuftraege[Datum Ausgaben],"<"&EDATE(F$5,1),tblAuftraege[Auftrag],$A64)) -> 0 | G64: =IF($A64="",0,SUMIFS(tblAuftraege[Ausgaben],tblAuftraege[Datum Ausgaben],">="&G$5,tblAuftraege[Datum Ausgaben],"<"&EDATE(G$5,1),tblAuftraege[Auftrag],$A64)) -> 0 | H64: =IF($A64="",0,SUMIFS(tblAuftraege[Ausgaben],tblAuftraege[Datum Ausgaben],">="&H$5,tblAuftraege[Datum Ausgaben],"<"&EDATE(H$5,1),tblAuftraege[Auftrag],$A64)) -> 0 | I64: =IF($A64="",0,SUMIFS(tblAuftraege[Ausgaben],tblAuftraege[Datum Ausgaben],">="&I$5,tblAuftraege[Datum Ausgaben],"<"&EDATE(I$5,1),tblAuftraege[Auftrag],$A64)) -> 0 | J64: =IF($A64="",0,SUMIFS(tblAuftraege[Ausgaben],tblAuftraege[Datum Ausgaben],">="&J$5,tblAuftraege[Datum Ausgaben],"<"&EDATE(J$5,1),tblAuftraege[Auftrag],$A64)) -> 0 | K64: =IF($A64="",0,SUMIFS(tblAuftraege[Ausgaben],tblAuftraege[Datum Ausgaben],">="&K$5,tblAuftraege[Datum Ausgaben],"<"&EDATE(K$5,1),tblAuftraege[Auftrag],$A64)) -> 0 | L64: =IF($A64="",0,SUMIFS(tblAuftraege[Ausgaben],tblAuftraege[Datum Ausgaben],">="&L$5,tblAuftraege[Datum Ausgaben],"<"&EDATE(L$5,1),tblAuftraege[Auftrag],$A64)) -> 0 | ... BF64: =IF($A64="",0,SUMIFS(tblAuftraege[Ausgaben],tblAuftraege[Datum Ausgaben],">="&BF$5,tblAuftraege[Datum Ausgaben],"<"&EDATE(BF$5,1),tblAuftraege[Auftrag],$A64)) -> 0 | BG64: =SUM(E64:J64) -> 0 | BH64: =SUM(K64:V64) -> 0 | BI64: =SUM(W64:AH64) -> 0 | BJ64: =SUM(AI64:AT64) -> 0 | BK64: =SUM(AU64:BF64) -> 0 | BL64: =SUM(E64:BF64) -> 0
B65: =IF($A65="","",IFERROR(INDEX(tblAuftraege[Kostenstelle],MATCH($A65,tblAuftraege[Auftrag],0)),"")) | C65: =IF($A65="","",IFERROR(INDEX(tblAuftraege[Themenfeld],MATCH($A65,tblAuftraege[Auftrag],0)),"")) | D65: =IF($A65="","",IFERROR(INDEX(tblAuftraege[Kategorie],MATCH($A65,tblAuftraege[Auftrag],0)),"")) | E65: =IF($A65="",0,SUMIFS(tblAuftraege[Ausgaben],tblAuftraege[Datum Ausgaben],">="&E$5,tblAuftraege[Datum Ausgaben],"<"&EDATE(E$5,1),tblAuftraege[Auftrag],$A65)) -> 0 | F65: =IF($A65="",0,SUMIFS(tblAuftraege[Ausgaben],tblAuftraege[Datum Ausgaben],">="&F$5,tblAuftraege[Datum Ausgaben],"<"&EDATE(F$5,1),tblAuftraege[Auftrag],$A65)) -> 0 | G65: =IF($A65="",0,SUMIFS(tblAuftraege[Ausgaben],tblAuftraege[Datum Ausgaben],">="&G$5,tblAuftraege[Datum Ausgaben],"<"&EDATE(G$5,1),tblAuftraege[Auftrag],$A65)) -> 0 | H65: =IF($A65="",0,SUMIFS(tblAuftraege[Ausgaben],tblAuftraege[Datum Ausgaben],">="&H$5,tblAuftraege[Datum Ausgaben],"<"&EDATE(H$5,1),tblAuftraege[Auftrag],$A65)) -> 0 | I65: =IF($A65="",0,SUMIFS(tblAuftraege[Ausgaben],tblAuftraege[Datum Ausgaben],">="&I$5,tblAuftraege[Datum Ausgaben],"<"&EDATE(I$5,1),tblAuftraege[Auftrag],$A65)) -> 0 | J65: =IF($A65="",0,SUMIFS(tblAuftraege[Ausgaben],tblAuftraege[Datum Ausgaben],">="&J$5,tblAuftraege[Datum Ausgaben],"<"&EDATE(J$5,1),tblAuftraege[Auftrag],$A65)) -> 0 | K65: =IF($A65="",0,SUMIFS(tblAuftraege[Ausgaben],tblAuftraege[Datum Ausgaben],">="&K$5,tblAuftraege[Datum Ausgaben],"<"&EDATE(K$5,1),tblAuftraege[Auftrag],$A65)) -> 0 | L65: =IF($A65="",0,SUMIFS(tblAuftraege[Ausgaben],tblAuftraege[Datum Ausgaben],">="&L$5,tblAuftraege[Datum Ausgaben],"<"&EDATE(L$5,1),tblAuftraege[Auftrag],$A65)) -> 0 | ... BF65: =IF($A65="",0,SUMIFS(tblAuftraege[Ausgaben],tblAuftraege[Datum Ausgaben],">="&BF$5,tblAuftraege[Datum Ausgaben],"<"&EDATE(BF$5,1),tblAuftraege[Auftrag],$A65)) -> 0 | BG65: =SUM(E65:J65) -> 0 | BH65: =SUM(K65:V65) -> 0 | BI65: =SUM(W65:AH65) -> 0 | BJ65: =SUM(AI65:AT65) -> 0 | BK65: =SUM(AU65:BF65) -> 0 | BL65: =SUM(E65:BF65) -> 0
B66: =IF($A66="","",IFERROR(INDEX(tblAuftraege[Kostenstelle],MATCH($A66,tblAuftraege[Auftrag],0)),"")) | C66: =IF($A66="","",IFERROR(INDEX(tblAuftraege[Themenfeld],MATCH($A66,tblAuftraege[Auftrag],0)),"")) | D66: =IF($A66="","",IFERROR(INDEX(tblAuftraege[Kategorie],MATCH($A66,tblAuftraege[Auftrag],0)),"")) | E66: =IF($A66="",0,SUMIFS(tblAuftraege[Ausgaben],tblAuftraege[Datum Ausgaben],">="&E$5,tblAuftraege[Datum Ausgaben],"<"&EDATE(E$5,1),tblAuftraege[Auftrag],$A66)) -> 0 | F66: =IF($A66="",0,SUMIFS(tblAuftraege[Ausgaben],tblAuftraege[Datum Ausgaben],">="&F$5,tblAuftraege[Datum Ausgaben],"<"&EDATE(F$5,1),tblAuftraege[Auftrag],$A66)) -> 0 | G66: =IF($A66="",0,SUMIFS(tblAuftraege[Ausgaben],tblAuftraege[Datum Ausgaben],">="&G$5,tblAuftraege[Datum Ausgaben],"<"&EDATE(G$5,1),tblAuftraege[Auftrag],$A66)) -> 0 | H66: =IF($A66="",0,SUMIFS(tblAuftraege[Ausgaben],tblAuftraege[Datum Ausgaben],">="&H$5,tblAuftraege[Datum Ausgaben],"<"&EDATE(H$5,1),tblAuftraege[Auftrag],$A66)) -> 0 | I66: =IF($A66="",0,SUMIFS(tblAuftraege[Ausgaben],tblAuftraege[Datum Ausgaben],">="&I$5,tblAuftraege[Datum Ausgaben],"<"&EDATE(I$5,1),tblAuftraege[Auftrag],$A66)) -> 0 | J66: =IF($A66="",0,SUMIFS(tblAuftraege[Ausgaben],tblAuftraege[Datum Ausgaben],">="&J$5,tblAuftraege[Datum Ausgaben],"<"&EDATE(J$5,1),tblAuftraege[Auftrag],$A66)) -> 0 | K66: =IF($A66="",0,SUMIFS(tblAuftraege[Ausgaben],tblAuftraege[Datum Ausgaben],">="&K$5,tblAuftraege[Datum Ausgaben],"<"&EDATE(K$5,1),tblAuftraege[Auftrag],$A66)) -> 0 | L66: =IF($A66="",0,SUMIFS(tblAuftraege[Ausgaben],tblAuftraege[Datum Ausgaben],">="&L$5,tblAuftraege[Datum Ausgaben],"<"&EDATE(L$5,1),tblAuftraege[Auftrag],$A66)) -> 0 | ... BF66: =IF($A66="",0,SUMIFS(tblAuftraege[Ausgaben],tblAuftraege[Datum Ausgaben],">="&BF$5,tblAuftraege[Datum Ausgaben],"<"&EDATE(BF$5,1),tblAuftraege[Auftrag],$A66)) -> 0 | BG66: =SUM(E66:J66) -> 0 | BH66: =SUM(K66:V66) -> 0 | BI66: =SUM(W66:AH66) -> 0 | BJ66: =SUM(AI66:AT66) -> 0 | BK66: =SUM(AU66:BF66) -> 0 | BL66: =SUM(E66:BF66) -> 0
B67: =IF($A67="","",IFERROR(INDEX(tblAuftraege[Kostenstelle],MATCH($A67,tblAuftraege[Auftrag],0)),"")) | C67: =IF($A67="","",IFERROR(INDEX(tblAuftraege[Themenfeld],MATCH($A67,tblAuftraege[Auftrag],0)),"")) | D67: =IF($A67="","",IFERROR(INDEX(tblAuftraege[Kategorie],MATCH($A67,tblAuftraege[Auftrag],0)),"")) | E67: =IF($A67="",0,SUMIFS(tblAuftraege[Ausgaben],tblAuftraege[Datum Ausgaben],">="&E$5,tblAuftraege[Datum Ausgaben],"<"&EDATE(E$5,1),tblAuftraege[Auftrag],$A67)) -> 0 | F67: =IF($A67="",0,SUMIFS(tblAuftraege[Ausgaben],tblAuftraege[Datum Ausgaben],">="&F$5,tblAuftraege[Datum Ausgaben],"<"&EDATE(F$5,1),tblAuftraege[Auftrag],$A67)) -> 0 | G67: =IF($A67="",0,SUMIFS(tblAuftraege[Ausgaben],tblAuftraege[Datum Ausgaben],">="&G$5,tblAuftraege[Datum Ausgaben],"<"&EDATE(G$5,1),tblAuftraege[Auftrag],$A67)) -> 0 | H67: =IF($A67="",0,SUMIFS(tblAuftraege[Ausgaben],tblAuftraege[Datum Ausgaben],">="&H$5,tblAuftraege[Datum Ausgaben],"<"&EDATE(H$5,1),tblAuftraege[Auftrag],$A67)) -> 0 | I67: =IF($A67="",0,SUMIFS(tblAuftraege[Ausgaben],tblAuftraege[Datum Ausgaben],">="&I$5,tblAuftraege[Datum Ausgaben],"<"&EDATE(I$5,1),tblAuftraege[Auftrag],$A67)) -> 0 | J67: =IF($A67="",0,SUMIFS(tblAuftraege[Ausgaben],tblAuftraege[Datum Ausgaben],">="&J$5,tblAuftraege[Datum Ausgaben],"<"&EDATE(J$5,1),tblAuftraege[Auftrag],$A67)) -> 0 | K67: =IF($A67="",0,SUMIFS(tblAuftraege[Ausgaben],tblAuftraege[Datum Ausgaben],">="&K$5,tblAuftraege[Datum Ausgaben],"<"&EDATE(K$5,1),tblAuftraege[Auftrag],$A67)) -> 0 | L67: =IF($A67="",0,SUMIFS(tblAuftraege[Ausgaben],tblAuftraege[Datum Ausgaben],">="&L$5,tblAuftraege[Datum Ausgaben],"<"&EDATE(L$5,1),tblAuftraege[Auftrag],$A67)) -> 0 | ... BF67: =IF($A67="",0,SUMIFS(tblAuftraege[Ausgaben],tblAuftraege[Datum Ausgaben],">="&BF$5,tblAuftraege[Datum Ausgaben],"<"&EDATE(BF$5,1),tblAuftraege[Auftrag],$A67)) -> 0 | BG67: =SUM(E67:J67) -> 0 | BH67: =SUM(K67:V67) -> 0 | BI67: =SUM(W67:AH67) -> 0 | BJ67: =SUM(AI67:AT67) -> 0 | BK67: =SUM(AU67:BF67) -> 0 | BL67: =SUM(E67:BF67) -> 0
B68: =IF($A68="","",IFERROR(INDEX(tblAuftraege[Kostenstelle],MATCH($A68,tblAuftraege[Auftrag],0)),"")) | C68: =IF($A68="","",IFERROR(INDEX(tblAuftraege[Themenfeld],MATCH($A68,tblAuftraege[Auftrag],0)),"")) | D68: =IF($A68="","",IFERROR(INDEX(tblAuftraege[Kategorie],MATCH($A68,tblAuftraege[Auftrag],0)),"")) | E68: =IF($A68="",0,SUMIFS(tblAuftraege[Ausgaben],tblAuftraege[Datum Ausgaben],">="&E$5,tblAuftraege[Datum Ausgaben],"<"&EDATE(E$5,1),tblAuftraege[Auftrag],$A68)) -> 0 | F68: =IF($A68="",0,SUMIFS(tblAuftraege[Ausgaben],tblAuftraege[Datum Ausgaben],">="&F$5,tblAuftraege[Datum Ausgaben],"<"&EDATE(F$5,1),tblAuftraege[Auftrag],$A68)) -> 0 | G68: =IF($A68="",0,SUMIFS(tblAuftraege[Ausgaben],tblAuftraege[Datum Ausgaben],">="&G$5,tblAuftraege[Datum Ausgaben],"<"&EDATE(G$5,1),tblAuftraege[Auftrag],$A68)) -> 0 | H68: =IF($A68="",0,SUMIFS(tblAuftraege[Ausgaben],tblAuftraege[Datum Ausgaben],">="&H$5,tblAuftraege[Datum Ausgaben],"<"&EDATE(H$5,1),tblAuftraege[Auftrag],$A68)) -> 0 | I68: =IF($A68="",0,SUMIFS(tblAuftraege[Ausgaben],tblAuftraege[Datum Ausgaben],">="&I$5,tblAuftraege[Datum Ausgaben],"<"&EDATE(I$5,1),tblAuftraege[Auftrag],$A68)) -> 0 | J68: =IF($A68="",0,SUMIFS(tblAuftraege[Ausgaben],tblAuftraege[Datum Ausgaben],">="&J$5,tblAuftraege[Datum Ausgaben],"<"&EDATE(J$5,1),tblAuftraege[Auftrag],$A68)) -> 0 | K68: =IF($A68="",0,SUMIFS(tblAuftraege[Ausgaben],tblAuftraege[Datum Ausgaben],">="&K$5,tblAuftraege[Datum Ausgaben],"<"&EDATE(K$5,1),tblAuftraege[Auftrag],$A68)) -> 0 | L68: =IF($A68="",0,SUMIFS(tblAuftraege[Ausgaben],tblAuftraege[Datum Ausgaben],">="&L$5,tblAuftraege[Datum Ausgaben],"<"&EDATE(L$5,1),tblAuftraege[Auftrag],$A68)) -> 0 | ... BF68: =IF($A68="",0,SUMIFS(tblAuftraege[Ausgaben],tblAuftraege[Datum Ausgaben],">="&BF$5,tblAuftraege[Datum Ausgaben],"<"&EDATE(BF$5,1),tblAuftraege[Auftrag],$A68)) -> 0 | BG68: =SUM(E68:J68) -> 0 | BH68: =SUM(K68:V68) -> 0 | BI68: =SUM(W68:AH68) -> 0 | BJ68: =SUM(AI68:AT68) -> 0 | BK68: =SUM(AU68:BF68) -> 0 | BL68: =SUM(E68:BF68) -> 0
B69: =IF($A69="","",IFERROR(INDEX(tblAuftraege[Kostenstelle],MATCH($A69,tblAuftraege[Auftrag],0)),"")) | C69: =IF($A69="","",IFERROR(INDEX(tblAuftraege[Themenfeld],MATCH($A69,tblAuftraege[Auftrag],0)),"")) | D69: =IF($A69="","",IFERROR(INDEX(tblAuftraege[Kategorie],MATCH($A69,tblAuftraege[Auftrag],0)),"")) | E69: =IF($A69="",0,SUMIFS(tblAuftraege[Ausgaben],tblAuftraege[Datum Ausgaben],">="&E$5,tblAuftraege[Datum Ausgaben],"<"&EDATE(E$5,1),tblAuftraege[Auftrag],$A69)) -> 0 | F69: =IF($A69="",0,SUMIFS(tblAuftraege[Ausgaben],tblAuftraege[Datum Ausgaben],">="&F$5,tblAuftraege[Datum Ausgaben],"<"&EDATE(F$5,1),tblAuftraege[Auftrag],$A69)) -> 0 | G69: =IF($A69="",0,SUMIFS(tblAuftraege[Ausgaben],tblAuftraege[Datum Ausgaben],">="&G$5,tblAuftraege[Datum Ausgaben],"<"&EDATE(G$5,1),tblAuftraege[Auftrag],$A69)) -> 0 | H69: =IF($A69="",0,SUMIFS(tblAuftraege[Ausgaben],tblAuftraege[Datum Ausgaben],">="&H$5,tblAuftraege[Datum Ausgaben],"<"&EDATE(H$5,1),tblAuftraege[Auftrag],$A69)) -> 0 | I69: =IF($A69="",0,SUMIFS(tblAuftraege[Ausgaben],tblAuftraege[Datum Ausgaben],">="&I$5,tblAuftraege[Datum Ausgaben],"<"&EDATE(I$5,1),tblAuftraege[Auftrag],$A69)) -> 0 | J69: =IF($A69="",0,SUMIFS(tblAuftraege[Ausgaben],tblAuftraege[Datum Ausgaben],">="&J$5,tblAuftraege[Datum Ausgaben],"<"&EDATE(J$5,1),tblAuftraege[Auftrag],$A69)) -> 0 | K69: =IF($A69="",0,SUMIFS(tblAuftraege[Ausgaben],tblAuftraege[Datum Ausgaben],">="&K$5,tblAuftraege[Datum Ausgaben],"<"&EDATE(K$5,1),tblAuftraege[Auftrag],$A69)) -> 0 | L69: =IF($A69="",0,SUMIFS(tblAuftraege[Ausgaben],tblAuftraege[Datum Ausgaben],">="&L$5,tblAuftraege[Datum Ausgaben],"<"&EDATE(L$5,1),tblAuftraege[Auftrag],$A69)) -> 0 | ... BF69: =IF($A69="",0,SUMIFS(tblAuftraege[Ausgaben],tblAuftraege[Datum Ausgaben],">="&BF$5,tblAuftraege[Datum Ausgaben],"<"&EDATE(BF$5,1),tblAuftraege[Auftrag],$A69)) -> 0 | BG69: =SUM(E69:J69) -> 0 | BH69: =SUM(K69:V69) -> 0 | BI69: =SUM(W69:AH69) -> 0 | BJ69: =SUM(AI69:AT69) -> 0 | BK69: =SUM(AU69:BF69) -> 0 | BL69: =SUM(E69:BF69) -> 0
B70: =IF($A70="","",IFERROR(INDEX(tblAuftraege[Kostenstelle],MATCH($A70,tblAuftraege[Auftrag],0)),"")) | C70: =IF($A70="","",IFERROR(INDEX(tblAuftraege[Themenfeld],MATCH($A70,tblAuftraege[Auftrag],0)),"")) | D70: =IF($A70="","",IFERROR(INDEX(tblAuftraege[Kategorie],MATCH($A70,tblAuftraege[Auftrag],0)),"")) | E70: =IF($A70="",0,SUMIFS(tblAuftraege[Ausgaben],tblAuftraege[Datum Ausgaben],">="&E$5,tblAuftraege[Datum Ausgaben],"<"&EDATE(E$5,1),tblAuftraege[Auftrag],$A70)) -> 0 | F70: =IF($A70="",0,SUMIFS(tblAuftraege[Ausgaben],tblAuftraege[Datum Ausgaben],">="&F$5,tblAuftraege[Datum Ausgaben],"<"&EDATE(F$5,1),tblAuftraege[Auftrag],$A70)) -> 0 | G70: =IF($A70="",0,SUMIFS(tblAuftraege[Ausgaben],tblAuftraege[Datum Ausgaben],">="&G$5,tblAuftraege[Datum Ausgaben],"<"&EDATE(G$5,1),tblAuftraege[Auftrag],$A70)) -> 0 | H70: =IF($A70="",0,SUMIFS(tblAuftraege[Ausgaben],tblAuftraege[Datum Ausgaben],">="&H$5,tblAuftraege[Datum Ausgaben],"<"&EDATE(H$5,1),tblAuftraege[Auftrag],$A70)) -> 0 | I70: =IF($A70="",0,SUMIFS(tblAuftraege[Ausgaben],tblAuftraege[Datum Ausgaben],">="&I$5,tblAuftraege[Datum Ausgaben],"<"&EDATE(I$5,1),tblAuftraege[Auftrag],$A70)) -> 0 | J70: =IF($A70="",0,SUMIFS(tblAuftraege[Ausgaben],tblAuftraege[Datum Ausgaben],">="&J$5,tblAuftraege[Datum Ausgaben],"<"&EDATE(J$5,1),tblAuftraege[Auftrag],$A70)) -> 0 | K70: =IF($A70="",0,SUMIFS(tblAuftraege[Ausgaben],tblAuftraege[Datum Ausgaben],">="&K$5,tblAuftraege[Datum Ausgaben],"<"&EDATE(K$5,1),tblAuftraege[Auftrag],$A70)) -> 0 | L70: =IF($A70="",0,SUMIFS(tblAuftraege[Ausgaben],tblAuftraege[Datum Ausgaben],">="&L$5,tblAuftraege[Datum Ausgaben],"<"&EDATE(L$5,1),tblAuftraege[Auftrag],$A70)) -> 0 | ... BF70: =IF($A70="",0,SUMIFS(tblAuftraege[Ausgaben],tblAuftraege[Datum Ausgaben],">="&BF$5,tblAuftraege[Datum Ausgaben],"<"&EDATE(BF$5,1),tblAuftraege[Auftrag],$A70)) -> 0 | BG70: =SUM(E70:J70) -> 0 | BH70: =SUM(K70:V70) -> 0 | BI70: =SUM(W70:AH70) -> 0 | BJ70: =SUM(AI70:AT70) -> 0 | BK70: =SUM(AU70:BF70) -> 0 | BL70: =SUM(E70:BF70) -> 0
B71: =IF($A71="","",IFERROR(INDEX(tblAuftraege[Kostenstelle],MATCH($A71,tblAuftraege[Auftrag],0)),"")) | C71: =IF($A71="","",IFERROR(INDEX(tblAuftraege[Themenfeld],MATCH($A71,tblAuftraege[Auftrag],0)),"")) | D71: =IF($A71="","",IFERROR(INDEX(tblAuftraege[Kategorie],MATCH($A71,tblAuftraege[Auftrag],0)),"")) | E71: =IF($A71="",0,SUMIFS(tblAuftraege[Ausgaben],tblAuftraege[Datum Ausgaben],">="&E$5,tblAuftraege[Datum Ausgaben],"<"&EDATE(E$5,1),tblAuftraege[Auftrag],$A71)) -> 0 | F71: =IF($A71="",0,SUMIFS(tblAuftraege[Ausgaben],tblAuftraege[Datum Ausgaben],">="&F$5,tblAuftraege[Datum Ausgaben],"<"&EDATE(F$5,1),tblAuftraege[Auftrag],$A71)) -> 0 | G71: =IF($A71="",0,SUMIFS(tblAuftraege[Ausgaben],tblAuftraege[Datum Ausgaben],">="&G$5,tblAuftraege[Datum Ausgaben],"<"&EDATE(G$5,1),tblAuftraege[Auftrag],$A71)) -> 0 | H71: =IF($A71="",0,SUMIFS(tblAuftraege[Ausgaben],tblAuftraege[Datum Ausgaben],">="&H$5,tblAuftraege[Datum Ausgaben],"<"&EDATE(H$5,1),tblAuftraege[Auftrag],$A71)) -> 0 | I71: =IF($A71="",0,SUMIFS(tblAuftraege[Ausgaben],tblAuftraege[Datum Ausgaben],">="&I$5,tblAuftraege[Datum Ausgaben],"<"&EDATE(I$5,1),tblAuftraege[Auftrag],$A71)) -> 0 | J71: =IF($A71="",0,SUMIFS(tblAuftraege[Ausgaben],tblAuftraege[Datum Ausgaben],">="&J$5,tblAuftraege[Datum Ausgaben],"<"&EDATE(J$5,1),tblAuftraege[Auftrag],$A71)) -> 0 | K71: =IF($A71="",0,SUMIFS(tblAuftraege[Ausgaben],tblAuftraege[Datum Ausgaben],">="&K$5,tblAuftraege[Datum Ausgaben],"<"&EDATE(K$5,1),tblAuftraege[Auftrag],$A71)) -> 0 | L71: =IF($A71="",0,SUMIFS(tblAuftraege[Ausgaben],tblAuftraege[Datum Ausgaben],">="&L$5,tblAuftraege[Datum Ausgaben],"<"&EDATE(L$5,1),tblAuftraege[Auftrag],$A71)) -> 0 | ... BF71: =IF($A71="",0,SUMIFS(tblAuftraege[Ausgaben],tblAuftraege[Datum Ausgaben],">="&BF$5,tblAuftraege[Datum Ausgaben],"<"&EDATE(BF$5,1),tblAuftraege[Auftrag],$A71)) -> 0 | BG71: =SUM(E71:J71) -> 0 | BH71: =SUM(K71:V71) -> 0 | BI71: =SUM(W71:AH71) -> 0 | BJ71: =SUM(AI71:AT71) -> 0 | BK71: =SUM(AU71:BF71) -> 0 | BL71: =SUM(E71:BF71) -> 0
B72: =IF($A72="","",IFERROR(INDEX(tblAuftraege[Kostenstelle],MATCH($A72,tblAuftraege[Auftrag],0)),"")) | C72: =IF($A72="","",IFERROR(INDEX(tblAuftraege[Themenfeld],MATCH($A72,tblAuftraege[Auftrag],0)),"")) | D72: =IF($A72="","",IFERROR(INDEX(tblAuftraege[Kategorie],MATCH($A72,tblAuftraege[Auftrag],0)),"")) | E72: =IF($A72="",0,SUMIFS(tblAuftraege[Ausgaben],tblAuftraege[Datum Ausgaben],">="&E$5,tblAuftraege[Datum Ausgaben],"<"&EDATE(E$5,1),tblAuftraege[Auftrag],$A72)) -> 0 | F72: =IF($A72="",0,SUMIFS(tblAuftraege[Ausgaben],tblAuftraege[Datum Ausgaben],">="&F$5,tblAuftraege[Datum Ausgaben],"<"&EDATE(F$5,1),tblAuftraege[Auftrag],$A72)) -> 0 | G72: =IF($A72="",0,SUMIFS(tblAuftraege[Ausgaben],tblAuftraege[Datum Ausgaben],">="&G$5,tblAuftraege[Datum Ausgaben],"<"&EDATE(G$5,1),tblAuftraege[Auftrag],$A72)) -> 0 | H72: =IF($A72="",0,SUMIFS(tblAuftraege[Ausgaben],tblAuftraege[Datum Ausgaben],">="&H$5,tblAuftraege[Datum Ausgaben],"<"&EDATE(H$5,1),tblAuftraege[Auftrag],$A72)) -> 0 | I72: =IF($A72="",0,SUMIFS(tblAuftraege[Ausgaben],tblAuftraege[Datum Ausgaben],">="&I$5,tblAuftraege[Datum Ausgaben],"<"&EDATE(I$5,1),tblAuftraege[Auftrag],$A72)) -> 0 | J72: =IF($A72="",0,SUMIFS(tblAuftraege[Ausgaben],tblAuftraege[Datum Ausgaben],">="&J$5,tblAuftraege[Datum Ausgaben],"<"&EDATE(J$5,1),tblAuftraege[Auftrag],$A72)) -> 0 | K72: =IF($A72="",0,SUMIFS(tblAuftraege[Ausgaben],tblAuftraege[Datum Ausgaben],">="&K$5,tblAuftraege[Datum Ausgaben],"<"&EDATE(K$5,1),tblAuftraege[Auftrag],$A72)) -> 0 | L72: =IF($A72="",0,SUMIFS(tblAuftraege[Ausgaben],tblAuftraege[Datum Ausgaben],">="&L$5,tblAuftraege[Datum Ausgaben],"<"&EDATE(L$5,1),tblAuftraege[Auftrag],$A72)) -> 0 | ... BF72: =IF($A72="",0,SUMIFS(tblAuftraege[Ausgaben],tblAuftraege[Datum Ausgaben],">="&BF$5,tblAuftraege[Datum Ausgaben],"<"&EDATE(BF$5,1),tblAuftraege[Auftrag],$A72)) -> 0 | BG72: =SUM(E72:J72) -> 0 | BH72: =SUM(K72:V72) -> 0 | BI72: =SUM(W72:AH72) -> 0 | BJ72: =SUM(AI72:AT72) -> 0 | BK72: =SUM(AU72:BF72) -> 0 | BL72: =SUM(E72:BF72) -> 0
B73: =IF($A73="","",IFERROR(INDEX(tblAuftraege[Kostenstelle],MATCH($A73,tblAuftraege[Auftrag],0)),"")) | C73: =IF($A73="","",IFERROR(INDEX(tblAuftraege[Themenfeld],MATCH($A73,tblAuftraege[Auftrag],0)),"")) | D73: =IF($A73="","",IFERROR(INDEX(tblAuftraege[Kategorie],MATCH($A73,tblAuftraege[Auftrag],0)),"")) | E73: =IF($A73="",0,SUMIFS(tblAuftraege[Ausgaben],tblAuftraege[Datum Ausgaben],">="&E$5,tblAuftraege[Datum Ausgaben],"<"&EDATE(E$5,1),tblAuftraege[Auftrag],$A73)) -> 0 | F73: =IF($A73="",0,SUMIFS(tblAuftraege[Ausgaben],tblAuftraege[Datum Ausgaben],">="&F$5,tblAuftraege[Datum Ausgaben],"<"&EDATE(F$5,1),tblAuftraege[Auftrag],$A73)) -> 0 | G73: =IF($A73="",0,SUMIFS(tblAuftraege[Ausgaben],tblAuftraege[Datum Ausgaben],">="&G$5,tblAuftraege[Datum Ausgaben],"<"&EDATE(G$5,1),tblAuftraege[Auftrag],$A73)) -> 0 | H73: =IF($A73="",0,SUMIFS(tblAuftraege[Ausgaben],tblAuftraege[Datum Ausgaben],">="&H$5,tblAuftraege[Datum Ausgaben],"<"&EDATE(H$5,1),tblAuftraege[Auftrag],$A73)) -> 0 | I73: =IF($A73="",0,SUMIFS(tblAuftraege[Ausgaben],tblAuftraege[Datum Ausgaben],">="&I$5,tblAuftraege[Datum Ausgaben],"<"&EDATE(I$5,1),tblAuftraege[Auftrag],$A73)) -> 0 | J73: =IF($A73="",0,SUMIFS(tblAuftraege[Ausgaben],tblAuftraege[Datum Ausgaben],">="&J$5,tblAuftraege[Datum Ausgaben],"<"&EDATE(J$5,1),tblAuftraege[Auftrag],$A73)) -> 0 | K73: =IF($A73="",0,SUMIFS(tblAuftraege[Ausgaben],tblAuftraege[Datum Ausgaben],">="&K$5,tblAuftraege[Datum Ausgaben],"<"&EDATE(K$5,1),tblAuftraege[Auftrag],$A73)) -> 0 | L73: =IF($A73="",0,SUMIFS(tblAuftraege[Ausgaben],tblAuftraege[Datum Ausgaben],">="&L$5,tblAuftraege[Datum Ausgaben],"<"&EDATE(L$5,1),tblAuftraege[Auftrag],$A73)) -> 0 | ... BF73: =IF($A73="",0,SUMIFS(tblAuftraege[Ausgaben],tblAuftraege[Datum Ausgaben],">="&BF$5,tblAuftraege[Datum Ausgaben],"<"&EDATE(BF$5,1),tblAuftraege[Auftrag],$A73)) -> 0 | BG73: =SUM(E73:J73) -> 0 | BH73: =SUM(K73:V73) -> 0 | BI73: =SUM(W73:AH73) -> 0 | BJ73: =SUM(AI73:AT73) -> 0 | BK73: =SUM(AU73:BF73) -> 0 | BL73: =SUM(E73:BF73) -> 0
... B111: =IF($A111="","",IFERROR(INDEX(tblAuftraege[Kostenstelle],MATCH($A111,tblAuftraege[Auftrag],0)),"")) | C111: =IF($A111="","",IFERROR(INDEX(tblAuftraege[Themenfeld],MATCH($A111,tblAuftraege[Auftrag],0)),"")) | D111: =IF($A111="","",IFERROR(INDEX(tblAuftraege[Kategorie],MATCH($A111,tblAuftraege[Auftrag],0)),"")) | E111: =IF($A111="",0,SUMIFS(tblAuftraege[Ausgaben],tblAuftraege[Datum Ausgaben],">="&E$5,tblAuftraege[Datum Ausgaben],"<"&EDATE(E$5,1),tblAuftraege[Auftrag],$A111)) -> 0 | F111: =IF($A111="",0,SUMIFS(tblAuftraege[Ausgaben],tblAuftraege[Datum Ausgaben],">="&F$5,tblAuftraege[Datum Ausgaben],"<"&EDATE(F$5,1),tblAuftraege[Auftrag],$A111)) -> 0 | G111: =IF($A111="",0,SUMIFS(tblAuftraege[Ausgaben],tblAuftraege[Datum Ausgaben],">="&G$5,tblAuftraege[Datum Ausgaben],"<"&EDATE(G$5,1),tblAuftraege[Auftrag],$A111)) -> 0 | H111: =IF($A111="",0,SUMIFS(tblAuftraege[Ausgaben],tblAuftraege[Datum Ausgaben],">="&H$5,tblAuftraege[Datum Ausgaben],"<"&EDATE(H$5,1),tblAuftraege[Auftrag],$A111)) -> 0 | I111: =IF($A111="",0,SUMIFS(tblAuftraege[Ausgaben],tblAuftraege[Datum Ausgaben],">="&I$5,tblAuftraege[Datum Ausgaben],"<"&EDATE(I$5,1),tblAuftraege[Auftrag],$A111)) -> 0 | J111: =IF($A111="",0,SUMIFS(tblAuftraege[Ausgaben],tblAuftraege[Datum Ausgaben],">="&J$5,tblAuftraege[Datum Ausgaben],"<"&EDATE(J$5,1),tblAuftraege[Auftrag],$A111)) -> 0 | K111: =IF($A111="",0,SUMIFS(tblAuftraege[Ausgaben],tblAuftraege[Datum Ausgaben],">="&K$5,tblAuftraege[Datum Ausgaben],"<"&EDATE(K$5,1),tblAuftraege[Auftrag],$A111)) -> 0 | L111: =IF($A111="",0,SUMIFS(tblAuftraege[Ausgaben],tblAuftraege[Datum Ausgaben],">="&L$5,tblAuftraege[Datum Ausgaben],"<"&EDATE(L$5,1),tblAuftraege[Auftrag],$A111)) -> 0 | ... BF111: =IF($A111="",0,SUMIFS(tblAuftraege[Ausgaben],tblAuftraege[Datum Ausgaben],">="&BF$5,tblAuftraege[Datum Ausgaben],"<"&EDATE(BF$5,1),tblAuftraege[Auftrag],$A111)) -> 0 | BG111: =SUM(E111:J111) -> 0 | BH111: =SUM(K111:V111) -> 0 | BI111: =SUM(W111:AH111) -> 0 | BJ111: =SUM(AI111:AT111) -> 0 | BK111: =SUM(AU111:BF111) -> 0 | BL111: =SUM(E111:BF111) -> 0
A112: Noch nicht erfasste Aufträge | B112: Differenz | E112: =E113-SUM(E62:E111) -> 0 | F112: =F113-SUM(F62:F111) -> 0 | G112: =G113-SUM(G62:G111) -> 0 | H112: =H113-SUM(H62:H111) -> 0 | I112: =I113-SUM(I62:I111) -> 0 | J112: =J113-SUM(J62:J111) -> 0 | K112: =K113-SUM(K62:K111) -> 0 | L112: =L113-SUM(L62:L111) -> 0 | ... BL112: =BL113-SUM(BL62:BL111) -> 0
A113: Summe Ausgaben | E113: =SUMIFS(tblAuftraege[Ausgaben],tblAuftraege[Datum Ausgaben],">="&E$5,tblAuftraege[Datum Ausgaben],"<"&EDATE(E$5,1)) -> 0 | F113: =SUMIFS(tblAuftraege[Ausgaben],tblAuftraege[Datum Ausgaben],">="&F$5,tblAuftraege[Datum Ausgaben],"<"&EDATE(F$5,1)) -> 0 | G113: =SUMIFS(tblAuftraege[Ausgaben],tblAuftraege[Datum Ausgaben],">="&G$5,tblAuftraege[Datum Ausgaben],"<"&EDATE(G$5,1)) -> 0 | H113: =SUMIFS(tblAuftraege[Ausgaben],tblAuftraege[Datum Ausgaben],">="&H$5,tblAuftraege[Datum Ausgaben],"<"&EDATE(H$5,1)) -> 0 | I113: =SUMIFS(tblAuftraege[Ausgaben],tblAuftraege[Datum Ausgaben],">="&I$5,tblAuftraege[Datum Ausgaben],"<"&EDATE(I$5,1)) -> 0 | J113: =SUMIFS(tblAuftraege[Ausgaben],tblAuftraege[Datum Ausgaben],">="&J$5,tblAuftraege[Datum Ausgaben],"<"&EDATE(J$5,1)) -> 0 | K113: =SUMIFS(tblAuftraege[Ausgaben],tblAuftraege[Datum Ausgaben],">="&K$5,tblAuftraege[Datum Ausgaben],"<"&EDATE(K$5,1)) -> 0 | L113: =SUMIFS(tblAuftraege[Ausgaben],tblAuftraege[Datum Ausgaben],">="&L$5,tblAuftraege[Datum Ausgaben],"<"&EDATE(L$5,1)) -> 0 | ... BF113: =SUMIFS(tblAuftraege[Ausgaben],tblAuftraege[Datum Ausgaben],">="&BF$5,tblAuftraege[Datum Ausgaben],"<"&EDATE(BF$5,1)) -> 0 | BG113: =SUM(E113:J113) -> 0 | BH113: =SUM(K113:V113) -> 0 | BI113: =SUM(W113:AH113) -> 0 | BJ113: =SUM(AI113:AT113) -> 0 | BK113: =SUM(AU113:BF113) -> 0 | BL113: =SUM(E113:BF113) -> 0
A115: 3 KENNZAHLEN (automatisch berechnet)
A116: Summe Einnahmen | E116: =E59 -> 0 | F116: =F59 -> 0 | G116: =G59 -> 0 | H116: =H59 -> 0 | I116: =I59 -> 0 | J116: =J59 -> 0 | K116: =K59 -> 0 | L116: =L59 -> 0 | ... BL116: =BL59 -> 0
...

Sheet Aufträge
A1: Aufträge – zentrale Datenerfassung
A2: SmartInfra / IoT-Büro · DusL Plus Autostrom
A3: Jeder Auftrag bzw. finanzielle Vorgang wird hier einmalig erfasst. Der Reiter „Cashflow“ aggregiert daraus automatisch nach Monat.
A4: Datum Einnahmen und Datum Ausgaben sind unabhängig – ein Auftrag kann z. B. im September Ausgaben und erst im November Einnahmen haben. LLM = Lastmanagement.
A6: Auftrag | B6: Themenfeld | C6: Kategorie | D6: Kostenstelle | E6: Datum Einnahmen | F6: Datum Ausgaben | G6: Einnahmen | H6: Ausgaben | I6: Auftragswahrscheinlichkeit

Sheet Übersicht
A1: Übersicht Cashflow – DusL Plus Autostrom
A2: SmartInfra / IoT-Büro · Juli 2026 – Dezember 2030
A3: Alle Werte werden automatisch aus dem Blatt „Cashflow“ übernommen.
A5: Kennzahl | B5: Betrag
A6: H2 2026 (Jul 26 – Dez 26)
A7: Einnahmen H2 2026 | B7: =Cashflow!BG116 -> 0
A8: Ausgaben H2 2026 | B8: =Cashflow!BG117 -> 0
A9: Netto-Cashflow H2 2026 | B9: =Cashflow!BG118 -> 0
A10: 2027 (Jan 27 – Dez 27)
A11: Einnahmen 2027 | B11: =Cashflow!BH116 -> 0
A12: Ausgaben 2027 | B12: =Cashflow!BH117 -> 0
A13: Netto-Cashflow 2027 | B13: =Cashflow!BH118 -> 0
A14: 2028 (Jan 28 – Dez 28)
A15: Einnahmen 2028 | B15: =Cashflow!BI116 -> 0
A16: Ausgaben 2028 | B16: =Cashflow!BI117 -> 0
A17: Netto-Cashflow 2028 | B17: =Cashflow!BI118 -> 0
A18: 2029 (Jan 29 – Dez 29)
A19: Einnahmen 2029 | B19: =Cashflow!BJ116 -> 0
A20: Ausgaben 2029 | B20: =Cashflow!BJ117 -> 0
A21: Netto-Cashflow 2029 | B21: =Cashflow!BJ118 -> 0
A22: 2030 (Jan 30 – Dez 30)
A23: Einnahmen 2030 | B23: =Cashflow!BK116 -> 0
A24: Ausgaben 2030 | B24: =Cashflow!BK117 -> 0
A25: Netto-Cashflow 2030 | B25: =Cashflow!BK118 -> 0
A26: Gesamtzeitraum (54 Monate)
A27: Gesamteinnahmen | B27: =Cashflow!BL116 -> 0
A28: Gesamtausgaben | B28: =Cashflow!BL117 -> 0
A29: Gesamt-Netto-Cashflow | B29: =Cashflow!BL118 -> 0
