Workbook

Sheet Cockpit
A1: Cockpit – Anforderungen Autostrom / LKW-Laden
A2: Status, Erfüllung und Dokumentationsqualität auf einen Blick
A3: Alle Kennzahlen rechnen direkt aus den Registern „Anforderungen“ und „Komponenten“ – inklusive des vollständigen Bieterfragenkatalogs.
A5: Kennzahl | B5: Wert
A6: Anforderungen gesamt | B6: =COUNTA(Anforderungen!$B$7:$B$2000) -> 1382
A7: Erfasst | B7: =COUNTIF(Anforderungen!$K$7:$K$2000,"erfasst") -> 1211
A8: Bewertet | B8: =COUNTIF(Anforderungen!$K$7:$K$2000,"bewertet") -> 3
A9: Erfüllt | B9: =COUNTIF(Anforderungen!$K$7:$K$2000,"erfüllt") -> 10
A10: davon vollständig dokumentiert | B10: =COUNTIFS(Anforderungen!$K$7:$K$2000,"erfüllt",Anforderungen!$L$7:$L$2000,"<>",Anforderungen!$M$7:$M$2000,"<>") -> 10
A11: Trifft nicht zu | B11: =COUNTIF(Anforderungen!$K$7:$K$2000,"trifft nicht zu") -> 158
A12: Erfüllt ohne Datum | B12: =COUNTIFS(Anforderungen!$K$7:$K$2000,"erfüllt",Anforderungen!$L$7:$L$2000,"") -> 0
A13: Erfüllt ohne Nachweis / Notiz | B13: =COUNTIFS(Anforderungen!$K$7:$K$2000,"erfüllt",Anforderungen!$M$7:$M$2000,"") -> 0
A14: Trifft nicht zu ohne Begründung | B14: =COUNTIFS(Anforderungen!$K$7:$K$2000,"trifft nicht zu",Anforderungen!$M$7:$M$2000,"") -> 2
A15: Erfüllungsgrad | B15: =IFERROR(COUNTIF(Anforderungen!$K$7:$K$2000,"erfüllt")/(COUNTA(Anforderungen!$B$7:$B$2000)-COUNTIF(Anforderungen!$K$7:$K$2000,"trifft nicht zu")),0) -> 0.0081699346
A16: Dokumentationsgrad erfüllt | B16: =IFERROR(COUNTIFS(Anforderungen!$K$7:$K$2000,"erfüllt",Anforderungen!$L$7:$L$2000,"<>",Anforderungen!$M$7:$M$2000,"<>")/COUNTIF(Anforderungen!$K$7:$K$2000,"erfüllt"),0) -> 1
A17: Komponenten/Schnittstellen erfüllt | B17: =COUNTIF(Komponenten!$J$6:$J$29,"erfüllt") -> 0
A18: Bieterfragen im Register | B18: =COUNTIF(Anforderungen!$C$7:$C$2000,"Bieterfragenkatalog") -> 663
A19: Offene Zuordnungen (Komponente/Partner) | B19: =COUNTIF(Anforderungen!$J$7:$J$2000,"Zuordnung prüfen")+COUNTIF(Anforderungen!$I$7:$I$2000,"Zuordnung prüfen") -> 460
A20: Anforderungen im betrachteten Umfang | B20: =COUNTIF(Anforderungen!$N$7:$N$2000,"im Umfang") -> 62

Sheet Anforderungen
A1: Anforderungen – Autostrom / LKW-Laden
A2: Zentrales Anforderungsregister: Der Block „Erfüllung / Nachweis“ verbindet Status, tatsächliches Erfüllungsdatum und Dokumentation.
A3: Logik: erfasst → bewertet → erfüllt. Bei „erfüllt“ sind Datum und Nachweis/Notiz erforderlich, bei „trifft nicht zu“ eine Begründung. Gelb markierte Zuordnungen (Partner/Komponente) sind fachlich zu prüfen.
B5: Anforderung & Zuordnung | K5: Erfüllung / Nachweis (Konzept)
B6: ID | C6: Dokument | D6: Fundstelle | E6: Themenfeld | F6: Kernaussage | G6: Anforderung / Frage (Originaltext) | H6: Bemerkung | I6: Partner | J6: Komponente(n) | K6: Status | L6: Erfüllt am | M6: Nachweis / Notiz | N6: Umfang | O6: Filter-Rang
B7: ANF-001 | C7: Betreibervertrag | D7: § 25 (1) | E7: Reservierung | F7: OCPI Schnittstelle | G7: Der Auftragnehmer stellt sicher, dass die Reservierung von Ladepunkten über Reservierungsplattformen während der Laufzeit dieses Vertrags möglich ist. Hierzu hält der Auftragnehmer eine auf OCPI (Open Charge Point Interface) basierende Schnittstelle vor, über die sich Reservierungsplattformen nach Maßgabe der folgenden Absätze anbinden können. | I7: eRound | J7: OCPI Buchungskalender | K7: erfasst | N7: außerhalb | O7: =IF($B7="",0,IF(AND(OR(Filter!$B$5="(alle)",$N7=Filter!$B$5),OR(Filter!$E$5="(alle)",$K7=Filter!$E$5),OR(Filter!$H$5="(alle)",$C7=Filter!$H$5),OR(Filter!$B$7="(alle)",$E7=Filter!$B$7),OR(Filter!$E$7="(alle)",ISNUMBER(SEARCH(Filter!$E$7,$J7))),OR(Filter!$H$7="(alle)",ISNUMBER(SEARCH(Filter!$H$7,$I7))),OR(Filter!$B$9="",ISNUMBER(SEARCH(Filter!$B$9,$F7&" "&$G7)))),COUNTIF($O$6:$O6,">0")+1,0)) -> 1
B8: ANF-002 | C8: Betreibervertrag | D8: § 25 (2) | E8: Reservierung | F8: OCPI Kostenfrei | G8: Der Auftragnehmer ist verpflichtet, jeder Reservierungsplattform die Anbindung über die in Absatz 1 genannte Schnittstelle kostenfrei zu ermöglichen, soweit die Reservierungsplattform die folgenden Mindestvoraussetzungen erfüllt: | I8: eRound | J8: OCPI Buchungskalender | K8: erfasst | N8: außerhalb | O8: =IF($B8="",0,IF(AND(OR(Filter!$B$5="(alle)",$N8=Filter!$B$5),OR(Filter!$E$5="(alle)",$K8=Filter!$E$5),OR(Filter!$H$5="(alle)",$C8=Filter!$H$5),OR(Filter!$B$7="(alle)",$E8=Filter!$B$7),OR(Filter!$E$7="(alle)",ISNUMBER(SEARCH(Filter!$E$7,$J8))),OR(Filter!$H$7="(alle)",ISNUMBER(SEARCH(Filter!$H$7,$I8))),OR(Filter!$B$9="",ISNUMBER(SEARCH(Filter!$B$9,$F8&" "&$G8)))),COUNTIF($O$6:$O7,">0")+1,0)) -> 2
B9: ANF-003 | C9: Betreibervertrag | D9: § 25 (2) a | E9: Reservierung | F9: OCPI Kostenfrei | G9: Die Reservierungsplattform stellt dem Auftragnehmer für die Anbindung der Reservierungsplattform keine Anbindungskosten in Rechnung | I9: eRound | J9: Anbindung | K9: erfasst | N9: außerhalb | O9: =IF($B9="",0,IF(AND(OR(Filter!$B$5="(alle)",$N9=Filter!$B$5),OR(Filter!$E$5="(alle)",$K9=Filter!$E$5),OR(Filter!$H$5="(alle)",$C9=Filter!$H$5),OR(Filter!$B$7="(alle)",$E9=Filter!$B$7),OR(Filter!$E$7="(alle)",ISNUMBER(SEARCH(Filter!$E$7,$J9))),OR(Filter!$H$7="(alle)",ISNUMBER(SEARCH(Filter!$H$7,$I9))),OR(Filter!$B$9="",ISNUMBER(SEARCH(Filter!$B$9,$F9&" "&$G9)))),COUNTIF($O$6:$O8,">0")+1,0)) -> 3
B10: ANF-004 | C10: Betreibervertrag | D10: § 25 (2) b | E10: Reservierung | F10: Anbindung verpflichtend, wenn alle AN angebunden werden oder AG2 auffordert | G10: Die Reservierungsplattform ermöglicht Endnutzern und Mobilitätsdienstleistern die Reservierung von Ladepunkten im gesamten Gebiet der Bundesrepublik Deutschland gegen ein angemessenes Entgelt. Ermöglicht eine Reservierungsplattform eine Reservierung von Ladepunkten nur in Teilen des Gebiets der Bundesrepublik Deutschland, ist der Auftragnehmer zur Anbindung nur verpflichtet, wenn der Auftraggeber 2 den Auftragnehmer hierzu auffordert. | I10: eRound | J10: OCPI Buchungskalender | K10: erfasst | N10: außerhalb | O10: =IF($B10="",0,IF(AND(OR(Filter!$B$5="(alle)",$N10=Filter!$B$5),OR(Filter!$E$5="(alle)",$K10=Filter!$E$5),OR(Filter!$H$5="(alle)",$C10=Filter!$H$5),OR(Filter!$B$7="(alle)",$E10=Filter!$B$7),OR(Filter!$E$7="(alle)",ISNUMBER(SEARCH(Filter!$E$7,$J10))),OR(Filter!$H$7="(alle)",ISNUMBER(SEARCH(Filter!$H$7,$I10))),OR(Filter!$B$9="",ISNUMBER(SEARCH(Filter!$B$9,$F10&" "&$G10)))),COUNTIF($O$6:$O9,">0")+1,0)) -> 4
B11: ANF-005 | C11: Betreibervertrag | D11: § 25 (2) c | E11: Reservierung | F11: Reservierung mit Vorlauf von max. 7 Tagen und min. 15 min. Kostenfreie Stornierung und Änderung bis 30min vorher. Kennzeichenabgleich zur Unterbindung von Doppelbuchungen. | G11: Die Reservierungsplattform ermöglicht eine Reservierung von Ladepunkten mit einer Vorlaufzeit von maximal 7 Kalendertagen und mindestens 15 Minuten. Eine kostenfreie Stornierung oder Änderung der Reservierung über die Reservierungsplattform muss, soweit möglich, bis zu 30 Minuten vor Beginn des in der Reservierung angegebenen Startzeitpunkts möglich sein. Die Reservierungsplattform stellt durch geeignete Vorkehrungen (z. B. durch einen Kennzeichenabgleich) sicher, dass für einen E-LKW in einem Zeitintervall nur ein Ladepunkt reserviert wird. | I11: eRound | J11: OCPI Buchungskalender | K11: erfasst | N11: im Umfang | O11: =IF($B11="",0,IF(AND(OR(Filter!$B$5="(alle)",$N11=Filter!$B$5),OR(Filter!$E$5="(alle)",$K11=Filter!$E$5),OR(Filter!$H$5="(alle)",$C11=Filter!$H$5),OR(Filter!$B$7="(alle)",$E11=Filter!$B$7),OR(Filter!$E$7="(alle)",ISNUMBER(SEARCH(Filter!$E$7,$J11))),OR(Filter!$H$7="(alle)",ISNUMBER(SEARCH(Filter!$H$7,$I11))),OR(Filter!$B$9="",ISNUMBER(SEARCH(Filter!$B$9,$F11&" "&$G11)))),COUNTIF($O$6:$O10,">0")+1,0)) -> 5
B12: ANF-006 | C12: Betreibervertrag | D12: § 25 (2) d | E12: Reservierung | F12: Entschädigung an AN von der Reservierungsplattform i.H.v. mind. 30€ nach 15/30 min Wartezeit bei No-Show. | G12: Die Reservierungsplattform entschädigt den Auftragnehmer in angemessener Höhe, wenn an der reservierten Ladeeinrichtung ab dem in der Reservierung angegebenen Startzeitpunkt und Ablauf einer Wartezeit von 15 Minuten bei Ladepunkten zum Zwischenladen, bzw. 30 Minuten bei Ladepunkten zum Übernachtladen (sog. „no-show“) kein Start eines Ladevorgangs erfolgt. Die Entschädigung des Auftragnehmers ist angemessen, wenn der Auftragnehmer im Fall eines „no-show“ mindestens € 30,00 erhält. | I12: eRound | J12: Abrechnungskomponente | K12: erfasst | N12: außerhalb | O12: =IF($B12="",0,IF(AND(OR(Filter!$B$5="(alle)",$N12=Filter!$B$5),OR(Filter!$E$5="(alle)",$K12=Filter!$E$5),OR(Filter!$H$5="(alle)",$C12=Filter!$H$5),OR(Filter!$B$7="(alle)",$E12=Filter!$B$7),OR(Filter!$E$7="(alle)",ISNUMBER(SEARCH(Filter!$E$7,$J12))),OR(Filter!$H$7="(alle)",ISNUMBER(SEARCH(Filter!$H$7,$I12))),OR(Filter!$B$9="",ISNUMBER(SEARCH(Filter!$B$9,$F12&" "&$G12)))),COUNTIF($O$6:$O11,">0")+1,0)) -> 6
B13: ANF-007 | C13: Betreibervertrag | D13: § 25 (3) | E13: Reservierung | F13: Anpassung an Marktstandards mit 2 Monaten Vorlauf. | G13: Der Auftraggeber 2 ist berechtigt, die in Absatz 2 definierten Mindestvoraussetzungen im Fall abweichender Marktstandards mit einer Vorlaufzeit von zwei Monaten anzupassen | I13: eRound | J13: OCPI Buchungskalender | K13: erfasst | N13: außerhalb | O13: =IF($B13="",0,IF(AND(OR(Filter!$B$5="(alle)",$N13=Filter!$B$5),OR(Filter!$E$5="(alle)",$K13=Filter!$E$5),OR(Filter!$H$5="(alle)",$C13=Filter!$H$5),OR(Filter!$B$7="(alle)",$E13=Filter!$B$7),OR(Filter!$E$7="(alle)",ISNUMBER(SEARCH(Filter!$E$7,$J13))),OR(Filter!$H$7="(alle)",ISNUMBER(SEARCH(Filter!$H$7,$I13))),OR(Filter!$B$9="",ISNUMBER(SEARCH(Filter!$B$9,$F13&" "&$G13)))),COUNTIF($O$6:$O12,">0")+1,0)) -> 7
B14: ANF-008 | C14: Betreibervertrag | D14: § 25 (4) | E14: Reservierung | F14: Ladepunkte an einem Standort können von der Reservierung ausgenommen werden. | G14: Der Auftragnehmer kann CCS- und MCS-Ladepunkten an einem Standort von der Reservierungsmöglichkeit ausnehmen. | I14: eRound | J14: OCPI Buchungskalender | K14: erfasst | N14: außerhalb | O14: =IF($B14="",0,IF(AND(OR(Filter!$B$5="(alle)",$N14=Filter!$B$5),OR(Filter!$E$5="(alle)",$K14=Filter!$E$5),OR(Filter!$H$5="(alle)",$C14=Filter!$H$5),OR(Filter!$B$7="(alle)",$E14=Filter!$B$7),OR(Filter!$E$7="(alle)",ISNUMBER(SEARCH(Filter!$E$7,$J14))),OR(Filter!$H$7="(alle)",ISNUMBER(SEARCH(Filter!$H$7,$I14))),OR(Filter!$B$9="",ISNUMBER(SEARCH(Filter!$B$9,$F14&" "&$G14)))),COUNTIF($O$6:$O13,">0")+1,0)) -> 8
B15: ANF-009 | C15: Betreibervertrag | D15: § 25 (5) | E15: Zufahrt & Schranke | F15: Bauliche Maßnahme zur Reservierung an jedem Ladepunkt. | G15: Der Auftragnehmer hat geeignete Vorkehrungen, insbesondere die in Vertragsanlage 4: Leistungsbeschreibung Errichtung vorgesehenen baulichen Maßnahmen, zu treffen, um ein anderweitiges Laden an dem Ladepunkt der Ladeeinrichtung während des reservierten Zeitraums zu verhindern. | H15: Schrankensteuerung | I15: Schrankenhersteller | J15: Schrankenanlage | K15: erfasst | N15: im Umfang | O15: =IF($B15="",0,IF(AND(OR(Filter!$B$5="(alle)",$N15=Filter!$B$5),OR(Filter!$E$5="(alle)",$K15=Filter!$E$5),OR(Filter!$H$5="(alle)",$C15=Filter!$H$5),OR(Filter!$B$7="(alle)",$E15=Filter!$B$7),OR(Filter!$E$7="(alle)",ISNUMBER(SEARCH(Filter!$E$7,$J15))),OR(Filter!$H$7="(alle)",ISNUMBER(SEARCH(Filter!$H$7,$I15))),OR(Filter!$B$9="",ISNUMBER(SEARCH(Filter!$B$9,$F15&" "&$G15)))),COUNTIF($O$6:$O14,">0")+1,0)) -> 9
B16: ANF-010 | C16: Betreibervertrag | D16: § 25 (6) | E16: Reservierung | F16: Mindestens 40% der Ladepunkte müssen reserviert werden können. | G16: Verstößt der Auftragnehmer gegen die Pflicht nach Absatz 1, wird für jeden Standort, an dem die Reservierung von Ladepunkten aufgrund des Verstoßes gegen die Pflicht nach Absatz 1 nicht möglich ist, eine Vertragsstrafe fällig. Die Reservierung von Ladepunkten an einem Standort gilt als nicht möglich, wenn mindestens 40 % der Ladepunkte an dem Standort nicht reserviert werden können. Die Höhe der Vertragsstrafe beträgt € 2.500,00 für jeden Kalendertag, an dem die Reservierung von Ladepunkten an einem Standort nicht möglich ist, höchstens jedoch € 40.000,00 pro Kalendermonat und pro Standort. | H16: 40% der Schranken offen lassen? | I16: eRound | J16: OCPI Buchungskalender | K16: erfasst | N16: im Umfang | O16: =IF($B16="",0,IF(AND(OR(Filter!$B$5="(alle)",$N16=Filter!$B$5),OR(Filter!$E$5="(alle)",$K16=Filter!$E$5),OR(Filter!$H$5="(alle)",$C16=Filter!$H$5),OR(Filter!$B$7="(alle)",$E16=Filter!$B$7),OR(Filter!$E$7="(alle)",ISNUMBER(SEARCH(Filter!$E$7,$J16))),OR(Filter!$H$7="(alle)",ISNUMBER(SEARCH(Filter!$H$7,$I16))),OR(Filter!$B$9="",ISNUMBER(SEARCH(Filter!$B$9,$F16&" "&$G16)))),COUNTIF($O$6:$O15,">0")+1,0)) -> 10
B17: ANF-011 | C17: Betreibervertrag | D17: § 31 (1) | E17: Authentifizierung & Zugang | F17: Es muss Adhoc geladen werden können | G17: Der Auftragnehmer ist verpflichtet, potenziellen Endnutzern diskriminierungsfrei zu angemessenen Bedingungen ein Ad-hoc-Laden (punktuelles Aufladen i. S. d. AFIR) zu ermöglichen, soweit es ihm zumutbar ist (z. B. mit Blick auf die Bonität des Endnutzers). | H17: Adhoc muss möglich sein -> Schranke -> wie? | I17: eRound / SCS | J17: Authentifizierungskomponente / Schrankensteuerung | K17: erfasst | N17: im Umfang | O17: =IF($B17="",0,IF(AND(OR(Filter!$B$5="(alle)",$N17=Filter!$B$5),OR(Filter!$E$5="(alle)",$K17=Filter!$E$5),OR(Filter!$H$5="(alle)",$C17=Filter!$H$5),OR(Filter!$B$7="(alle)",$E17=Filter!$B$7),OR(Filter!$E$7="(alle)",ISNUMBER(SEARCH(Filter!$E$7,$J17))),OR(Filter!$H$7="(alle)",ISNUMBER(SEARCH(Filter!$H$7,$I17))),OR(Filter!$B$9="",ISNUMBER(SEARCH(Filter!$B$9,$F17&" "&$G17)))),COUNTIF($O$6:$O16,">0")+1,0)) -> 11
B18: ANF-012 | C18: Betreibervertrag | D18: § 38 (1) | E18: Nutzungszeit & Entgelte | F18: Blockadeentgelte und maximale Nutzungsdauer | G18: Start- und zeitabhängige Entgelte dürfen nicht erhoben werden. Dies gilt nicht für vertraglich vereinbarte Blockadeentgelte, die nach Ablauf einer maximalen Nutzungszeit vom Endnutzer bzw. Mobilitätsdienstleister unabhängig davon, welches der Zugangsmodelle des § 30 Abs. 2 gewählt wird, erhoben werden. Die maximale Nutzungszeit beginnt mit Beginn des Ladevorgangs und beträgt | H18: Schnittstelle Nutzungszeit | I18: eRound | J18: OCPI Buchungskalender | K18: erfasst | N18: außerhalb | O18: =IF($B18="",0,IF(AND(OR(Filter!$B$5="(alle)",$N18=Filter!$B$5),OR(Filter!$E$5="(alle)",$K18=Filter!$E$5),OR(Filter!$H$5="(alle)",$C18=Filter!$H$5),OR(Filter!$B$7="(alle)",$E18=Filter!$B$7),OR(Filter!$E$7="(alle)",ISNUMBER(SEARCH(Filter!$E$7,$J18))),OR(Filter!$H$7="(alle)",ISNUMBER(SEARCH(Filter!$H$7,$I18))),OR(Filter!$B$9="",ISNUMBER(SEARCH(Filter!$B$9,$F18&" "&$G18)))),COUNTIF($O$6:$O17,">0")+1,0)) -> 12
B19: ANF-013 | C19: Betreibervertrag | D19: § 38 (1) a | E19: Nutzungszeit & Entgelte | F19: Maximale Nutzungsdauer Zwischenladen ist 1h. | G19: bei MCS-Ladepunkten und CCS-Ladepunkten zum Zwischenladen 1 Stunde. | H19: Schnittstelle Nutzungszeit | I19: eRound | J19: OCPI Buchungskalender | K19: erfasst | N19: außerhalb | O19: =IF($B19="",0,IF(AND(OR(Filter!$B$5="(alle)",$N19=Filter!$B$5),OR(Filter!$E$5="(alle)",$K19=Filter!$E$5),OR(Filter!$H$5="(alle)",$C19=Filter!$H$5),OR(Filter!$B$7="(alle)",$E19=Filter!$B$7),OR(Filter!$E$7="(alle)",ISNUMBER(SEARCH(Filter!$E$7,$J19))),OR(Filter!$H$7="(alle)",ISNUMBER(SEARCH(Filter!$H$7,$I19))),OR(Filter!$B$9="",ISNUMBER(SEARCH(Filter!$B$9,$F19&" "&$G19)))),COUNTIF($O$6:$O18,">0")+1,0)) -> 13
B20: ANF-014 | C20: Betreibervertrag | D20: § 38 (1) b | E20: Nutzungszeit & Entgelte | F20: Maximale Nutzungsdauer Übernachtladen ist 12h. | G20: bei CCS-Ladepunkten zum Übernachtladen und MCS- oder CCS-Ladepunkte zum Zwischenladen, die zum Übernachtladen freigegeben wurden, 12 Stunden. | H20: Schnittstelle Nutzungszeit | I20: eRound | J20: OCPI Buchungskalender | K20: erfasst | N20: außerhalb | O20: =IF($B20="",0,IF(AND(OR(Filter!$B$5="(alle)",$N20=Filter!$B$5),OR(Filter!$E$5="(alle)",$K20=Filter!$E$5),OR(Filter!$H$5="(alle)",$C20=Filter!$H$5),OR(Filter!$B$7="(alle)",$E20=Filter!$B$7),OR(Filter!$E$7="(alle)",ISNUMBER(SEARCH(Filter!$E$7,$J20))),OR(Filter!$H$7="(alle)",ISNUMBER(SEARCH(Filter!$H$7,$I20))),OR(Filter!$B$9="",ISNUMBER(SEARCH(Filter!$B$9,$F20&" "&$G20)))),COUNTIF($O$6:$O19,">0")+1,0)) -> 14
B21: ANF-015 | C21: Betreibervertrag | D21: § 38 (2) | E21: Nutzungszeit & Entgelte | F21: Bei nidriger Auslastung kann die maximale Nutzungszeit vom AN verlängert werden. Bei nachfolgender Reservierung kann die maximale Nutzungszeit verkürzt werden. Bei Verkürzung zusätzliche Karenzzeit vor Blockadeentgeld von 5min. | G21: Der Auftragnehmer kann die maximalen Nutzungszeiten in Zeiten geringer Auslastung verlängern. Zudem kann er mit der Gestattung der Nutzung von MCS-Ladepunkten und CCS-Ladepunkten zum Zwischenladen dem Endnutzer bzw. Mobilitätsdienstleister auch ausdrücklich eine kürzere maximale Nutzungszeit einräumen, wenn wegen nachfolgender Reservierungen die maximale Nutzungszeit nach Absatz 1 lit. a nicht eingeräumt werden kann. In den Fällen des Satzes 2 ist dem Endnutzer bzw. Mobilitätsdienstleister zusätzlich eine Karenzzeit zum Verlassen des Ladeplatzes von 5 Minuten einzuräumen, nach deren Ablauf erst ein Blockadeentgelt erhoben werden darf | H21: SCS: Reaktionszeit System | I21: eRound | J21: OCPI Buchungskalender | K21: erfasst | N21: außerhalb | O21: =IF($B21="",0,IF(AND(OR(Filter!$B$5="(alle)",$N21=Filter!$B$5),OR(Filter!$E$5="(alle)",$K21=Filter!$E$5),OR(Filter!$H$5="(alle)",$C21=Filter!$H$5),OR(Filter!$B$7="(alle)",$E21=Filter!$B$7),OR(Filter!$E$7="(alle)",ISNUMBER(SEARCH(Filter!$E$7,$J21))),OR(Filter!$H$7="(alle)",ISNUMBER(SEARCH(Filter!$H$7,$I21))),OR(Filter!$B$9="",ISNUMBER(SEARCH(Filter!$B$9,$F21&" "&$G21)))),COUNTIF($O$6:$O20,">0")+1,0)) -> 15
B22: ANF-016 | C22: Betreibervertrag | D22: § 38 (3) | E22: Nutzungszeit & Entgelte | F22: Maximale Nutzungszeit endet mit Ablauf Reservierung. Maximale Nutzungsdauer kann vom AN verlängert werden. | G22: Hat ein Mobilitätsdienstleister einen Ladepunkt reserviert, so endet die maximale Nutzungszeit mit dem Ablauf des reservierten Zeitraums, auch wenn der Ladeplatz erst später belegt wurde, es sei denn, der Betreiber räumt ihm eine längere maximale Nutzungszeit ein. | I22: eRound | J22: OCPI Buchungskalender | K22: erfasst | N22: außerhalb | O22: =IF($B22="",0,IF(AND(OR(Filter!$B$5="(alle)",$N22=Filter!$B$5),OR(Filter!$E$5="(alle)",$K22=Filter!$E$5),OR(Filter!$H$5="(alle)",$C22=Filter!$H$5),OR(Filter!$B$7="(alle)",$E22=Filter!$B$7),OR(Filter!$E$7="(alle)",ISNUMBER(SEARCH(Filter!$E$7,$J22))),OR(Filter!$H$7="(alle)",ISNUMBER(SEARCH(Filter!$H$7,$I22))),OR(Filter!$B$9="",ISNUMBER(SEARCH(Filter!$B$9,$F22&" "&$G22)))),COUNTIF($O$6:$O21,">0")+1,0)) -> 16
B23: ANF-017 | C23: Betreibervertrag | D23: § 38 (4) | E23: Nutzungszeit & Entgelte | F23: Ladestart 15min Wartezeit Blockadeentgeld ggf. Pönalisierung Entfall maximale Nutzungsdauer | G23: Wird ein Ladevorgang nicht innerhalb von 15 Minuten nach Besetzung des Stellplatzes gestartet, entfällt die maximale Nutzungszeit und es kann ein Blockadeentgelt erhoben werden. | I23: eRound / SCS | J23: OCPI Buchungskalender / Abrechnungskomponente / Belegungsdetektion / Pönalisierungssystem | K23: erfasst | N23: außerhalb | O23: =IF($B23="",0,IF(AND(OR(Filter!$B$5="(alle)",$N23=Filter!$B$5),OR(Filter!$E$5="(alle)",$K23=Filter!$E$5),OR(Filter!$H$5="(alle)",$C23=Filter!$H$5),OR(Filter!$B$7="(alle)",$E23=Filter!$B$7),OR(Filter!$E$7="(alle)",ISNUMBER(SEARCH(Filter!$E$7,$J23))),OR(Filter!$H$7="(alle)",ISNUMBER(SEARCH(Filter!$H$7,$I23))),OR(Filter!$B$9="",ISNUMBER(SEARCH(Filter!$B$9,$F23&" "&$G23)))),COUNTIF($O$6:$O22,">0")+1,0)) -> 17
B24: ANF-018 | C24: Betreibervertrag | D24: § 38 (5) | E24: Nutzungszeit & Entgelte | F24: Kein Blockadeentgeld während Nachtruhezeiten, Sonn- und Feiertage der Bundesländer. | G24: An Sonn- und Feiertagen sowie zwischen 22 Uhr abends und 5 Uhr morgens (Nachtruhezeit) darf der Auftragnehmer für CCS-Ladepunkte zum Übernachtladen bzw. MCS- und CCS- Ladepunkten zum Zwischenladen, die zum Übernachtladen freigegeben wurden, keine Blockadeentgelte erheben. Hat der Ladevorgang bereits vor Beginn der Nachtruhezeiten begonnen und endet die maximale Nutzungszeit nach Absatz 1 während der Nachtruhezeit, so werden Blockadeentgelte mithin erst nach Ende der Nachtruhezeit berechnet. Satz 1 und 2 gelten entsprechend für Sonntage und gesetzliche Feiertage in dem Bundesland, in dem der jeweilige Standort gelegen ist. | H24: Einfluss auf Reservierung? | I24: eRound | J24: OCPI Buchungskalender | K24: erfasst | N24: außerhalb | O24: =IF($B24="",0,IF(AND(OR(Filter!$B$5="(alle)",$N24=Filter!$B$5),OR(Filter!$E$5="(alle)",$K24=Filter!$E$5),OR(Filter!$H$5="(alle)",$C24=Filter!$H$5),OR(Filter!$B$7="(alle)",$E24=Filter!$B$7),OR(Filter!$E$7="(alle)",ISNUMBER(SEARCH(Filter!$E$7,$J24))),OR(Filter!$H$7="(alle)",ISNUMBER(SEARCH(Filter!$H$7,$I24))),OR(Filter!$B$9="",ISNUMBER(SEARCH(Filter!$B$9,$F24&" "&$G24)))),COUNTIF($O$6:$O23,">0")+1,0)) -> 18
B25: ANF-019 | C25: Betreibervertrag | D25: § 38 (6) | E25: Nutzungszeit & Entgelte | F25: Blockadeentgeld Höhe 0,50€ / 0,15€ pro Min. | G25: Die Höhe des Blockadeentgelts darf bei MCS-Ladepunkten und bei CCS-Ladepunkten zum Zwischenladen maximal 0,50 €/Minute und bei CCS-Ladepunkten bzw. CCS- und MCS- Ladepunkten zum Zwischenladen, während des Zeitraums, für den sie zum Übernachtladen freigegeben wurden, maximal 0,15 €/Minute betragen. Das vereinnahmte Blockadeentgelt steht dem Auftragnehmer zu. | I25: eRound | J25: Abrechnungskomponente | K25: erfasst | N25: außerhalb | O25: =IF($B25="",0,IF(AND(OR(Filter!$B$5="(alle)",$N25=Filter!$B$5),OR(Filter!$E$5="(alle)",$K25=Filter!$E$5),OR(Filter!$H$5="(alle)",$C25=Filter!$H$5),OR(Filter!$B$7="(alle)",$E25=Filter!$B$7),OR(Filter!$E$7="(alle)",ISNUMBER(SEARCH(Filter!$E$7,$J25))),OR(Filter!$H$7="(alle)",ISNUMBER(SEARCH(Filter!$H$7,$I25))),OR(Filter!$B$9="",ISNUMBER(SEARCH(Filter!$B$9,$F25&" "&$G25)))),COUNTIF($O$6:$O24,">0")+1,0)) -> 19
B26: ANF-020 | C26: Betreibervertrag | D26: § 38 (7) | E26: Nutzungszeit & Entgelte | F26: Änderungen an maximaler Nutzungsdauer, Blockadeentgelt und Sperrzeiten mit Vorlauf möglich. | G26: Der Auftraggeber 2 kann die maximale Höhe der Blockadeentgelte nach Absatz 6 und die maximalen Nutzungszeiten bzw. Sperrzeiten für die Erhebung eines Blockadeentgeltes nach den Absätzen 1 bis 4 während der Laufzeit des Vertrags mit einer Frist von vier Monaten auf den Beginn eines Quartals schriftlich mit Wirkung gegenüber dem Auftragnehmer anpassen. Absenkungen der Höhe oder Verlängerungen die maximalen Nutzungszeiten bzw. Sperrzeiten sind nur mit Zustimmung des Auftragnehmers zulässig. Die Zustimmung gilt als erteilt, sofern der Auftragnehmer dem Auftraggeber 2 nicht innerhalb von zwei Wochen nach Mitteilung der geplanten Absenkung in Textform widerspricht. | I26: eRound | J26: Abrechnungskomponente | K26: erfasst | N26: außerhalb | O26: =IF($B26="",0,IF(AND(OR(Filter!$B$5="(alle)",$N26=Filter!$B$5),OR(Filter!$E$5="(alle)",$K26=Filter!$E$5),OR(Filter!$H$5="(alle)",$C26=Filter!$H$5),OR(Filter!$B$7="(alle)",$E26=Filter!$B$7),OR(Filter!$E$7="(alle)",ISNUMBER(SEARCH(Filter!$E$7,$J26))),OR(Filter!$H$7="(alle)",ISNUMBER(SEARCH(Filter!$H$7,$I26))),OR(Filter!$B$9="",ISNUMBER(SEARCH(Filter!$B$9,$F26&" "&$G26)))),COUNTIF($O$6:$O25,">0")+1,0)) -> 20
B27: ANF-021 | C27: Betreibervertrag | D27: § 38 (8) | E27: Nutzungszeit & Entgelte | F27: Mindestabnahmemenge und Vergütung bei Unterschreitung. | G27: Für jeden Übernachtladevorgang ist eine Mindestabnahmemenge von 150 kWh vorzusehen, dies gilt auch für MCS- und CCS-Ladepunkte, die nach Maßgabe dieses Vertrags zum Übernachtladen freigegeben werden. Wird die Mindestabnahmemenge nicht erreicht, so ist für die Differenz zwischen der tatsächlich abgenommenen Strommenge und der vertraglich vorgesehenen Mindestabnahmemenge vom Endnutzer bzw. Mobilitätsdienstleister eine Entschädigung in Höhe von 30 ct/kWh an den Auftragnehmer zu leisten. Die Entschädigungshöhe kann vom Auftraggeber 2 in Absprache mit dem Auftragnehmer zu einem späteren Zeitpunkt angepasst werden. | I27: eRound | J27: Abrechnungskomponente | K27: erfasst | N27: außerhalb | O27: =IF($B27="",0,IF(AND(OR(Filter!$B$5="(alle)",$N27=Filter!$B$5),OR(Filter!$E$5="(alle)",$K27=Filter!$E$5),OR(Filter!$H$5="(alle)",$C27=Filter!$H$5),OR(Filter!$B$7="(alle)",$E27=Filter!$B$7),OR(Filter!$E$7="(alle)",ISNUMBER(SEARCH(Filter!$E$7,$J27))),OR(Filter!$H$7="(alle)",ISNUMBER(SEARCH(Filter!$H$7,$I27))),OR(Filter!$B$9="",ISNUMBER(SEARCH(Filter!$B$9,$F27&" "&$G27)))),COUNTIF($O$6:$O26,">0")+1,0)) -> 21
B28: ANF-022 | C28: Betreibervertrag | D28: § 38 (9) | E28: Nutzungszeit & Entgelte | F28: Warnung NutzerIn vor Blockadeentgeld | G28: Endnutzer sind über eine gut sichtbare Beschilderung darauf hinzuweisen, dass der Stellplatz nach Abschluss des Ladevorgangs unverzüglich freizugeben ist; der Text der Beschilderung bedarf der Zustimmung des Auftraggebers 2. Zusätzlich soll der Endnutzer über eine App oder – falls er eine solche nicht nutzt – an der Ladeeinrichtung, vor Erhebung von Blockadeentgelt oder einer Vertragsstrafe einen Hinweis erhalten, dass der Ladevorgang beendet wurde und der Ladeplatz unverzüglich zu räumen ist | H28: ggf. Mitteilung? | I28: eRound | J28: Abrechnungskomponente / Beschilderung | K28: trifft nicht zu | L28: 46259 | M28: ggf. Thema für eRound ansonsten Beschilderung -> Bau GU | N28: außerhalb | O28: =IF($B28="",0,IF(AND(OR(Filter!$B$5="(alle)",$N28=Filter!$B$5),OR(Filter!$E$5="(alle)",$K28=Filter!$E$5),OR(Filter!$H$5="(alle)",$C28=Filter!$H$5),OR(Filter!$B$7="(alle)",$E28=Filter!$B$7),OR(Filter!$E$7="(alle)",ISNUMBER(SEARCH(Filter!$E$7,$J28))),OR(Filter!$H$7="(alle)",ISNUMBER(SEARCH(Filter!$H$7,$I28))),OR(Filter!$B$9="",ISNUMBER(SEARCH(Filter!$B$9,$F28&" "&$G28)))),COUNTIF($O$6:$O27,">0")+1,0)) -> 22
B29: ANF-023 | C29: Betreibervertrag | D29: § 42 (5) | E29: Betrieb & Auslastung | F29: Updates verpflichtend. | G29: Der Auftragnehmer ist auf Aufforderung des Auftraggebers 2 verpflichtet, die Ladeeinrichtungen technisch und/oder mit Blick auf die Software (insbesondere Schnittstellen und Protokolle) weiterzuentwickeln und zu verbessern. Die Erstattung der tatsächlich erforderlichen Kosten (zuzüglich angemessener Zuschläge für allgemeine Geschäftskosten, Wagnis und Gewinn) erfolgt nach den Regelungen über geänderte oder zusätzliche Leistungen nach § 40. | I29: Alpitronic | J29: Ladeeinrichtung | K29: trifft nicht zu | L29: 46260 | M29: Betrifft LIS | N29: außerhalb | O29: =IF($B29="",0,IF(AND(OR(Filter!$B$5="(alle)",$N29=Filter!$B$5),OR(Filter!$E$5="(alle)",$K29=Filter!$E$5),OR(Filter!$H$5="(alle)",$C29=Filter!$H$5),OR(Filter!$B$7="(alle)",$E29=Filter!$B$7),OR(Filter!$E$7="(alle)",ISNUMBER(SEARCH(Filter!$E$7,$J29))),OR(Filter!$H$7="(alle)",ISNUMBER(SEARCH(Filter!$H$7,$I29))),OR(Filter!$B$9="",ISNUMBER(SEARCH(Filter!$B$9,$F29&" "&$G29)))),COUNTIF($O$6:$O28,">0")+1,0)) -> 23
B30: ANF-024 | C30: Betreibervertrag | D30: § 22 (3) | E30: Betrieb & Auslastung | F30: Bei nidriger Auslastung: Zwischenladepunkte können zwischen 17 und 6 Uhr für Übernachtladen freigegeben werden. Aber mind. 40% Zwischenladepunkte, aber mind. 2 MCS und 1 CCS. | G30: CCS- und MCS-Ladepunkte zum Zwischenladen sind bei fehlender Auslastung ab 17:00 Uhr sowie an Wochenenden zum Übernachtladen freizugegeben. Es müssen jedoch auch in dieser Zeit 40 %, aber mindestens zwei MCS-Ladepunkte bzw. ein CCS-Ladepunkt, zum Zwischenladen für das Zwischenladen freigehalten werden. An Standorten, an denen nur ein MCS-Ladepunkt vorhanden ist, ist dieser für das Zwischenladen freizuhalten. Der Auftragnehmer hat sicherzustellen, dass die MCS- und CCS-Ladepunkte zum Zwischenladen ab 06:00 Uhr wieder für das Zwischenladen bereitstehen. Auftragnehmer und Auftraggeber 2 können sich je nach Auslastung der Ladepunkte auf abweichende Vorgaben zur Freigabe von Ladepunkten zum Zwischenladen einigen. | H30: 40% Zwischenladen | I30: eRound / SCS | J30: OCPI Buchungskalender / Dynamische Anzeige | K30: erfüllt | L30: 46259 | M30: eRound regelt - SCS zeigt an | N30: im Umfang | O30: =IF($B30="",0,IF(AND(OR(Filter!$B$5="(alle)",$N30=Filter!$B$5),OR(Filter!$E$5="(alle)",$K30=Filter!$E$5),OR(Filter!$H$5="(alle)",$C30=Filter!$H$5),OR(Filter!$B$7="(alle)",$E30=Filter!$B$7),OR(Filter!$E$7="(alle)",ISNUMBER(SEARCH(Filter!$E$7,$J30))),OR(Filter!$H$7="(alle)",ISNUMBER(SEARCH(Filter!$H$7,$I30))),OR(Filter!$B$9="",ISNUMBER(SEARCH(Filter!$B$9,$F30&" "&$G30)))),COUNTIF($O$6:$O29,">0")+1,0)) -> 24
B31: ANF-025 | C31: Betreibervertrag | D31: § 4 (52) | E31: Reservierung | F31: Mindestens AN plus ein weiterer. | G31: "Reservierungssystem“: Ein System zur Reservierung von Ladepunkten, das Mobilitätsdienstleistern ermöglicht, Ladepunkte bei dem Auftragnehmer und mindestens einem weiteren Ladepunktbetreiber zu reservieren. | H31: Mehr als 1 Anbieter | I31: Autostrom+ | J31: Anbindung | K31: bewertet | N31: außerhalb | O31: =IF($B31="",0,IF(AND(OR(Filter!$B$5="(alle)",$N31=Filter!$B$5),OR(Filter!$E$5="(alle)",$K31=Filter!$E$5),OR(Filter!$H$5="(alle)",$C31=Filter!$H$5),OR(Filter!$B$7="(alle)",$E31=Filter!$B$7),OR(Filter!$E$7="(alle)",ISNUMBER(SEARCH(Filter!$E$7,$J31))),OR(Filter!$H$7="(alle)",ISNUMBER(SEARCH(Filter!$H$7,$I31))),OR(Filter!$B$9="",ISNUMBER(SEARCH(Filter!$B$9,$F31&" "&$G31)))),COUNTIF($O$6:$O30,">0")+1,0)) -> 25
B32: ANF-026 | C32: Vertragsanlage 4 | D32: § 3.13.2 | E32: Zufahrt & Schranke | F32: Schrankenanlage auf Schrankeninsel | G32: Anforderungen an Lade-, Schrankeninseln und physische Zufahrtbeschränkungen | I32: Schrankenhersteller | J32: Schrankenanlage | K32: erfasst | L32: 46259 | M32: Schranke auf Schrankeninsel geplant | N32: im Umfang | O32: =IF($B32="",0,IF(AND(OR(Filter!$B$5="(alle)",$N32=Filter!$B$5),OR(Filter!$E$5="(alle)",$K32=Filter!$E$5),OR(Filter!$H$5="(alle)",$C32=Filter!$H$5),OR(Filter!$B$7="(alle)",$E32=Filter!$B$7),OR(Filter!$E$7="(alle)",ISNUMBER(SEARCH(Filter!$E$7,$J32))),OR(Filter!$H$7="(alle)",ISNUMBER(SEARCH(Filter!$H$7,$I32))),OR(Filter!$B$9="",ISNUMBER(SEARCH(Filter!$B$9,$F32&" "&$G32)))),COUNTIF($O$6:$O31,">0")+1,0)) -> 26
B33: ANF-027 | C33: Vertragsanlage 4 | D33: § 3.13.2 (1) | E33: Zufahrt & Schranke | F33: Schranke an Einfahrt Ladepunkt und Ausfahrt Ladepunkt. Bei Schrägparken Poller? | G33: Für den Zweck einer geordneten Zufahrt und Abfahrt sowie zur Sicherstellung der Verfügbarkeit der Ladeinfrastruktur sind Ladeinseln, Schrankeninseln sowie physische Zufahrtsbeschränkungen zu errichten. Diese dienen der Vermeidung unbefugter Inanspruchnahmen der Ladeplätze durch nichtladende Fahrzeuge aus allen Fahrtrichtungen und gewährleisten den bestimmungsgemäßen Betrieb der Ladeinfrastruktur. | H33: Schranke gefordert aus allen Richtungen | I33: Schrankenhersteller | J33: Schrankenanlage | K33: erfüllt | L33: 46259 | M33: Schranken auf beiden Seiten gepplant | N33: im Umfang | O33: =IF($B33="",0,IF(AND(OR(Filter!$B$5="(alle)",$N33=Filter!$B$5),OR(Filter!$E$5="(alle)",$K33=Filter!$E$5),OR(Filter!$H$5="(alle)",$C33=Filter!$H$5),OR(Filter!$B$7="(alle)",$E33=Filter!$B$7),OR(Filter!$E$7="(alle)",ISNUMBER(SEARCH(Filter!$E$7,$J33))),OR(Filter!$H$7="(alle)",ISNUMBER(SEARCH(Filter!$H$7,$I33))),OR(Filter!$B$9="",ISNUMBER(SEARCH(Filter!$B$9,$F33&" "&$G33)))),COUNTIF($O$6:$O32,">0")+1,0)) -> 27
B34: ANF-028 | C34: Vertragsanlage 4 | D34: § 3.13.4 | E34: Anzeige & Beschilderung | F34: Darstellung statischer und dynamischer Infos. | G34: Jeder Ladeplatz ist mit einer Kennzeichnung bzw. Anzeige mit folgenden Informationen auszurüsten: - Ladeplatznummer (Schild mit schwarzer Nummer auf weißem retroreflektierendem Hintergrund mit der Reflektionsklasse RA1 A) - Dynamische Anzeige mit - Typ des Ladeplatzes (MCS, CCS-Zwischenladen, CCS-Übernachtladen) - Leistung der Ladesäule - Status (verfügbar, reserviert ab XX:XX Uhr, belegt, außer Betrieb) - optional: Kennzeichen/Reservierungsnummer - Der Status des Ladeplatzes ist zusätzlich zur dynamischen Anzeige über eine farbcodierte Statuskennzeichnung darzustellen (Grün = verfügbar, Gelb = reserviert, Rot = belegt / außer Betrieb). Die farbcodierte Kennzeichnung dient der optischen Erkennbarkeit des Betriebszustands, insbesondere bei Ausfall der digitalen Anzeige. Die Platzierung der Kennzeichnung und Anzeigen hat bei Parkständen in Schrägaufstellung gut sichtbar auf der Schrankeninsel zu erfolgen. Die Platzierung der Kennzeichnung und Anzeigen hat bei Parkständen in Längsaufstellung gut sichtbar, dem entsprechenden Ladeplatz zugehörig im Bereich der Ladeinsel bzw. Ladesäule zu erfolgen. Weitere Anforderungen im Zusammenhang mit dynamischen Anzeigen sind der Vertragsanlage 6: Anforderungen an die Ladeinfrastruktur zu entnehmen. | H34: LED Anzeigen | I34: eRound / SCS | J34: Dynamische Anzeige | K34: erfüllt | L34: 46259 | M34: LIS zeigt Zustand an, Rest auf Anzeige | N34: im Umfang | O34: =IF($B34="",0,IF(AND(OR(Filter!$B$5="(alle)",$N34=Filter!$B$5),OR(Filter!$E$5="(alle)",$K34=Filter!$E$5),OR(Filter!$H$5="(alle)",$C34=Filter!$H$5),OR(Filter!$B$7="(alle)",$E34=Filter!$B$7),OR(Filter!$E$7="(alle)",ISNUMBER(SEARCH(Filter!$E$7,$J34))),OR(Filter!$H$7="(alle)",ISNUMBER(SEARCH(Filter!$H$7,$I34))),OR(Filter!$B$9="",ISNUMBER(SEARCH(Filter!$B$9,$F34&" "&$G34)))),COUNTIF($O$6:$O33,">0")+1,0)) -> 28
B35: ANF-029 | C35: Vertragsanlage 4 | D35: § 3.13.5 | E35: Zufahrt & Schranke | G35: Zur Gewährleistung eines sicheren und zuverlässigen Betriebs sind Schrankenanlagen und automatische Poller gemäß den folgenden technischen Anforderungen auszuführen: - robuste Witterungsbeständige und korrosionsgeschützte Ausführung für den ganzjährigen Einsatz im Außenbereich - automatisches Öffnen nach Abschluss des Ladevorgangs oder bei entsprechender Systemfreigabe - Erkennung der Fahrzeugposition sowie von Hindernissen vor dem Schließvorgang zur Vermeidung von Kollisionen - manuelle Notentriegelung durch autorisiertes Personal, um die Betriebsfähigkeit auch im Stör- oder Spannungsfall sicherzustellen - Integration in das zentrale Steuerungssystem (Backend oder lokales Steuergerät) zur Überwachung, Steuerung und Protokollierung der Schranken- und Pollerfunktionen - Schrankenbäume sind gemäß geltender Vorschriften mit rot-weißer Schraffierung zu kennzeichnen - Ausstattung von Schrankenbäumen und automatischen Pollern mit integrierter Beleuchtung zur Verbesserung der Sichtbarkeit und Betriebssicherheit; dabei sind die Vorgaben zur Blendwirkung gemäß ERS zu beachten Weitere Anforderungen für den Betrieb der Schranken sind der Vertragsanlage 6: Anforderungen an die Ladeinfrastruktur zu entnehmen. | H35: Öffnen bei Ladevorgangs-Ende wiederspricht sich mit Vertragsanlage 6 §10 Abs 2 Und funktioniert für Poller nicht -> da LKW darüber steht. Einheitliche Ansteuerung reduziert komplexität Bei Partnern | I35: Schrankenhersteller / SCS / eRound | J35: Schrankenanlage | K35: erfüllt | L35: 46260 | M35: Sicherheitseinrichtung geplant LED in Schrankenbaum geplant Integration des Schrankenstatus in eRound | N35: im Umfang | O35: =IF($B35="",0,IF(AND(OR(Filter!$B$5="(alle)",$N35=Filter!$B$5),OR(Filter!$E$5="(alle)",$K35=Filter!$E$5),OR(Filter!$H$5="(alle)",$C35=Filter!$H$5),OR(Filter!$B$7="(alle)",$E35=Filter!$B$7),OR(Filter!$E$7="(alle)",ISNUMBER(SEARCH(Filter!$E$7,$J35))),OR(Filter!$H$7="(alle)",ISNUMBER(SEARCH(Filter!$H$7,$I35))),OR(Filter!$B$9="",ISNUMBER(SEARCH(Filter!$B$9,$F35&" "&$G35)))),COUNTIF($O$6:$O34,">0")+1,0)) -> 29
B36: ANF-030 | C36: Vertragsanlage 4 | D36: § 3.13.2.2 | E36: Zufahrt & Schranke | G36: Bei Parkständen in Längsaufstellung sind automatisch versenkbare Poller zur Zufahrtsbeschränkung vorzusehen. Pro Parkstand sind drei Poller so anzuordnen, dass Fehlbelegungen ausgeschlossen sind. Die Abstände der Poller untereinander sowie zur Fahrgasse ergeben sich aus der Referenzplanung (Anhang 1a: Referenzplanung Längs- und Schrägparken). Das Ein- und Ausfahren zum Ladeplatz muss jederzeit gewährleistet bleiben, auch wenn die benachbarten Stellplätze durch ausgefahrene Poller gesichert sind. Die Dauer der Öffnungs- und Schließvorgänge ist auf das technisch mögliche Minimum zu begrenzen, um einen unterbrechungsarmen Verkehrsfluss sicherzustellen. Die Regelbreite der Parkstände muss 4,50 m betragen, die Länge entspricht den Vorgaben gemäß ERS für Längsparker von 25,00 m. Ergeben sich aufgrund der örtlichen Bestandsituation Abweichungen von der Regelbreite, ist die Befahrbarkeit stets durch einen Schleppkurvennachweis zu belegen. Die Poller sind elektrisch oder hydraulisch versenkbar auszuführen und müssen über eine automatische Höhenverstellung verfügen. Das Absenken erfolgt im Regelbetrieb ausschließlich bei autorisiertem Zugang (Ladevorgang oder Reservierung). Nach Beendigung des Ladevorgangs und nach erfolgter Ausfahrt des Fahrzeuges müssen sich Poller automatisch wieder heben. Eine Notabsenkung bei Ausfall muss durch autorisiertes Personal jederzeit möglich sein. Die Poller müssen widerstandsfähig gegen Anprall und sonstige auf Rastplätzen zu erwartende Einwirkungen sein sowie frost- und salzbeständig ausgeführt werden. Zudem ist ein Schutz gegen Fremdsteuerung und Manipulation sicherzustellen. Die Steuerung der Poller muss in das übergeordnete Zugangskontrollsystem integrierbar sein. Die Erkennbarkeit des Hindernissesist stets sicherzustellen. Die Poller sind zu beleuchten. Die Ladesäule ist im Randbereich des Stellplatzes in einem praktikablen Abstand zum fahrzeugseitigen Ladeanschluss zu positionieren. Die Fläche um die Ladesäule ist in Betonbauweise auszuführen und mit zweckdienlichen Mitteln gegen Anprall und sonstige übliche Einwirkungen auf Rastplätzen zu sichern. Befindet sich im Randbereich bereits eine Bordanlage, ist eine zusätzliche Hochbordabsicherung der Ladesäule nicht erforderlich. In allen übrigen Fällen ist, neben einem Anprallschutz, eine ausreichend dimensionierte Ladeinsel zum Schutz der Ladeinfrastruktur vorzusehen. | H36: Längsparken | I36: Autostrom+ | J36: – | K36: trifft nicht zu | L36: 45894 | M36: Los 2 hat keine Poller - betrifft nur längsparkplätze | N36: im Umfang | O36: =IF($B36="",0,IF(AND(OR(Filter!$B$5="(alle)",$N36=Filter!$B$5),OR(Filter!$E$5="(alle)",$K36=Filter!$E$5),OR(Filter!$H$5="(alle)",$C36=Filter!$H$5),OR(Filter!$B$7="(alle)",$E36=Filter!$B$7),OR(Filter!$E$7="(alle)",ISNUMBER(SEARCH(Filter!$E$7,$J36))),OR(Filter!$H$7="(alle)",ISNUMBER(SEARCH(Filter!$H$7,$I36))),OR(Filter!$B$9="",ISNUMBER(SEARCH(Filter!$B$9,$F36&" "&$G36)))),COUNTIF($O$6:$O35,">0")+1,0)) -> 30
B37: ANF-031 | C37: Vertragsanlage 4 | D37: § 3.6 | E37: Bau & Dokumentation | G37: Antrag auf Baufreigabe und Ausführungs-, Werk- und Montageplanung | H37: Mitwirkung an Planung und Freigabe | I37: Autostrom+ | J37: – | K37: bewertet | N37: außerhalb | O37: =IF($B37="",0,IF(AND(OR(Filter!$B$5="(alle)",$N37=Filter!$B$5),OR(Filter!$E$5="(alle)",$K37=Filter!$E$5),OR(Filter!$H$5="(alle)",$C37=Filter!$H$5),OR(Filter!$B$7="(alle)",$E37=Filter!$B$7),OR(Filter!$E$7="(alle)",ISNUMBER(SEARCH(Filter!$E$7,$J37))),OR(Filter!$H$7="(alle)",ISNUMBER(SEARCH(Filter!$H$7,$I37))),OR(Filter!$B$9="",ISNUMBER(SEARCH(Filter!$B$9,$F37&" "&$G37)))),COUNTIF($O$6:$O36,">0")+1,0)) -> 31
B38: ANF-032 | C38: Vertragsanlage 4 | D38: § 3.7 | E38: Bau & Dokumentation | G38: Bestandsunterlagen (As-Built) | H38: Verantwortlich für Dokumentation und Erstellung Unterlagen | I38: Autostrom+ | J38: – | K38: bewertet | N38: außerhalb | O38: =IF($B38="",0,IF(AND(OR(Filter!$B$5="(alle)",$N38=Filter!$B$5),OR(Filter!$E$5="(alle)",$K38=Filter!$E$5),OR(Filter!$H$5="(alle)",$C38=Filter!$H$5),OR(Filter!$B$7="(alle)",$E38=Filter!$B$7),OR(Filter!$E$7="(alle)",ISNUMBER(SEARCH(Filter!$E$7,$J38))),OR(Filter!$H$7="(alle)",ISNUMBER(SEARCH(Filter!$H$7,$I38))),OR(Filter!$B$9="",ISNUMBER(SEARCH(Filter!$B$9,$F38&" "&$G38)))),COUNTIF($O$6:$O37,">0")+1,0)) -> 32
B39: ANF-033 | C39: Vertragsanlage 6 | D39: § 8 | E39: Authentifizierung & Zugang | F39: Öffnung innerhalb von 45 Sekunden. | G39: Folgende Authentifizierungsoptionen (Anmeldung, Freischaltung der physischen Zufahrtsbeschränkungen und Start des Ladevorgangs etc.) müssen möglich sein: ▪ RFID-Token (Ladekarte etc.) von vertraglich angebundenen Mobilitätsdienstleister, ▪ App von vertraglich angebundenen Mobilitätsdienstleister, ▪ Ad hoc-Laden ohne Registrierung und ▪ ISO 15118 (nach Verfügbarkeit – s. o. Abschnitt 7.). Der Authentifizierungsvorgang zur Freigabe des Ladeplatzes muss innerhalb von maximal 45 Sekunden abgeschlossen sein und sollte so gestaltet sein, dass der Verkehrsfluss möglichst wenig beeinträchtigt wird. Die angegebene Zeitspanne umfasst alle praktische und technische Schritte der Authentifizierung bis zur Öffnung der Schranke bzw. des Pollers und gilt für alle vorgesehenen Zugangsarten | H39: 45 Sekunden (!) Wie (wer) Erfüllt das? Bieterfrage 441 nach Bezahlterminal ? | I39: eRound / SCS | J39: Authentifizierungskomponente / Schrankensteuerung | K39: erfasst | N39: im Umfang | O39: =IF($B39="",0,IF(AND(OR(Filter!$B$5="(alle)",$N39=Filter!$B$5),OR(Filter!$E$5="(alle)",$K39=Filter!$E$5),OR(Filter!$H$5="(alle)",$C39=Filter!$H$5),OR(Filter!$B$7="(alle)",$E39=Filter!$B$7),OR(Filter!$E$7="(alle)",ISNUMBER(SEARCH(Filter!$E$7,$J39))),OR(Filter!$H$7="(alle)",ISNUMBER(SEARCH(Filter!$H$7,$I39))),OR(Filter!$B$9="",ISNUMBER(SEARCH(Filter!$B$9,$F39&" "&$G39)))),COUNTIF($O$6:$O38,">0")+1,0)) -> 33
B40: ANF-034 | C40: Vertragsanlage 6 | D40: § 9 (1) | E40: Belegungsdetektion | F40: Belegungsdetektion ist gefordert. | G40: Jeder MCS- / CCS-Ladepunkt muss über eine Detektion verfügen. Die MCS- / CCSLadeplatzdetektion ist so auszustatten, dass Objekte auf dem zum MCS- / CCSLadepunkt gehörigen MCS- / CCS-Ladeplatz detektiert werden können. | H40: Deckensensoren Pönalisierung / Falschparker | I40: Schrankenhersteller / SCS | J40: Belegungsdetektion | K40: erfüllt | L40: 46259 | M40: Radarsensor stellt Belegung der Ladesäule bereit | N40: außerhalb | O40: =IF($B40="",0,IF(AND(OR(Filter!$B$5="(alle)",$N40=Filter!$B$5),OR(Filter!$E$5="(alle)",$K40=Filter!$E$5),OR(Filter!$H$5="(alle)",$C40=Filter!$H$5),OR(Filter!$B$7="(alle)",$E40=Filter!$B$7),OR(Filter!$E$7="(alle)",ISNUMBER(SEARCH(Filter!$E$7,$J40))),OR(Filter!$H$7="(alle)",ISNUMBER(SEARCH(Filter!$H$7,$I40))),OR(Filter!$B$9="",ISNUMBER(SEARCH(Filter!$B$9,$F40&" "&$G40)))),COUNTIF($O$6:$O39,">0")+1,0)) -> 34
B41: ANF-035 | C41: Vertragsanlage 6 | D41: § 9 (2) | E41: Belegungsdetektion | F41: Roaming-Infos müssen veröffentlicht werden Pönalisierung gefordert. Entfernung Falschparker gefordert. | G41: Die Information der Reservierung des MCS- / CCS-Ladepunkts muss dem IT-Backend der MCS- / CCS-Ladeeinrichtung zur Verfügung stehen und muss angebundenen Mobilitätsdienstleistern und Betreibern von Online-Plattformen zur Darstellung von Statusinformationen zur Verfügung gestellt werden. Zudem soll dem Betreiber die Pönalisierung und Entfernung von Falschparkern ermöglicht werden. | H41: Pönalisierung / Falschparker | I41: eRound / SCS | J41: OCPI Buchungskalender / Kennzeichenerfassung / Pönalisierungssystem | K41: erfasst | N41: im Umfang | O41: =IF($B41="",0,IF(AND(OR(Filter!$B$5="(alle)",$N41=Filter!$B$5),OR(Filter!$E$5="(alle)",$K41=Filter!$E$5),OR(Filter!$H$5="(alle)",$C41=Filter!$H$5),OR(Filter!$B$7="(alle)",$E41=Filter!$B$7),OR(Filter!$E$7="(alle)",ISNUMBER(SEARCH(Filter!$E$7,$J41))),OR(Filter!$H$7="(alle)",ISNUMBER(SEARCH(Filter!$H$7,$I41))),OR(Filter!$B$9="",ISNUMBER(SEARCH(Filter!$B$9,$F41&" "&$G41)))),COUNTIF($O$6:$O40,">0")+1,0)) -> 35
...

Sheet Filter
A1: Filter – Anforderungen gezielt anzeigen | V1: Auswahllisten (Grundlage der Dropdowns)
A2: Auswahl in den gelben Feldern treffen; die Liste unten aktualisiert sich sofort. „(alle)“ lässt das Feld unberücksichtigt. Komponente und Partner suchen als Teiltext, finden also auch Mehrfachzuordnungen. Gepflegt wird weiterhin nur im Register „Anforderungen“. | U2: (alle) | V2: (alle) | W2: (alle) | X2: (alle) | Y2: (alle) | Z2: (alle)
U3: außerhalb | V3: bewertet | W3: Betreibervertrag | X3: Anzeige & Beschilderung | Y3: Abrechnungskomponente | Z3: Alpitronic
B4: Umfang | E4: Status | H4: Dokument | U4: im Umfang | V4: erfasst | W4: Bieterfragenkatalog | X4: Authentifizierung & Zugang | Y4: Anbindung | Z4: Autostrom+
B5: (alle) | E5: (alle) | H5: (alle) | V5: erfüllt | W5: Vertragsanlage 10 | X5: Bau & Dokumentation | Y5: Authentifizierungskomponente | Z5: Reservierungsplattform
B6: Themenfeld | E6: Komponente | H6: Partner | V6: trifft nicht zu | W6: Vertragsanlage 13 | X6: Belegungsdetektion | Y6: Belegungsdetektion | Z6: SCS
B7: (alle) | E7: (alle) | H7: (alle) | W7: Vertragsanlage 4 | X7: Betrieb & Auslastung | Y7: Beschilderung | Z7: Schrankenhersteller
B8: Suchbegriff | W8: Vertragsanlage 6 | X8: Flächen & Genehmigungen | Y8: Dynamische Anzeige | Z8: Schrankenhersteller / SCS
X9: Monitoring & Reporting | Y9: Kennzeichenerfassung | Z9: Schrankenhersteller / SCS / eRound
A10: Der Suchbegriff wirkt auf Kernaussage und Originaltext. „(alle)“ lässt ein Feld unberücksichtigt; Komponente und Partner suchen als Teiltext. | X10: Netzanschluss & Energie | Y10: Ladeeinrichtung | Z10: WWL
X11: Nutzungszeit & Entgelte | Y11: Monitoring | Z11: Zuordnung prüfen
A12: Treffer | B12: =COUNTIF(Anforderungen!$O$7:$O$2000,">0") -> 1382 | D12: erfasst | E12: =SUMPRODUCT((Anforderungen!$O$7:$O$2000>0)*(Anforderungen!$K$7:$K$2000="erfasst")) -> 1211 | F12: bewertet | G12: =SUMPRODUCT((Anforderungen!$O$7:$O$2000>0)*(Anforderungen!$K$7:$K$2000="bewertet")) -> 3 | H12: erfüllt | I12: =SUMPRODUCT((Anforderungen!$O$7:$O$2000>0)*(Anforderungen!$K$7:$K$2000="erfüllt")) -> 10 | J12: trifft nicht zu | K12: =SUMPRODUCT((Anforderungen!$O$7:$O$2000>0)*(Anforderungen!$K$7:$K$2000="trifft nicht zu")) -> 158 | X12: Reservierung | Y12: OCPI Buchungskalender | Z12: eRound
A13: Angezeigt werden die ersten 300 Treffer. Bei mehr Treffern die Auswahl weiter eingrenzen. | X13: Sonstiges / Zuordnung prüfen | Y13: Pönalisierungssystem | Z13: eRound / SCS
X14: Technik Ladeinfrastruktur | Y14: Reservierungsplattform | Z14: offen
A15: ID | B15: Dokument | C15: Fundstelle | D15: Themenfeld | E15: Kernaussage | F15: Originaltext | G15: Partner | H15: Komponente(n) | I15: Status | J15: Erfüllt am | K15: Nachweis / Notiz | X15: Vergabeverfahren & Angebot | Y15: Schrankenanlage | Z15: tbd
A16: =IF($R16="","",INDEX(Anforderungen!$B:$B,$R16)) -> ANF-001 | B16: =IF($R16="","",INDEX(Anforderungen!$C:$C,$R16)) -> Betreibervertrag | C16: =IF($R16="","",INDEX(Anforderungen!$D:$D,$R16)) -> § 25 (1) | D16: =IF($R16="","",INDEX(Anforderungen!$E:$E,$R16)) -> Reservierung | E16: =IF($R16="","",INDEX(Anforderungen!$F:$F,$R16)) -> OCPI Schnittstelle | F16: =IF($R16="","",INDEX(Anforderungen!$G:$G,$R16)) -> Der Auftragnehmer stellt sicher, dass die Reservierung von Ladepunkten über Reservierungsplattformen während der Laufzeit dieses Vertrags möglich ist. Hierzu hält der Auftragnehmer eine auf OCPI (Open Charge Point Interface) basierende Schnittstelle vor, über die sich Reservierungsplattformen nach Maßgabe der folgenden Absätze anbinden können. | G16: =IF($R16="","",INDEX(Anforderungen!$I:$I,$R16)) -> eRound | H16: =IF($R16="","",INDEX(Anforderungen!$J:$J,$R16)) -> OCPI Buchungskalender | I16: =IF($R16="","",INDEX(Anforderungen!$K:$K,$R16)) -> erfasst | J16: =IF($R16="","",INDEX(Anforderungen!$L:$L,$R16)) -> 0 | K16: =IF($R16="","",INDEX(Anforderungen!$M:$M,$R16)) -> 0 | R16: =IFERROR(MATCH(ROWS($A$16:$A16),Anforderungen!$O$7:$O$2000,0)+6,"") -> 7 | X16: Vertrag & Recht | Y16: Schrankensteuerung
A17: =IF($R17="","",INDEX(Anforderungen!$B:$B,$R17)) -> ANF-002 | B17: =IF($R17="","",INDEX(Anforderungen!$C:$C,$R17)) -> Betreibervertrag | C17: =IF($R17="","",INDEX(Anforderungen!$D:$D,$R17)) -> § 25 (2) | D17: =IF($R17="","",INDEX(Anforderungen!$E:$E,$R17)) -> Reservierung | E17: =IF($R17="","",INDEX(Anforderungen!$F:$F,$R17)) -> OCPI Kostenfrei | F17: =IF($R17="","",INDEX(Anforderungen!$G:$G,$R17)) -> Der Auftragnehmer ist verpflichtet, jeder Reservierungsplattform die Anbindung über die in Absatz 1 genannte Schnittstelle kostenfrei zu ermöglichen, soweit die Reservierungsplattform die folgenden Mindestvoraussetzungen erfüllt: | G17: =IF($R17="","",INDEX(Anforderungen!$I:$I,$R17)) -> eRound | H17: =IF($R17="","",INDEX(Anforderungen!$J:$J,$R17)) -> OCPI Buchungskalender | I17: =IF($R17="","",INDEX(Anforderungen!$K:$K,$R17)) -> erfasst | J17: =IF($R17="","",INDEX(Anforderungen!$L:$L,$R17)) -> 0 | K17: =IF($R17="","",INDEX(Anforderungen!$M:$M,$R17)) -> 0 | R17: =IFERROR(MATCH(ROWS($A$16:$A17),Anforderungen!$O$7:$O$2000,0)+6,"") -> 8 | X17: Zufahrt & Schranke | Y17: Zuordnung prüfen
A18: =IF($R18="","",INDEX(Anforderungen!$B:$B,$R18)) -> ANF-003 | B18: =IF($R18="","",INDEX(Anforderungen!$C:$C,$R18)) -> Betreibervertrag | C18: =IF($R18="","",INDEX(Anforderungen!$D:$D,$R18)) -> § 25 (2) a | D18: =IF($R18="","",INDEX(Anforderungen!$E:$E,$R18)) -> Reservierung | E18: =IF($R18="","",INDEX(Anforderungen!$F:$F,$R18)) -> OCPI Kostenfrei | F18: =IF($R18="","",INDEX(Anforderungen!$G:$G,$R18)) -> Die Reservierungsplattform stellt dem Auftragnehmer für die Anbindung der Reservierungsplattform keine Anbindungskosten in Rechnung | G18: =IF($R18="","",INDEX(Anforderungen!$I:$I,$R18)) -> eRound | H18: =IF($R18="","",INDEX(Anforderungen!$J:$J,$R18)) -> Anbindung | I18: =IF($R18="","",INDEX(Anforderungen!$K:$K,$R18)) -> erfasst | J18: =IF($R18="","",INDEX(Anforderungen!$L:$L,$R18)) -> 0 | K18: =IF($R18="","",INDEX(Anforderungen!$M:$M,$R18)) -> 0 | R18: =IFERROR(MATCH(ROWS($A$16:$A18),Anforderungen!$O$7:$O$2000,0)+6,"") -> 9 | Y18: –
A19: =IF($R19="","",INDEX(Anforderungen!$B:$B,$R19)) -> ANF-004 | B19: =IF($R19="","",INDEX(Anforderungen!$C:$C,$R19)) -> Betreibervertrag | C19: =IF($R19="","",INDEX(Anforderungen!$D:$D,$R19)) -> § 25 (2) b | D19: =IF($R19="","",INDEX(Anforderungen!$E:$E,$R19)) -> Reservierung | E19: =IF($R19="","",INDEX(Anforderungen!$F:$F,$R19)) -> Anbindung verpflichtend, wenn alle AN angebunden werden oder AG2 auffordert | F19: =IF($R19="","",INDEX(Anforderungen!$G:$G,$R19)) -> Die Reservierungsplattform ermöglicht Endnutzern und Mobilitätsdienstleistern die Reservierung von Ladepunkten im gesamten Gebiet der Bundesrepublik Deutschland gegen ein angemessenes Entgelt. Ermöglicht eine Reservierungsplattform eine Reservierung von Ladepunkten nur in Teilen des Gebiets der Bundesrepublik Deutschland, ist der Auftragnehmer zur Anbindung nur verpflichtet, wenn der Auftraggeber 2 den Auftragnehmer hierzu auffordert. | G19: =IF($R19="","",INDEX(Anforderungen!$I:$I,$R19)) -> eRound | H19: =IF($R19="","",INDEX(Anforderungen!$J:$J,$R19)) -> OCPI Buchungskalender | I19: =IF($R19="","",INDEX(Anforderungen!$K:$K,$R19)) -> erfasst | J19: =IF($R19="","",INDEX(Anforderungen!$L:$L,$R19)) -> 0 | K19: =IF($R19="","",INDEX(Anforderungen!$M:$M,$R19)) -> 0 | R19: =IFERROR(MATCH(ROWS($A$16:$A19),Anforderungen!$O$7:$O$2000,0)+6,"") -> 10
A20: =IF($R20="","",INDEX(Anforderungen!$B:$B,$R20)) -> ANF-005 | B20: =IF($R20="","",INDEX(Anforderungen!$C:$C,$R20)) -> Betreibervertrag | C20: =IF($R20="","",INDEX(Anforderungen!$D:$D,$R20)) -> § 25 (2) c | D20: =IF($R20="","",INDEX(Anforderungen!$E:$E,$R20)) -> Reservierung | E20: =IF($R20="","",INDEX(Anforderungen!$F:$F,$R20)) -> Reservierung mit Vorlauf von max. 7 Tagen und min. 15 min. Kostenfreie Stornierung und Änderung bis 30min vorher. Kennzeichenabgleich zur Unterbindung von Doppelbuchungen. | F20: =IF($R20="","",INDEX(Anforderungen!$G:$G,$R20)) -> Die Reservierungsplattform ermöglicht eine Reservierung von Ladepunkten mit einer Vorlaufzeit von maximal 7 Kalendertagen und mindestens 15 Minuten. Eine kostenfreie Stornierung oder Änderung der Reservierung über die Reservierungsplattform muss, soweit möglich, bis zu 30 Minuten vor Beginn des in der Reservierung angegebenen Startzeitpunkts möglich sein. Die Reservierungsplattform stellt durch geeignete Vorkehrungen (z. B. durch einen Kennzeichenabgleich) sicher, dass für einen E-LKW in einem Zeitintervall nur ein Ladepunkt reserviert wird. | G20: =IF($R20="","",INDEX(Anforderungen!$I:$I,$R20)) -> eRound | H20: =IF($R20="","",INDEX(Anforderungen!$J:$J,$R20)) -> OCPI Buchungskalender | I20: =IF($R20="","",INDEX(Anforderungen!$K:$K,$R20)) -> erfasst | J20: =IF($R20="","",INDEX(Anforderungen!$L:$L,$R20)) -> 0 | K20: =IF($R20="","",INDEX(Anforderungen!$M:$M,$R20)) -> 0 | R20: =IFERROR(MATCH(ROWS($A$16:$A20),Anforderungen!$O$7:$O$2000,0)+6,"") -> 11
A21: =IF($R21="","",INDEX(Anforderungen!$B:$B,$R21)) -> ANF-006 | B21: =IF($R21="","",INDEX(Anforderungen!$C:$C,$R21)) -> Betreibervertrag | C21: =IF($R21="","",INDEX(Anforderungen!$D:$D,$R21)) -> § 25 (2) d | D21: =IF($R21="","",INDEX(Anforderungen!$E:$E,$R21)) -> Reservierung | E21: =IF($R21="","",INDEX(Anforderungen!$F:$F,$R21)) -> Entschädigung an AN von der Reservierungsplattform i.H.v. mind. 30€ nach 15/30 min Wartezeit bei No-Show. | F21: =IF($R21="","",INDEX(Anforderungen!$G:$G,$R21)) -> Die Reservierungsplattform entschädigt den Auftragnehmer in angemessener Höhe, wenn an der reservierten Ladeeinrichtung ab dem in der Reservierung angegebenen Startzeitpunkt und Ablauf einer Wartezeit von 15 Minuten bei Ladepunkten zum Zwischenladen, bzw. 30 Minuten bei Ladepunkten zum Übernachtladen (sog. „no-show“) kein Start eines Ladevorgangs erfolgt. Die Entschädigung des Auftragnehmers ist angemessen, wenn der Auftragnehmer im Fall eines „no-show“ mindestens € 30,00 erhält. | G21: =IF($R21="","",INDEX(Anforderungen!$I:$I,$R21)) -> eRound | H21: =IF($R21="","",INDEX(Anforderungen!$J:$J,$R21)) -> Abrechnungskomponente | I21: =IF($R21="","",INDEX(Anforderungen!$K:$K,$R21)) -> erfasst | J21: =IF($R21="","",INDEX(Anforderungen!$L:$L,$R21)) -> 0 | K21: =IF($R21="","",INDEX(Anforderungen!$M:$M,$R21)) -> 0 | R21: =IFERROR(MATCH(ROWS($A$16:$A21),Anforderungen!$O$7:$O$2000,0)+6,"") -> 12
A22: =IF($R22="","",INDEX(Anforderungen!$B:$B,$R22)) -> ANF-007 | B22: =IF($R22="","",INDEX(Anforderungen!$C:$C,$R22)) -> Betreibervertrag | C22: =IF($R22="","",INDEX(Anforderungen!$D:$D,$R22)) -> § 25 (3) | D22: =IF($R22="","",INDEX(Anforderungen!$E:$E,$R22)) -> Reservierung | E22: =IF($R22="","",INDEX(Anforderungen!$F:$F,$R22)) -> Anpassung an Marktstandards mit 2 Monaten Vorlauf. | F22: =IF($R22="","",INDEX(Anforderungen!$G:$G,$R22)) -> Der Auftraggeber 2 ist berechtigt, die in Absatz 2 definierten Mindestvoraussetzungen im Fall abweichender Marktstandards mit einer Vorlaufzeit von zwei Monaten anzupassen | G22: =IF($R22="","",INDEX(Anforderungen!$I:$I,$R22)) -> eRound | H22: =IF($R22="","",INDEX(Anforderungen!$J:$J,$R22)) -> OCPI Buchungskalender | I22: =IF($R22="","",INDEX(Anforderungen!$K:$K,$R22)) -> erfasst | J22: =IF($R22="","",INDEX(Anforderungen!$L:$L,$R22)) -> 0 | K22: =IF($R22="","",INDEX(Anforderungen!$M:$M,$R22)) -> 0 | R22: =IFERROR(MATCH(ROWS($A$16:$A22),Anforderungen!$O$7:$O$2000,0)+6,"") -> 13
A23: =IF($R23="","",INDEX(Anforderungen!$B:$B,$R23)) -> ANF-008 | B23: =IF($R23="","",INDEX(Anforderungen!$C:$C,$R23)) -> Betreibervertrag | C23: =IF($R23="","",INDEX(Anforderungen!$D:$D,$R23)) -> § 25 (4) | D23: =IF($R23="","",INDEX(Anforderungen!$E:$E,$R23)) -> Reservierung | E23: =IF($R23="","",INDEX(Anforderungen!$F:$F,$R23)) -> Ladepunkte an einem Standort können von der Reservierung ausgenommen werden. | F23: =IF($R23="","",INDEX(Anforderungen!$G:$G,$R23)) -> Der Auftragnehmer kann CCS- und MCS-Ladepunkten an einem Standort von der Reservierungsmöglichkeit ausnehmen. | G23: =IF($R23="","",INDEX(Anforderungen!$I:$I,$R23)) -> eRound | H23: =IF($R23="","",INDEX(Anforderungen!$J:$J,$R23)) -> OCPI Buchungskalender | I23: =IF($R23="","",INDEX(Anforderungen!$K:$K,$R23)) -> erfasst | J23: =IF($R23="","",INDEX(Anforderungen!$L:$L,$R23)) -> 0 | K23: =IF($R23="","",INDEX(Anforderungen!$M:$M,$R23)) -> 0 | R23: =IFERROR(MATCH(ROWS($A$16:$A23),Anforderungen!$O$7:$O$2000,0)+6,"") -> 14
A24: =IF($R24="","",INDEX(Anforderungen!$B:$B,$R24)) -> ANF-009 | B24: =IF($R24="","",INDEX(Anforderungen!$C:$C,$R24)) -> Betreibervertrag | C24: =IF($R24="","",INDEX(Anforderungen!$D:$D,$R24)) -> § 25 (5) | D24: =IF($R24="","",INDEX(Anforderungen!$E:$E,$R24)) -> Zufahrt & Schranke | E24: =IF($R24="","",INDEX(Anforderungen!$F:$F,$R24)) -> Bauliche Maßnahme zur Reservierung an jedem Ladepunkt. | F24: =IF($R24="","",INDEX(Anforderungen!$G:$G,$R24)) -> Der Auftragnehmer hat geeignete Vorkehrungen, insbesondere die in Vertragsanlage 4: Leistungsbeschreibung Errichtung vorgesehenen baulichen Maßnahmen, zu treffen, um ein anderweitiges Laden an dem Ladepunkt der Ladeeinrichtung während des reservierten Zeitraums zu verhindern. | G24: =IF($R24="","",INDEX(Anforderungen!$I:$I,$R24)) -> Schrankenhersteller | H24: =IF($R24="","",INDEX(Anforderungen!$J:$J,$R24)) -> Schrankenanlage | I24: =IF($R24="","",INDEX(Anforderungen!$K:$K,$R24)) -> erfasst | J24: =IF($R24="","",INDEX(Anforderungen!$L:$L,$R24)) -> 0 | K24: =IF($R24="","",INDEX(Anforderungen!$M:$M,$R24)) -> 0 | R24: =IFERROR(MATCH(ROWS($A$16:$A24),Anforderungen!$O$7:$O$2000,0)+6,"") -> 15
A25: =IF($R25="","",INDEX(Anforderungen!$B:$B,$R25)) -> ANF-010 | B25: =IF($R25="","",INDEX(Anforderungen!$C:$C,$R25)) -> Betreibervertrag | C25: =IF($R25="","",INDEX(Anforderungen!$D:$D,$R25)) -> § 25 (6) | D25: =IF($R25="","",INDEX(Anforderungen!$E:$E,$R25)) -> Reservierung | E25: =IF($R25="","",INDEX(Anforderungen!$F:$F,$R25)) -> Mindestens 40% der Ladepunkte müssen reserviert werden können. | F25: =IF($R25="","",INDEX(Anforderungen!$G:$G,$R25)) -> Verstößt der Auftragnehmer gegen die Pflicht nach Absatz 1, wird für jeden Standort, an dem die Reservierung von Ladepunkten aufgrund des Verstoßes gegen die Pflicht nach Absatz 1 nicht möglich ist, eine Vertragsstrafe fällig. Die Reservierung von Ladepunkten an einem Standort gilt als nicht möglich, wenn mindestens 40 % der Ladepunkte an dem Standort nicht reserviert werden können. Die Höhe der Vertragsstrafe beträgt € 2.500,00 für jeden Kalendertag, an dem die Reservierung von Ladepunkten an einem Standort nicht möglich ist, höchstens jedoch € 40.000,00 pro Kalendermonat und pro Standort. | G25: =IF($R25="","",INDEX(Anforderungen!$I:$I,$R25)) -> eRound | H25: =IF($R25="","",INDEX(Anforderungen!$J:$J,$R25)) -> OCPI Buchungskalender | I25: =IF($R25="","",INDEX(Anforderungen!$K:$K,$R25)) -> erfasst | J25: =IF($R25="","",INDEX(Anforderungen!$L:$L,$R25)) -> 0 | K25: =IF($R25="","",INDEX(Anforderungen!$M:$M,$R25)) -> 0 | R25: =IFERROR(MATCH(ROWS($A$16:$A25),Anforderungen!$O$7:$O$2000,0)+6,"") -> 16
A26: =IF($R26="","",INDEX(Anforderungen!$B:$B,$R26)) -> ANF-011 | B26: =IF($R26="","",INDEX(Anforderungen!$C:$C,$R26)) -> Betreibervertrag | C26: =IF($R26="","",INDEX(Anforderungen!$D:$D,$R26)) -> § 31 (1) | D26: =IF($R26="","",INDEX(Anforderungen!$E:$E,$R26)) -> Authentifizierung & Zugang | E26: =IF($R26="","",INDEX(Anforderungen!$F:$F,$R26)) -> Es muss Adhoc geladen werden können | F26: =IF($R26="","",INDEX(Anforderungen!$G:$G,$R26)) -> Der Auftragnehmer ist verpflichtet, potenziellen Endnutzern diskriminierungsfrei zu angemessenen Bedingungen ein Ad-hoc-Laden (punktuelles Aufladen i. S. d. AFIR) zu ermöglichen, soweit es ihm zumutbar ist (z. B. mit Blick auf die Bonität des Endnutzers). | G26: =IF($R26="","",INDEX(Anforderungen!$I:$I,$R26)) -> eRound / SCS | H26: =IF($R26="","",INDEX(Anforderungen!$J:$J,$R26)) -> Authentifizierungskomponente / Schrankensteuerung | I26: =IF($R26="","",INDEX(Anforderungen!$K:$K,$R26)) -> erfasst | J26: =IF($R26="","",INDEX(Anforderungen!$L:$L,$R26)) -> 0 | K26: =IF($R26="","",INDEX(Anforderungen!$M:$M,$R26)) -> 0 | R26: =IFERROR(MATCH(ROWS($A$16:$A26),Anforderungen!$O$7:$O$2000,0)+6,"") -> 17
