Workbook

Sheet Cockpit
A1: Cockpit – Anforderungen Autostrom / LKW-Laden
A2: Status, Erfüllung und Dokumentationsqualität auf einen Blick
A3: Alle Kennzahlen rechnen direkt aus den Registern „Anforderungen“ und „Komponenten“ – inklusive des vollständigen Bieterfragenkatalogs.
A5: Kennzahl | B5: Wert
A6: Anforderungen gesamt | B6: =COUNTA(Anforderungen!$B$7:$B$2000) -> 1382
A7: Erfasst | B7: =COUNTIF(Anforderungen!$K$7:$K$2000,"erfasst") -> 1364
A8: Bewertet | B8: =COUNTIF(Anforderungen!$K$7:$K$2000,"bewertet") -> 3
A9: Erfüllt | B9: =COUNTIF(Anforderungen!$K$7:$K$2000,"erfüllt") -> 10
A10: davon vollständig dokumentiert | B10: =COUNTIFS(Anforderungen!$K$7:$K$2000,"erfüllt",Anforderungen!$L$7:$L$2000,"<>",Anforderungen!$M$7:$M$2000,"<>") -> 10
A11: Trifft nicht zu | B11: =COUNTIF(Anforderungen!$K$7:$K$2000,"trifft nicht zu") -> 5
A12: Erfüllt ohne Datum | B12: =COUNTIFS(Anforderungen!$K$7:$K$2000,"erfüllt",Anforderungen!$L$7:$L$2000,"") -> 0
A13: Erfüllt ohne Nachweis / Notiz | B13: =COUNTIFS(Anforderungen!$K$7:$K$2000,"erfüllt",Anforderungen!$M$7:$M$2000,"") -> 0
A14: Trifft nicht zu ohne Begründung | B14: =COUNTIFS(Anforderungen!$K$7:$K$2000,"trifft nicht zu",Anforderungen!$M$7:$M$2000,"") -> 2
A15: Erfüllungsgrad | B15: =IFERROR(COUNTIF(Anforderungen!$K$7:$K$2000,"erfüllt")/(COUNTA(Anforderungen!$B$7:$B$2000)-COUNTIF(Anforderungen!$K$7:$K$2000,"trifft nicht zu")),0) -> 0.0072621641
A16: Dokumentationsgrad erfüllt | B16: =IFERROR(COUNTIFS(Anforderungen!$K$7:$K$2000,"erfüllt",Anforderungen!$L$7:$L$2000,"<>",Anforderungen!$M$7:$M$2000,"<>")/COUNTIF(Anforderungen!$K$7:$K$2000,"erfüllt"),0) -> 1
A17: Komponenten/Schnittstellen erfüllt | B17: =COUNTIF(Komponenten!$J$6:$J$29,"erfüllt") -> 0
A18: Bieterfragen im Register | B18: =COUNTIF(Anforderungen!$C$7:$C$2000,"Bieterfragenkatalog") -> 663
A19: Offene Zuordnungen (Komponente/Partner) | B19: =COUNTIF(Anforderungen!$J$7:$J$2000,"Zuordnung prüfen")+COUNTIF(Anforderungen!$I$7:$I$2000,"Zuordnung prüfen") -> 460

Sheet Anforderungen
A1: Anforderungen – Autostrom / LKW-Laden
A2: Zentrales Anforderungsregister: Der Block „Erfüllung / Nachweis“ verbindet Status, tatsächliches Erfüllungsdatum und Dokumentation.
A3: Logik: erfasst → bewertet → erfüllt. Bei „erfüllt“ sind Datum und Nachweis/Notiz erforderlich, bei „trifft nicht zu“ eine Begründung. Gelb markierte Zuordnungen (Partner/Komponente) sind fachlich zu prüfen.
B5: Anforderung & Zuordnung | K5: Erfüllung / Nachweis (Konzept)
B6: ID | C6: Dokument | D6: Fundstelle | E6: Themenfeld | F6: Kernaussage | G6: Anforderung / Frage (Originaltext) | H6: Bemerkung | I6: Partner | J6: Komponente(n) | K6: Status | L6: Erfüllt am | M6: Nachweis / Notiz
B7: ANF-001 | C7: Betreibervertrag | D7: § 25 (1) | E7: Reservierung | F7: OCPI Schnittstelle | G7: Der Auftragnehmer stellt sicher, dass die Reservierung von Ladepunkten über Reservierungsplattformen während der Laufzeit dieses Vertrags möglich ist. Hierzu hält der Auftragnehmer eine auf OCPI (Open Charge Point Interface) basierende Schnittstelle vor, über die sich Reservierungsplattformen nach Maßgabe der folgenden Absätze anbinden können. | I7: eRound | J7: OCPI Buchungskalender | K7: erfasst
B8: ANF-002 | C8: Betreibervertrag | D8: § 25 (2) | E8: Reservierung | F8: OCPI Kostenfrei | G8: Der Auftragnehmer ist verpflichtet, jeder Reservierungsplattform die Anbindung über die in Absatz 1 genannte Schnittstelle kostenfrei zu ermöglichen, soweit die Reservierungsplattform die folgenden Mindestvoraussetzungen erfüllt: | I8: eRound | J8: OCPI Buchungskalender | K8: erfasst
B9: ANF-003 | C9: Betreibervertrag | D9: § 25 (2) a | E9: Reservierung | F9: OCPI Kostenfrei | G9: Die Reservierungsplattform stellt dem Auftragnehmer für die Anbindung der Reservierungsplattform keine Anbindungskosten in Rechnung | I9: eRound | J9: Anbindung | K9: erfasst
B10: ANF-004 | C10: Betreibervertrag | D10: § 25 (2) b | E10: Reservierung | F10: Anbindung verpflichtend, wenn alle AN angebunden werden oder AG2 auffordert | G10: Die Reservierungsplattform ermöglicht Endnutzern und Mobilitätsdienstleistern die Reservierung von Ladepunkten im gesamten Gebiet der Bundesrepublik Deutschland gegen ein angemessenes Entgelt. Ermöglicht eine Reservierungsplattform eine Reservierung von Ladepunkten nur in Teilen des Gebiets der Bundesrepublik Deutschland, ist der Auftragnehmer zur Anbindung nur verpflichtet, wenn der Auftraggeber 2 den Auftragnehmer hierzu auffordert. | I10: eRound | J10: OCPI Buchungskalender | K10: erfasst
B11: ANF-005 | C11: Betreibervertrag | D11: § 25 (2) c | E11: Reservierung | F11: Reservierung mit Vorlauf von max. 7 Tagen und min. 15 min. Kostenfreie Stornierung und Änderung bis 30min vorher. Kennzeichenabgleich zur Unterbindung von Doppelbuchungen. | G11: Die Reservierungsplattform ermöglicht eine Reservierung von Ladepunkten mit einer Vorlaufzeit von maximal 7 Kalendertagen und mindestens 15 Minuten. Eine kostenfreie Stornierung oder Änderung der Reservierung über die Reservierungsplattform muss, soweit möglich, bis zu 30 Minuten vor Beginn des in der Reservierung angegebenen Startzeitpunkts möglich sein. Die Reservierungsplattform stellt durch geeignete Vorkehrungen (z. B. durch einen Kennzeichenabgleich) sicher, dass für einen E-LKW in einem Zeitintervall nur ein Ladepunkt reserviert wird. | I11: eRound | J11: OCPI Buchungskalender | K11: erfasst
B12: ANF-006 | C12: Betreibervertrag | D12: § 25 (2) d | E12: Reservierung | F12: Entschädigung an AN von der Reservierungsplattform i.H.v. mind. 30€ nach 15/30 min Wartezeit bei No-Show. | G12: Die Reservierungsplattform entschädigt den Auftragnehmer in angemessener Höhe, wenn an der reservierten Ladeeinrichtung ab dem in der Reservierung angegebenen Startzeitpunkt und Ablauf einer Wartezeit von 15 Minuten bei Ladepunkten zum Zwischenladen, bzw. 30 Minuten bei Ladepunkten zum Übernachtladen (sog. „no-show“) kein Start eines Ladevorgangs erfolgt. Die Entschädigung des Auftragnehmers ist angemessen, wenn der Auftragnehmer im Fall eines „no-show“ mindestens € 30,00 erhält. | I12: eRound | J12: Abrechnungskomponente | K12: erfasst
B13: ANF-007 | C13: Betreibervertrag | D13: § 25 (3) | E13: Reservierung | F13: Anpassung an Marktstandards mit 2 Monaten Vorlauf. | G13: Der Auftraggeber 2 ist berechtigt, die in Absatz 2 definierten Mindestvoraussetzungen im Fall abweichender Marktstandards mit einer Vorlaufzeit von zwei Monaten anzupassen | I13: eRound | J13: OCPI Buchungskalender | K13: erfasst
B14: ANF-008 | C14: Betreibervertrag | D14: § 25 (4) | E14: Reservierung | F14: Ladepunkte an einem Standort können von der Reservierung ausgenommen werden. | G14: Der Auftragnehmer kann CCS- und MCS-Ladepunkten an einem Standort von der Reservierungsmöglichkeit ausnehmen. | I14: eRound | J14: OCPI Buchungskalender | K14: erfasst
B15: ANF-009 | C15: Betreibervertrag | D15: § 25 (5) | E15: Zufahrt & Schranke | F15: Bauliche Maßnahme zur Reservierung an jedem Ladepunkt. | G15: Der Auftragnehmer hat geeignete Vorkehrungen, insbesondere die in Vertragsanlage 4: Leistungsbeschreibung Errichtung vorgesehenen baulichen Maßnahmen, zu treffen, um ein anderweitiges Laden an dem Ladepunkt der Ladeeinrichtung während des reservierten Zeitraums zu verhindern. | H15: Schrankensteuerung | I15: Schrankenhersteller | J15: Schrankenanlage | K15: erfasst
B16: ANF-010 | C16: Betreibervertrag | D16: § 25 (6) | E16: Reservierung | F16: Mindestens 40% der Ladepunkte müssen reserviert werden können. | G16: Verstößt der Auftragnehmer gegen die Pflicht nach Absatz 1, wird für jeden Standort, an dem die Reservierung von Ladepunkten aufgrund des Verstoßes gegen die Pflicht nach Absatz 1 nicht möglich ist, eine Vertragsstrafe fällig. Die Reservierung von Ladepunkten an einem Standort gilt als nicht möglich, wenn mindestens 40 % der Ladepunkte an dem Standort nicht reserviert werden können. Die Höhe der Vertragsstrafe beträgt € 2.500,00 für jeden Kalendertag, an dem die Reservierung von Ladepunkten an einem Standort nicht möglich ist, höchstens jedoch € 40.000,00 pro Kalendermonat und pro Standort. | H16: 40% der Schranken offen lassen? | I16: eRound | J16: OCPI Buchungskalender | K16: erfasst
B17: ANF-011 | C17: Betreibervertrag | D17: § 31 (1) | E17: Authentifizierung & Zugang | F17: Es muss Adhoc geladen werden können | G17: Der Auftragnehmer ist verpflichtet, potenziellen Endnutzern diskriminierungsfrei zu angemessenen Bedingungen ein Ad-hoc-Laden (punktuelles Aufladen i. S. d. AFIR) zu ermöglichen, soweit es ihm zumutbar ist (z. B. mit Blick auf die Bonität des Endnutzers). | H17: Adhoc muss möglich sein -> Schranke -> wie? | I17: eRound / SCS | J17: Authentifizierungskomponente / Schrankensteuerung | K17: erfasst
B18: ANF-012 | C18: Betreibervertrag | D18: § 38 (1) | E18: Nutzungszeit & Entgelte | F18: Blockadeentgelte und maximale Nutzungsdauer | G18: Start- und zeitabhängige Entgelte dürfen nicht erhoben werden. Dies gilt nicht für vertraglich vereinbarte Blockadeentgelte, die nach Ablauf einer maximalen Nutzungszeit vom Endnutzer bzw. Mobilitätsdienstleister unabhängig davon, welches der Zugangsmodelle des § 30 Abs. 2 gewählt wird, erhoben werden. Die maximale Nutzungszeit beginnt mit Beginn des Ladevorgangs und beträgt | H18: Schnittstelle Nutzungszeit | I18: eRound | J18: OCPI Buchungskalender | K18: erfasst
B19: ANF-013 | C19: Betreibervertrag | D19: § 38 (1) a | E19: Nutzungszeit & Entgelte | F19: Maximale Nutzungsdauer Zwischenladen ist 1h. | G19: bei MCS-Ladepunkten und CCS-Ladepunkten zum Zwischenladen 1 Stunde. | H19: Schnittstelle Nutzungszeit | I19: eRound | J19: OCPI Buchungskalender | K19: erfasst
B20: ANF-014 | C20: Betreibervertrag | D20: § 38 (1) b | E20: Nutzungszeit & Entgelte | F20: Maximale Nutzungsdauer Übernachtladen ist 12h. | G20: bei CCS-Ladepunkten zum Übernachtladen und MCS- oder CCS-Ladepunkte zum Zwischenladen, die zum Übernachtladen freigegeben wurden, 12 Stunden. | H20: Schnittstelle Nutzungszeit | I20: eRound | J20: OCPI Buchungskalender | K20: erfasst
B21: ANF-015 | C21: Betreibervertrag | D21: § 38 (2) | E21: Nutzungszeit & Entgelte | F21: Bei nidriger Auslastung kann die maximale Nutzungszeit vom AN verlängert werden. Bei nachfolgender Reservierung kann die maximale Nutzungszeit verkürzt werden. Bei Verkürzung zusätzliche Karenzzeit vor Blockadeentgeld von 5min. | G21: Der Auftragnehmer kann die maximalen Nutzungszeiten in Zeiten geringer Auslastung verlängern. Zudem kann er mit der Gestattung der Nutzung von MCS-Ladepunkten und CCS-Ladepunkten zum Zwischenladen dem Endnutzer bzw. Mobilitätsdienstleister auch ausdrücklich eine kürzere maximale Nutzungszeit einräumen, wenn wegen nachfolgender Reservierungen die maximale Nutzungszeit nach Absatz 1 lit. a nicht eingeräumt werden kann. In den Fällen des Satzes 2 ist dem Endnutzer bzw. Mobilitätsdienstleister zusätzlich eine Karenzzeit zum Verlassen des Ladeplatzes von 5 Minuten einzuräumen, nach deren Ablauf erst ein Blockadeentgelt erhoben werden darf | H21: SCS: Reaktionszeit System | I21: eRound | J21: OCPI Buchungskalender | K21: erfasst
B22: ANF-016 | C22: Betreibervertrag | D22: § 38 (3) | E22: Nutzungszeit & Entgelte | F22: Maximale Nutzungszeit endet mit Ablauf Reservierung. Maximale Nutzungsdauer kann vom AN verlängert werden. | G22: Hat ein Mobilitätsdienstleister einen Ladepunkt reserviert, so endet die maximale Nutzungszeit mit dem Ablauf des reservierten Zeitraums, auch wenn der Ladeplatz erst später belegt wurde, es sei denn, der Betreiber räumt ihm eine längere maximale Nutzungszeit ein. | I22: eRound | J22: OCPI Buchungskalender | K22: erfasst
B23: ANF-017 | C23: Betreibervertrag | D23: § 38 (4) | E23: Nutzungszeit & Entgelte | F23: Ladestart 15min Wartezeit Blockadeentgeld ggf. Pönalisierung Entfall maximale Nutzungsdauer | G23: Wird ein Ladevorgang nicht innerhalb von 15 Minuten nach Besetzung des Stellplatzes gestartet, entfällt die maximale Nutzungszeit und es kann ein Blockadeentgelt erhoben werden. | I23: eRound / SCS | J23: OCPI Buchungskalender / Abrechnungskomponente / Belegungsdetektion / Pönalisierungssystem | K23: erfasst
B24: ANF-018 | C24: Betreibervertrag | D24: § 38 (5) | E24: Nutzungszeit & Entgelte | F24: Kein Blockadeentgeld während Nachtruhezeiten, Sonn- und Feiertage der Bundesländer. | G24: An Sonn- und Feiertagen sowie zwischen 22 Uhr abends und 5 Uhr morgens (Nachtruhezeit) darf der Auftragnehmer für CCS-Ladepunkte zum Übernachtladen bzw. MCS- und CCS- Ladepunkten zum Zwischenladen, die zum Übernachtladen freigegeben wurden, keine Blockadeentgelte erheben. Hat der Ladevorgang bereits vor Beginn der Nachtruhezeiten begonnen und endet die maximale Nutzungszeit nach Absatz 1 während der Nachtruhezeit, so werden Blockadeentgelte mithin erst nach Ende der Nachtruhezeit berechnet. Satz 1 und 2 gelten entsprechend für Sonntage und gesetzliche Feiertage in dem Bundesland, in dem der jeweilige Standort gelegen ist. | H24: Einfluss auf Reservierung? | I24: eRound | J24: OCPI Buchungskalender | K24: erfasst
B25: ANF-019 | C25: Betreibervertrag | D25: § 38 (6) | E25: Nutzungszeit & Entgelte | F25: Blockadeentgeld Höhe 0,50€ / 0,15€ pro Min. | G25: Die Höhe des Blockadeentgelts darf bei MCS-Ladepunkten und bei CCS-Ladepunkten zum Zwischenladen maximal 0,50 €/Minute und bei CCS-Ladepunkten bzw. CCS- und MCS- Ladepunkten zum Zwischenladen, während des Zeitraums, für den sie zum Übernachtladen freigegeben wurden, maximal 0,15 €/Minute betragen. Das vereinnahmte Blockadeentgelt steht dem Auftragnehmer zu. | I25: eRound | J25: Abrechnungskomponente | K25: erfasst
B26: ANF-020 | C26: Betreibervertrag | D26: § 38 (7) | E26: Nutzungszeit & Entgelte | F26: Änderungen an maximaler Nutzungsdauer, Blockadeentgelt und Sperrzeiten mit Vorlauf möglich. | G26: Der Auftraggeber 2 kann die maximale Höhe der Blockadeentgelte nach Absatz 6 und die maximalen Nutzungszeiten bzw. Sperrzeiten für die Erhebung eines Blockadeentgeltes nach den Absätzen 1 bis 4 während der Laufzeit des Vertrags mit einer Frist von vier Monaten auf den Beginn eines Quartals schriftlich mit Wirkung gegenüber dem Auftragnehmer anpassen. Absenkungen der Höhe oder Verlängerungen die maximalen Nutzungszeiten bzw. Sperrzeiten sind nur mit Zustimmung des Auftragnehmers zulässig. Die Zustimmung gilt als erteilt, sofern der Auftragnehmer dem Auftraggeber 2 nicht innerhalb von zwei Wochen nach Mitteilung der geplanten Absenkung in Textform widerspricht. | I26: eRound | J26: Abrechnungskomponente | K26: erfasst
B27: ANF-021 | C27: Betreibervertrag | D27: § 38 (8) | E27: Nutzungszeit & Entgelte | F27: Mindestabnahmemenge und Vergütung bei Unterschreitung. | G27: Für jeden Übernachtladevorgang ist eine Mindestabnahmemenge von 150 kWh vorzusehen, dies gilt auch für MCS- und CCS-Ladepunkte, die nach Maßgabe dieses Vertrags zum Übernachtladen freigegeben werden. Wird die Mindestabnahmemenge nicht erreicht, so ist für die Differenz zwischen der tatsächlich abgenommenen Strommenge und der vertraglich vorgesehenen Mindestabnahmemenge vom Endnutzer bzw. Mobilitätsdienstleister eine Entschädigung in Höhe von 30 ct/kWh an den Auftragnehmer zu leisten. Die Entschädigungshöhe kann vom Auftraggeber 2 in Absprache mit dem Auftragnehmer zu einem späteren Zeitpunkt angepasst werden. | I27: eRound | J27: Abrechnungskomponente | K27: erfasst
B28: ANF-022 | C28: Betreibervertrag | D28: § 38 (9) | E28: Nutzungszeit & Entgelte | F28: Warnung NutzerIn vor Blockadeentgeld | G28: Endnutzer sind über eine gut sichtbare Beschilderung darauf hinzuweisen, dass der Stellplatz nach Abschluss des Ladevorgangs unverzüglich freizugeben ist; der Text der Beschilderung bedarf der Zustimmung des Auftraggebers 2. Zusätzlich soll der Endnutzer über eine App oder – falls er eine solche nicht nutzt – an der Ladeeinrichtung, vor Erhebung von Blockadeentgelt oder einer Vertragsstrafe einen Hinweis erhalten, dass der Ladevorgang beendet wurde und der Ladeplatz unverzüglich zu räumen ist | H28: ggf. Mitteilung? | I28: eRound | J28: Abrechnungskomponente / Beschilderung | K28: trifft nicht zu | L28: 46259 | M28: ggf. Thema für eRound ansonsten Beschilderung -> Bau GU
B29: ANF-023 | C29: Betreibervertrag | D29: § 42 (5) | E29: Betrieb & Auslastung | F29: Updates verpflichtend. | G29: Der Auftragnehmer ist auf Aufforderung des Auftraggebers 2 verpflichtet, die Ladeeinrichtungen technisch und/oder mit Blick auf die Software (insbesondere Schnittstellen und Protokolle) weiterzuentwickeln und zu verbessern. Die Erstattung der tatsächlich erforderlichen Kosten (zuzüglich angemessener Zuschläge für allgemeine Geschäftskosten, Wagnis und Gewinn) erfolgt nach den Regelungen über geänderte oder zusätzliche Leistungen nach § 40. | I29: Alpitronic | J29: Ladeeinrichtung | K29: trifft nicht zu | L29: 46260 | M29: Betrifft LIS
B30: ANF-024 | C30: Betreibervertrag | D30: § 22 (3) | E30: Betrieb & Auslastung | F30: Bei nidriger Auslastung: Zwischenladepunkte können zwischen 17 und 6 Uhr für Übernachtladen freigegeben werden. Aber mind. 40% Zwischenladepunkte, aber mind. 2 MCS und 1 CCS. | G30: CCS- und MCS-Ladepunkte zum Zwischenladen sind bei fehlender Auslastung ab 17:00 Uhr sowie an Wochenenden zum Übernachtladen freizugegeben. Es müssen jedoch auch in dieser Zeit 40 %, aber mindestens zwei MCS-Ladepunkte bzw. ein CCS-Ladepunkt, zum Zwischenladen für das Zwischenladen freigehalten werden. An Standorten, an denen nur ein MCS-Ladepunkt vorhanden ist, ist dieser für das Zwischenladen freizuhalten. Der Auftragnehmer hat sicherzustellen, dass die MCS- und CCS-Ladepunkte zum Zwischenladen ab 06:00 Uhr wieder für das Zwischenladen bereitstehen. Auftragnehmer und Auftraggeber 2 können sich je nach Auslastung der Ladepunkte auf abweichende Vorgaben zur Freigabe von Ladepunkten zum Zwischenladen einigen. | H30: 40% Zwischenladen | I30: eRound / SCS | J30: OCPI Buchungskalender / Dynamische Anzeige | K30: erfüllt | L30: 46259 | M30: eRound regelt - SCS zeigt an
B31: ANF-025 | C31: Betreibervertrag | D31: § 4 (52) | E31: Reservierung | F31: Mindestens AN plus ein weiterer. | G31: "Reservierungssystem“: Ein System zur Reservierung von Ladepunkten, das Mobilitätsdienstleistern ermöglicht, Ladepunkte bei dem Auftragnehmer und mindestens einem weiteren Ladepunktbetreiber zu reservieren. | H31: Mehr als 1 Anbieter | I31: Autostrom+ | J31: Anbindung | K31: bewertet
B32: ANF-026 | C32: Vertragsanlage 4 | D32: § 3.13.2 | E32: Zufahrt & Schranke | F32: Schrankenanlage auf Schrankeninsel | G32: Anforderungen an Lade-, Schrankeninseln und physische Zufahrtbeschränkungen | I32: Schrankenhersteller | J32: Schrankenanlage | K32: erfasst | L32: 46259 | M32: Schranke auf Schrankeninsel geplant
B33: ANF-027 | C33: Vertragsanlage 4 | D33: § 3.13.2 (1) | E33: Zufahrt & Schranke | F33: Schranke an Einfahrt Ladepunkt und Ausfahrt Ladepunkt. Bei Schrägparken Poller? | G33: Für den Zweck einer geordneten Zufahrt und Abfahrt sowie zur Sicherstellung der Verfügbarkeit der Ladeinfrastruktur sind Ladeinseln, Schrankeninseln sowie physische Zufahrtsbeschränkungen zu errichten. Diese dienen der Vermeidung unbefugter Inanspruchnahmen der Ladeplätze durch nichtladende Fahrzeuge aus allen Fahrtrichtungen und gewährleisten den bestimmungsgemäßen Betrieb der Ladeinfrastruktur. | H33: Schranke gefordert aus allen Richtungen | I33: Schrankenhersteller | J33: Schrankenanlage | K33: erfüllt | L33: 46259 | M33: Schranken auf beiden Seiten gepplant
B34: ANF-028 | C34: Vertragsanlage 4 | D34: § 3.13.4 | E34: Anzeige & Beschilderung | F34: Darstellung statischer und dynamischer Infos. | G34: Jeder Ladeplatz ist mit einer Kennzeichnung bzw. Anzeige mit folgenden Informationen auszurüsten: - Ladeplatznummer (Schild mit schwarzer Nummer auf weißem retroreflektierendem Hintergrund mit der Reflektionsklasse RA1 A) - Dynamische Anzeige mit - Typ des Ladeplatzes (MCS, CCS-Zwischenladen, CCS-Übernachtladen) - Leistung der Ladesäule - Status (verfügbar, reserviert ab XX:XX Uhr, belegt, außer Betrieb) - optional: Kennzeichen/Reservierungsnummer - Der Status des Ladeplatzes ist zusätzlich zur dynamischen Anzeige über eine farbcodierte Statuskennzeichnung darzustellen (Grün = verfügbar, Gelb = reserviert, Rot = belegt / außer Betrieb). Die farbcodierte Kennzeichnung dient der optischen Erkennbarkeit des Betriebszustands, insbesondere bei Ausfall der digitalen Anzeige. Die Platzierung der Kennzeichnung und Anzeigen hat bei Parkständen in Schrägaufstellung gut sichtbar auf der Schrankeninsel zu erfolgen. Die Platzierung der Kennzeichnung und Anzeigen hat bei Parkständen in Längsaufstellung gut sichtbar, dem entsprechenden Ladeplatz zugehörig im Bereich der Ladeinsel bzw. Ladesäule zu erfolgen. Weitere Anforderungen im Zusammenhang mit dynamischen Anzeigen sind der Vertragsanlage 6: Anforderungen an die Ladeinfrastruktur zu entnehmen. | H34: LED Anzeigen | I34: eRound / SCS | J34: Dynamische Anzeige | K34: erfüllt | L34: 46259 | M34: LIS zeigt Zustand an, Rest auf Anzeige
B35: ANF-029 | C35: Vertragsanlage 4 | D35: § 3.13.5 | E35: Zufahrt & Schranke | G35: Zur Gewährleistung eines sicheren und zuverlässigen Betriebs sind Schrankenanlagen und automatische Poller gemäß den folgenden technischen Anforderungen auszuführen: - robuste Witterungsbeständige und korrosionsgeschützte Ausführung für den ganzjährigen Einsatz im Außenbereich - automatisches Öffnen nach Abschluss des Ladevorgangs oder bei entsprechender Systemfreigabe - Erkennung der Fahrzeugposition sowie von Hindernissen vor dem Schließvorgang zur Vermeidung von Kollisionen - manuelle Notentriegelung durch autorisiertes Personal, um die Betriebsfähigkeit auch im Stör- oder Spannungsfall sicherzustellen - Integration in das zentrale Steuerungssystem (Backend oder lokales Steuergerät) zur Überwachung, Steuerung und Protokollierung der Schranken- und Pollerfunktionen - Schrankenbäume sind gemäß geltender Vorschriften mit rot-weißer Schraffierung zu kennzeichnen - Ausstattung von Schrankenbäumen und automatischen Pollern mit integrierter Beleuchtung zur Verbesserung der Sichtbarkeit und Betriebssicherheit; dabei sind die Vorgaben zur Blendwirkung gemäß ERS zu beachten Weitere Anforderungen für den Betrieb der Schranken sind der Vertragsanlage 6: Anforderungen an die Ladeinfrastruktur zu entnehmen. | H35: Öffnen bei Ladevorgangs-Ende wiederspricht sich mit Vertragsanlage 6 §10 Abs 2 Und funktioniert für Poller nicht -> da LKW darüber steht. Einheitliche Ansteuerung reduziert komplexität Bei Partnern | I35: Schrankenhersteller / SCS / eRound | J35: Schrankenanlage | K35: erfüllt | L35: 46260 | M35: Sicherheitseinrichtung geplant LED in Schrankenbaum geplant Integration des Schrankenstatus in eRound
B36: ANF-030 | C36: Vertragsanlage 4 | D36: § 3.13.2.2 | E36: Zufahrt & Schranke | G36: Bei Parkständen in Längsaufstellung sind automatisch versenkbare Poller zur Zufahrtsbeschränkung vorzusehen. Pro Parkstand sind drei Poller so anzuordnen, dass Fehlbelegungen ausgeschlossen sind. Die Abstände der Poller untereinander sowie zur Fahrgasse ergeben sich aus der Referenzplanung (Anhang 1a: Referenzplanung Längs- und Schrägparken). Das Ein- und Ausfahren zum Ladeplatz muss jederzeit gewährleistet bleiben, auch wenn die benachbarten Stellplätze durch ausgefahrene Poller gesichert sind. Die Dauer der Öffnungs- und Schließvorgänge ist auf das technisch mögliche Minimum zu begrenzen, um einen unterbrechungsarmen Verkehrsfluss sicherzustellen. Die Regelbreite der Parkstände muss 4,50 m betragen, die Länge entspricht den Vorgaben gemäß ERS für Längsparker von 25,00 m. Ergeben sich aufgrund der örtlichen Bestandsituation Abweichungen von der Regelbreite, ist die Befahrbarkeit stets durch einen Schleppkurvennachweis zu belegen. Die Poller sind elektrisch oder hydraulisch versenkbar auszuführen und müssen über eine automatische Höhenverstellung verfügen. Das Absenken erfolgt im Regelbetrieb ausschließlich bei autorisiertem Zugang (Ladevorgang oder Reservierung). Nach Beendigung des Ladevorgangs und nach erfolgter Ausfahrt des Fahrzeuges müssen sich Poller automatisch wieder heben. Eine Notabsenkung bei Ausfall muss durch autorisiertes Personal jederzeit möglich sein. Die Poller müssen widerstandsfähig gegen Anprall und sonstige auf Rastplätzen zu erwartende Einwirkungen sein sowie frost- und salzbeständig ausgeführt werden. Zudem ist ein Schutz gegen Fremdsteuerung und Manipulation sicherzustellen. Die Steuerung der Poller muss in das übergeordnete Zugangskontrollsystem integrierbar sein. Die Erkennbarkeit des Hindernissesist stets sicherzustellen. Die Poller sind zu beleuchten. Die Ladesäule ist im Randbereich des Stellplatzes in einem praktikablen Abstand zum fahrzeugseitigen Ladeanschluss zu positionieren. Die Fläche um die Ladesäule ist in Betonbauweise auszuführen und mit zweckdienlichen Mitteln gegen Anprall und sonstige übliche Einwirkungen auf Rastplätzen zu sichern. Befindet sich im Randbereich bereits eine Bordanlage, ist eine zusätzliche Hochbordabsicherung der Ladesäule nicht erforderlich. In allen übrigen Fällen ist, neben einem Anprallschutz, eine ausreichend dimensionierte Ladeinsel zum Schutz der Ladeinfrastruktur vorzusehen. | H36: Längsparken | I36: Autostrom+ | J36: – | K36: trifft nicht zu | L36: 45894 | M36: Los 2 hat keine Poller - betrifft nur längsparkplätze
B37: ANF-031 | C37: Vertragsanlage 4 | D37: § 3.6 | E37: Bau & Dokumentation | G37: Antrag auf Baufreigabe und Ausführungs-, Werk- und Montageplanung | H37: Mitwirkung an Planung und Freigabe | I37: Autostrom+ | J37: – | K37: bewertet
B38: ANF-032 | C38: Vertragsanlage 4 | D38: § 3.7 | E38: Bau & Dokumentation | G38: Bestandsunterlagen (As-Built) | H38: Verantwortlich für Dokumentation und Erstellung Unterlagen | I38: Autostrom+ | J38: – | K38: bewertet
B39: ANF-033 | C39: Vertragsanlage 6 | D39: § 8 | E39: Authentifizierung & Zugang | F39: Öffnung innerhalb von 45 Sekunden. | G39: Folgende Authentifizierungsoptionen (Anmeldung, Freischaltung der physischen Zufahrtsbeschränkungen und Start des Ladevorgangs etc.) müssen möglich sein: ▪ RFID-Token (Ladekarte etc.) von vertraglich angebundenen Mobilitätsdienstleister, ▪ App von vertraglich angebundenen Mobilitätsdienstleister, ▪ Ad hoc-Laden ohne Registrierung und ▪ ISO 15118 (nach Verfügbarkeit – s. o. Abschnitt 7.). Der Authentifizierungsvorgang zur Freigabe des Ladeplatzes muss innerhalb von maximal 45 Sekunden abgeschlossen sein und sollte so gestaltet sein, dass der Verkehrsfluss möglichst wenig beeinträchtigt wird. Die angegebene Zeitspanne umfasst alle praktische und technische Schritte der Authentifizierung bis zur Öffnung der Schranke bzw. des Pollers und gilt für alle vorgesehenen Zugangsarten | H39: 45 Sekunden (!) Wie (wer) Erfüllt das? Bieterfrage 441 nach Bezahlterminal ? | I39: eRound / SCS | J39: Authentifizierungskomponente / Schrankensteuerung | K39: erfasst
B40: ANF-034 | C40: Vertragsanlage 6 | D40: § 9 (1) | E40: Belegungsdetektion | F40: Belegungsdetektion ist gefordert. | G40: Jeder MCS- / CCS-Ladepunkt muss über eine Detektion verfügen. Die MCS- / CCSLadeplatzdetektion ist so auszustatten, dass Objekte auf dem zum MCS- / CCSLadepunkt gehörigen MCS- / CCS-Ladeplatz detektiert werden können. | H40: Deckensensoren Pönalisierung / Falschparker | I40: Schrankenhersteller / SCS | J40: Belegungsdetektion | K40: erfüllt | L40: 46259 | M40: Radarsensor stellt Belegung der Ladesäule bereit
B41: ANF-035 | C41: Vertragsanlage 6 | D41: § 9 (2) | E41: Belegungsdetektion | F41: Roaming-Infos müssen veröffentlicht werden Pönalisierung gefordert. Entfernung Falschparker gefordert. | G41: Die Information der Reservierung des MCS- / CCS-Ladepunkts muss dem IT-Backend der MCS- / CCS-Ladeeinrichtung zur Verfügung stehen und muss angebundenen Mobilitätsdienstleistern und Betreibern von Online-Plattformen zur Darstellung von Statusinformationen zur Verfügung gestellt werden. Zudem soll dem Betreiber die Pönalisierung und Entfernung von Falschparkern ermöglicht werden. | H41: Pönalisierung / Falschparker | I41: eRound / SCS | J41: OCPI Buchungskalender / Kennzeichenerfassung / Pönalisierungssystem | K41: erfasst
...

Sheet Auswertung
A1: Auswertung – Anforderungen
A2: Automatische Auswertung des Statusprozesses erfasst → bewertet → erfüllt bzw. trifft nicht zu – inklusive Bieterfragenkatalog.
A3: Erfüllungsgrad = erfüllte Anforderungen / anwendbare Anforderungen (Status „trifft nicht zu“ wird aus dem Nenner ausgeschlossen).
A5: 1 Nach Themenfeld
A6: Merkmal | B6: Gesamt | C6: Erfasst | D6: Bewertet | E6: Erfüllt | F6: Trifft nicht zu | G6: Erfüllungsgrad
A7: Anzeige & Beschilderung | B7: =COUNTIF(Anforderungen!$E$7:$E$2000,$A7) -> 14 | C7: =COUNTIFS(Anforderungen!$E$7:$E$2000,$A7,Anforderungen!$K$7:$K$2000,"erfasst") -> 12 | D7: =COUNTIFS(Anforderungen!$E$7:$E$2000,$A7,Anforderungen!$K$7:$K$2000,"bewertet") -> 0 | E7: =COUNTIFS(Anforderungen!$E$7:$E$2000,$A7,Anforderungen!$K$7:$K$2000,"erfüllt") -> 2 | F7: =COUNTIFS(Anforderungen!$E$7:$E$2000,$A7,Anforderungen!$K$7:$K$2000,"trifft nicht zu") -> 0 | G7: =IFERROR(E7/(B7-F7),0) -> 0.14285714
A8: Authentifizierung & Zugang | B8: =COUNTIF(Anforderungen!$E$7:$E$2000,$A8) -> 51 | C8: =COUNTIFS(Anforderungen!$E$7:$E$2000,$A8,Anforderungen!$K$7:$K$2000,"erfasst") -> 51 | D8: =COUNTIFS(Anforderungen!$E$7:$E$2000,$A8,Anforderungen!$K$7:$K$2000,"bewertet") -> 0 | E8: =COUNTIFS(Anforderungen!$E$7:$E$2000,$A8,Anforderungen!$K$7:$K$2000,"erfüllt") -> 0 | F8: =COUNTIFS(Anforderungen!$E$7:$E$2000,$A8,Anforderungen!$K$7:$K$2000,"trifft nicht zu") -> 0 | G8: =IFERROR(E8/(B8-F8),0) -> 0
A9: Bau & Dokumentation | B9: =COUNTIF(Anforderungen!$E$7:$E$2000,$A9) -> 98 | C9: =COUNTIFS(Anforderungen!$E$7:$E$2000,$A9,Anforderungen!$K$7:$K$2000,"erfasst") -> 96 | D9: =COUNTIFS(Anforderungen!$E$7:$E$2000,$A9,Anforderungen!$K$7:$K$2000,"bewertet") -> 2 | E9: =COUNTIFS(Anforderungen!$E$7:$E$2000,$A9,Anforderungen!$K$7:$K$2000,"erfüllt") -> 0 | F9: =COUNTIFS(Anforderungen!$E$7:$E$2000,$A9,Anforderungen!$K$7:$K$2000,"trifft nicht zu") -> 0 | G9: =IFERROR(E9/(B9-F9),0) -> 0
A10: Belegungsdetektion | B10: =COUNTIF(Anforderungen!$E$7:$E$2000,$A10) -> 4 | C10: =COUNTIFS(Anforderungen!$E$7:$E$2000,$A10,Anforderungen!$K$7:$K$2000,"erfasst") -> 3 | D10: =COUNTIFS(Anforderungen!$E$7:$E$2000,$A10,Anforderungen!$K$7:$K$2000,"bewertet") -> 0 | E10: =COUNTIFS(Anforderungen!$E$7:$E$2000,$A10,Anforderungen!$K$7:$K$2000,"erfüllt") -> 1 | F10: =COUNTIFS(Anforderungen!$E$7:$E$2000,$A10,Anforderungen!$K$7:$K$2000,"trifft nicht zu") -> 0 | G10: =IFERROR(E10/(B10-F10),0) -> 0.25
A11: Betrieb & Auslastung | B11: =COUNTIF(Anforderungen!$E$7:$E$2000,$A11) -> 76 | C11: =COUNTIFS(Anforderungen!$E$7:$E$2000,$A11,Anforderungen!$K$7:$K$2000,"erfasst") -> 74 | D11: =COUNTIFS(Anforderungen!$E$7:$E$2000,$A11,Anforderungen!$K$7:$K$2000,"bewertet") -> 0 | E11: =COUNTIFS(Anforderungen!$E$7:$E$2000,$A11,Anforderungen!$K$7:$K$2000,"erfüllt") -> 1 | F11: =COUNTIFS(Anforderungen!$E$7:$E$2000,$A11,Anforderungen!$K$7:$K$2000,"trifft nicht zu") -> 1 | G11: =IFERROR(E11/(B11-F11),0) -> 0.013333333
A12: Flächen & Genehmigungen | B12: =COUNTIF(Anforderungen!$E$7:$E$2000,$A12) -> 94 | C12: =COUNTIFS(Anforderungen!$E$7:$E$2000,$A12,Anforderungen!$K$7:$K$2000,"erfasst") -> 94 | D12: =COUNTIFS(Anforderungen!$E$7:$E$2000,$A12,Anforderungen!$K$7:$K$2000,"bewertet") -> 0 | E12: =COUNTIFS(Anforderungen!$E$7:$E$2000,$A12,Anforderungen!$K$7:$K$2000,"erfüllt") -> 0 | F12: =COUNTIFS(Anforderungen!$E$7:$E$2000,$A12,Anforderungen!$K$7:$K$2000,"trifft nicht zu") -> 0 | G12: =IFERROR(E12/(B12-F12),0) -> 0
A13: Monitoring & Reporting | B13: =COUNTIF(Anforderungen!$E$7:$E$2000,$A13) -> 34 | C13: =COUNTIFS(Anforderungen!$E$7:$E$2000,$A13,Anforderungen!$K$7:$K$2000,"erfasst") -> 34 | D13: =COUNTIFS(Anforderungen!$E$7:$E$2000,$A13,Anforderungen!$K$7:$K$2000,"bewertet") -> 0 | E13: =COUNTIFS(Anforderungen!$E$7:$E$2000,$A13,Anforderungen!$K$7:$K$2000,"erfüllt") -> 0 | F13: =COUNTIFS(Anforderungen!$E$7:$E$2000,$A13,Anforderungen!$K$7:$K$2000,"trifft nicht zu") -> 0 | G13: =IFERROR(E13/(B13-F13),0) -> 0
A14: Netzanschluss & Energie | B14: =COUNTIF(Anforderungen!$E$7:$E$2000,$A14) -> 228 | C14: =COUNTIFS(Anforderungen!$E$7:$E$2000,$A14,Anforderungen!$K$7:$K$2000,"erfasst") -> 227 | D14: =COUNTIFS(Anforderungen!$E$7:$E$2000,$A14,Anforderungen!$K$7:$K$2000,"bewertet") -> 0 | E14: =COUNTIFS(Anforderungen!$E$7:$E$2000,$A14,Anforderungen!$K$7:$K$2000,"erfüllt") -> 0 | F14: =COUNTIFS(Anforderungen!$E$7:$E$2000,$A14,Anforderungen!$K$7:$K$2000,"trifft nicht zu") -> 1 | G14: =IFERROR(E14/(B14-F14),0) -> 0
A15: Nutzungszeit & Entgelte | B15: =COUNTIF(Anforderungen!$E$7:$E$2000,$A15) -> 44 | C15: =COUNTIFS(Anforderungen!$E$7:$E$2000,$A15,Anforderungen!$K$7:$K$2000,"erfasst") -> 43 | D15: =COUNTIFS(Anforderungen!$E$7:$E$2000,$A15,Anforderungen!$K$7:$K$2000,"bewertet") -> 0 | E15: =COUNTIFS(Anforderungen!$E$7:$E$2000,$A15,Anforderungen!$K$7:$K$2000,"erfüllt") -> 0 | F15: =COUNTIFS(Anforderungen!$E$7:$E$2000,$A15,Anforderungen!$K$7:$K$2000,"trifft nicht zu") -> 1 | G15: =IFERROR(E15/(B15-F15),0) -> 0
A16: Reservierung | B16: =COUNTIF(Anforderungen!$E$7:$E$2000,$A16) -> 74 | C16: =COUNTIFS(Anforderungen!$E$7:$E$2000,$A16,Anforderungen!$K$7:$K$2000,"erfasst") -> 73 | D16: =COUNTIFS(Anforderungen!$E$7:$E$2000,$A16,Anforderungen!$K$7:$K$2000,"bewertet") -> 1 | E16: =COUNTIFS(Anforderungen!$E$7:$E$2000,$A16,Anforderungen!$K$7:$K$2000,"erfüllt") -> 0 | F16: =COUNTIFS(Anforderungen!$E$7:$E$2000,$A16,Anforderungen!$K$7:$K$2000,"trifft nicht zu") -> 0 | G16: =IFERROR(E16/(B16-F16),0) -> 0
A17: Sonstiges / Zuordnung prüfen | B17: =COUNTIF(Anforderungen!$E$7:$E$2000,$A17) -> 98 | C17: =COUNTIFS(Anforderungen!$E$7:$E$2000,$A17,Anforderungen!$K$7:$K$2000,"erfasst") -> 98 | D17: =COUNTIFS(Anforderungen!$E$7:$E$2000,$A17,Anforderungen!$K$7:$K$2000,"bewertet") -> 0 | E17: =COUNTIFS(Anforderungen!$E$7:$E$2000,$A17,Anforderungen!$K$7:$K$2000,"erfüllt") -> 0 | F17: =COUNTIFS(Anforderungen!$E$7:$E$2000,$A17,Anforderungen!$K$7:$K$2000,"trifft nicht zu") -> 0 | G17: =IFERROR(E17/(B17-F17),0) -> 0
A18: Technik Ladeinfrastruktur | B18: =COUNTIF(Anforderungen!$E$7:$E$2000,$A18) -> 153 | C18: =COUNTIFS(Anforderungen!$E$7:$E$2000,$A18,Anforderungen!$K$7:$K$2000,"erfasst") -> 153 | D18: =COUNTIFS(Anforderungen!$E$7:$E$2000,$A18,Anforderungen!$K$7:$K$2000,"bewertet") -> 0 | E18: =COUNTIFS(Anforderungen!$E$7:$E$2000,$A18,Anforderungen!$K$7:$K$2000,"erfüllt") -> 0 | F18: =COUNTIFS(Anforderungen!$E$7:$E$2000,$A18,Anforderungen!$K$7:$K$2000,"trifft nicht zu") -> 0 | G18: =IFERROR(E18/(B18-F18),0) -> 0
... A21: Zufahrt & Schranke | B21: =COUNTIF(Anforderungen!$E$7:$E$2000,$A21) -> 30 | C21: =COUNTIFS(Anforderungen!$E$7:$E$2000,$A21,Anforderungen!$K$7:$K$2000,"erfasst") -> 23 | D21: =COUNTIFS(Anforderungen!$E$7:$E$2000,$A21,Anforderungen!$K$7:$K$2000,"bewertet") -> 0 | E21: =COUNTIFS(Anforderungen!$E$7:$E$2000,$A21,Anforderungen!$K$7:$K$2000,"erfüllt") -> 6 | F21: =COUNTIFS(Anforderungen!$E$7:$E$2000,$A21,Anforderungen!$K$7:$K$2000,"trifft nicht zu") -> 1 | G21: =IFERROR(E21/(B21-F21),0) -> 0.20689655
A24: 2 Nach Partner
A25: Merkmal | B25: Gesamt | C25: Erfasst | D25: Bewertet | E25: Erfüllt | F25: Trifft nicht zu | G25: Erfüllungsgrad
A26: Aplitronic | B26: =SUMPRODUCT(ISNUMBER(SEARCH($A26,Anforderungen!$I$7:$I$2000))*(Anforderungen!$B$7:$B$2000<>"")) -> 104 | C26: =SUMPRODUCT(ISNUMBER(SEARCH($A26,Anforderungen!$I$7:$I$2000))*(Anforderungen!$K$7:$K$2000="erfasst")) -> 104 | D26: =SUMPRODUCT(ISNUMBER(SEARCH($A26,Anforderungen!$I$7:$I$2000))*(Anforderungen!$K$7:$K$2000="bewertet")) -> 0 | E26: =SUMPRODUCT(ISNUMBER(SEARCH($A26,Anforderungen!$I$7:$I$2000))*(Anforderungen!$K$7:$K$2000="erfüllt")) -> 0 | F26: =SUMPRODUCT(ISNUMBER(SEARCH($A26,Anforderungen!$I$7:$I$2000))*(Anforderungen!$K$7:$K$2000="trifft nicht zu")) -> 0 | G26: =IFERROR(E26/(B26-F26),0) -> 0
A27: eRound | B27: =SUMPRODUCT(ISNUMBER(SEARCH($A27,Anforderungen!$I$7:$I$2000))*(Anforderungen!$B$7:$B$2000<>"")) -> 225 | C27: =SUMPRODUCT(ISNUMBER(SEARCH($A27,Anforderungen!$I$7:$I$2000))*(Anforderungen!$K$7:$K$2000="erfasst")) -> 219 | D27: =SUMPRODUCT(ISNUMBER(SEARCH($A27,Anforderungen!$I$7:$I$2000))*(Anforderungen!$K$7:$K$2000="bewertet")) -> 0 | E27: =SUMPRODUCT(ISNUMBER(SEARCH($A27,Anforderungen!$I$7:$I$2000))*(Anforderungen!$K$7:$K$2000="erfüllt")) -> 5 | F27: =SUMPRODUCT(ISNUMBER(SEARCH($A27,Anforderungen!$I$7:$I$2000))*(Anforderungen!$K$7:$K$2000="trifft nicht zu")) -> 1 | G27: =IFERROR(E27/(B27-F27),0) -> 0.022321429
A28: SCS | B28: =SUMPRODUCT(ISNUMBER(SEARCH($A28,Anforderungen!$I$7:$I$2000))*(Anforderungen!$B$7:$B$2000<>"")) -> 76 | C28: =SUMPRODUCT(ISNUMBER(SEARCH($A28,Anforderungen!$I$7:$I$2000))*(Anforderungen!$K$7:$K$2000="erfasst")) -> 70 | D28: =SUMPRODUCT(ISNUMBER(SEARCH($A28,Anforderungen!$I$7:$I$2000))*(Anforderungen!$K$7:$K$2000="bewertet")) -> 0 | E28: =SUMPRODUCT(ISNUMBER(SEARCH($A28,Anforderungen!$I$7:$I$2000))*(Anforderungen!$K$7:$K$2000="erfüllt")) -> 6 | F28: =SUMPRODUCT(ISNUMBER(SEARCH($A28,Anforderungen!$I$7:$I$2000))*(Anforderungen!$K$7:$K$2000="trifft nicht zu")) -> 0 | G28: =IFERROR(E28/(B28-F28),0) -> 0.078947368
A29: Reservierungsplattform | B29: =SUMPRODUCT(ISNUMBER(SEARCH($A29,Anforderungen!$I$7:$I$2000))*(Anforderungen!$B$7:$B$2000<>"")) -> 13 | C29: =SUMPRODUCT(ISNUMBER(SEARCH($A29,Anforderungen!$I$7:$I$2000))*(Anforderungen!$K$7:$K$2000="erfasst")) -> 13 | D29: =SUMPRODUCT(ISNUMBER(SEARCH($A29,Anforderungen!$I$7:$I$2000))*(Anforderungen!$K$7:$K$2000="bewertet")) -> 0 | E29: =SUMPRODUCT(ISNUMBER(SEARCH($A29,Anforderungen!$I$7:$I$2000))*(Anforderungen!$K$7:$K$2000="erfüllt")) -> 0 | F29: =SUMPRODUCT(ISNUMBER(SEARCH($A29,Anforderungen!$I$7:$I$2000))*(Anforderungen!$K$7:$K$2000="trifft nicht zu")) -> 0 | G29: =IFERROR(E29/(B29-F29),0) -> 0
A30: tbd | B30: =SUMPRODUCT(ISNUMBER(SEARCH($A30,Anforderungen!$I$7:$I$2000))*(Anforderungen!$B$7:$B$2000<>"")) -> 29 | C30: =SUMPRODUCT(ISNUMBER(SEARCH($A30,Anforderungen!$I$7:$I$2000))*(Anforderungen!$K$7:$K$2000="erfasst")) -> 29 | D30: =SUMPRODUCT(ISNUMBER(SEARCH($A30,Anforderungen!$I$7:$I$2000))*(Anforderungen!$K$7:$K$2000="bewertet")) -> 0 | E30: =SUMPRODUCT(ISNUMBER(SEARCH($A30,Anforderungen!$I$7:$I$2000))*(Anforderungen!$K$7:$K$2000="erfüllt")) -> 0 | F30: =SUMPRODUCT(ISNUMBER(SEARCH($A30,Anforderungen!$I$7:$I$2000))*(Anforderungen!$K$7:$K$2000="trifft nicht zu")) -> 0 | G30: =IFERROR(E30/(B30-F30),0) -> 0
A31: offen | B31: =SUMPRODUCT(ISNUMBER(SEARCH($A31,Anforderungen!$I$7:$I$2000))*(Anforderungen!$B$7:$B$2000<>"")) -> 731 | C31: =SUMPRODUCT(ISNUMBER(SEARCH($A31,Anforderungen!$I$7:$I$2000))*(Anforderungen!$K$7:$K$2000="erfasst")) -> 730 | D31: =SUMPRODUCT(ISNUMBER(SEARCH($A31,Anforderungen!$I$7:$I$2000))*(Anforderungen!$K$7:$K$2000="bewertet")) -> 0 | E31: =SUMPRODUCT(ISNUMBER(SEARCH($A31,Anforderungen!$I$7:$I$2000))*(Anforderungen!$K$7:$K$2000="erfüllt")) -> 0 | F31: =SUMPRODUCT(ISNUMBER(SEARCH($A31,Anforderungen!$I$7:$I$2000))*(Anforderungen!$K$7:$K$2000="trifft nicht zu")) -> 1 | G31: =IFERROR(E31/(B31-F31),0) -> 0
A32: Zuordnung prüfen | B32: =SUMPRODUCT(ISNUMBER(SEARCH($A32,Anforderungen!$I$7:$I$2000))*(Anforderungen!$B$7:$B$2000<>"")) -> 230 | C32: =SUMPRODUCT(ISNUMBER(SEARCH($A32,Anforderungen!$I$7:$I$2000))*(Anforderungen!$K$7:$K$2000="erfasst")) -> 230 | D32: =SUMPRODUCT(ISNUMBER(SEARCH($A32,Anforderungen!$I$7:$I$2000))*(Anforderungen!$K$7:$K$2000="bewertet")) -> 0 | E32: =SUMPRODUCT(ISNUMBER(SEARCH($A32,Anforderungen!$I$7:$I$2000))*(Anforderungen!$K$7:$K$2000="erfüllt")) -> 0 | F32: =SUMPRODUCT(ISNUMBER(SEARCH($A32,Anforderungen!$I$7:$I$2000))*(Anforderungen!$K$7:$K$2000="trifft nicht zu")) -> 0 | G32: =IFERROR(E32/(B32-F32),0) -> 0
A35: 3 Nach Komponente
A36: Merkmal | B36: Gesamt | C36: Erfasst | D36: Bewertet | E36: Erfüllt | F36: Trifft nicht zu | G36: Erfüllungsgrad
A37: Ladeeinrichtung | B37: =SUMPRODUCT(ISNUMBER(SEARCH($A37,Anforderungen!$J$7:$J$2000))*(Anforderungen!$B$7:$B$2000<>"")) -> 171 | C37: =SUMPRODUCT(ISNUMBER(SEARCH($A37,Anforderungen!$J$7:$J$2000))*(Anforderungen!$K$7:$K$2000="erfasst")) -> 170 | D37: =SUMPRODUCT(ISNUMBER(SEARCH($A37,Anforderungen!$J$7:$J$2000))*(Anforderungen!$K$7:$K$2000="bewertet")) -> 0 | E37: =SUMPRODUCT(ISNUMBER(SEARCH($A37,Anforderungen!$J$7:$J$2000))*(Anforderungen!$K$7:$K$2000="erfüllt")) -> 0 | F37: =SUMPRODUCT(ISNUMBER(SEARCH($A37,Anforderungen!$J$7:$J$2000))*(Anforderungen!$K$7:$K$2000="trifft nicht zu")) -> 1 | G37: =IFERROR(E37/(B37-F37),0) -> 0
A38: Abrechnungskomponente | B38: =SUMPRODUCT(ISNUMBER(SEARCH($A38,Anforderungen!$J$7:$J$2000))*(Anforderungen!$B$7:$B$2000<>"")) -> 50 | C38: =SUMPRODUCT(ISNUMBER(SEARCH($A38,Anforderungen!$J$7:$J$2000))*(Anforderungen!$K$7:$K$2000="erfasst")) -> 49 | D38: =SUMPRODUCT(ISNUMBER(SEARCH($A38,Anforderungen!$J$7:$J$2000))*(Anforderungen!$K$7:$K$2000="bewertet")) -> 0 | E38: =SUMPRODUCT(ISNUMBER(SEARCH($A38,Anforderungen!$J$7:$J$2000))*(Anforderungen!$K$7:$K$2000="erfüllt")) -> 0 | F38: =SUMPRODUCT(ISNUMBER(SEARCH($A38,Anforderungen!$J$7:$J$2000))*(Anforderungen!$K$7:$K$2000="trifft nicht zu")) -> 1 | G38: =IFERROR(E38/(B38-F38),0) -> 0
A39: Authentifizierungskomponente | B39: =SUMPRODUCT(ISNUMBER(SEARCH($A39,Anforderungen!$J$7:$J$2000))*(Anforderungen!$B$7:$B$2000<>"")) -> 66 | C39: =SUMPRODUCT(ISNUMBER(SEARCH($A39,Anforderungen!$J$7:$J$2000))*(Anforderungen!$K$7:$K$2000="erfasst")) -> 64 | D39: =SUMPRODUCT(ISNUMBER(SEARCH($A39,Anforderungen!$J$7:$J$2000))*(Anforderungen!$K$7:$K$2000="bewertet")) -> 0 | E39: =SUMPRODUCT(ISNUMBER(SEARCH($A39,Anforderungen!$J$7:$J$2000))*(Anforderungen!$K$7:$K$2000="erfüllt")) -> 2 | F39: =SUMPRODUCT(ISNUMBER(SEARCH($A39,Anforderungen!$J$7:$J$2000))*(Anforderungen!$K$7:$K$2000="trifft nicht zu")) -> 0 | G39: =IFERROR(E39/(B39-F39),0) -> 0.03030303
A40: Monitoring | B40: =SUMPRODUCT(ISNUMBER(SEARCH($A40,Anforderungen!$J$7:$J$2000))*(Anforderungen!$B$7:$B$2000<>"")) -> 44 | C40: =SUMPRODUCT(ISNUMBER(SEARCH($A40,Anforderungen!$J$7:$J$2000))*(Anforderungen!$K$7:$K$2000="erfasst")) -> 44 | D40: =SUMPRODUCT(ISNUMBER(SEARCH($A40,Anforderungen!$J$7:$J$2000))*(Anforderungen!$K$7:$K$2000="bewertet")) -> 0 | E40: =SUMPRODUCT(ISNUMBER(SEARCH($A40,Anforderungen!$J$7:$J$2000))*(Anforderungen!$K$7:$K$2000="erfüllt")) -> 0 | F40: =SUMPRODUCT(ISNUMBER(SEARCH($A40,Anforderungen!$J$7:$J$2000))*(Anforderungen!$K$7:$K$2000="trifft nicht zu")) -> 0 | G40: =IFERROR(E40/(B40-F40),0) -> 0
A41: OCPI Buchungskalender | B41: =SUMPRODUCT(ISNUMBER(SEARCH($A41,Anforderungen!$J$7:$J$2000))*(Anforderungen!$B$7:$B$2000<>"")) -> 102 | C41: =SUMPRODUCT(ISNUMBER(SEARCH($A41,Anforderungen!$J$7:$J$2000))*(Anforderungen!$K$7:$K$2000="erfasst")) -> 101 | D41: =SUMPRODUCT(ISNUMBER(SEARCH($A41,Anforderungen!$J$7:$J$2000))*(Anforderungen!$K$7:$K$2000="bewertet")) -> 0 | E41: =SUMPRODUCT(ISNUMBER(SEARCH($A41,Anforderungen!$J$7:$J$2000))*(Anforderungen!$K$7:$K$2000="erfüllt")) -> 1 | F41: =SUMPRODUCT(ISNUMBER(SEARCH($A41,Anforderungen!$J$7:$J$2000))*(Anforderungen!$K$7:$K$2000="trifft nicht zu")) -> 0 | G41: =IFERROR(E41/(B41-F41),0) -> 0.0098039216
A42: Anbindung | B42: =SUMPRODUCT(ISNUMBER(SEARCH($A42,Anforderungen!$J$7:$J$2000))*(Anforderungen!$B$7:$B$2000<>"")) -> 3 | C42: =SUMPRODUCT(ISNUMBER(SEARCH($A42,Anforderungen!$J$7:$J$2000))*(Anforderungen!$K$7:$K$2000="erfasst")) -> 2 | D42: =SUMPRODUCT(ISNUMBER(SEARCH($A42,Anforderungen!$J$7:$J$2000))*(Anforderungen!$K$7:$K$2000="bewertet")) -> 1 | E42: =SUMPRODUCT(ISNUMBER(SEARCH($A42,Anforderungen!$J$7:$J$2000))*(Anforderungen!$K$7:$K$2000="erfüllt")) -> 0 | F42: =SUMPRODUCT(ISNUMBER(SEARCH($A42,Anforderungen!$J$7:$J$2000))*(Anforderungen!$K$7:$K$2000="trifft nicht zu")) -> 0 | G42: =IFERROR(E42/(B42-F42),0) -> 0
A43: Reservierungsplattform | B43: =SUMPRODUCT(ISNUMBER(SEARCH($A43,Anforderungen!$J$7:$J$2000))*(Anforderungen!$B$7:$B$2000<>"")) -> 12 | C43: =SUMPRODUCT(ISNUMBER(SEARCH($A43,Anforderungen!$J$7:$J$2000))*(Anforderungen!$K$7:$K$2000="erfasst")) -> 12 | D43: =SUMPRODUCT(ISNUMBER(SEARCH($A43,Anforderungen!$J$7:$J$2000))*(Anforderungen!$K$7:$K$2000="bewertet")) -> 0 | E43: =SUMPRODUCT(ISNUMBER(SEARCH($A43,Anforderungen!$J$7:$J$2000))*(Anforderungen!$K$7:$K$2000="erfüllt")) -> 0 | F43: =SUMPRODUCT(ISNUMBER(SEARCH($A43,Anforderungen!$J$7:$J$2000))*(Anforderungen!$K$7:$K$2000="trifft nicht zu")) -> 0 | G43: =IFERROR(E43/(B43-F43),0) -> 0
A44: Belegungsdetektion | B44: =SUMPRODUCT(ISNUMBER(SEARCH($A44,Anforderungen!$J$7:$J$2000))*(Anforderungen!$B$7:$B$2000<>"")) -> 5 | C44: =SUMPRODUCT(ISNUMBER(SEARCH($A44,Anforderungen!$J$7:$J$2000))*(Anforderungen!$K$7:$K$2000="erfasst")) -> 4 | D44: =SUMPRODUCT(ISNUMBER(SEARCH($A44,Anforderungen!$J$7:$J$2000))*(Anforderungen!$K$7:$K$2000="bewertet")) -> 0 | E44: =SUMPRODUCT(ISNUMBER(SEARCH($A44,Anforderungen!$J$7:$J$2000))*(Anforderungen!$K$7:$K$2000="erfüllt")) -> 1 | F44: =SUMPRODUCT(ISNUMBER(SEARCH($A44,Anforderungen!$J$7:$J$2000))*(Anforderungen!$K$7:$K$2000="trifft nicht zu")) -> 0 | G44: =IFERROR(E44/(B44-F44),0) -> 0.2
A45: Dynamische Anzeige | B45: =SUMPRODUCT(ISNUMBER(SEARCH($A45,Anforderungen!$J$7:$J$2000))*(Anforderungen!$B$7:$B$2000<>"")) -> 12 | C45: =SUMPRODUCT(ISNUMBER(SEARCH($A45,Anforderungen!$J$7:$J$2000))*(Anforderungen!$K$7:$K$2000="erfasst")) -> 10 | D45: =SUMPRODUCT(ISNUMBER(SEARCH($A45,Anforderungen!$J$7:$J$2000))*(Anforderungen!$K$7:$K$2000="bewertet")) -> 0 | E45: =SUMPRODUCT(ISNUMBER(SEARCH($A45,Anforderungen!$J$7:$J$2000))*(Anforderungen!$K$7:$K$2000="erfüllt")) -> 2 | F45: =SUMPRODUCT(ISNUMBER(SEARCH($A45,Anforderungen!$J$7:$J$2000))*(Anforderungen!$K$7:$K$2000="trifft nicht zu")) -> 0 | G45: =IFERROR(E45/(B45-F45),0) -> 0.16666667
A46: Kennzeichenerfassung | B46: =SUMPRODUCT(ISNUMBER(SEARCH($A46,Anforderungen!$J$7:$J$2000))*(Anforderungen!$B$7:$B$2000<>"")) -> 8 | C46: =SUMPRODUCT(ISNUMBER(SEARCH($A46,Anforderungen!$J$7:$J$2000))*(Anforderungen!$K$7:$K$2000="erfasst")) -> 8 | D46: =SUMPRODUCT(ISNUMBER(SEARCH($A46,Anforderungen!$J$7:$J$2000))*(Anforderungen!$K$7:$K$2000="bewertet")) -> 0 | E46: =SUMPRODUCT(ISNUMBER(SEARCH($A46,Anforderungen!$J$7:$J$2000))*(Anforderungen!$K$7:$K$2000="erfüllt")) -> 0 | F46: =SUMPRODUCT(ISNUMBER(SEARCH($A46,Anforderungen!$J$7:$J$2000))*(Anforderungen!$K$7:$K$2000="trifft nicht zu")) -> 0 | G46: =IFERROR(E46/(B46-F46),0) -> 0
A47: Pönalisierungssystem | B47: =SUMPRODUCT(ISNUMBER(SEARCH($A47,Anforderungen!$J$7:$J$2000))*(Anforderungen!$B$7:$B$2000<>"")) -> 35 | C47: =SUMPRODUCT(ISNUMBER(SEARCH($A47,Anforderungen!$J$7:$J$2000))*(Anforderungen!$K$7:$K$2000="erfasst")) -> 35 | D47: =SUMPRODUCT(ISNUMBER(SEARCH($A47,Anforderungen!$J$7:$J$2000))*(Anforderungen!$K$7:$K$2000="bewertet")) -> 0 | E47: =SUMPRODUCT(ISNUMBER(SEARCH($A47,Anforderungen!$J$7:$J$2000))*(Anforderungen!$K$7:$K$2000="erfüllt")) -> 0 | F47: =SUMPRODUCT(ISNUMBER(SEARCH($A47,Anforderungen!$J$7:$J$2000))*(Anforderungen!$K$7:$K$2000="trifft nicht zu")) -> 0 | G47: =IFERROR(E47/(B47-F47),0) -> 0
...

Sheet Komponenten
A1: Komponenten & Schnittstellen
A2: Struktur Vergabeeinheit → Partner → Art → Komponente. Anzahl und Status der Anforderungen werden automatisch aus dem Register „Anforderungen“ abgeleitet.
A3: Statuslogik: erfasst hat Vorrang vor bewertet; erst wenn keine offenen Vorstufen mehr vorhanden sind, wird erfüllt bzw. trifft nicht zu angezeigt. Nur die Felder Vergabeeinheit, Partner, Art, Komponente und Bemerkung werden gepflegt – alles Übrige rechnet sich selbst.
A5: Vergabeeinheit | B5: Partner | C5: Art | D5: Komponente | E5: Anforderungen | F5: erfasst | G5: bewertet | H5: erfüllt | I5: trifft nicht zu | J5: Status | K5: Bemerkung / Schnittstelle | N5: Partner
A6: LIS | B6: Alpitronic | C6: Komponente | D6: Ladeeinrichtung | E6: =IF($D6="","",SUMPRODUCT(ISNUMBER(SEARCH($D6,Anforderungen!$J$7:$J$2000))*(Anforderungen!$B$7:$B$2000<>""))) -> 171 | F6: =IF($D6="","",SUMPRODUCT(ISNUMBER(SEARCH($D6,Anforderungen!$J$7:$J$2000))*(Anforderungen!$K$7:$K$2000="erfasst"))) -> 170 | G6: =IF($D6="","",SUMPRODUCT(ISNUMBER(SEARCH($D6,Anforderungen!$J$7:$J$2000))*(Anforderungen!$K$7:$K$2000="bewertet"))) -> 0 | H6: =IF($D6="","",SUMPRODUCT(ISNUMBER(SEARCH($D6,Anforderungen!$J$7:$J$2000))*(Anforderungen!$K$7:$K$2000="erfüllt"))) -> 0 | I6: =IF($D6="","",SUMPRODUCT(ISNUMBER(SEARCH($D6,Anforderungen!$J$7:$J$2000))*(Anforderungen!$K$7:$K$2000="trifft nicht zu"))) -> 1 | J6: =IF($D6="","",IF($E6=0,"keine Anforderungen",IF($F6>0,"erfasst",IF($G6>0,"bewertet",IF($H6>0,"erfüllt","trifft nicht zu"))))) -> erfasst | N6: Alpitronic
A7: WWL | B7: eRound | C7: Komponente | D7: Abrechnungskomponente | E7: =IF($D7="","",SUMPRODUCT(ISNUMBER(SEARCH($D7,Anforderungen!$J$7:$J$2000))*(Anforderungen!$B$7:$B$2000<>""))) -> 50 | F7: =IF($D7="","",SUMPRODUCT(ISNUMBER(SEARCH($D7,Anforderungen!$J$7:$J$2000))*(Anforderungen!$K$7:$K$2000="erfasst"))) -> 49 | G7: =IF($D7="","",SUMPRODUCT(ISNUMBER(SEARCH($D7,Anforderungen!$J$7:$J$2000))*(Anforderungen!$K$7:$K$2000="bewertet"))) -> 0 | H7: =IF($D7="","",SUMPRODUCT(ISNUMBER(SEARCH($D7,Anforderungen!$J$7:$J$2000))*(Anforderungen!$K$7:$K$2000="erfüllt"))) -> 0 | I7: =IF($D7="","",SUMPRODUCT(ISNUMBER(SEARCH($D7,Anforderungen!$J$7:$J$2000))*(Anforderungen!$K$7:$K$2000="trifft nicht zu"))) -> 1 | J7: =IF($D7="","",IF($E7=0,"keine Anforderungen",IF($F7>0,"erfasst",IF($G7>0,"bewertet",IF($H7>0,"erfüllt","trifft nicht zu"))))) -> erfasst | N7: eRound
A8: WWL | B8: eRound | C8: Komponente | D8: Authentifizierungskomponente | E8: =IF($D8="","",SUMPRODUCT(ISNUMBER(SEARCH($D8,Anforderungen!$J$7:$J$2000))*(Anforderungen!$B$7:$B$2000<>""))) -> 66 | F8: =IF($D8="","",SUMPRODUCT(ISNUMBER(SEARCH($D8,Anforderungen!$J$7:$J$2000))*(Anforderungen!$K$7:$K$2000="erfasst"))) -> 64 | G8: =IF($D8="","",SUMPRODUCT(ISNUMBER(SEARCH($D8,Anforderungen!$J$7:$J$2000))*(Anforderungen!$K$7:$K$2000="bewertet"))) -> 0 | H8: =IF($D8="","",SUMPRODUCT(ISNUMBER(SEARCH($D8,Anforderungen!$J$7:$J$2000))*(Anforderungen!$K$7:$K$2000="erfüllt"))) -> 2 | I8: =IF($D8="","",SUMPRODUCT(ISNUMBER(SEARCH($D8,Anforderungen!$J$7:$J$2000))*(Anforderungen!$K$7:$K$2000="trifft nicht zu"))) -> 0 | J8: =IF($D8="","",IF($E8=0,"keine Anforderungen",IF($F8>0,"erfasst",IF($G8>0,"bewertet",IF($H8>0,"erfüllt","trifft nicht zu"))))) -> erfasst | N8: Reservierungsplattform
A9: WWL | B9: eRound | C9: Komponente | D9: Monitoring | E9: =IF($D9="","",SUMPRODUCT(ISNUMBER(SEARCH($D9,Anforderungen!$J$7:$J$2000))*(Anforderungen!$B$7:$B$2000<>""))) -> 44 | F9: =IF($D9="","",SUMPRODUCT(ISNUMBER(SEARCH($D9,Anforderungen!$J$7:$J$2000))*(Anforderungen!$K$7:$K$2000="erfasst"))) -> 44 | G9: =IF($D9="","",SUMPRODUCT(ISNUMBER(SEARCH($D9,Anforderungen!$J$7:$J$2000))*(Anforderungen!$K$7:$K$2000="bewertet"))) -> 0 | H9: =IF($D9="","",SUMPRODUCT(ISNUMBER(SEARCH($D9,Anforderungen!$J$7:$J$2000))*(Anforderungen!$K$7:$K$2000="erfüllt"))) -> 0 | I9: =IF($D9="","",SUMPRODUCT(ISNUMBER(SEARCH($D9,Anforderungen!$J$7:$J$2000))*(Anforderungen!$K$7:$K$2000="trifft nicht zu"))) -> 0 | J9: =IF($D9="","",IF($E9=0,"keine Anforderungen",IF($F9>0,"erfasst",IF($G9>0,"bewertet",IF($H9>0,"erfüllt","trifft nicht zu"))))) -> erfasst | N9: SCS
A10: WWL | B10: eRound | C10: Komponente | D10: OCPI Buchungskalender | E10: =IF($D10="","",SUMPRODUCT(ISNUMBER(SEARCH($D10,Anforderungen!$J$7:$J$2000))*(Anforderungen!$B$7:$B$2000<>""))) -> 102 | F10: =IF($D10="","",SUMPRODUCT(ISNUMBER(SEARCH($D10,Anforderungen!$J$7:$J$2000))*(Anforderungen!$K$7:$K$2000="erfasst"))) -> 101 | G10: =IF($D10="","",SUMPRODUCT(ISNUMBER(SEARCH($D10,Anforderungen!$J$7:$J$2000))*(Anforderungen!$K$7:$K$2000="bewertet"))) -> 0 | H10: =IF($D10="","",SUMPRODUCT(ISNUMBER(SEARCH($D10,Anforderungen!$J$7:$J$2000))*(Anforderungen!$K$7:$K$2000="erfüllt"))) -> 1 | I10: =IF($D10="","",SUMPRODUCT(ISNUMBER(SEARCH($D10,Anforderungen!$J$7:$J$2000))*(Anforderungen!$K$7:$K$2000="trifft nicht zu"))) -> 0 | J10: =IF($D10="","",IF($E10=0,"keine Anforderungen",IF($F10>0,"erfasst",IF($G10>0,"bewertet",IF($H10>0,"erfüllt","trifft nicht zu"))))) -> erfasst | N10: Schrankenhersteller
A11: SmartInfra | B11: Reservierungsplattform | C11: Komponente | D11: Anbindung | E11: =IF($D11="","",SUMPRODUCT(ISNUMBER(SEARCH($D11,Anforderungen!$J$7:$J$2000))*(Anforderungen!$B$7:$B$2000<>""))) -> 3 | F11: =IF($D11="","",SUMPRODUCT(ISNUMBER(SEARCH($D11,Anforderungen!$J$7:$J$2000))*(Anforderungen!$K$7:$K$2000="erfasst"))) -> 2 | G11: =IF($D11="","",SUMPRODUCT(ISNUMBER(SEARCH($D11,Anforderungen!$J$7:$J$2000))*(Anforderungen!$K$7:$K$2000="bewertet"))) -> 1 | H11: =IF($D11="","",SUMPRODUCT(ISNUMBER(SEARCH($D11,Anforderungen!$J$7:$J$2000))*(Anforderungen!$K$7:$K$2000="erfüllt"))) -> 0 | I11: =IF($D11="","",SUMPRODUCT(ISNUMBER(SEARCH($D11,Anforderungen!$J$7:$J$2000))*(Anforderungen!$K$7:$K$2000="trifft nicht zu"))) -> 0 | J11: =IF($D11="","",IF($E11=0,"keine Anforderungen",IF($F11>0,"erfasst",IF($G11>0,"bewertet",IF($H11>0,"erfüllt","trifft nicht zu"))))) -> erfasst | N11: WWL
A12: SmartInfra | B12: Reservierungsplattform | C12: Komponente | D12: Reservierungsplattform | E12: =IF($D12="","",SUMPRODUCT(ISNUMBER(SEARCH($D12,Anforderungen!$J$7:$J$2000))*(Anforderungen!$B$7:$B$2000<>""))) -> 12 | F12: =IF($D12="","",SUMPRODUCT(ISNUMBER(SEARCH($D12,Anforderungen!$J$7:$J$2000))*(Anforderungen!$K$7:$K$2000="erfasst"))) -> 12 | G12: =IF($D12="","",SUMPRODUCT(ISNUMBER(SEARCH($D12,Anforderungen!$J$7:$J$2000))*(Anforderungen!$K$7:$K$2000="bewertet"))) -> 0 | H12: =IF($D12="","",SUMPRODUCT(ISNUMBER(SEARCH($D12,Anforderungen!$J$7:$J$2000))*(Anforderungen!$K$7:$K$2000="erfüllt"))) -> 0 | I12: =IF($D12="","",SUMPRODUCT(ISNUMBER(SEARCH($D12,Anforderungen!$J$7:$J$2000))*(Anforderungen!$K$7:$K$2000="trifft nicht zu"))) -> 0 | J12: =IF($D12="","",IF($E12=0,"keine Anforderungen",IF($F12>0,"erfasst",IF($G12>0,"bewertet",IF($H12>0,"erfüllt","trifft nicht zu"))))) -> erfasst | N12: Autostrom+
A13: SmartInfra | B13: SCS | C13: Komponente | D13: Belegungsdetektion | E13: =IF($D13="","",SUMPRODUCT(ISNUMBER(SEARCH($D13,Anforderungen!$J$7:$J$2000))*(Anforderungen!$B$7:$B$2000<>""))) -> 5 | F13: =IF($D13="","",SUMPRODUCT(ISNUMBER(SEARCH($D13,Anforderungen!$J$7:$J$2000))*(Anforderungen!$K$7:$K$2000="erfasst"))) -> 4 | G13: =IF($D13="","",SUMPRODUCT(ISNUMBER(SEARCH($D13,Anforderungen!$J$7:$J$2000))*(Anforderungen!$K$7:$K$2000="bewertet"))) -> 0 | H13: =IF($D13="","",SUMPRODUCT(ISNUMBER(SEARCH($D13,Anforderungen!$J$7:$J$2000))*(Anforderungen!$K$7:$K$2000="erfüllt"))) -> 1 | I13: =IF($D13="","",SUMPRODUCT(ISNUMBER(SEARCH($D13,Anforderungen!$J$7:$J$2000))*(Anforderungen!$K$7:$K$2000="trifft nicht zu"))) -> 0 | J13: =IF($D13="","",IF($E13=0,"keine Anforderungen",IF($F13>0,"erfasst",IF($G13>0,"bewertet",IF($H13>0,"erfüllt","trifft nicht zu"))))) -> erfasst | N13: eRound / SCS
A14: SmartInfra | B14: SCS | C14: Komponente | D14: Dynamische Anzeige | E14: =IF($D14="","",SUMPRODUCT(ISNUMBER(SEARCH($D14,Anforderungen!$J$7:$J$2000))*(Anforderungen!$B$7:$B$2000<>""))) -> 12 | F14: =IF($D14="","",SUMPRODUCT(ISNUMBER(SEARCH($D14,Anforderungen!$J$7:$J$2000))*(Anforderungen!$K$7:$K$2000="erfasst"))) -> 10 | G14: =IF($D14="","",SUMPRODUCT(ISNUMBER(SEARCH($D14,Anforderungen!$J$7:$J$2000))*(Anforderungen!$K$7:$K$2000="bewertet"))) -> 0 | H14: =IF($D14="","",SUMPRODUCT(ISNUMBER(SEARCH($D14,Anforderungen!$J$7:$J$2000))*(Anforderungen!$K$7:$K$2000="erfüllt"))) -> 2 | I14: =IF($D14="","",SUMPRODUCT(ISNUMBER(SEARCH($D14,Anforderungen!$J$7:$J$2000))*(Anforderungen!$K$7:$K$2000="trifft nicht zu"))) -> 0 | J14: =IF($D14="","",IF($E14=0,"keine Anforderungen",IF($F14>0,"erfasst",IF($G14>0,"bewertet",IF($H14>0,"erfüllt","trifft nicht zu"))))) -> erfasst | N14: Schrankenhersteller / SCS
A15: SmartInfra | B15: SCS | C15: Komponente | D15: Kennzeichenerfassung | E15: =IF($D15="","",SUMPRODUCT(ISNUMBER(SEARCH($D15,Anforderungen!$J$7:$J$2000))*(Anforderungen!$B$7:$B$2000<>""))) -> 8 | F15: =IF($D15="","",SUMPRODUCT(ISNUMBER(SEARCH($D15,Anforderungen!$J$7:$J$2000))*(Anforderungen!$K$7:$K$2000="erfasst"))) -> 8 | G15: =IF($D15="","",SUMPRODUCT(ISNUMBER(SEARCH($D15,Anforderungen!$J$7:$J$2000))*(Anforderungen!$K$7:$K$2000="bewertet"))) -> 0 | H15: =IF($D15="","",SUMPRODUCT(ISNUMBER(SEARCH($D15,Anforderungen!$J$7:$J$2000))*(Anforderungen!$K$7:$K$2000="erfüllt"))) -> 0 | I15: =IF($D15="","",SUMPRODUCT(ISNUMBER(SEARCH($D15,Anforderungen!$J$7:$J$2000))*(Anforderungen!$K$7:$K$2000="trifft nicht zu"))) -> 0 | J15: =IF($D15="","",IF($E15=0,"keine Anforderungen",IF($F15>0,"erfasst",IF($G15>0,"bewertet",IF($H15>0,"erfüllt","trifft nicht zu"))))) -> erfasst | N15: Schrankenhersteller / SCS / eRound
A16: SmartInfra | B16: SCS | C16: Komponente | D16: Pönalisierungssystem | E16: =IF($D16="","",SUMPRODUCT(ISNUMBER(SEARCH($D16,Anforderungen!$J$7:$J$2000))*(Anforderungen!$B$7:$B$2000<>""))) -> 35 | F16: =IF($D16="","",SUMPRODUCT(ISNUMBER(SEARCH($D16,Anforderungen!$J$7:$J$2000))*(Anforderungen!$K$7:$K$2000="erfasst"))) -> 35 | G16: =IF($D16="","",SUMPRODUCT(ISNUMBER(SEARCH($D16,Anforderungen!$J$7:$J$2000))*(Anforderungen!$K$7:$K$2000="bewertet"))) -> 0 | H16: =IF($D16="","",SUMPRODUCT(ISNUMBER(SEARCH($D16,Anforderungen!$J$7:$J$2000))*(Anforderungen!$K$7:$K$2000="erfüllt"))) -> 0 | I16: =IF($D16="","",SUMPRODUCT(ISNUMBER(SEARCH($D16,Anforderungen!$J$7:$J$2000))*(Anforderungen!$K$7:$K$2000="trifft nicht zu"))) -> 0 | J16: =IF($D16="","",IF($E16=0,"keine Anforderungen",IF($F16>0,"erfasst",IF($G16>0,"bewertet",IF($H16>0,"erfüllt","trifft nicht zu"))))) -> erfasst
A17: SmartInfra | B17: SCS | C17: Komponente | D17: Schrankensteuerung | E17: =IF($D17="","",SUMPRODUCT(ISNUMBER(SEARCH($D17,Anforderungen!$J$7:$J$2000))*(Anforderungen!$B$7:$B$2000<>""))) -> 25 | F17: =IF($D17="","",SUMPRODUCT(ISNUMBER(SEARCH($D17,Anforderungen!$J$7:$J$2000))*(Anforderungen!$K$7:$K$2000="erfasst"))) -> 21 | G17: =IF($D17="","",SUMPRODUCT(ISNUMBER(SEARCH($D17,Anforderungen!$J$7:$J$2000))*(Anforderungen!$K$7:$K$2000="bewertet"))) -> 0 | H17: =IF($D17="","",SUMPRODUCT(ISNUMBER(SEARCH($D17,Anforderungen!$J$7:$J$2000))*(Anforderungen!$K$7:$K$2000="erfüllt"))) -> 4 | I17: =IF($D17="","",SUMPRODUCT(ISNUMBER(SEARCH($D17,Anforderungen!$J$7:$J$2000))*(Anforderungen!$K$7:$K$2000="trifft nicht zu"))) -> 0 | J17: =IF($D17="","",IF($E17=0,"keine Anforderungen",IF($F17>0,"erfasst",IF($G17>0,"bewertet",IF($H17>0,"erfüllt","trifft nicht zu"))))) -> erfasst
A18: AUP | B18: tbd | C18: Komponente | D18: Beschilderung | E18: =IF($D18="","",SUMPRODUCT(ISNUMBER(SEARCH($D18,Anforderungen!$J$7:$J$2000))*(Anforderungen!$B$7:$B$2000<>""))) -> 11 | F18: =IF($D18="","",SUMPRODUCT(ISNUMBER(SEARCH($D18,Anforderungen!$J$7:$J$2000))*(Anforderungen!$K$7:$K$2000="erfasst"))) -> 10 | G18: =IF($D18="","",SUMPRODUCT(ISNUMBER(SEARCH($D18,Anforderungen!$J$7:$J$2000))*(Anforderungen!$K$7:$K$2000="bewertet"))) -> 0 | H18: =IF($D18="","",SUMPRODUCT(ISNUMBER(SEARCH($D18,Anforderungen!$J$7:$J$2000))*(Anforderungen!$K$7:$K$2000="erfüllt"))) -> 0 | I18: =IF($D18="","",SUMPRODUCT(ISNUMBER(SEARCH($D18,Anforderungen!$J$7:$J$2000))*(Anforderungen!$K$7:$K$2000="trifft nicht zu"))) -> 1 | J18: =IF($D18="","",IF($E18=0,"keine Anforderungen",IF($F18>0,"erfasst",IF($G18>0,"bewertet",IF($H18>0,"erfüllt","trifft nicht zu"))))) -> erfasst
A19: SmartInfra | B19: CAME | C19: Komponente | D19: Schrankenanlage | E19: =IF($D19="","",SUMPRODUCT(ISNUMBER(SEARCH($D19,Anforderungen!$J$7:$J$2000))*(Anforderungen!$B$7:$B$2000<>""))) -> 23 | F19: =IF($D19="","",SUMPRODUCT(ISNUMBER(SEARCH($D19,Anforderungen!$J$7:$J$2000))*(Anforderungen!$K$7:$K$2000="erfasst"))) -> 21 | G19: =IF($D19="","",SUMPRODUCT(ISNUMBER(SEARCH($D19,Anforderungen!$J$7:$J$2000))*(Anforderungen!$K$7:$K$2000="bewertet"))) -> 0 | H19: =IF($D19="","",SUMPRODUCT(ISNUMBER(SEARCH($D19,Anforderungen!$J$7:$J$2000))*(Anforderungen!$K$7:$K$2000="erfüllt"))) -> 2 | I19: =IF($D19="","",SUMPRODUCT(ISNUMBER(SEARCH($D19,Anforderungen!$J$7:$J$2000))*(Anforderungen!$K$7:$K$2000="trifft nicht zu"))) -> 0 | J19: =IF($D19="","",IF($E19=0,"keine Anforderungen",IF($F19>0,"erfasst",IF($G19>0,"bewertet",IF($H19>0,"erfüllt","trifft nicht zu"))))) -> erfasst
